Workbook
Name BERLAKU: #REF!
Name BERLAKU: #REF!
Name H: #REF!

Sheet Home
A1: HOME
B2: SISTEM | H2: ALAT BANTU PENGHITUNGAN ANGKA PDRB MENURUT LAPANGAN USAHA
B3: INFORMASI
B4: RILIS
B5: ANGKA PDRB | K5: LAPANGAN USAHA | O5: : | P5: =mid(ADHB!C5,3,9)&" "&mid(ADHB!C7,3,100) -> Pertanian Tanaman Pangan
B6: MELALUI LEMBAR KERJA | K6: WILAYAH | O6: : | P6: Provinsi Sulawesi Tenggara
B7: BERBASIS | K7: TAHUN | O7: : | P7: =IFERROR(__xludf.DUMMYFUNCTION("IMPORTRANGE(""https://docs.google.com/spreadsheets/d/14EziMEzuXiAhzZqRuQw8kN9sLyynoE6QsPgaj062Fa0/edit#gid=214337323"",""'LK PDRB Lapus'!E3:E4"")"),2026.0) -> 2026
B8: ONLINE | K8: TRIWULAN | O8: : | P8: =IFERROR(__xludf.DUMMYFUNCTION("""COMPUTED_VALUE"""),"I") -> I
B11: INPUT DATA | K11: OUTPUT | T11: MONEV
B15: 1 | C15: Lembar Kerja Penghitungan PDRB Atas Dasar Harga Berlaku | K15: 1 | L15: Rekap Angka PDRB Lapangan Usaha | T15: 1 | U15: MONEV Pemasukan Data
B16: =B15+1 -> 2 | C16: Lembar Kerja Penghitungan PDRB Atas Dasar Harga Konstan | K16: =K15+1 -> 2 | T16: =T15+1 -> 2

Sheet Produksi dan Harga
A1: Home | B1: PRODUKSI PADI DAN PALAWIJA Sulawesi Tenggara | CE1: =sum(CE7:CE11)/sum(BZ7:BZ11)*100-100 -> -8.1692569 | CF1: =CE5/BZ5*100-100 -> -9.9184949 | CG1: =CE6/BZ6*100-100 -> -36.609168
B2: Komoditas | C2: 2010 (ATAP) | H2: 2011 (ATAP) | M2: 2012 (ATAP) | R2: 2013 (ATAP) | W2: 2014 (ATAP) | AB2: 2015 (ATAP) | AG2: 2016 (PPD Luas Panen Des) | AL2: 2017 | AQ2: 2018 | AV2: 2019 | BA2: 2020 | BF2: 2021 | BK2: 2022 | BP2: 2023 | BU2: 2024 | BZ2: 2025 | CE2: 2026 | CJ2: 2027
C3: triw.1 | D3: triw.2 | E3: triw.3 | F3: triw.4 | G3: Total | H3: triw.1 | I3: triw.2 | J3: triw.3 | K3: triw.4 | L3: Total | M3: triw.1 | N3: triw.2 | O3: triw.3 | P3: triw.4 | Q3: Total | R3: triw.1 | S3: triw.2 | T3: triw.3 | U3: triw.4 | V3: Total | W3: triw.1 | X3: triw.2 | Y3: triw.3 | Z3: triw.4 | AA3: Total | AB3: triw.1 | AC3: triw.2 | AD3: triw.3 | AE3: triw.4 | AF3: Total | AG3: triw.1 | AH3: triw.2 | AI3: triw.3 | AJ3: triw.4 | AK3: Total | AL3: triw.1 | AM3: triw.2 | AN3: triw.3 | AO3: triw.4 | AP3: Total | AQ3: triw.1 | AR3: triw.2 | AS3: triw.3 | AT3: triw.4 | AU3: Total | AV3: triw.1 | AW3: triw.2 | AX3: triw.3 | AY3: triw.4 | AZ3: Total | BA3: triw.1 | BB3: triw.2 | BC3: triw.3 | BD3: triw.4 | BE3: Total | BF3: triw.1 | BG3: triw.2 | BH3: triw.3 | BI3: triw.4 | BJ3: Total | BK3: triw.1 | BL3: triw.2 | BM3: triw.3 | BN3: triw.4 | BO3: Total | BP3: triw.1 | BQ3: triw.2 | BR3: triw.3 | BS3: triw.4 | BT3: Total | BU3: triw.1 | BV3: triw.2 | BW3: triw.3 | BX3: triw.4 | BY3: Total | BZ3: triw.1 | CA3: triw.2 | CB3: triw.3 | CC3: triw.4 | CD3: Total | CE3: triw.1 | CF3: triw.2 | CG3: triw.3 | CH3: triw.4 | CI3: Total | CJ3: triw.1 | CK3: triw.2 | CL3: triw.3 | CM3: triw.4 | CN3: Total
B4: -1 | C4: -10 | D4: -11 | E4: -12 | F4: -13 | G4: -14 | H4: -15 | I4: -16 | J4: -17 | K4: -18 | L4: -19 | M4: -20 | N4: -21 | O4: -22 | P4: -23 | Q4: -24 | R4: -25 | S4: -26 | T4: -27 | U4: -28 | V4: -29 | W4: -30 | X4: -31 | Y4: -32 | Z4: -33 | AA4: -34 | AB4: -35 | AC4: -36 | AD4: -37 | AE4: -38 | AF4: -39 | AG4: -40 | AH4: -41 | AI4: -42 | AJ4: -43 | AK4: -44 | AL4: -45 | AM4: -46 | AN4: -47 | AO4: -48 | AP4: -49 | AQ4: -50 | AR4: -51 | AS4: -52 | AT4: -53 | AU4: -54 | AV4: -55 | AW4: -56 | AX4: -57 | AY4: -58 | AZ4: -59 | BA4: -60 | BB4: -61 | BC4: -62 | BD4: -63 | BE4: -64 | BF4: -65 | BG4: -66 | BH4: -67 | BI4: -68 | BJ4: -69 | BK4: -65 | BL4: -66 | BM4: -67 | BN4: -68 | BO4: -69 | BP4: -65 | BQ4: -66 | BR4: -67 | BS4: -68 | BT4: -69 | BU4: -70 | BV4: -71 | BW4: -72 | BX4: -73 | BY4: -74 | BZ4: -75 | CA4: -76 | CB4: -77 | CC4: -78 | CD4: -79 | CE4: -75 | CF4: -76 | CG4: -77 | CH4: -78 | CI4: -79 | CJ4: -75 | CK4: -76 | CL4: -77 | CM4: -78 | CN4: -79
B5: Padi | C5: 31335 | D5: 176966 | E5: 125255 | F5: 121088 | G5: 454644 | H5: 82863 | I5: 162059 | J5: 121411 | K5: 125234 | L5: 491567 | M5: 77915 | N5: 186829 | O5: 132843 | P5: 118704 | Q5: 516291 | R5: 103437 | S5: 216142 | T5: 98738 | U5: 143044 | V5: 561361 | W5: 136549 | X5: 206959 | Y5: 183311 | Z5: 130798 | AA5: 657617 | AB5: 79720 | AC5: 256936 | AD5: 178940 | AE5: 145124 | AF5: 660720 | AG5: 58408 | AH5: 260888 | AI5: 138448 | AJ5: 237585 | AK5: 695329 | AL5: 83634 | AM5: 241329 | AN5: 141362 | AO5: 245076 | AP5: 711401 | AQ5: 99781.5 | AR5: 164109.1 | AS5: 116509.5 | AT5: 158476.1 | AU5: =SUM(AQ5:AT5) -> 538876.2 | AV5: 70489.5 | AW5: 182707.5 | AX5: 96714.1 | AY5: 169795.8 | AZ5: =SUM(AV5:AY5) -> 519706.9 | BA5: 55718.12 | BB5: 170258.17 | BC5: 103885.19 | BD5: 202912.01 | BE5: =SUM(BA5:BD5) -> 532773.49 | BF5: 55836 | BG5: 206451 | BH5: 79675 | BI5: 188066 | BJ5: =SUM(BF5:BI5) -> 530028 | BK5: 58297.77 | BL5: 179912.58 | BM5: 83404.77 | BN5: 157342.91 | BO5: =SUM(BK5:BN5) -> 478958.03 | BP5: 84612 | BQ5: 152272 | BR5: 114579 | BS5: 127944 | BT5: =SUM(BP5:BS5) -> 479407 | BU5: 60961.21 | BV5: 192874.86 | BW5: 125113.65 | BX5: 172745.33 | BY5: =SUM(BU5:BX5) -> 551695.05 | BZ5: 93185.61 | CA5: 237001.82 | CB5: 140977.19 | CC5: 209655.58 | CD5: =SUM(BZ5:CC5) -> 680820.2 | CE5: 83943 | CI5: =SUM(CE5:CH5) -> 83943 | CN5: =SUM(CJ5:CM5) -> 0
B6: Jagung | C6: 40409 | D6: 16838 | E6: 12821 | F6: 4772 | G6: 74840 | H6: 23521 | I6: 27023 | J6: 13916 | K6: 3537 | L6: 67997 | M6: 41584 | N6: 18711 | O6: 14357 | P6: 3795 | Q6: 78447 | R6: 39135 | S6: 13145 | T6: 13240 | U6: 2058 | V6: 67578 | W6: 37444 | X6: 9110 | Y6: 11746 | Z6: 2300 | AA6: 60600 | AB6: 31691 | AC6: 14166 | AD6: 16923 | AE6: 5361 | AF6: 68141 | AG6: 42393 | AH6: 27404 | AI6: 14888 | AJ6: 5405 | AK6: 90090 | AL6: 55837 | AM6: 40604 | AN6: 21562 | AO6: 54075 | AP6: 172078 | AQ6: 80123 | AR6: 49935 | AS6: 46541 | AT6: 42039 | AU6: =SUM(AQ6:AT6) -> 218638 | AV6: 86256.8 | AW6: 96678.1 | AX6: 48633.4 | AY6: 52882.2 | AZ6: =SUM(AV6:AY6) -> 284450.5 | BA6: 44148 | BB6: 49015 | BC6: 34757 | BD6: 30114 | BE6: =SUM(BA6:BD6) -> 158034 | BF6: 51638 | BG6: 32851 | BH6: 33050 | BI6: 33022 | BJ6: =SUM(BF6:BI6) -> 150561 | BK6: 55811 | BL6: 37005 | BM6: 17617 | BN6: 10681.65 | BO6: =SUM(BK6:BN6) -> 121114.65 | BP6: 21003 | BQ6: 17366 | BR6: 15337 | BS6: 15806 | BT6: =SUM(BP6:BS6) -> 69512 | BU6: 32353.41 | BV6: 38110.49 | BW6: 30655.56 | BX6: 23877.28 | BY6: =SUM(BU6:BX6) -> 124996.74 | BZ6: 35837.99 | CA6: 15538.93 | CB6: 16205.92 | CC6: 17077.59 | CD6: =SUM(BZ6:CC6) -> 84660.43 | CE6: 22718 | CI6: =SUM(CE6:CH6) -> 22718 | CN6: =SUM(CJ6:CM6) -> 0
B7: Ubi Kayu | C7: 38628 | D7: 37883 | E7: 47222 | F7: 39617 | G7: 163350 | H7: 36621 | I7: 34279 | J7: 53530 | K7: 40420 | L7: 164850 | M7: 32322 | N7: 39374 | O7: 56658 | P7: 47365 | Q7: 175719 | R7: 36532 | S7: 39124 | T7: 56616 | U7: 48408 | V7: 180680 | W7: 30649 | X7: 36268 | Y7: 64255 | Z7: 43914 | AA7: 175086 | AB7: 33774 | AC7: 41852 | AD7: 61011 | AE7: 38458 | AF7: 175095 | AG7: 22062 | AH7: 27661 | AI7: 53586 | AJ7: 58209 | AK7: 161518 | AL7: 59967 | AM7: 56023 | AN7: 63857 | AO7: 63054 | AP7: 242901 | AQ7: 47507 | AR7: 35829 | AS7: 55336 | AT7: 76658 | AU7: =SUM(AQ7:AT7) -> 215330 | AV7: 29489.7 | AW7: 32513.4 | AX7: 51597.1 | AY7: 35577.8 | AZ7: =SUM(AV7:AY7) -> 149178 | BA7: 22110 | BB7: 36493 | BC7: 59633 | BD7: 39006 | BE7: =SUM(BA7:BD7) -> 157242 | BF7: 31896 | BG7: 32473 | BH7: 37274 | BI7: 35059 | BJ7: =SUM(BF7:BI7) -> 136702 | BK7: 30979 | BL7: 24186 | BM7: 33609 | BN7: 32661.84 | BO7: =SUM(BK7:BN7) -> 121435.84 | BP7: 24004 | BQ7: 27117 | BR7: 32592 | BS7: 28549 | BT7: =SUM(BP7:BS7) -> 112262 | BU7: 22853.457 | BV7: 25288.86 | BW7: 37069.48 | BX7: 27239.176 | BY7: =SUM(BU7:BX7) -> 112450.97 | BZ7: 22734.893 | CA7: 18639.836 | CB7: 36997.79 | CC7: 29451.302 | CD7: =SUM(BZ7:CC7) -> 107823.82 | CE7: 20706.116 | CI7: =SUM(CE7:CH7) -> 20706.116 | CN7: =SUM(CJ7:CM7) -> 0
B8: Ubi Jalar | C8: 3108 | D8: 7557 | E8: 8236 | F8: 6403 | G8: 25304 | H8: 4399 | I8: 8007 | J8: 8036 | K8: 6034 | L8: 26476 | M8: 5299 | N8: 10663 | O8: 8637 | P8: 4812 | Q8: 29411 | R8: 3895 | S8: 5750 | T8: 8951 | U8: 5517 | V8: 24113 | W8: 5161 | X8: 5279 | Y8: 9476 | Z8: 4998 | AA8: 24914 | AB8: 4601 | AC8: 7298 | AD8: 9881 | AE8: 3960 | AF8: 25740 | AG8: 2025 | AH8: 5990 | AI8: 9447 | AJ8: 6513 | AK8: 23975 | AL8: 6057 | AM8: 5055 | AN8: 7505 | AO8: 6136 | AP8: 24753 | AQ8: 4210 | AR8: 5459 | AS8: 6763 | AT8: 3661 | AU8: =SUM(AQ8:AT8) -> 20093 | AV8: 3439.7 | AW8: 5462.4 | AX8: 5762.2 | AY8: 2963.2 | AZ8: =SUM(AV8:AY8) -> 17627.5 | BA8: 1239 | BB8: 4504 | BC8: 7123 | BD8: 4492 | BE8: =SUM(BA8:BD8) -> 17358 | BF8: 1925 | BG8: 4421 | BH8: 6073 | BI8: 3050 | BJ8: =SUM(BF8:BI8) -> 15469 | BK8: 2197 | BL8: 3140 | BM8: 4122 | BN8: 3094.21 | BO8: =SUM(BK8:BN8) -> 12553.21 | BP8: 2231 | BQ8: 3616 | BR8: 7421 | BS8: 6726 | BT8: =SUM(BP8:BS8) -> 19994 | BU8: 5377.9203 | BV8: 2690.5723 | BW8: 3319.5651 | BX8: 2491.1737 | BY8: =SUM(BU8:BX8) -> 13879.231 | BZ8: 2192.3961 | CA8: 2864.6668 | CB8: 2802.8372 | CC8: 1877.5071 | CD8: =SUM(BZ8:CC8) -> 9737.4072 | CE8: 2239.9569 | CI8: =SUM(CE8:CH8) -> 2239.9569 | CN8: =SUM(CJ8:CM8) -> 0
B9: Kacang Tanah | C9: 1683 | D9: 1134 | E9: 1523 | F9: 602 | G9: 4942 | H9: 1374 | I9: 1271 | J9: 1408 | K9: 487 | L9: 4540 | M9: 2069 | N9: 997 | O9: 1790 | P9: 343 | Q9: 5199 | R9: 2266 | S9: 1067 | T9: 1195 | U9: 414 | V9: 4942 | W9: 2701 | X9: 580 | Y9: 1083 | Z9: 288 | AA9: 4652 | AB9: 1935 | AC9: 526 | AD9: 813 | AE9: 197 | AF9: 3471 | AG9: 877 | AH9: 795 | AI9: 1005 | AJ9: 346 | AK9: 3023 | AL9: 1168 | AM9: 343 | AN9: 919 | AO9: 187 | AP9: 2617 | AQ9: 1030 | AR9: 321 | AS9: 436 | AT9: 163 | AU9: =SUM(AQ9:AT9) -> 1950 | AV9: 1577.7 | AW9: 629.2 | AX9: 759.2 | AY9: 311.7 | AZ9: =SUM(AV9:AY9) -> 3277.8 | BA9: 932 | BB9: 735 | BC9: 1449 | BD9: 286 | BE9: =SUM(BA9:BD9) -> 3402 | BF9: 1467 | BG9: 428 | BH9: 1113 | BI9: 97 | BJ9: =SUM(BF9:BI9) -> 3105 | BK9: 960 | BL9: 387 | BM9: 604 | BN9: 106.79 | BO9: =SUM(BK9:BN9) -> 2057.79 | BP9: 796 | BQ9: 468 | BR9: 493 | BS9: 210 | BT9: =SUM(BP9:BS9) -> 1967 | BU9: 1205.5425 | BV9: 309.37227 | BW9: 730.02755 | BX9: 230.88634 | BY9: =SUM(BU9:BX9) -> 2475.8286 | BZ9: 864.42407 | CA9: 332.30896 | CB9: 453.19892 | CC9: 195.65627 | CD9: =SUM(BZ9:CC9) -> 1845.5882 | CE9: 748.15303 | CI9: =SUM(CE9:CH9) -> 748.15303 | CN9: =SUM(CJ9:CM9) -> 0
B10: Kedelai | C10: 1382 | D10: 887 | E10: 822 | F10: 112 | G10: 3203 | H10: 371 | I10: 2352 | J10: 2449 | K10: 941 | L10: 6113 | M10: 1234 | N10: 834 | O10: 487 | P10: 1155 | Q10: 3710 | R10: 1299 | S10: 860 | T10: 557 | U10: 879 | V10: 3595 | W10: 1073 | X10: 492 | Y10: 1057 | Z10: 3069 | AA10: 5691 | AB10: 3198 | AC10: 1210 | AD10: 2763 | AE10: 5628 | AF10: 12799 | AG10: 5963 | AH10: 4789 | AI10: 1983 | AJ10: 3401 | AK10: 16136 | AL10: 2217 | AM10: 1026 | AN10: 450 | AO10: 362 | AP10: 4055 | AQ10: 1902 | AR10: 2692 | AS10: 730 | AT10: 3930 | AU10: =SUM(AQ10:AT10) -> 9254 | AV10: 856.6 | AW10: 261.1 | AX10: 115 | AY10: 260.7 | AZ10: =SUM(AV10:AY10) -> 1493.4 | BA10: 124 | BB10: 282 | BC10: 74 | BD10: 341 | BE10: =SUM(BA10:BD10) -> 821 | BF10: 112 | BG10: 176 | BH10: 81 | BI10: 205 | BJ10: =SUM(BF10:BI10) -> 574 | BK10: 4896 | BL10: 4612 | BM10: 672 | BN10: 177.16 | BO10: =SUM(BK10:BN10) -> 10357.16 | BP10: 1049 | BQ10: 2225 | BR10: 538 | BS10: 835 | BT10: =SUM(BP10:BS10) -> 4647 | BU10: 202.81953 | BV10: 111.71221 | BW10: 37.864714 | BX10: 232.4052 | BY10: =SUM(BU10:BX10) -> 584.80165 | BZ10: 167.60963 | CA10: 83.404192 | CB10: 25.501822 | CC10: 241.53526 | CD10: =SUM(BZ10:CC10) -> 518.0509 | CE10: 138.51224 | CI10: =SUM(CE10:CH10) -> 138.51224 | CN10: =SUM(CJ10:CM10) -> 0
B11: Kacang Hijau | C11: 284 | D11: 203 | E11: 185 | F11: 228 | G11: 900 | H11: 318 | I11: 442 | J11: 443 | K11: 324 | L11: 1527 | M11: 250 | N11: 301 | O11: 283 | P11: 242 | Q11: 1076 | R11: 197 | S11: 293 | T11: 264 | U11: 329 | V11: 1083 | W11: 425 | X11: 286 | Y11: 256 | Z11: 225 | AA11: 1192 | AB11: 239 | AC11: 240 | AD11: 314 | AE11: 243 | AF11: 1036 | AG11: 172 | AH11: 155 | AI11: 287 | AJ11: 392 | AK11: 1006 | AL11: 236 | AM11: 168 | AN11: 179 | AO11: 99 | AP11: 682 | AQ11: 241 | AR11: 72 | AS11: 120 | AT11: 195 | AU11: =SUM(AQ11:AT11) -> 628 | AV11: 104.2 | AW11: 137.5 | AX11: 84.4 | AY11: 203.3 | AZ11: =SUM(AV11:AY11) -> 529.4 | BA11: 61 | BB11: 49 | BC11: 155 | BD11: 523 | BE11: =SUM(BA11:BD11) -> 788 | BF11: 131 | BG11: 40 | BH11: 50 | BI11: 74 | BJ11: =SUM(BF11:BI11) -> 295 | BK11: 85 | BL11: 76 | BM11: 65 | BN11: 75.1 | BO11: =SUM(BK11:BN11) -> 301.1 | BP11: 81 | BQ11: 91 | BR11: 163 | BS11: 146 | BT11: =SUM(BP11:BS11) -> 481 | BU11: 104.2 | BV11: 65.6 | BW11: 77.1 | BX11: 65.9 | BY11: =SUM(BU11:BX11) -> 312.8 | BZ11: 40.4 | CA11: 18.4 | CB11: 35.9 | CC11: 48.75 | CD11: =SUM(BZ11:CC11) -> 143.45 | CE11: 43 | CI11: =SUM(CE11:CH11) -> 43 | CN11: =SUM(CJ11:CM11) -> 0
BA12: =sum(BA5:BA11) -> 124332.12 | BB12: =sum(BB5:BB11) -> 261336.17 | BC12: =sum(BC5:BC11) -> 207076.19 | BD12: =sum(BD5:BD11) -> 277674.01 | BE12: =sum(BE5:BE11) -> 870418.49 | BF12: =sum(BF5:BF11) -> 143005 | BG12: =sum(BG5:BG11) -> 276840 | BH12: =sum(BH5:BH11) -> 157316 | ... CN12: =sum(CN5:CN11) -> 0
AV13: =AV5/AQ5*100-100 -> -29.356143 | AW13: =AW5/AR5*100-100 -> 11.332949 | AX13: =AX5/AS5*100-100 -> -16.990374 | AY13: =AY5/AT5*100-100 -> 7.1428436 | BP13: =BP12/BK12*100-100 -> -12.693537 | BS13: =BS12/BR12*100-100 -> 5.3137217 | BU13: =BU12/BP12*100-100 -> -8.0114825 | CE13: =CE12/CC12*100-100 -> -49.511588
CE14: =CE12/BZ12*100-100 -> -15.795419
B16: HARGA | C16: 2010 | H16: 2011 | M16: 2012 | R16: 2013 | W16: 2014 | AB16: 2015 | AG16: 2016 | AL16: 2017 | AQ16: 2018 | AV16: 2019 | BA16: 2020 | BF16: 2021 | BK16: 2022 | BP16: 2023 | BU16: 2024 | BZ16: 2025 | CE16: 2026 | CJ16: 2027
C17: triw.1 | D17: triw.2 | E17: triw.3 | F17: triw.4 | G17: Total | H17: triw.1 | I17: triw.2 | J17: triw.3 | K17: triw.4 | L17: Total | M17: triw.1 | N17: triw.2 | O17: triw.3 | P17: triw.4 | Q17: Total | R17: triw.1 | S17: triw.2 | T17: triw.3 | U17: triw.4 | V17: Total | W17: triw.1 | X17: triw.2 | Y17: triw.3 | Z17: triw.4 | AA17: Total | AB17: triw.1 | AC17: triw.2 | AD17: triw.3 | AE17: triw.4 | AF17: Total | AG17: triw.1 | AH17: triw.2 | AI17: triw.3 | AJ17: triw.4 | AK17: Total | AL17: triw.1 | AM17: triw.2 | AN17: triw.3 | AO17: triw.4 | AP17: Total | AQ17: triw.1 | AR17: triw.2 | AS17: triw.3 | AT17: triw.4 | AU17: Total | AV17: triw.1 | AW17: triw.2 | AX17: triw.3 | AY17: triw.4 | AZ17: Total | BA17: triw.1 | BB17: triw.2 | BC17: triw.3 | BD17: triw.4 | BE17: Total | BF17: triw.1 | BG17: triw.2 | BH17: triw.3 | BI17: triw.4 | BJ17: Total | BK17: triw.1 | BL17: triw.2 | BM17: triw.3 | BN17: triw.4 | BO17: Total | BP17: triw.1 | BQ17: triw.2 | BR17: triw.3 | BS17: triw.4 | BT17: Total | BU17: triw.1 | BV17: triw.2 | BW17: triw.3 | BX17: triw.4 | BY17: Total | BZ17: triw.1 | CA17: triw.2 | CB17: triw.3 | CC17: triw.4 | CD17: Total | CE17: triw.1 | CF17: triw.2 | CG17: triw.3 | CH17: triw.4 | CI17: Total | CJ17: triw.1 | CK17: triw.2 | CL17: triw.3 | CM17: triw.4 | CN17: Total
B18: -1 | C18: -10 | D18: -11 | E18: -12 | F18: -13 | G18: -14 | H18: -15 | I18: -16 | J18: -17 | K18: -18 | L18: -19 | M18: -20 | N18: -21 | O18: -22 | P18: -23 | Q18: -24 | R18: -25 | S18: -26 | T18: -27 | U18: -28 | V18: -29 | W18: -30 | X18: -31 | Y18: -32 | Z18: -33 | AA18: -34 | AB18: -35 | AC18: -36 | AD18: -37 | AE18: -38 | AF18: -39 | AG18: -40 | AH18: -41 | AI18: -42 | AJ18: -43 | AK18: -44 | AL18: -45 | AM18: -46 | AN18: -47 | AO18: -48 | AP18: -49 | AQ18: -50 | AR18: -51 | AS18: -52 | AT18: -53 | AU18: -54 | AV18: -55 | AW18: -56 | AX18: -57 | AY18: -58 | AZ18: -59 | BA18: -60 | BB18: -61 | BC18: -62 | BD18: -63 | BE18: -64 | BF18: -65 | BG18: -66 | BH18: -67 | BI18: -68 | BJ18: -69 | BK18: -65 | BL18: -66 | BM18: -67 | BN18: -68 | BO18: -69 | BP18: -65 | BQ18: -66 | BR18: -67 | BS18: -68 | BT18: -69 | BU18: -70 | BV18: -71 | BW18: -72 | BX18: -73 | BY18: -74 | BZ18: -75 | CA18: -76 | CB18: -77 | CC18: -78 | CD18: -79 | CE18: -75 | CF18: -76 | CG18: -77 | CH18: -78 | CI18: -79 | CJ18: -75 | CK18: -76 | CL18: -77 | CM18: -78 | CN18: -79
B19: Padi | C19: 3645300 | D19: 3645300 | E19: 3645300 | F19: 3645300 | G19: =AVERAGE(C19:F19) -> 3645300 | H19: =H32/F32*F19 -> 3618543.1 | I19: =I32/H32*H19 -> 3488557.9 | J19: =J32/I32*I19 -> 3927326.7 | K19: =K32/J32*J19 -> 4228593.8 | L19: =AVERAGE(H19:K19) -> 3815755.4 | M19: =M32/K32*K19 -> 4276261.2 | N19: =N32/M32*M19 -> 4037237.4 | O19: =O32/N32*N19 -> 4109133.1 | P19: =P32/O32*O19 -> 4289593.9 | Q19: =AVERAGE(M19:P19) -> 4178056.4 | R19: =R32/P32*P19 -> 4387978.8 | S19: =S32/R32*R19 -> 4036438 | T19: =T32/S32*S19 -> 4192582.9 | U19: =U32/T32*T19 -> 4416431.1 | V19: =AVERAGE(R19:U19) -> 4258357.7 | W19: =W32/U32*U19 -> 4596485.9 | X19: =X32/W32*W19 -> 4351877.8 | Y19: =Y32/X32*X19 -> 4447830.5 | Z19: =Z32/Y32*Y19 -> 4894171.8 | AA19: =AVERAGE(W19:Z19) -> 4572591.5 | AB19: =AB32/Z32*Z19 -> 5120964.4 | AC19: =AC32/AB32*AB19 -> 4598806.8 | AD19: =AD32/AC32*AC19 -> 4891642.9 | AE19: =AE32/AD32*AD19 -> 5348607.2 | AF19: =AVERAGE(AB19:AE19) -> 4990005.3 | AG19: =AG32/AE32*AE19 -> 5358102.4 | AH19: =AH32/AG32*AG19 -> 4679210.5 | AI19: =AI32/AH32*AH19 -> 4745986.7 | AJ19: =AJ32/AI32*AI19 -> 4852252.9 | AK19: =AVERAGE(AG19:AJ19) -> 4908888.1 | AL19: =AL32/AJ32*AJ19 -> 4878453.2 | AM19: =AM32/AL32*AL19 -> 4720617.1 | AN19: =AN32/AM32*AM19 -> 4836338.4 | AO19: =AO32/AN32*AN19 -> 5191473.9 | AP19: =AVERAGE(AL19:AO19) -> 4906720.7 | AQ19: =AQ32/AO32*AO19 -> 5450331.9 | AR19: =AR32/AQ32*AQ19 -> 4876716.2 | AS19: =AS32/AR32*AR19 -> 5066160.3 | AT19: =AT32/AS32*AS19 -> 5418405.8 | AU19: =AVERAGE(AQ19:AT19) -> 5202903.5 | AV19: =AV32/AT32*AT19 -> 5340851.2 | AW19: =AW32/AV32*AV19 -> 4837898.4 | AX19: =AX32/AW32*AW19 -> 4991943.5 | AY19: =AY32/AX32*AX19 -> 5179794.8 | AZ19: =AVERAGE(AV19:AY19) -> 5087622 | BA19: =BA32/AY32*AY19 -> 5232768.1 | BB19: =BB32/BA32*BA19 -> 5074440.3 | BC19: =BC32/BB32*BB19 -> 5102735.8 | BD19: =BD32/BC32*BC19 -> 5152173.5 | BE19: =AVERAGE(BA19:BD19) -> 5140529.4 | BF19: =BF32/BD32*BD19 -> 5086362.5 | BG19: =BG32/BF32*BF19 -> 4914681.7 | BH19: =BH32/BG32*BG19 -> 4930896 | BI19: =BI32/BH32*BH19 -> 5095423.5 | BJ19: =AVERAGE(BF19:BI19) -> 5006840.9 | BK19: =BK32/BI32*BI19 -> 5210504.6 | BL19: =BL32/BK32*BK19 -> 5063417.9 | BM19: =BM32/BL32*BL19 -> 5242566.2 | BN19: =BN32/BM32*BM19 -> 5546986.1 | BO19: =AVERAGE(BK19:BN19) -> 5265868.7 | BP19: =BP32/BN32*BN19 -> 5808436.8 | BQ19: =BQ32/BP32*BP19 -> 5745635.7 | BR19: =BR32/BQ32*BQ19 -> 5763153.9 | BS19: =BS32/BR32*BR19 -> 5942632.7 | BT19: =AVERAGE(BP19:BS19) -> 5814964.8 | BU19: =BU32/BS32*BS19 -> 6114374.8 | BV19: =BV32/BU32*BU19 -> 5914434.8 | BW19: =BW32/BV32*BV19 -> 5981267.9 | BX19: =BX32/BW32*BW19 -> 5983660.4 | BZ19: =BZ32/BX32*BX19 -> 6044693.7 | CA19: =CA32/BZ32*BZ19 -> 6163774.2 | CB19: =CB32/CA32*CA19 -> 6351769.3 | CC19: =CC32/CB32*CB19 -> 6391785.4 | CE19: =CE32/CC32*CC19 -> 6435888.8 | CF19: =CF32/CE32*CE19 -> 0 | CG19: =CG32/CF32*CF19 -> #DIV/0! | CH19: =CH32/CG32*CG19 -> #DIV/0! | CJ19: =CJ32/CH32*CH19 -> #DIV/0! | CK19: =CK32/CJ32*CJ19 -> #DIV/0! | CL19: =CL32/CK32*CK19 -> #DIV/0! | CM19: =CM32/CL32*CL19 -> #DIV/0!
B20: Jagung | C20: 2135342.2 | D20: 2135342.2 | E20: 2135342.2 | F20: 2135342.2 | G20: =AVERAGE(C20:F20) -> 2135342.2 | H20: =H33/F33*F20 -> 2165669.3 | I20: =I33/H33*H20 -> 2211018.7 | J20: =J33/I33*I20 -> 2235318.9 | K20: =K33/J33*J20 -> 2259108.6 | L20: =AVERAGE(H20:K20) -> 2217778.9 | M20: =M33/K33*K20 -> 2258149.1 | N20: =N33/M33*M20 -> 2260506.3 | O20: =O33/N33*N20 -> 2296260.6 | P20: =P33/O33*O20 -> 2347026.4 | Q20: =AVERAGE(M20:P20) -> 2290485.6 | R20: =R33/P33*P20 -> 2376407 | S20: =S33/R33*R20 -> 2388882.7 | T20: =T33/S33*S20 -> 2454755.1 | U20: =U33/T33*T20 -> 2478607.4 | V20: =AVERAGE(R20:U20) -> 2424663 | W20: =W33/U33*U20 -> 2495439.5 | X20: =X33/W33*W20 -> 2508332.7 | Y20: =Y33/X33*X20 -> 2523962.2 | Z20: =Z33/Y33*Y20 -> 2552679 | AA20: =AVERAGE(W20:Z20) -> 2520103.4 | AB20: =AB33/Z33*Z20 -> 2576357.1 | AC20: =AC33/AB33*AB20 -> 2567310.7 | AD20: =AD33/AC33*AC20 -> 2589196.5 | AE20: =AE33/AD33*AD20 -> 2732792.9 | AF20: =AVERAGE(AB20:AE20) -> 2616414.3 | AG20: =AG33/AE33*AE20 -> 2797973.4 | AH20: =AH33/AG33*AG20 -> 2769553.8 | AI20: =AI33/AH33*AH20 -> 2795722.7 | AJ20: =AJ33/AI33*AI20 -> 2837537.3 | AK20: =AVERAGE(AG20:AJ20) -> 2800196.8 | AL20: =AL33/AJ33*AJ20 -> 2835809.3 | AM20: =AM33/AL33*AL20 -> 2876841.7 | AN20: =AN33/AM33*AM20 -> 2916248.7 | AO20: =AO33/AN33*AN20 -> 2936282.3 | AP20: =AVERAGE(AL20:AO20) -> 2891295.5 | AQ20: =AQ33/AO33*AO20 -> 2890187.3 | AR20: =AR33/AQ33*AQ20 -> 2908122.1 | AS20: =AS33/AR33*AR20 -> 2972101.5 | AT20: =AT33/AS33*AS20 -> 3103180.5 | AU20: =AVERAGE(AQ20:AT20) -> 2968397.9 | AV20: =AV33/AT33*AT20 -> 3187741 | AW20: =AW33/AV33*AV20 -> 3207449.7 | AX20: =AX33/AW33*AW20 -> 3242675.6 | AY20: =AY33/AX33*AX20 -> 3267582.5 | AZ20: =AVERAGE(AV20:AY20) -> 3226362.2 | BA20: =BA33/AY33*AY20 -> 3239412 | BB20: =BB33/BA33*BA20 -> 3108038.3 | BC20: =BC33/BB33*BB20 -> 3023588.2 | BD20: =BD33/BC33*BC20 -> 3076318.4 | BE20: =AVERAGE(BA20:BD20) -> 3111839.2 | BF20: =BF33/BD33*BD20 -> 3147094.1 | BG20: =BG33/BF33*BF20 -> 3290173.7 | BH20: =BH33/BG33*BG20 -> 3400677.9 | BI20: =BI33/BH33*BH20 -> 3422131.8 | BJ20: =AVERAGE(BF20:BI20) -> 3315019.4 | BK20: =BK33/BI33*BI20 -> 3422422.6 | BL20: =BL33/BK33*BK20 -> 3448737.7 | BM20: =BM33/BL33*BL20 -> 3397360.7 | BN20: =BN33/BM33*BM20 -> 3361020.8 | BO20: =AVERAGE(BK20:BN20) -> 3407385.5 | BP20: =BP33/BN33*BN20 -> 3412397.8 | BQ20: =BQ33/BP33*BP20 -> 3484242.2 | BR20: =BR33/BQ33*BQ20 -> 3511810.4 | BS20: =BS33/BR33*BR20 -> 3641506.1 | BT20: =AVERAGE(BP20:BS20) -> 3512489.1 | BU20: =BU33/BS33*BS20 -> 3731815.5 | BV20: =BV33/BU33*BU20 -> 3537014.7 | BW20: =BW33/BV33*BV20 -> 3503413.1 | BX20: =BX33/BW33*BW20 -> 3513222.6 | BZ20: =BZ33/BX33*BX20 -> 3537112.6 | CA20: =CA33/BZ33*BZ20 -> 3480165 | CB20: =CB33/CA33*CA20 -> 3562296.9 | CC20: =CC33/CB33*CB20 -> 3734355.9 | CE20: =CE33/CC33*CC20 -> 3809043 | CF20: =CF33/CE33*CE20 -> 0 | CG20: =CG33/CF33*CF20 -> #DIV/0! | CH20: =CH33/CG33*CG20 -> #DIV/0! | CJ20: =CJ33/CH33*CH20 -> #DIV/0! | CK20: =CK33/CJ33*CJ20 -> #DIV/0! | CL20: =CL33/CK33*CK20 -> #DIV/0! | CM20: =CM33/CL33*CL20 -> #DIV/0!
B21: Ubi Kayu | C21: 1009000 | D21: 1009000 | E21: 1009000 | F21: 1009000 | G21: =AVERAGE(C21:F21) -> 1009000 | H21: =H34/F34*F21 -> 1015553.3 | I21: =I34/H34*H21 -> 1018455.3 | J21: =J34/I34*I21 -> 1046577 | K21: =K34/J34*J21 -> 1063305.4 | L21: =AVERAGE(H21:K21) -> 1035972.8 | M21: =M34/K34*K21 -> 1079575.3 | N21: =N34/M34*M21 -> 1100895.2 | O21: =O34/N34*N21 -> 1119569.7 | P21: =P34/O34*O21 -> 1127732.4 | Q21: =AVERAGE(M21:P21) -> 1106943.2 | R21: =R34/P34*P21 -> 1136779.2 | S21: =S34/R34*R21 -> 1143789.6 | T21: =T34/S34*S21 -> 1174652 | U21: =U34/T34*T21 -> 1173290.3 | V21: =AVERAGE(R21:U21) -> 1157127.8 | W21: =W34/U34*U21 -> 1178978.5 | X21: =X34/W34*W21 -> 1197253.4 | Y21: =Y34/X34*X21 -> 1227506.1 | Z21: =Z34/Y34*Y21 -> 1264631.4 | AA21: =AVERAGE(W21:Z21) -> 1217092.4 | AB21: =AB34/Z34*Z21 -> 1293866.1 | AC21: =AC34/AB34*AB21 -> 1331884.7 | AD21: =AD34/AC34*AC21 -> 1353605.6 | AE21: =AE34/AD34*AD21 -> 1374646.1 | AF21: =AVERAGE(AB21:AE21) -> 1338500.6 | AG21: =AG34/AE34*AE21 -> 1368659.9 | AH21: =AH34/AG34*AG21 -> 1367114.7 | AI21: =AI34/AH34*AH21 -> 1369107.9 | AJ21: =AJ34/AI34*AI21 -> 1354049 | AK21: =AVERAGE(AG21:AJ21) -> 1364732.9 | AL21: =AL34/AJ34*AJ21 -> 1359024.3 | AM21: =AM34/AL34*AL21 -> 1363161 | AN21: =AN34/AM34*AM21 -> 1371675.6 | AO21: =AO34/AN34*AN21 -> 1389947.4 | AP21: =AVERAGE(AL21:AO21) -> 1370952.1 | AQ21: =AQ34/AO34*AO21 -> 1426240.6 | AR21: =AR34/AQ34*AQ21 -> 1458785.5 | AS21: =AS34/AR34*AR21 -> 1486462.4 | AT21: =AT34/AS34*AS21 -> 1514456.2 | AU21: =AVERAGE(AQ21:AT21) -> 1471486.2 | AV21: =AV34/AT34*AT21 -> 1548585.5 | AW21: =AW34/AV34*AV21 -> 1587709.4 | AX21: =AX34/AW34*AW21 -> 1612461 | AY21: =AY34/AX34*AX21 -> 1621093.1 | AZ21: =AVERAGE(AV21:AY21) -> 1592462.3 | BA21: =BA34/AY34*AY21 -> 1639807.1 | BB21: =BB34/BA34*BA21 -> 1659554 | BC21: =BC34/BB34*BB21 -> 1649355.7 | BD21: =BD34/BC34*BC21 -> 1626461.5 | BE21: =AVERAGE(BA21:BD21) -> 1643794.6 | BF21: =BF34/BD34*BD21 -> 1608108.9 | BG21: =BG34/BF34*BF21 -> 1610436.4 | BH21: =BH34/BG34*BG21 -> 1616529.3 | BI21: =BI34/BH34*BH21 -> 1624202.5 | BJ21: =AVERAGE(BF21:BI21) -> 1614819.3 | BK21: =BK34/BI34*BI21 -> 1658804.9 | BL21: =BL34/BK34*BK21 -> 1708093.9 | BM21: =BM34/BL34*BL21 -> 1748673.3 | BN21: =BN34/BM34*BM21 -> 1777771.6 | BO21: =AVERAGE(BK21:BN21) -> 1723335.9 | BP21: =BP34/BN34*BN21 -> 1860118 | BQ21: =BQ34/BP34*BP21 -> 1892185.6 | BR21: =BR34/BQ34*BQ21 -> 1910792.8 | BS21: =BS34/BR34*BR21 -> 1945334.7 | BT21: =AVERAGE(BP21:BS21) -> 1902107.8 | BU21: =BU34/BS34*BS21 -> 1989299.3 | BV21: =BV34/BU34*BU21 -> 1982336.7 | BW21: =BW34/BV34*BV21 -> 1963504.5 | BX21: =BX34/BW34*BW21 -> 1960755.6 | BZ21: =BZ34/BX34*BX21 -> 1967814.3 | CA21: =CA34/BZ34*BZ21 -> 1976866.3 | CB21: =CB34/CA34*CA21 -> 1972714.9 | CC21: =CC34/CB34*CB21 -> 1987312.9 | CE21: =CE34/CC34*CC21 -> 2008974.7 | CF21: =CF34/CE34*CE21 -> 0 | CG21: =CG34/CF34*CF21 -> #DIV/0! | CH21: =CH34/CG34*CG21 -> #DIV/0! | CJ21: =CJ34/CH34*CH21 -> #DIV/0! | CK21: =CK34/CJ34*CJ21 -> #DIV/0! | CL21: =CL34/CK34*CK21 -> #DIV/0! | CM21: =CM34/CL34*CL21 -> #DIV/0!
B22: Ubi Jalar | C22: 1405000 | D22: 1405000 | E22: 1405000 | F22: 1405000 | G22: =AVERAGE(C22:F22) -> 1405000 | H22: =H35/F35*F22 -> 1427971.5 | I22: =I35/H35*H22 -> 1460482.5 | J22: =J35/I35*I22 -> 1487536.7 | K22: =K35/J35*J22 -> 1510960.1 | L22: =AVERAGE(H22:K22) -> 1471737.7 | M22: =M35/K35*K22 -> 1521796.3 | N22: =N35/M35*M22 -> 1532293.5 | O22: =O35/N35*N22 -> 1552295 | P22: =P35/O35*O22 -> 1564726.7 | Q22: =AVERAGE(M22:P22) -> 1542777.9 | R22: =R35/P35*P22 -> 1596257.5 | S22: =S35/R35*R22 -> 1614431.7 | T22: =T35/S35*S22 -> 1652739.4 | U22: =U35/T35*T22 -> 1653279.4 | V22: =AVERAGE(R22:U22) -> 1629177 | W22: =W35/U35*U22 -> 1676955.6 | X22: =X35/W35*W22 -> 1700426 | Y22: =Y35/X35*X22 -> 1747059.3 | Z22: =Z35/Y35*Y22 -> 1786791.7 | AA22: =AVERAGE(W22:Z22) -> 1727808.1 | AB22: =AB35/Z35*Z22 -> 1859646.1 | AC22: =AC35/AB35*AB22 -> 1870663.3 | AD22: =AD35/AC35*AC22 -> 1890803.8 | AE22: =AE35/AD35*AD22 -> 1921777.8 | AF22: =AVERAGE(AB22:AE22) -> 1885722.7 | AG22: =AG35/AE35*AE22 -> 1950237.4 | AH22: =AH35/AG35*AG22 -> 1936931.1 | AI22: =AI35/AH35*AH22 -> 1931717.8 | AJ22: =AJ35/AI35*AI22 -> 1906400.5 | AK22: =AVERAGE(AG22:AJ22) -> 1931321.7 | AL22: =AL35/AJ35*AJ22 -> 1923969 | AM22: =AM35/AL35*AL22 -> 1949633.5 | AN22: =AN35/AM35*AM22 -> 1961033.7 | AO22: =AO35/AN35*AN22 -> 1977476.3 | AP22: =AVERAGE(AL22:AO22) -> 1953028.1 | AQ22: =AQ35/AO35*AO22 -> 2007265.6 | AR22: =AR35/AQ35*AQ22 -> 2046469.7 | AS22: =AS35/AR35*AR22 -> 2044978.5 | AT22: =AT35/AS35*AS22 -> 2074773.9 | AU22: =AVERAGE(AQ22:AT22) -> 2043371.9 | AV22: =AV35/AT35*AT22 -> 2109406.6 | AW22: =AW35/AV35*AV22 -> 2129681.7 | AX22: =AX35/AW35*AW22 -> 2120720.9 | AY22: =AY35/AX35*AX22 -> 2144726.9 | AZ22: =AVERAGE(AV22:AY22) -> 2126134 | BA22: =BA35/AY35*AY22 -> 2191002.5 | BB22: =BB35/BA35*BA22 -> 2216846.1 | BC22: =BC35/BB35*BB22 -> 2183164.8 | BD22: =BD35/BC35*BC22 -> 2119757.5 | BE22: =AVERAGE(BA22:BD22) -> 2177692.7 | BF22: =BF35/BD35*BD22 -> 2053059.8 | BG22: =BG35/BF35*BF22 -> 2078888.6 | BH22: =BH35/BG35*BG22 -> 2125670.2 | BI22: =BI35/BH35*BH22 -> 2196823.4 | BJ22: =AVERAGE(BF22:BI22) -> 2113610.5 | BK22: =BK35/BI35*BI22 -> 2234107.8 | BL22: =BL35/BK35*BK22 -> 2262960.6 | BM22: =BM35/BL35*BL22 -> 2282925.1 | BN22: =BN35/BM35*BM22 -> 2326409.4 | BO22: =AVERAGE(BK22:BN22) -> 2276600.7 | BP22: =BP35/BN35*BN22 -> 2365381.2 | BQ22: =BQ35/BP35*BP22 -> 2377277.8 | BR22: =BR35/BQ35*BQ22 -> 2400797.6 | BS22: =BS35/BR35*BR22 -> 2478330.9 | BT22: =AVERAGE(BP22:BS22) -> 2405446.9 | BU22: =BU35/BS35*BS22 -> 2571020.5 | BV22: =BV35/BU35*BU22 -> 2610871.3 | BW22: =BW35/BV35*BV22 -> 2608260.4 | BX22: =BX35/BW35*BW22 -> 2585046.9 | BZ22: =BZ35/BX35*BX22 -> 2558938 | CA22: =CA35/BZ35*BZ22 -> 2538466.4 | CB22: =CB35/CA35*CA22 -> 2608782 | CC22: =CC35/CB35*CB22 -> 2664609.9 | CE22: =CE35/CC35*CC22 -> 2692321.8 | CF22: =CF35/CE35*CE22 -> 0 | CG22: =CG35/CF35*CF22 -> #DIV/0! | CH22: =CH35/CG35*CG22 -> #DIV/0! | CJ22: =CJ35/CH35*CH22 -> #DIV/0! | CK22: =CK35/CJ35*CJ22 -> #DIV/0! | CL22: =CL35/CK35*CK22 -> #DIV/0! | CM22: =CM35/CL35*CL22 -> #DIV/0!
B23: Kacang Tanah | C23: 7695000 | D23: 7695000 | E23: 7695000 | F23: 7695000 | G23: =AVERAGE(C23:F23) -> 7695000 | H23: =H36/F36*F23 -> 7876263.1 | I23: =I36/H36*H23 -> 8024407.7 | J23: =J36/I36*I23 -> 8271268.5 | K23: =K36/J36*J23 -> 8309578.9 | L23: =AVERAGE(H23:K23) -> 8120379.6 | M23: =M36/K36*K23 -> 8336718.9 | N23: =N36/M36*M23 -> 8463815.3 | O23: =O36/N36*N23 -> 8665923.8 | P23: =P36/O36*O23 -> 8710975.4 | Q23: =AVERAGE(M23:P23) -> 8544358.4 | R23: =R36/P36*P23 -> 8842543.9 | S23: =S36/R36*R23 -> 8860757.3 | T23: =T36/S36*S23 -> 9145143 | U23: =U36/T36*T23 -> 9147458.7 | V23: =AVERAGE(R23:U23) -> 8998975.8 | W23: =W36/U36*U23 -> 9177908.5 | X23: =X36/W36*W23 -> 9229518.2 | Y23: =Y36/X36*X23 -> 9427099.8 | Z23: =Z36/Y36*Y23 -> 9628120.4 | AA23: =AVERAGE(W23:Z23) -> 9365661.7 | AB23: =AB36/Z36*Z23 -> 9764364.4 | AC23: =AC36/AB36*AB23 -> 9881246 | AD23: =AD36/AC36*AC23 -> 10398081 | AE23: =AE36/AD36*AD23 -> 10657479 | AF23: =AVERAGE(AB23:AE23) -> 10175293 | AG23: =AG36/AE36*AE23 -> 10733654 | AH23: =AH36/AG36*AG23 -> 10718169 | AI23: =AI36/AH36*AH23 -> 10917769 | AJ23: =AJ36/AI36*AI23 -> 10905606 | AK23: =AVERAGE(AG23:AJ23) -> 10818800 | AL23: =AL36/AJ36*AJ23 -> 10932088 | AM23: =AM36/AL36*AL23 -> 11118289 | AN23: =AN36/AM36*AM23 -> 11289543 | AO23: =AO36/AN36*AN23 -> 11338261 | AP23: =AVERAGE(AL23:AO23) -> 11169545 | AQ23: =AQ36/AO36*AO23 -> 11428784 | AR23: =AR36/AQ36*AQ23 -> 11480371 | AS23: =AS36/AR36*AR23 -> 11549944 | AT23: =AT36/AS36*AS23 -> 11512046 | AU23: =AVERAGE(AQ23:AT23) -> 11492786 | AV23: =AV36/AT36*AT23 -> 11409413 | AW23: =AW36/AV36*AV23 -> 11564782 | AX23: =AX36/AW36*AW23 -> 11783219 | AY23: =AY36/AX36*AX23 -> 11944407 | AZ23: =AVERAGE(AV23:AY23) -> 11675456 | BA23: =BA36/AY36*AY23 -> 12067856 | BB23: =BB36/BA36*BA23 -> 12174591 | BC23: =BC36/BB36*BB23 -> 12183130 | BD23: =BD36/BC36*BC23 -> 12091395 | BE23: =AVERAGE(BA23:BD23) -> 12129243 | BF23: =BF36/BD36*BD23 -> 12139807 | BG23: =BG36/BF36*BF23 -> 12298632 | BH23: =BH36/BG36*BG23 -> 12434932 | BI23: =BI36/BH36*BH23 -> 12493440 | BJ23: =AVERAGE(BF23:BI23) -> 12341703 | BK23: =BK36/BI36*BI23 -> 12802275 | BL23: =BL36/BK36*BK23 -> 13059880 | BM23: =BM36/BL36*BL23 -> 13151934 | BN23: =BN36/BM36*BM23 -> 13206128 | BO23: =AVERAGE(BK23:BN23) -> 13055054 | BP23: =BP36/BN36*BN23 -> 13560984 | BQ23: =BQ36/BP36*BP23 -> 13667886 | BR23: =BR36/BQ36*BQ23 -> 13765879 | BS23: =BS36/BR36*BR23 -> 13913612 | BT23: =AVERAGE(BP23:BS23) -> 13727090 | BU23: =BU36/BS36*BS23 -> 14058314 | BV23: =BV36/BU36*BU23 -> 14210144 | BW23: =BW36/BV36*BV23 -> 14335193 | BX23: =BX36/BW36*BW23 -> 14315124 | BZ23: =BZ36/BX36*BX23 -> 14433939 | CA23: =CA36/BZ36*BZ23 -> 14507552 | CB23: =CB36/CA36*CA23 -> 14590245 | CC23: =CC36/CB36*CB23 -> 14744902 | CE23: =CE36/CC36*CC23 -> 15583887 | CF23: =CF36/CE36*CE23 -> 0 | CG23: =CG36/CF36*CF23 -> #DIV/0! | CH23: =CH36/CG36*CG23 -> #DIV/0! | CJ23: =CJ36/CH36*CH23 -> #DIV/0! | CK23: =CK36/CJ36*CJ23 -> #DIV/0! | CL23: =CL36/CK36*CK23 -> #DIV/0! | CM23: =CM36/CL36*CL23 -> #DIV/0!
B24: Kedelai | C24: 5645000 | D24: 5645000 | E24: 5645000 | F24: 5645000 | G24: =AVERAGE(C24:F24) -> 5645000 | H24: =H37/F37*F24 -> 5831633.9 | I24: =I37/H37*H24 -> 5911106.4 | J24: =J37/I37*I24 -> 5895145.4 | K24: =K37/J37*J24 -> 5876576.7 | L24: =AVERAGE(H24:K24) -> 5878615.6 | M24: =M37/K37*K24 -> 5895217.9 | N24: =N37/M37*M24 -> 5928474.8 | O24: =O37/N37*N24 -> 6037454.9 | P24: =P37/O37*O24 -> 6119574.6 | Q24: =AVERAGE(M24:P24) -> 5995180.5 | R24: =R37/P37*P24 -> 6185392.8 | S24: =S37/R37*R24 -> 6190941.2 | T24: =T37/S37*S24 -> 6302783.2 | U24: =U37/T37*T24 -> 6501443.6 | V24: =AVERAGE(R24:U24) -> 6295140.2 | W24: =W37/U37*U24 -> 6559336 | X24: =X37/W37*W24 -> 6577326.8 | Y24: =Y37/X37*X24 -> 6593257.8 | Z24: =Z37/Y37*Y24 -> 6635834.4 | AA24: =AVERAGE(W24:Z24) -> 6591438.8 | AB24: =AB37/Z37*Z24 -> 6637012.5 | AC24: =AC37/AB37*AB24 -> 6650298.7 | AD24: =AD37/AC37*AC24 -> 6657602.7 | AE24: =AE37/AD37*AD24 -> 6603950.8 | AF24: =AVERAGE(AB24:AE24) -> 6637216.2 | AG24: =AG37/AE37*AE24 -> 6678025.8 | AH24: =AH37/AG37*AG24 -> 6722456.5 | AI24: =AI37/AH37*AH24 -> 6785146.9 | AJ24: =AJ37/AI37*AI24 -> 6807115.6 | AK24: =AVERAGE(AG24:AJ24) -> 6748186.2 | AL24: =AL37/AJ37*AJ24 -> 6884002.2 | AM24: =AM37/AL37*AL24 -> 6928440.6 | AN24: =AN37/AM37*AM24 -> 6958035.9 | AO24: =AO37/AN37*AN24 -> 6962211.7 | AP24: =AVERAGE(AL24:AO24) -> 6933172.6 | AQ24: =AQ37/AO37*AO24 -> 7657214.7 | AR24: =AR37/AQ37*AQ24 -> 7704730.7 | AS24: =AS37/AR37*AR24 -> 7874236.8 | AT24: =AT37/AS37*AS24 -> 8221515.4 | AU24: =AVERAGE(AQ24:AT24) -> 7864424.4 | AV24: =AV37/AT37*AT24 -> 7023978.3 | AW24: =AW37/AV37*AV24 -> 7063236.6 | AX24: =AX37/AW37*AW24 -> 7132016.1 | AY24: =AY37/AX37*AX24 -> 7135601.5 | AZ24: =AVERAGE(AV24:AY24) -> 7088708.1 | BA24: =BA37/AY37*AY24 -> 7249391.2 | BB24: =BB37/BA37*BA24 -> 7301560.7 | BC24: =BC37/BB37*BB24 -> 7323586.1 | BD24: =BD37/BC37*BC24 -> 7381207 | BE24: =AVERAGE(BA24:BD24) -> 7313936.3 | BF24: =BF37/BD37*BD24 -> 7474272.8 | BG24: =BG37/BF37*BF24 -> 7591530.7 | BH24: =BH37/BG37*BG24 -> 7649371.4 | BI24: =BI37/BH37*BH24 -> 7634619.8 | BJ24: =AVERAGE(BF24:BI24) -> 7587448.7 | BK24: =BK37/BI37*BI24 -> 7702261.4 | BL24: =BL37/BK37*BK24 -> 7726607.6 | BM24: =BM37/BL37*BL24 -> 7772533.5 | BN24: =BN37/BM37*BM24 -> 7932997.3 | BO24: =AVERAGE(BK24:BN24) -> 7783599.9 | BP24: =BP37/BN37*BN24 -> 8072434.8 | BQ24: =BQ37/BP37*BP24 -> 8029275.5 | BR24: =BR37/BQ37*BQ24 -> 8120573.9 | BS24: =BS37/BR37*BR24 -> 8150453.3 | BT24: =AVERAGE(BP24:BS24) -> 8093184.4 | BU24: =BU37/BS37*BS24 -> 8213211.8 | BV24: =BV37/BU37*BU24 -> 8263312.4 | BW24: =BW37/BV37*BV24 -> 8136057.4 | BX24: =BX37/BW37*BW24 -> 8015643.8 | BZ24: =BZ37/BX37*BX24 -> 7997207.8 | CA24: =CA37/BZ37*BZ24 -> 8008403.9 | CB24: =CB37/CA37*CA24 -> 8008403.9 | CC24: =CC37/CB37*CB24 -> 7999594.6 | CE24: =CE37/CC37*CC24 -> 8075590.8 | CF24: =CF37/CE37*CE24 -> 0 | CG24: =CG37/CF37*CF24 -> #DIV/0! | CH24: =CH37/CG37*CG24 -> #DIV/0! | CJ24: =CJ37/CH37*CH24 -> #DIV/0! | CK24: =CK37/CJ37*CJ24 -> #DIV/0! | CL24: =CL37/CK37*CK24 -> #DIV/0! | CM24: =CM37/CL37*CL24 -> #DIV/0!
B25: Kacang Hijau | C25: 8947000 | D25: 8947000 | E25: 8947000 | F25: 8947000 | G25: =AVERAGE(C25:F25) -> 8947000 | H25: =H38/F38*F25 -> 9580915.8 | I25: =I38/H38*H25 -> 9770208.1 | J25: =J38/I38*I25 -> 9818312 | K25: =K38/J38*J25 -> 9571898.6 | L25: =AVERAGE(H25:K25) -> 9685333.6 | M25: =M38/K38*K25 -> 9403592.4 | N25: =N38/M38*M25 -> 9357985 | O25: =O38/N38*N25 -> 9394592.1 | P25: =P38/O38*O25 -> 9412868.2 | Q25: =AVERAGE(M25:P25) -> 9392259.4 | R25: =R38/P38*P25 -> 9582942.3 | S25: =S38/R38*R25 -> 9789994.8 | T25: =T38/S38*S25 -> 10133416 | U25: =U38/T38*T25 -> 10378468 | V25: =AVERAGE(R25:U25) -> 9971205.3 | W25: =W38/U38*U25 -> 10635853 | X25: =X38/W38*W25 -> 10877699 | Y25: =Y38/X38*X25 -> 11050550 | Z25: =Z38/Y38*Y25 -> 11177379 | AA25: =AVERAGE(W25:Z25) -> 10935370 | AB25: =AB38/Z38*Z25 -> 11420377 | AC25: =AC38/AB38*AB25 -> 11581868 | AD25: =AD38/AC38*AC25 -> 11860406 | AE25: =AE38/AD38*AD25 -> 11932114 | AF25: =AVERAGE(AB25:AE25) -> 11698691 | AG25: =AG38/AE38*AE25 -> 11984107 | AH25: =AH38/AG38*AG25 -> 11988626 | AI25: =AI38/AH38*AH25 -> 12058974 | AJ25: =AJ38/AI38*AI25 -> 11829899 | AK25: =AVERAGE(AG25:AJ25) -> 11965402 | AL25: =AL38/AJ38*AJ25 -> 11893696 | AM25: =AM38/AL38*AL25 -> 12134179 | AN25: =AN38/AM38*AM25 -> 12227867 | AO25: =AO38/AN38*AN25 -> 12251726 | AP25: =AVERAGE(AL25:AO25) -> 12126867 | AQ25: =AQ38/AO38*AO25 -> 12478545 | AR25: =AR38/AQ38*AQ25 -> 12513152 | AS25: =AS38/AR38*AR25 -> 12501463 | AT25: =AT38/AS38*AS25 -> 12292359 | AU25: =AVERAGE(AQ25:AT25) -> 12446380 | AV25: =AV38/AT38*AT25 -> 12490405 | AW25: =AW38/AV38*AV25 -> 12746727 | AX25: =AX38/AW38*AW25 -> 12844269 | AY25: =AY38/AX38*AX25 -> 12905363 | AZ25: =AVERAGE(AV25:AY25) -> 12746691 | BA25: =BA38/AY38*AY25 -> 12918023 | BB25: =BB38/BA38*BA25 -> 13343276 | BC25: =BC38/BB38*BB25 -> 13375343 | BD25: =BD38/BC38*BC25 -> 13355044 | BE25: =AVERAGE(BA25:BD25) -> 13247921 | BF25: =BF38/BD38*BD25 -> 13498317 | BG25: =BG38/BF38*BF25 -> 13813302 | BH25: =BH38/BG38*BG25 -> 13826818 | BI25: =BI38/BH38*BH25 -> 13834491 | BJ25: =AVERAGE(BF25:BI25) -> 13743232 | BK25: =BK38/BI38*BI25 -> 13920143 | BL25: =BL38/BK38*BK25 -> 14191677 | BM25: =BM38/BL38*BL25 -> 14290648 | BN25: =BN38/BM38*BM25 -> 14495356 | BO25: =AVERAGE(BK25:BN25) -> 14224456 | BP25: =BP38/BN38*BN25 -> 14865860 | BQ25: =BQ38/BP38*BP25 -> 14925919 | BR25: =BR38/BQ38*BQ25 -> 14904772 | BS25: =BS38/BR38*BR25 -> 14780424 | BT25: =AVERAGE(BP25:BS25) -> 14869244 | BU25: =BU38/BS38*BS25 -> 14795205 | BV25: =BV38/BU38*BU25 -> 14881017 | BW25: =BW38/BV38*BV25 -> 14924172 | BX25: =BX38/BW38*BW25 -> 14767468 | BZ25: =BZ38/BX38*BX25 -> 14726119 | CA25: =CA38/BZ38*BZ25 -> 15269513 | CB25: =CB38/CA38*CA25 -> 15229812 | CC25: =CC38/CB38*CB25 -> 15575529 | CE25: =CE38/CC38*CC25 -> 16324712 | CF25: =CF38/CE38*CE25 -> 0 | CG25: =CG38/CF38*CF25 -> #DIV/0! | CH25: =CH38/CG38*CG25 -> #DIV/0! | CJ25: =CJ38/CH38*CH25 -> #DIV/0! | CK25: =CK38/CJ38*CJ25 -> #DIV/0! | CL25: =CL38/CK38*CK25 -> #DIV/0! | CM25: =CM38/CL38*CL25 -> #DIV/0!
W28: IHP
B29: IHP (2010=100) | C29: 2010 | H29: 2011 | M29: 2012 | R29: 2013 | W29: 2014 | AB29: 2015 | AG29: 2016 | AL29: 2017 | AQ29: 2018 | AV29: 2019 | BA29: 2020 | BF29: 2021 | BK29: 2022 | BP29: 2023 | BU29: 2024 | BZ29: 2025 | CE29: 2026 | CJ29: 2027
C30: triw.1 | D30: triw.2 | E30: triw.3 | F30: triw.4 | H30: triw.1 | I30: triw.2 | J30: triw.3 | K30: triw.4 | M30: triw.1 | N30: triw.2 | O30: triw.3 | P30: triw.4 | R30: triw.1 | S30: triw.2 | T30: triw.3 | U30: triw.4 | W30: triw.1 | X30: triw.2 | Y30: triw.3 | Z30: triw.4 | AB30: triw.1 | AC30: triw.2 | AD30: triw.3 | AE30: triw.4 | AG30: triw.1 | AH30: triw.2 | AI30: triw.3 | AJ30: triw.4 | AL30: triw.1 | AM30: triw.2 | AN30: triw.3 | AO30: triw.4 | AQ30: triw.1 | AR30: triw.2 | AS30: triw.3 | AT30: triw.4 | AV30: triw.1 | AW30: triw.2 | AX30: triw.3 | AY30: triw.4 | BA30: triw.1 | BB30: triw.2 | BC30: triw.3 | BD30: triw.4 | BF30: triw.1 | BG30: triw.2 | BH30: triw.3 | BI30: triw.4 | BJ30: Total | BK30: triw.1 | BL30: triw.2 | BM30: triw.3 | BN30: triw.4 | BO30: Total | BP30: triw.1 | BQ30: triw.2 | BR30: triw.3 | BS30: triw.4 | BT30: Total | BU30: triw.1 | BV30: triw.2 | BW30: triw.3 | BX30: triw.4 | BY30: Total | BZ30: triw.1 | CA30: triw.2 | CB30: triw.3 | CC30: triw.4 | CD30: Total | CE30: triw.1 | CF30: triw.2 | CG30: triw.3 | CH30: triw.4 | CI30: Total | CJ30: triw.1 | CK30: triw.2 | CL30: triw.3 | CM30: triw.4 | CN30: Total
B31: -1 | C31: -10 | D31: -11 | E31: -12 | F31: -13 | G31: -14 | H31: -15 | I31: -16 | J31: -17 | K31: -18 | L31: -19 | M31: -20 | N31: -21 | O31: -22 | P31: -23 | Q31: -24 | R31: -25 | S31: -26 | T31: -27 | U31: -28 | V31: -29 | W31: -30 | X31: -31 | Y31: -32 | Z31: -33 | AA31: -34 | AB31: -35 | AC31: -36 | AD31: -37 | AE31: -38 | AF31: -39 | AG31: -40 | AH31: -41 | AI31: -42 | AJ31: -43 | AK31: -44 | AL31: -45 | AM31: -46 | AN31: -47 | AO31: -48 | AP31: -49 | AQ31: -50 | AR31: -51 | AS31: -52 | AT31: -53 | AU31: -54 | AV31: -55 | AW31: -56 | AX31: -57 | AY31: -58 | AZ31: -59 | BA31: -60 | BB31: -61 | BC31: -62 | BD31: -63 | BE31: -64 | BF31: -65 | BG31: -66 | BH31: -67 | BI31: -68 | BJ31: -69 | BK31: -65 | BL31: -66 | BM31: -67 | BN31: -68 | BO31: -69 | BP31: -65 | BQ31: -66 | BR31: -67 | BS31: -68 | BT31: -69 | BU31: -70 | BV31: -71 | BW31: -72 | BX31: -73 | BY31: -74 | BZ31: -75 | CA31: -76 | CB31: -77 | CC31: -78 | CD31: -79 | CE31: -75 | CF31: -76 | CG31: -77 | CH31: -78 | CI31: -79 | CJ31: -75 | CK31: -76 | CL31: -77 | CM31: -78 | CN31: -79
B32: Padi | C32: 97.046987 | D32: 91.504442 | E32: 101.16269 | F32: 110.28588 | G32: 100 | H32: 109.47637 | I32: 105.54376 | J32: 118.81839 | K32: 127.93301 | L32: 115.44288 | M32: 129.37515 | N32: 122.14366 | O32: 124.31881 | P32: 129.77852 | Q32: 126.40404 | R32: 132.75508 | S32: 122.11947 | T32: 126.84352 | U32: 133.61589 | V32: 128.83349 | W32: 139.06331 | X32: 131.66287 | Y32: 134.56585 | Z32: 148.06958 | AA32: 138.34041 | AB32: 154.93103 | AC32: 139.13353 | AD32: 147.99307 | AE32: 161.81819 | AF32: 150.96896 | AG32: 162.10546 | AH32: 141.56609 | AI32: 143.58635 | AJ32: 146.80136 | AL32: 147.59403 | AM32: 142.81881 | AN32: 146.31988 | AO32: 157.06424 | AQ32: 164.8958 | AR32: 147.54148 | AS32: 153.27297 | AT32: 163.9299 | AV32: 161.58354 | AW32: 146.36707 | AX32: 151.02759 | AY32: 156.7109 | BA32: 158.31357 | BB32: 153.52347 | BC32: 154.37953 | BD32: 155.87524 | BF32: 153.88417 | BG32: 148.69009 | BH32: 149.18065 | BI32: 154.1583 | BK32: 157.64 | BL32: 153.19 | BM32: 158.61 | BN32: 167.82 | BP32: 175.73 | BQ32: 173.83 | BR32: 174.36 | BS32: 179.79 | BU32: =BS32+(BS32*2.89/100) -> 184.98593 | BV32: =BU32+(BU32*-3.27/100) -> 178.93689 | BW32: =BV32+(BV32*1.13/100) -> 180.95888 | BX32: =BW32+(BW32*0.04/100) -> 181.03126 | BZ32: =BX32+(BX32*1.02/100) -> 182.87778 | CA32: =BZ32+(BZ32*1.97/100) -> 186.48047 | CB32: =CA32+(CA32*3.05/100) -> 192.16813 | CC32: =CB32+(CB32*0.63/100) -> 193.37879 | CE32: =CC32+(CC32*0.69/100) -> 194.7131
B33: Jagung | C33: 98.166894 | D33: 98.948663 | E33: 100.64151 | F33: 102.24293 | G33: 100 | H33: 103.69503 | I33: 105.86642 | J33: 107.02994 | K33: 108.16902 | L33: 106.19011 | M33: 108.12309 | N33: 108.23595 | O33: 109.94791 | P33: 112.37864 | Q33: 109.6714 | R33: 113.78542 | S33: 114.38278 | T33: 117.53683 | U33: 118.67891 | V33: 116.09599 | W33: 119.48486 | X33: 120.1022 | Y33: 120.85056 | Z33: 122.22555 | AA33: 120.66579 | AB33: 123.35929 | AC33: 122.92614 | AD33: 123.97406 | AE33: 130.84964 | AF33: 125.27728 | AG33: 133.97057 | AH33: 132.6098 | AI33: 133.8628 | AJ33: 135.86494 | AL33: 135.7822 | AM33: 137.74688 | AN33: 139.63374 | AO33: 140.59298 | AQ33: 138.38589 | AR33: 139.24463 | AS33: 142.30805 | AT33: 148.58428 | AV33: 152.63314 | AW33: 153.57682 | AX33: 155.26348 | AY33: 156.45605 | BA33: 155.10721 | BB33: 148.81688 | BC33: 144.77329 | BD33: 147.29808 | BF33: 150.68692 | BG33: 157.53775 | BH33: 162.82884 | BI33: 163.85608 | BK33: 163.87 | BL33: 165.13 | BM33: 162.67 | BN33: 160.93 | BP33: 163.39 | BQ33: 166.83 | BR33: 168.15 | BS33: 174.36 | BU33: =BS33+(BS33*2.48/100) -> 178.68413 | BV33: =BU33+(BU33*-5.22/100) -> 169.35682 | BW33: =BV33+(BV33*-0.95/100) -> 167.74793 | BX33: =BW33+(BW33*0.28/100) -> 168.21762 | BZ33: =BX33+(BX33*0.68/100) -> 169.3615 | CA33: =BZ33+(BZ33*-1.61/100) -> 166.63478 | CB33: =CA33+(CA33*2.36/100) -> 170.56736 | CC33: =CB33+(CB33*4.83/100) -> 178.80577 | CE33: =CC33+(CC33*2/100) -> 182.38188
B34: Ubi Kayu | C34: 97.63822 | D34: 99.036761 | E34: 101.37909 | F34: 101.94593 | G34: 100 | H34: 102.60805 | I34: 102.90126 | J34: 105.74258 | K34: 107.43276 | L34: 104.67116 | M34: 109.07661 | N34: 111.23071 | O34: 113.11752 | P34: 113.94225 | Q34: 111.84177 | R34: 114.8563 | S34: 115.56461 | T34: 118.68284 | U34: 118.54526 | V34: 116.91225 | W34: 119.11998 | X34: 120.96641 | Y34: 124.02304 | Z34: 127.77406 | AA34: 122.97087 | AB34: 130.72783 | AC34: 134.5691 | AD34: 136.7637 | AE34: 138.88957 | AF34: 135.23755 | AG34: 138.28474 | AH34: 138.12862 | AI34: 138.33 | AJ34: 136.80851 | AL34: 137.31119 | AM34: 137.72915 | AN34: 138.58944 | AO34: 140.43555 | AQ34: 144.1025 | AR34: 147.39073 | AS34: 150.18711 | AT34: 153.0155 | AV34: 156.46381 | AW34: 160.41676 | AX34: 162.91758 | AY34: 163.78973 | BA34: 165.68053 | BB34: 167.67569 | BC34: 166.64529 | BD34: 164.33214 | BF34: 162.47785 | BG34: 162.71301 | BH34: 163.32862 | BI34: 164.1039 | BK34: 167.6 | BL34: 172.58 | BM34: 176.68 | BN34: 179.62 | BP34: 187.94 | BQ34: 191.18 | BR34: 193.06 | BS34: 196.55 | BU34: =BS34+(BS34*2.26/100) -> 200.99203 | BV34: =BU34+(BU34*-0.35/100) -> 200.28856 | BW34: =BV34+(BV34*-0.95/100) -> 198.38582 | BX34: =BW34+(BW34*-0.14/100) -> 198.10808 | BZ34: =BX34+(BX34*0.36/100) -> 198.82127 | CA34: =BZ34+(BZ34*0.46/100) -> 199.73584 | CB34: =CA34+(CA34*-0.21/100) -> 199.3164 | CC34: =CB34+(CB34*0.74/100) -> 200.79134 | CE34: =CC34+(CC34*1.09/100) -> 202.97996
B35: Ubi Jalar | C35: 97.346001 | D35: 98.484423 | E35: 101.42212 | F35: 102.74746 | G35: 100 | H35: 104.42736 | I35: 106.80488 | J35: 108.78336 | K35: 110.4963 | L35: 107.62798 | M35: 111.28876 | N35: 112.05641 | O35: 113.51912 | P35: 114.42825 | Q35: 112.82314 | R35: 116.73409 | S35: 118.06317 | T35: 120.8646 | U35: 120.9041 | V35: 119.14149 | W35: 122.63553 | X35: 124.35192 | Y35: 127.7622 | Z35: 130.66783 | AA35: 126.35437 | AB35: 135.99566 | AC35: 136.80135 | AD35: 138.27422 | AE35: 140.53935 | AF35: 137.90265 | AG35: 142.62059 | AH35: 141.64751 | AI35: 141.26626 | AJ35: 139.41481 | AL35: 140.69959 | AM35: 142.57643 | AN35: 143.41012 | AO35: 144.61257 | AQ35: 146.79106 | AR35: 149.65805 | AS35: 149.549 | AT35: 151.72793 | AV35: 154.26061 | AW35: 155.74333 | AX35: 155.08802 | AY35: 156.84358 | BA35: 160.22771 | BB35: 162.11765 | BC35: 159.65454 | BD35: 155.01758 | BF35: 150.13998 | BG35: 152.02884 | BH35: 155.44997 | BI35: 160.65339 | BK35: 163.38 | BL35: 165.49 | BM35: 166.95 | BN35: 170.13 | BP35: 172.98 | BQ35: 173.85 | BR35: 175.57 | BS35: 181.24 | BU35: =BS35+(BS35*3.74/100) -> 188.01838 | BV35: =BU35+(BU35*1.55/100) -> 190.93266 | BW35: =BV35+(BV35*-0.1/100) -> 190.74173 | BX35: =BW35+(BW35*-0.89/100) -> 189.04413 | BZ35: =BX35+(BX35*-1.01/100) -> 187.13478 | CA35: =BZ35+(BZ35*-0.8/100) -> 185.6377 | CB35: =CA35+(CA35*2.77/100) -> 190.77987 | CC35: =CB35+(CB35*2.14/100) -> 194.86256 | CE35: =CC35+(CC35*1.04/100) -> 196.88913
B36: Kacang Tanah | C36: 96.928804 | D36: 98.127742 | E36: 101.28979 | F36: 103.65366 | G36: 100 | H36: 106.09533 | I36: 108.09087 | J36: 111.41615 | K36: 111.9322 | L36: 109.38364 | M36: 112.29779 | N36: 114.00981 | O36: 116.73226 | P36: 117.33912 | Q36: 115.09474 | R36: 119.11138 | S36: 119.35672 | T36: 123.18747 | U36: 123.21866 | V36: 121.21856 | W36: 123.62883 | X36: 124.32403 | Y36: 126.9855 | Z36: 129.6933 | AA36: 126.15792 | AB36: 131.52855 | AC36: 133.10297 | AD36: 140.06488 | AE36: 143.55904 | AF36: 137.06386 | AG36: 144.58514 | AH36: 144.37654 | AI36: 147.0652 | AJ36: 146.90137 | AL36: 147.25809 | AM36: 149.76626 | AN36: 152.07309 | AO36: 152.72935 | AQ36: 153.94871 | AR36: 154.64361 | AS36: 155.58077 | AT36: 155.07027 | AV36: 153.68779 | AW36: 155.78065 | AX36: 158.72305 | AY36: 160.89429 | BA36: 162.55718 | BB36: 163.99492 | BC36: 164.10995 | BD36: 162.87425 | BF36: 163.52638 | BG36: 165.6658 | BH36: 167.50179 | BI36: 168.28991 | BK36: 172.45 | BL36: 175.92 | BM36: 177.16 | BN36: 177.89 | BP36: 182.67 | BQ36: 184.11 | BR36: 185.43 | BS36: 187.42 | BU36: =BS36+(BS36*1.04/100) -> 189.36917 | BV36: =BU36+(BU36*1.08/100) -> 191.41436 | BW36: =BV36+(BV36*0.88/100) -> 193.0988 | BX36: =BW36+(BW36*-0.14/100) -> 192.82846 | BZ36: =BX36+(BX36*0.83/100) -> 194.42894 | CA36: =BZ36+(BZ36*0.51/100) -> 195.42053 | CB36: =CA36+(CA36*0.57/100) -> 196.53442 | CC36: =CB36+(CB36*1.06/100) -> 198.61769 | CE36: =CC36+(CC36*5.69/100) -> 209.91904
B37: Kedelai | C37: 99.010899 | D37: 98.595838 | E37: 100.37335 | F37: 102.01991 | G37: 100 | H37: 105.39287 | I37: 106.82915 | J37: 106.54069 | K37: 106.2051 | L37: 106.24195 | M37: 106.542 | N37: 107.14304 | O37: 109.11259 | P37: 110.59671 | Q37: 108.34859 | R37: 111.78622 | S37: 111.88649 | T37: 113.90777 | U37: 117.49808 | V37: 113.76964 | W37: 118.54435 | X37: 118.86949 | Y37: 119.15741 | Z37: 119.92688 | AA37: 119.12453 | AB37: 119.94817 | AC37: 120.18828 | AD37: 120.32029 | AE37: 119.35066 | AF37: 119.95185 | AG37: 120.68939 | AH37: 121.49236 | AI37: 122.62534 | AJ37: 123.02238 | AL37: 124.41192 | AM37: 125.21504 | AN37: 125.7499 | AO37: 125.82537 | AQ37: 138.38589 | AR37: 139.24463 | AS37: 142.30805 | AT37: 148.58428 | AV37: 126.94165 | AW37: 127.65115 | AX37: 128.89418 | AY37: 128.95897 | BA37: 131.01545 | BB37: 131.95829 | BC37: 132.35635 | BD37: 133.39771 | BF37: 135.07965 | BG37: 137.19881 | BH37: 138.24414 | BI37: 137.97754 | BK37: 139.2 | BL37: 139.64 | BM37: 140.47 | BN37: 143.37 | BP37: 145.89 | BQ37: 145.11 | BR37: 146.76 | BS37: 147.3 | BU37: =BS37+(BS37*0.77/100) -> 148.43421 | BV37: =BU37+(BU37*0.61/100) -> 149.33966 | BW37: =BV37+(BV37*-1.54/100) -> 147.03983 | BX37: =BW37+(BW37*-1.48/100) -> 144.86364 | BZ37: =BX37+(BX37*-0.23/100) -> 144.53045 | CA37: =BZ37+(BZ37*0.14/100) -> 144.73279 | CB37: =CA37+(CA37*0/100) -> 144.73279 | CC37: =CB37+(CB37*-0.11/100) -> 144.57359 | CE37: =CC37+(CC37*0.95/100) -> 145.94704
B38: Kacang Hijau | C38: 94.390885 | D38: 97.503925 | E38: 102.33628 | F38: 105.76891 | G38: 100 | H38: 113.26288 | I38: 115.50064 | J38: 116.06931 | K38: 113.15628 | L38: 114.49728 | M38: 111.16661 | N38: 110.62746 | O38: 111.06021 | P38: 111.27627 | Q38: 111.03264 | R38: 113.28684 | S38: 115.73455 | T38: 119.79438 | U38: 122.69132 | V38: 117.87677 | W38: 125.73405 | X38: 128.59308 | Y38: 130.63649 | Z38: 132.13582 | AA38: 129.27486 | AB38: 135.00847 | AC38: 136.91758 | AD38: 140.21037 | AE38: 141.05808 | AF38: 138.29862 | AG38: 141.67273 | AH38: 141.72615 | AI38: 142.55779 | AJ38: 139.84973 | AL38: 140.60391 | AM38: 143.44684 | AN38: 144.55439 | AO38: 144.83644 | AQ38: 147.51783 | AR38: 147.92695 | AS38: 147.78876 | AT38: 145.3168 | AV38: 147.65804 | AW38: 150.6882 | AX38: 151.84133 | AY38: 152.56356 | BA38: 152.71322 | BB38: 157.74043 | BC38: 158.11952 | BD38: 157.87955 | BF38: 159.57329 | BG38: 163.29695 | BH38: 163.45674 | BI38: 163.54745 | BK38: 164.56 | BL38: 167.77 | BM38: 168.94 | BN38: 171.36 | BP38: 175.74 | BQ38: 176.45 | BR38: 176.2 | BS38: 174.73 | BU38: =BS38+(BS38*0.1/100) -> 174.90473 | BV38: =BU38+(BU38*0.58/100) -> 175.91918 | BW38: =BV38+(BV38*0.29/100) -> 176.42934 | BX38: =BW38+(BW38*-1.05/100) -> 174.57683 | BZ38: =BX38+(BX38*-0.28/100) -> 174.08802 | CA38: =BZ38+(BZ38*3.69/100) -> 180.51187 | CB38: =CA38+(CA38*-0.26/100) -> 180.04254 | CC38: =CB38+(CB38*2.27/100) -> 184.1295 | CE38: =CC38+(CC38*4.81/100) -> 192.98613
BU39: =BU32/BS32*100-100 -> 2.89
BU40: =BU32/BP32*100-100 -> 5.267132
B41: Y-on Y
C42: 2010 | H42: 2011 | M42: 2012 | R42: 2013 | W42: 2014 | AB42: 2015 | AG42: 2016 | AL42: 2017 | AQ42: 2018 | AV42: 2019 | BA42: 2020 | BF42: 2021 | BK42: 2022 | BP42: 2023 | BU42: 2024 | BZ42: 2025 | CE42: 2026 | CJ42: 2027
C43: triw.1 | D43: triw.2 | E43: triw.3 | F43: triw.4 | H43: triw.1 | I43: triw.2 | J43: triw.3 | K43: triw.4 | M43: triw.1 | N43: triw.2 | O43: triw.3 | P43: triw.4 | R43: triw.1 | S43: triw.2 | T43: triw.3 | U43: triw.4 | W43: triw.1 | X43: triw.2 | Y43: triw.3 | Z43: triw.4 | AB43: triw.1 | AC43: triw.2 | AD43: triw.3 | AE43: triw.4 | AG43: triw.1 | AH43: triw.2 | AI43: triw.3 | AJ43: triw.4 | AL43: triw.1 | AM43: triw.2 | AN43: triw.3 | AO43: triw.4 | AQ43: triw.1 | AR43: triw.2 | AS43: triw.3 | AT43: triw.4 | AV43: triw.1 | AW43: triw.2 | AX43: triw.3 | AY43: triw.4 | BA43: triw.1 | BB43: triw.2 | BC43: triw.3 | BD43: triw.4 | BF43: triw.1 | BG43: triw.2 | BH43: triw.3 | BI43: triw.4 | BK43: triw.1 | BL43: triw.2 | BM43: triw.3 | BN43: triw.4 | BP43: triw.1 | BQ43: triw.2 | BR43: triw.3 | BS43: triw.4 | BU43: triw.1 | BV43: triw.2 | BW43: triw.3 | BX43: triw.4 | BZ43: triw.1 | CA43: triw.2 | CB43: triw.3 | CC43: triw.4 | CE43: triw.1 | CF43: triw.2 | CG43: triw.3 | CH43: triw.4 | CJ43: triw.1 | CK43: triw.2 | CL43: triw.3 | CM43: triw.4
...

Sheet ADHK
A1: Home | B1: 1.1 Pertanian, Kehutanan & Perikanan | D1: 2010 | E1: 2012 | F1: 2014 | G1: 2016 | H1: 2018 | I1: 2020 | J1: 2022 | K1: 2024 | U1: 2010 | V1: 2012 | W1: 2014 | X1: 2016 | Y1: 2018 | Z1: 2020 | AA1: 2022 | AB1: 2024 | AL1: 2010 | AM1: 2012 | AN1: 2014 | AO1: 2016 | AP1: 2018 | AQ1: 2020 | AR1: 2022 | AS1: 2024 | BC1: 2010 | BD1: 2012 | BE1: 2014 | BF1: 2016 | BG1: 2018 | BH1: 2020 | BI1: 2022 | BJ1: 2024 | BT1: 2010 | BU1: 2012 | BV1: 2014 | BW1: 2016 | BX1: 2018 | BY1: 2020 | BZ1: 2022 | CA1: 2024 | CK1: 2010 | CL1: 2012 | CM1: 2014 | CN1: 2016 | CO1: 2018 | CP1: 2020 | CQ1: 2022 | CR1: 2024 | DB1: 2010 | DC1: 2012 | DD1: 2014 | DE1: 2016 | DF1: 2018 | DG1: 2020 | DH1: 2022 | DI1: 2024 | DS1: 2010 | DT1: 2012 | DU1: 2014 | DV1: 2016 | DW1: 2018 | DX1: 2020 | DY1: 2022 | DZ1: 2024 | EJ1: 2010 | EK1: 2012 | EL1: 2014 | EM1: 2016 | EN1: 2018 | EO1: 2020 | EP1: 2022 | EQ1: 2024 | FA1: 2010 | FB1: 2012 | FC1: 2014 | FD1: 2016 | FE1: 2018 | FF1: 2020 | FG1: 2022 | FH1: 2024 | FR1: 2010 | FS1: 2012 | FT1: 2014 | FU1: 2016 | FV1: 2018 | FW1: 2020 | FX1: 2022 | FY1: 2024 | GI1: 2010 | GJ1: 2012 | GK1: 2014 | GL1: 2016 | GM1: 2018 | GN1: 2020 | GO1: 2022 | GP1: 2024 | GZ1: 2010 | HA1: 2012 | HB1: 2014 | HC1: 2016 | HD1: 2018 | HE1: 2020 | HF1: 2022 | HG1: 2024 | HQ1: 2010 | HR1: 2012 | HS1: 2014 | HT1: 2016 | HU1: 2018 | HV1: 2020 | HW1: 2022 | HX1: 2024 | IH1: 2010 | II1: 2012 | IJ1: 2014 | IK1: 2016 | IL1: 2018 | IM1: 2020 | IN1: 2022 | IO1: 2024 | IY1: 2010 | IZ1: 2012 | JA1: 2014 | JB1: 2016 | JC1: 2018 | JD1: 2020 | JE1: 2022 | JF1: 2024 | JP1: 2010 | JQ1: 2012 | JR1: 2014 | JS1: 2016 | JT1: 2018 | JU1: 2020 | JV1: 2022 | JW1: 2024 | KG1: 2010 | KH1: 2012 | KI1: 2014 | KJ1: 2016 | KK1: 2018 | KL1: 2020 | KM1: 2022 | KN1: 2024
D2: 2011 | E2: 2013 | F2: 2015 | G2: 2017 | H2: 2019 | I2: 2021 | J2: 2023 | K2: 2025 | U2: 2011 | V2: 2013 | W2: 2015 | X2: 2017 | Y2: 2019 | Z2: 2021 | AA2: 2023 | AB2: 2025 | AL2: 2011 | AM2: 2013 | AN2: 2015 | AO2: 2017 | AP2: 2019 | AQ2: 2021 | AR2: 2023 | AS2: 2025 | BC2: 2011 | BD2: 2013 | BE2: 2015 | BF2: 2017 | BG2: 2019 | BH2: 2021 | BI2: 2023 | BJ2: 2025 | BT2: 2011 | BU2: 2013 | BV2: 2015 | BW2: 2017 | BX2: 2019 | BY2: 2021 | BZ2: 2023 | CA2: 2025 | CK2: 2011 | CL2: 2013 | CM2: 2015 | CN2: 2017 | CO2: 2019 | CP2: 2021 | CQ2: 2023 | CR2: 2025 | DB2: 2011 | DC2: 2013 | DD2: 2015 | DE2: 2017 | DF2: 2019 | DG2: 2021 | DH2: 2023 | DI2: 2025 | DS2: 2011 | DT2: 2013 | DU2: 2015 | DV2: 2017 | DW2: 2019 | DX2: 2021 | DY2: 2023 | DZ2: 2025 | EJ2: 2011 | EK2: 2013 | EL2: 2015 | EM2: 2017 | EN2: 2019 | EO2: 2021 | EP2: 2023 | EQ2: 2025 | FA2: 2011 | FB2: 2013 | FC2: 2015 | FD2: 2017 | FE2: 2019 | FF2: 2021 | FG2: 2023 | FH2: 2025 | FR2: 2011 | FS2: 2013 | FT2: 2015 | FU2: 2017 | FV2: 2019 | FW2: 2021 | FX2: 2023 | FY2: 2025 | GI2: 2011 | GJ2: 2013 | GK2: 2015 | GL2: 2017 | GM2: 2019 | GN2: 2021 | GO2: 2023 | GP2: 2025 | GZ2: 2011 | HA2: 2013 | HB2: 2015 | HC2: 2017 | HD2: 2019 | HE2: 2021 | HF2: 2023 | HG2: 2025 | HQ2: 2011 | HR2: 2013 | HS2: 2015 | HT2: 2017 | HU2: 2019 | HV2: 2021 | HW2: 2023 | HX2: 2025 | IH2: 2011 | II2: 2013 | IJ2: 2015 | IK2: 2017 | IL2: 2019 | IM2: 2021 | IN2: 2023 | IO2: 2025 | IY2: 2011 | IZ2: 2013 | JA2: 2015 | JB2: 2017 | JC2: 2019 | JD2: 2021 | JE2: 2023 | JF2: 2025 | JP2: 2011 | JQ2: 2013 | JR2: 2015 | JS2: 2017 | JT2: 2019 | JU2: 2021 | JV2: 2023 | JW2: 2025 | KG2: 2011 | KH2: 2013 | KI2: 2015 | KJ2: 2017 | KK2: 2019 | KL2: 2021 | KM2: 2023 | KN2: 2025
B4: Wilayah | C4: : Provinsi Sulawesi Tenggara | G4: Lembar Pengolahan Penghitungan | P4: ADHK | S4: Wilayah | T4: : Provinsi Sulawesi Tenggara | X4: Lembar Pengolahan Penghitungan | AG4: ADHK | AJ4: Wilayah | AK4: : Provinsi Sulawesi Tenggara | AO4: Lembar Pengolahan Penghitungan | AX4: ADHK | BA4: Wilayah | BB4: : Provinsi Sulawesi Tenggara | BF4: Lembar Pengolahan Penghitungan | BO4: ADHK | BR4: Wilayah | BS4: : Provinsi Sulawesi Tenggara | BW4: Lembar Pengolahan Penghitungan | CF4: ADHK | CI4: Wilayah | CJ4: : Provinsi Sulawesi Tenggara | CN4: Lembar Pengolahan Penghitungan | CW4: ADHK | CZ4: Wilayah | DA4: : Provinsi Sulawesi Tenggara | DE4: Lembar Pengolahan Penghitungan | DN4: ADHK | DQ4: Wilayah | DR4: : Provinsi Sulawesi Tenggara | DV4: Lembar Pengolahan Penghitungan | EE4: ADHK | EH4: Wilayah | EI4: : Provinsi Sulawesi Tenggara | EM4: Lembar Pengolahan Penghitungan | EV4: ADHK | EY4: Wilayah | EZ4: : Provinsi Sulawesi Tenggara | FD4: Lembar Pengolahan Penghitungan | FM4: ADHK | FP4: Wilayah | FQ4: : Provinsi Sulawesi Tenggara | FU4: Lembar Pengolahan Penghitungan | GD4: ADHK | GG4: Wilayah | GH4: : Provinsi Sulawesi Tenggara | GL4: Lembar Pengolahan Penghitungan | GU4: ADHK | GX4: Wilayah | GY4: : Provinsi Sulawesi Tenggara | HC4: Lembar Pengolahan Penghitungan | HL4: ADHK | HO4: Wilayah | HP4: : Provinsi Sulawesi Tenggara | HT4: Lembar Pengolahan Penghitungan | IC4: ADHK | IF4: Wilayah | IG4: : Provinsi Sulawesi Tenggara | IK4: Lembar Pengolahan Penghitungan | IT4: ADHK | IW4: Wilayah | IX4: : Provinsi Sulawesi Tenggara | JB4: Lembar Pengolahan Penghitungan | JK4: ADHK | JN4: Wilayah | JO4: : Provinsi Sulawesi Tenggara | JS4: Lembar Pengolahan Penghitungan | KB4: ADHK | KE4: Wilayah | KF4: : Provinsi Sulawesi Tenggara | KJ4: Lembar Pengolahan Penghitungan | KS4: ADHK
B5: Kategori | C5: : Pertanian, Kehutanan, dan Perikanan | G5: Nilai Tambah Bruto | S5: Kategori | T5: : Pertanian, Kehutanan, dan Perikanan | X5: Nilai Tambah Bruto | AJ5: Kategori | AK5: : Pertanian, Kehutanan, dan Perikanan | AO5: Nilai Tambah Bruto | BA5: Kategori | BB5: : Pertanian, Kehutanan, dan Perikanan | BF5: Nilai Tambah Bruto | BR5: Kategori | BS5: : Pertanian, Kehutanan, dan Perikanan | BW5: Nilai Tambah Bruto | CI5: Kategori | CJ5: : Pertanian, Kehutanan, dan Perikanan | CN5: Nilai Tambah Bruto | CZ5: Kategori | DA5: : Pertanian, Kehutanan, dan Perikanan | DE5: Nilai Tambah Bruto | DQ5: Kategori | DR5: : Pertanian, Kehutanan, dan Perikanan | DV5: Nilai Tambah Bruto | EH5: Kategori | EI5: : Pertanian, Kehutanan, dan Perikanan | EM5: Nilai Tambah Bruto | EY5: Kategori | EZ5: : Pertanian, Kehutanan, dan Perikanan | FD5: Nilai Tambah Bruto | FP5: Kategori | FQ5: : Pertanian, Kehutanan, dan Perikanan | FU5: Nilai Tambah Bruto | GG5: Kategori | GH5: : Pertanian, Kehutanan, dan Perikanan | GL5: Nilai Tambah Bruto | GX5: Kategori | GY5: : Pertanian, Kehutanan, dan Perikanan | HC5: Nilai Tambah Bruto | HO5: Kategori | HP5: : Pertanian, Kehutanan, dan Perikanan | HT5: Nilai Tambah Bruto | IF5: Kategori | IG5: : Pertanian, Kehutanan, dan Perikanan | IK5: Nilai Tambah Bruto | IW5: Kategori | IX5: : Pertanian, Kehutanan, dan Perikanan | JB5: Nilai Tambah Bruto | JN5: Kategori | JO5: : Pertanian, Kehutanan, dan Perikanan | JS5: Nilai Tambah Bruto | KE5: Kategori | KF5: : Pertanian, Kehutanan, dan Perikanan | KJ5: Nilai Tambah Bruto
