Workbook
Name BERLAKU: #REF!
Name BERLAKU: #REF!
Name H: #REF!

Sheet Home
A1: HOME
B2: SISTEM | H2: ALAT BANTU PENGHITUNGAN ANGKA PDRB MENURUT LAPANGAN USAHA
B3: INFORMASI
B4: RILIS
B5: ANGKA PDRB | K5: LAPANGAN USAHA | O5: : | P5: =mid(ADHB!C5,3,9)&" "&mid(ADHB!C7,3,100) -> Pertanian Tanaman Hortikultura Semusim
B6: MELALUI LEMBAR KERJA | K6: WILAYAH | O6: : | P6: Provinsi Sulawesi Tenggara
B7: BERBASIS | K7: TAHUN | O7: : | P7: =IFERROR(__xludf.DUMMYFUNCTION("IMPORTRANGE(""https://docs.google.com/spreadsheets/d/14EziMEzuXiAhzZqRuQw8kN9sLyynoE6QsPgaj062Fa0/edit#gid=214337323"",""'LK PDRB Lapus'!E3:E4"")"),2026.0) -> 2026
B8: ONLINE | K8: TRIWULAN | O8: : | P8: =IFERROR(__xludf.DUMMYFUNCTION("""COMPUTED_VALUE"""),"I") -> I
B11: INPUT DATA | K11: OUTPUT | T11: MONEV
B15: 1 | C15: Lembar Kerja Penghitungan PDRB Atas Dasar Harga Berlaku | K15: 1 | L15: Rekap Angka PDRB Lapangan Usaha | T15: 1 | U15: MONEV Pemasukan Data
B16: =B15+1 -> 2 | C16: Lembar Kerja Penghitungan PDRB Atas Dasar Harga Konstan | K16: =K15+1 -> 2 | T16: =T15+1 -> 2

Sheet Produksi dan Harga
A1: PRODUKSI HORTIKULTURA SEMUSIM | AS1: =SUM(AS4:AS27) -> 60337 | AW1: =SUM(AW4:AW27) -> 71317 | AX1: =SUM(AX4:AX27) -> 65645
A2: Sayur Buah Semusim | C2: satuan | D2: 2010 | I2: 2011 | N2: 2012 | S2: 2013 | X2: 2014 | AC2: 2015 | AH2: 2016 | AM2: 2017 | AR2: 2018 | AW2: 2019 | BB2: 2020 | BG2: 2021 | BL2: 2022 | BQ2: 2023 | BV2: 2024 | CA2: 2025 | CF2: 2026
D3: Triw.1 | E3: Triw.2 | F3: Triw.3 | G3: Triw.4 | H3: Jumlah | I3: Triw.1 | J3: Triw.2 | K3: Triw.3 | L3: Triw.4 | M3: Jumlah | N3: Triw.1 | O3: Triw.2 | P3: Triw.3 | Q3: Triw.4 | R3: Jumlah | S3: Triw.1 | T3: Triw.2 | U3: Triw.3 | V3: Triw.4 | W3: Jumlah | X3: Triw.1 | Y3: Triw.2 | Z3: Triw.3 | AA3: Triw.4 | AB3: Jumlah | AC3: Triw.1 | AD3: Triw.2 | AE3: Triw.3 | AF3: Triw.4 | AG3: Jumlah | AH3: Triw.1 | AI3: Triw.2 | AJ3: Triw.3 | AK3: Triw.4 | AL3: Jumlah | AM3: Triw.1 | AN3: Triw.2 | AO3: Triw.3 | AP3: Triw.4 | AQ3: Jumlah | AR3: Triw.1 | AS3: Triw.2 | AT3: Triw.3 | AU3: Triw.4 | AV3: Jumlah | AW3: Triw.1 | AX3: Triw.2 | AY3: Triw.3 | AZ3: Triw.4 | BA3: Jumlah | BB3: Triw.1 | BC3: Triw.2 | BD3: Triw.3 | BE3: Triw.4 | BF3: Jumlah | BG3: Triw.1 | BH3: Triw.2 | BI3: Triw.3 | BJ3: Triw.4 | BK3: Jumlah | BL3: Triw. 1 | BM3: Triw.2 | BN3: Triw.3 | BO3: Triw.4 | BP3: Jumlah | BQ3: Triw. 1 | BR3: Triw.2 | BS3: Triw.3 | BT3: Triw.4 | BU3: Jumlah | BV3: Triw. 1 | BW3: Triw.2 | BX3: Triw.3 | BY3: Triw.4 | BZ3: Jumlah | CA3: Triw. 1 | CB3: Triw.2 | CC3: Triw.3 | CD3: Triw.4 | CE3: Jumlah | CF3: Triw. 1 | CG3: Triw.2 | CH3: Triw.3 | CI3: Triw.4 | CJ3: Jumlah
A4: 1 | B4: Kentang | C4: kuintal | D4: 0 | E4: 0 | F4: 0 | G4: 0 | H4: 0 | I4: 0 | J4: 0 | K4: 0 | L4: 0 | M4: 0 | N4: 0 | O4: 0 | P4: 0 | Q4: 0 | R4: 0 | S4: 0 | T4: 0 | U4: 0 | V4: 0 | W4: 0 | X4: 0 | Y4: 0 | Z4: 0 | AA4: 0 | AB4: 0 | AC4: 250 | AD4: 0 | AE4: 0 | AF4: 0 | AG4: 250 | AH4: 57 | AI4: 0 | AJ4: 0 | AK4: 0 | AL4: 57 | AM4: 0 | AN4: 0 | AO4: 0 | AP4: 0 | AQ4: 0 | AR4: 0 | AS4: 0 | AT4: 0 | AU4: 0 | AV4: 0 | AW4: 20 | AX4: 0 | AY4: 0 | AZ4: 28 | BA4: =SUM(AW4:AZ4) -> 48 | BB4: 0 | BC4: 0 | BD4: 0 | BE4: 0 | BF4: =SUM(BB4:BE4) -> 0 | BG4: 0 | BH4: 0 | BI4: 0 | BJ4: 0 | BK4: =SUM(BG4:BJ4) -> 0 | BL4: 0 | BM4: 0 | BN4: 0 | BO4: 0 | BP4: =SUM(BL4:BO4) -> 0 | BQ4: 0 | BR4: 0 | BS4: 2 | BT4: 4 | BU4: =SUM(BQ4:BT4) -> 6 | BV4: 6 | BW4: 4 | BX4: 11 | BY4: 32 | BZ4: =SUM(BV4:BY4) -> 53 | CA4: 6 | CB4: 4 | CC4: 5 | CD4: 8 | CE4: =SUM(CA4:CD4) -> 23 | CF4: 0 | CJ4: =SUM(CF4:CI4) -> 0
A5: 2 | B5: Bawang Merah | C5: kuintal | D5: 4371 | E5: 1371 | F5: 622 | G5: 98 | H5: 6462 | I5: 296 | J5: 262 | K5: 516 | L5: 142 | M5: 1216 | N5: 611 | O5: 486 | P5: 745 | Q5: 157 | R5: 1999 | S5: 225 | T5: 53 | U5: 112 | V5: 67 | W5: 457 | X5: 1874 | Y5: 183 | Z5: 1447 | AA5: 65 | AB5: 3569 | AC5: 5506 | AD5: 420 | AE5: 659 | AF5: 1299 | AG5: 7884 | AH5: 5202 | AI5: 1357 | AJ5: 1770 | AK5: 590 | AL5: 8919 | AM5: 1242 | AN5: 1170 | AO5: 502 | AP5: 1064 | AQ5: 3978 | AR5: 2042 | AS5: 645 | AT5: 647 | AU5: 1523 | AV5: 4857 | AW5: 2305 | AX5: 415 | AY5: 318 | AZ5: 862 | BA5: =SUM(AW5:AZ5) -> 3900 | BB5: 1710 | BC5: 372 | BD5: 1534 | BE5: 2248 | BF5: =SUM(BB5:BE5) -> 5864 | BG5: 3138.4 | BH5: 1245 | BI5: 1676.8 | BJ5: 665.4 | BK5: =SUM(BG5:BJ5) -> 6725.6 | BL5: 1452 | BM5: 1497.5 | BN5: 858.58 | BO5: 685.1 | BP5: =SUM(BL5:BO5) -> 4493.18 | BQ5: 2293.13 | BR5: 626.04 | BS5: 1118 | BT5: 870.25 | BU5: =SUM(BQ5:BT5) -> 4907.42 | BV5: 4365.36 | BW5: 1235.1 | BX5: 737.52 | BY5: 1483.5 | BZ5: =SUM(BV5:BY5) -> 7821.48 | CA5: 1808.83 | CB5: 577.12 | CC5: 719 | CD5: 865.4 | CE5: =SUM(CA5:CD5) -> 3970.35 | CF5: 773.48 | CJ5: =SUM(CF5:CI5) -> 773.48
A6: 3 | B6: Bawang Putih | C6: kuintal | D6: 0 | E6: 0 | F6: 0 | G6: 0 | H6: 0 | I6: 0 | J6: 0 | K6: 0 | L6: 0 | M6: 0 | N6: 0 | O6: 0 | P6: 0 | Q6: 0 | R6: 0 | S6: 0 | T6: 0 | U6: 0 | V6: 0 | W6: 0 | X6: 0 | Y6: 0 | Z6: 0 | AA6: 0 | AB6: 0 | AC6: 0 | AD6: 0 | AE6: 0 | AF6: 0 | AG6: 0 | AH6: 0 | AI6: 0 | AJ6: 0 | AK6: 0 | AL6: 0 | AM6: 0 | AN6: 0 | AO6: 0 | AP6: 10 | AQ6: 10 | AR6: 0 | AS6: 0 | AT6: 2 | AU6: 0 | AV6: 2 | AW6: 0 | AX6: 0 | AY6: 0 | AZ6: 0 | BA6: =SUM(AW6:AZ6) -> 0 | BB6: 0 | BC6: 0 | BD6: 0 | BE6: 0 | BF6: =SUM(BB6:BE6) -> 0 | BG6: - | BH6: - | BI6: - | BJ6: - | BK6: =SUM(BG6:BJ6) -> 0 | BL6: 0 | BM6: 0 | BN6: 0 | BO6: 0 | BP6: =SUM(BL6:BO6) -> 0 | BQ6: 0 | BR6: 0 | BS6: 0 | BT6: 0 | BU6: =SUM(BQ6:BT6) -> 0 | BV6: 0 | BW6: 0 | BX6: 0 | BY6: 0 | BZ6: =SUM(BV6:BY6) -> 0 | CA6: - | CB6: - | CC6: - | CD6: - | CE6: =SUM(CA6:CD6) -> 0 | CF6: 0 | CJ6: =SUM(CF6:CI6) -> 0
A7: 4 | B7: Bawang Daun | C7: kuintal | D7: 4037 | E7: 1886 | F7: 1922 | G7: 2494 | H7: 10339 | I7: 2210 | J7: 1479 | K7: 1839 | L7: 2034 | M7: 7562 | N7: 2553 | O7: 2289 | P7: 2449 | Q7: 1691 | R7: 8982 | S7: 1560 | T7: 1998 | U7: 1225 | V7: 1317 | W7: 6100 | X7: 1609 | Y7: 1361 | Z7: 1005 | AA7: 707 | AB7: 4682 | AC7: 692 | AD7: 863 | AE7: 930 | AF7: 282 | AG7: 2767 | AH7: 583 | AI7: 844 | AJ7: 1120 | AK7: 657 | AL7: 3204 | AM7: 814 | AN7: 802 | AO7: 976 | AP7: 792 | AQ7: 3384 | AR7: 1652 | AS7: 1187 | AT7: 826 | AU7: 759 | AV7: 4424 | AW7: 790 | AX7: 1035 | AY7: 658 | AZ7: 853 | BA7: =SUM(AW7:AZ7) -> 3336 | BB7: 859 | BC7: 1219 | BD7: 908 | BE7: 829.4 | BF7: =SUM(BB7:BE7) -> 3815.4 | BG7: 1227.2 | BH7: 1467.2 | BI7: 1199.3 | BJ7: 1190.5 | BK7: =SUM(BG7:BJ7) -> 5084.2 | BL7: 1130.75 | BM7: 1002.87 | BN7: 1052.63 | BO7: 876.05 | BP7: =SUM(BL7:BO7) -> 4062.3 | BQ7: 1900.9 | BR7: 1359.37 | BS7: 1269.8 | BT7: 1172.43 | BU7: =SUM(BQ7:BT7) -> 5702.5 | BV7: 1167.98 | BW7: 1167.98 | BX7: 778.53 | BY7: 1167.92 | BZ7: =SUM(BV7:BY7) -> 4282.41 | CA7: 1135.75 | CB7: 1470.05 | CC7: 1496.26 | CD7: 1612.3 | CE7: =SUM(CA7:CD7) -> 5714.36 | CF7: 1243.72 | CJ7: =SUM(CF7:CI7) -> 1243.72
A8: 5 | B8: Kubis/Kol | C8: kuintal | D8: 6100 | E8: 1650 | F8: 1603 | G8: 3219 | H8: 12572 | I8: 1892 | J8: 1304 | K8: 839 | L8: 1276 | M8: 5311 | N8: 1267 | O8: 2744 | P8: 1950 | Q8: 1082 | R8: 7043 | S8: 1021 | T8: 958 | U8: 824 | V8: 941 | W8: 3744 | X8: 874 | Y8: 1124 | Z8: 797 | AA8: 605 | AB8: 3400 | AC8: 1319 | AD8: 906 | AE8: 976 | AF8: 274 | AG8: 3475 | AH8: 665 | AI8: 482 | AJ8: 520 | AK8: 676 | AL8: 2343 | AM8: 482 | AN8: 202 | AO8: 206 | AP8: 767 | AQ8: 1657 | AR8: 226 | AS8: 630 | AT8: 294 | AU8: 363 | AV8: 1513 | AW8: 158 | AX8: 71 | AY8: 133 | AZ8: 343 | BA8: =SUM(AW8:AZ8) -> 705 | BB8: 72 | BC8: 83 | BD8: 491 | BE8: 579 | BF8: =SUM(BB8:BE8) -> 1225 | BG8: 253 | BH8: 199.1 | BI8: 370 | BJ8: 390 | BK8: =SUM(BG8:BJ8) -> 1212.1 | BL8: 535.16 | BM8: 1199.1 | BN8: 1075.9 | BO8: 837.6 | BP8: =SUM(BL8:BO8) -> 3647.76 | BQ8: 426.5 | BR8: 874 | BS8: 451 | BT8: 801 | BU8: =SUM(BQ8:BT8) -> 2552.5 | BV8: 469.18 | BW8: 848.9 | BX8: 1321.4 | BY8: 991.5 | BZ8: =SUM(BV8:BY8) -> 3630.98 | CA8: 811.45 | CB8: 768 | CC8: 1638 | CD8: 1211 | CE8: =SUM(CA8:CD8) -> 4428.45 | CF8: 354.7 | CJ8: =SUM(CF8:CI8) -> 354.7
A9: 6 | B9: Petsai/Sawi | C9: kuintal | D9: 9687 | E9: 5037 | F9: 5742 | G9: 6341 | H9: 26807 | I9: 6472 | J9: 5079 | K9: 7050 | L9: 7500 | M9: 26101 | N9: 8118 | O9: 5846 | P9: 6835 | Q9: 5582 | R9: 26381 | S9: 4744 | T9: 5119 | U9: 5151 | V9: 7139 | W9: 22153 | X9: 4411 | Y9: 4007 | Z9: 3660 | AA9: 2717 | AB9: 14795 | AC9: 3208 | AD9: 3597 | AE9: 3444 | AF9: 2244 | AG9: 12493 | AH9: 2210 | AI9: 2678 | AJ9: 3680 | AK9: 3342 | AL9: 11910 | AM9: 2429 | AN9: 2818 | AO9: 2770 | AP9: 3183 | AQ9: 11200 | AR9: 3186 | AS9: 2832 | AT9: 2033 | AU9: 2424 | AV9: 10475 | AW9: 2978 | AX9: 2745 | AY9: 2688 | AZ9: 1783 | BA9: =SUM(AW9:AZ9) -> 10194 | BB9: 2012 | BC9: 2183 | BD9: 2180 | BE9: 2558.5 | BF9: =SUM(BB9:BE9) -> 8933.5 | BG9: 2999 | BH9: 2959.95 | BI9: 1815.1 | BJ9: 3094 | BK9: =SUM(BG9:BJ9) -> 10868.05 | BL9: 3596.65 | BM9: 3023.19 | BN9: 3777.18 | BO9: 4127.36 | BP9: =SUM(BL9:BO9) -> 14524.38 | BQ9: 3950.72 | BR9: 4353.78 | BS9: 4268.38 | BT9: 3469.46 | BU9: =SUM(BQ9:BT9) -> 16042.34 | BV9: 3864.25 | BW9: 2789.93 | BX9: 3360.35 | BY9: 3272.6 | BZ9: =SUM(BV9:BY9) -> 13287.13 | CA9: 3532.94 | CB9: 5667.15 | CC9: 5818.18 | CD9: 4706.51 | CE9: =SUM(CA9:CD9) -> 19724.78 | CF9: 4289.42 | CJ9: =SUM(CF9:CI9) -> 4289.42
A10: 7 | B10: Wortel | C10: kg | D10: 5 | E10: 3 | F10: 317 | G10: 37 | H10: 362 | I10: 22 | J10: 57 | K10: 139 | L10: 133 | M10: 351 | N10: 14 | O10: 28 | P10: 0 | Q10: 0 | R10: 42 | S10: 0 | T10: 0 | U10: 0 | V10: 0 | W10: 0 | X10: 9 | Y10: 0 | Z10: 0 | AA10: 0 | AB10: 9 | AC10: 0 | AD10: 3 | AE10: 0 | AF10: 8 | AG10: 11 | AH10: 0 | AI10: 0 | AJ10: 0 | AK10: 0 | AL10: 0 | AM10: 0 | AN10: 0 | AO10: 0 | AP10: 2 | AQ10: 2 | AR10: 0 | AS10: 4 | AT10: 0 | AU10: 0 | AV10: 4 | AW10: 0 | AX10: 0 | AY10: 20 | AZ10: 0 | BA10: =SUM(AW10:AZ10) -> 20 | BB10: 0 | BC10: 0 | BD10: 0 | BE10: 0 | BF10: =SUM(BB10:BE10) -> 0 | BG10: - | BH10: - | BI10: 15 | BJ10: - | BK10: =SUM(BG10:BJ10) -> 15 | BL10: 0 | BM10: 0 | BN10: 0 | BO10: 0 | BP10: =SUM(BL10:BO10) -> 0 | BQ10: 0 | BR10: 0 | BS10: 0 | BT10: 0 | BU10: =SUM(BQ10:BT10) -> 0 | BV10: 0 | BW10: 0 | BX10: 0 | BY10: 0 | BZ10: =SUM(BV10:BY10) -> 0 | CA10: - | CB10: - | CC10: - | CD10: - | CE10: =SUM(CA10:CD10) -> 0 | CF10: 27 | CJ10: =SUM(CF10:CI10) -> 27
A11: 8 | B11: Kacang Panjang | C11: kuintal | D11: 43746 | E11: 34132 | F11: 18905 | G11: 22575 | H11: 119358 | I11: 22405 | J11: 18695 | K11: 20024 | L11: 19671 | M11: 80795 | N11: 32504 | O11: 23736 | P11: 26251 | Q11: 17282 | R11: 99773 | S11: 22311 | T11: 29529 | U11: 24266 | V11: 22365 | W11: 98471 | X11: 30758 | Y11: 29275 | Z11: 24446 | AA11: 15448 | AB11: 99927 | AC11: 10480 | AD11: 9839 | AE11: 7796 | AF11: 4438 | AG11: 32553 | AH11: 7704 | AI11: 18607 | AJ11: 20632 | AK11: 17405 | AL11: 64348 | AM11: 10479 | AN11: 10156 | AO11: 7462 | AP11: 7012 | AQ11: 35109 | AR11: 11008 | AS11: 9630 | AT11: 7534 | AU11: 8398 | AV11: 36570 | AW11: 10588 | AX11: 11200 | AY11: 15619 | AZ11: 9305 | BA11: =SUM(AW11:AZ11) -> 46712 | BB11: 6556 | BC11: 7869 | BD11: 12840 | BE11: 12269 | BF11: =SUM(BB11:BE11) -> 39534 | BG11: 14329.8 | BH11: 10537.7 | BI11: 8688.2 | BJ11: 9572.39 | BK11: =SUM(BG11:BJ11) -> 43128.09 | BL11: 9520.88 | BM11: 8324.7 | BN11: 10032.29 | BO11: 10333.06 | BP11: =SUM(BL11:BO11) -> 38210.93 | BQ11: 10610.82 | BR11: 10253.51 | BS11: 9685.49 | BT11: 6122.42 | BU11: =SUM(BQ11:BT11) -> 36672.24 | BV11: 9229.86 | BW11: 8115.11 | BX11: 8371.98 | BY11: 8827.35 | BZ11: =SUM(BV11:BY11) -> 34544.3 | CA11: 7849.58 | CB11: 10735.05 | CC11: 12440.5 | CD11: 8768.63 | CE11: =SUM(CA11:CD11) -> 39793.76 | CF11: 11959.13 | CJ11: =SUM(CF11:CI11) -> 11959.13
A12: 9 | B12: Tomat | C12: kuintal | D12: 36536 | E12: 26315 | F12: 16061 | G12: 17829 | H12: 96741 | I12: 16313 | J12: 14148 | K12: 16756 | L12: 15066 | M12: 62283 | N12: 34455 | O12: 18091 | P12: 22804 | Q12: 16881 | R12: 92231 | S12: 16094 | T12: 22060 | U12: 17466 | V12: 16278 | W12: 71898 | X12: 23044 | Y12: 28386 | Z12: 20021 | AA12: 14561 | AB12: 86012 | AC12: 9088 | AD12: 8062 | AE12: 4085.27 | AF12: 4817 | AG12: 26052.27 | AH12: 8530 | AI12: 20503 | AJ12: 21217 | AK12: 17707 | AL12: 67957 | AM12: 10882 | AN12: 7636 | AO12: 7123 | AP12: 7099 | AQ12: 32740 | AR12: 12535 | AS12: 8959 | AT12: 7216 | AU12: 9201 | AV12: 37911 | AW12: 13610 | AX12: 9629 | AY12: 23053 | AZ12: 9930 | BA12: =SUM(AW12:AZ12) -> 56222 | BB12: 9569.8 | BC12: 8996.4 | BD12: 15067.5 | BE12: 14567.8 | BF12: =SUM(BB12:BE12) -> 48201.5 | BG12: 15975.3 | BH12: 12365.75 | BI12: 10364.8 | BJ12: 9334.16 | BK12: =SUM(BG12:BJ12) -> 48040.01 | BL12: 10013.2 | BM12: 11009.03 | BN12: 10510.3 | BO12: 9617.55 | BP12: =SUM(BL12:BO12) -> 41150.08 | BQ12: 10496.91 | BR12: 13357.24 | BS12: 10509.59 | BT12: 9186.26 | BU12: =SUM(BQ12:BT12) -> 43550 | BV12: 11788.25 | BW12: 9642.01 | BX12: 10942.76 | BY12: 10035.03 | BZ12: =SUM(BV12:BY12) -> 42408.05 | CA12: 10101.51 | CB12: 11489.18 | CC12: 11876.51 | CD12: 10220.49 | CE12: =SUM(CA12:CD12) -> 43687.69 | CF12: 13618.04 | CJ12: =SUM(CF12:CI12) -> 13618.04
A13: 10 | B13: Terong | C13: kuintal | D13: 38993 | E13: 34131 | F13: 20781 | G13: 21170 | H13: 115075 | I13: 19879 | J13: 17108 | K13: 18602 | L13: 20272 | M13: 75861 | N13: 33034 | O13: 20549 | P13: 22940 | Q13: 16539 | R13: 93062 | S13: 18633 | T13: 27059 | U13: 23083 | V13: 18817 | W13: 87592 | X13: 27196 | Y13: 30140 | Z13: 24604 | AA13: 17187 | AB13: 99127 | AC13: 5073 | AD13: 7292 | AE13: 6814 | AF13: 2879 | AG13: 22058 | AH13: 6286 | AI13: 23745 | AJ13: 15117 | AK13: 12724 | AL13: 57872 | AM13: 10409 | AN13: 10767 | AO13: 8686 | AP13: 6597 | AQ13: 36459 | AR13: 11248 | AS13: 10482 | AT13: 7765 | AU13: 9205 | AV13: 38700 | AW13: 10954 | AX13: 12049 | AY13: 16825 | AZ13: 15659 | BA13: =SUM(AW13:AZ13) -> 55487 | BB13: 6941 | BC13: 10084 | BD13: 16556.5 | BE13: 17290.45 | BF13: =SUM(BB13:BE13) -> 50871.95 | BG13: 16909.05 | BH13: 14986.3 | BI13: 14150.9 | BJ13: 12207.7 | BK13: =SUM(BG13:BJ13) -> 58253.95 | BL13: 13903.8 | BM13: 11573.87 | BN13: 12520.85 | BO13: 14207.05 | BP13: =SUM(BL13:BO13) -> 52205.57 | BQ13: 11159.55 | BR13: 14659.94 | BS13: 10896.76 | BT13: 9775.82 | BU13: =SUM(BQ13:BT13) -> 46492.07 | BV13: 12896.54 | BW13: 10650.38 | BX13: 11615.12 | BY13: 12006.32 | BZ13: =SUM(BV13:BY13) -> 47168.36 | CA13: 10729.87 | CB13: 17988.02 | CC13: 13993.22 | CD13: 12039.82 | CE13: =SUM(CA13:CD13) -> 54750.93 | CF13: 15633.26 | CJ13: =SUM(CF13:CI13) -> 15633.26
A14: 11 | B14: Buncis | C14: kuintal | D14: 4629 | E14: 2564 | F14: 1609 | G14: 2160 | H14: 10962 | I14: 1492 | J14: 1383 | K14: 1444 | L14: 2049 | M14: 6368 | N14: 1988 | O14: 1919 | P14: 1750 | Q14: 1585 | R14: 7242 | S14: 1943 | T14: 2920 | U14: 3547 | V14: 3075 | W14: 11485 | X14: 3465 | Y14: 1956 | Z14: 1302 | AA14: 1150 | AB14: 7873 | AC14: 845 | AD14: 867 | AE14: 445 | AF14: 276 | AG14: 2433 | AH14: 358 | AI14: 1771 | AJ14: 3530 | AK14: 4415 | AL14: 10074 | AM14: 1386 | AN14: 853 | AO14: 615 | AP14: 766 | AQ14: 3620 | AR14: 1443 | AS14: 603 | AT14: 727 | AU14: 845 | AV14: 3618 | AW14: 1198 | AX14: 829 | AY14: 948 | AZ14: 1034 | BA14: =SUM(AW14:AZ14) -> 4009 | BB14: 507 | BC14: 565 | BD14: 480 | BE14: 537 | BF14: =SUM(BB14:BE14) -> 2089 | BG14: 447.25 | BH14: 311.4 | BI14: 658.4 | BJ14: 609.2 | BK14: =SUM(BG14:BJ14) -> 2026.25 | BL14: 675.24 | BM14: 544.5 | BN14: 281.02 | BO14: 858.65 | BP14: =SUM(BL14:BO14) -> 2359.41 | BQ14: 2095.3 | BR14: 1739.95 | BS14: 1730.1 | BT14: 642.7 | BU14: =SUM(BQ14:BT14) -> 6208.05 | BV14: 1050.83 | BW14: 1042.93 | BX14: 980.44 | BY14: 533.25 | BZ14: =SUM(BV14:BY14) -> 3607.45 | CA14: 584.73 | CB14: 709.84 | CC14: 886.35 | CD14: 767.55 | CE14: =SUM(CA14:CD14) -> 2948.47 | CF14: 1391.09 | CJ14: =SUM(CF14:CI14) -> 1391.09
A15: 12 | B15: Ketimun | C15: kuintal | D15: 15254 | E15: 7033 | F15: 5454 | G15: 7194 | H15: 34935 | I15: 7290 | J15: 6091 | K15: 6375 | L15: 7811 | M15: 27567 | N15: 12095 | O15: 6895 | P15: 7047 | Q15: 6546 | R15: 32583 | S15: 7416 | T15: 7968 | U15: 8708 | V15: 8879 | W15: 32971 | X15: 12660 | Y15: 9463 | Z15: 6893 | AA15: 4902 | AB15: 33918 | AC15: 3880 | AD15: 3904 | AE15: 3049 | AF15: 1671 | AG15: 12504 | AH15: 3638 | AI15: 10242 | AJ15: 11805 | AK15: 7634 | AL15: 33319 | AM15: 4797 | AN15: 3974 | AO15: 2621 | AP15: 3030 | AQ15: 14422 | AR15: 7853 | AS15: 3914 | AT15: 3516 | AU15: 3461 | AV15: 18744 | AW15: 5750 | AX15: 4384 | AY15: 4568 | AZ15: 3784 | BA15: =SUM(AW15:AZ15) -> 18486 | BB15: 3882 | BC15: 1725 | BD15: 4404 | BE15: 7029 | BF15: =SUM(BB15:BE15) -> 17040 | BG15: 8081.26 | BH15: 5411 | BI15: 4424.4 | BJ15: 3910.7 | BK15: =SUM(BG15:BJ15) -> 21827.36 | BL15: 11157.15 | BM15: 4111.45 | BN15: 5009.45 | BO15: 4064.6 | BP15: =SUM(BL15:BO15) -> 24342.65 | BQ15: 6026.85 | BR15: 7718.65 | BS15: 5727.94 | BT15: 4254.99 | BU15: =SUM(BQ15:BT15) -> 23728.43 | BV15: 7559.61 | BW15: 6313.29 | BX15: 5411.37 | BY15: 5895.35 | BZ15: =SUM(BV15:BY15) -> 25179.62 | CA15: 6244.48 | CB15: 7435.14 | CC15: 7575.2 | CD15: 5224.41 | CE15: =SUM(CA15:CD15) -> 26479.23 | CF15: 7148.84 | CJ15: =SUM(CF15:CI15) -> 7148.84
A16: 13 | B16: Kangkung | C16: kuintal | D16: 34861 | E16: 20411 | F16: 14777 | G16: 17182 | H16: 87231 | I16: 12928 | J16: 9808 | K16: 11235 | L16: 10595 | M16: 44566 | N16: 18166 | O16: 11544 | P16: 15042 | Q16: 11320 | R16: 56072 | S16: 13366 | T16: 26019 | U16: 19728 | V16: 19089 | W16: 78202 | X16: 21864 | Y16: 20763 | Z16: 18807 | AA16: 11321 | AB16: 72755 | AC16: 10059 | AD16: 11386 | AE16: 7389 | AF16: 4726 | AG16: 33560 | AH16: 7116 | AI16: 12982 | AJ16: 26854 | AK16: 16824 | AL16: 63776 | AM16: 6484 | AN16: 5422 | AO16: 6022 | AP16: 6606 | AQ16: 24534 | AR16: 10790 | AS16: 9967 | AT16: 6360 | AU16: 5268 | AV16: 32385 | AW16: 8555 | AX16: 7406 | AY16: 12466 | AZ16: 7505 | BA16: =SUM(AW16:AZ16) -> 35932 | BB16: 7689 | BC16: 6429 | BD16: 11112.5 | BE16: 8154 | BF16: =SUM(BB16:BE16) -> 33384.5 | BG16: 10817.5 | BH16: 10093 | BI16: 9049.3 | BJ16: 9550.6 | BK16: =SUM(BG16:BJ16) -> 39510.4 | BL16: 10777.2 | BM16: 9614.12 | BN16: 11843.36 | BO16: 10914.09 | BP16: =SUM(BL16:BO16) -> 43148.77 | BQ16: 10725.03 | BR16: 10470.16 | BS16: 9913.81 | BT16: 8689.23 | BU16: =SUM(BQ16:BT16) -> 39798.23 | BV16: 10516.39 | BW16: 10011.32 | BX16: 9896.13 | BY16: 11390.72 | BZ16: =SUM(BV16:BY16) -> 41814.56 | CA16: 10904.61 | CB16: 12858.49 | CC16: 12948.8 | CD16: 10212.11 | CE16: =SUM(CA16:CD16) -> 46924.01 | CF16: 12951.51 | CJ16: =SUM(CF16:CI16) -> 12951.51
A17: 14 | B17: Bayam | C17: kuintal | D17: 14563 | E17: 10441 | F17: 8500 | G17: 8622 | H17: 42126 | I17: 8890 | J17: 8486 | K17: 9261 | L17: 8799 | M17: 35436 | N17: 14668 | O17: 10792 | P17: 10416 | Q17: 7321 | R17: 43197 | S17: 12529 | T17: 16063 | U17: 15180 | V17: 15886 | W17: 59658 | X17: 17857 | Y17: 17155 | Z17: 14534 | AA17: 10226 | AC17: 8004 | AD17: 8854 | AE17: 5802 | AF17: 3035 | AH17: 5133 | AI17: 10433 | AJ17: 23183 | AK17: 13335 | AL17: 52084 | AM17: 6251 | AN17: 3421 | AO17: 3328 | AP17: 4606 | AQ17: 17606 | AR17: 5453 | AS17: 5809 | AT17: 4194 | AU17: 3651 | AV17: 19107 | AW17: 5992 | AX17: 4975 | AY17: 5951 | AZ17: 5299 | BA17: =SUM(AW17:AZ17) -> 22217 | BB17: 5465 | BC17: 3563 | BD17: 5825 | BE17: 6021 | BF17: =SUM(BB17:BE17) -> 20874 | BG17: 6352.2 | BH17: 6984.25 | BI17: 5516.12 | BJ17: 5532.15 | BK17: =SUM(BG17:BJ17) -> 24384.72 | BL17: 7085 | BM17: 5393.14 | BN17: 7754.59 | BO17: 6579.75 | BP17: =SUM(BL17:BO17) -> 26812.48 | BQ17: 6842.33 | BR17: 6896.75 | BS17: 6447.11 | BT17: 6130.18 | BU17: =SUM(BQ17:BT17) -> 26316.37 | BV17: 7196.78 | BW17: 6828.47 | BX17: 7302.02 | BY17: 5524.88 | BZ17: =SUM(BV17:BY17) -> 26852.15 | CA17: 7840.3 | CB17: 7171.16 | CC17: 7325.96 | CD17: 6856.05 | CE17: =SUM(CA17:CD17) -> 29193.47 | CF17: 4688.17 | CJ17: =SUM(CF17:CI17) -> 4688.17
A18: 15 | B18: Lobak | C18: kuintal | D18: 0 | E18: 0 | F18: 0 | G18: 0 | H18: 0 | I18: 0 | J18: 0 | K18: 0 | L18: 0 | M18: 0 | N18: 0 | O18: 0 | P18: 0 | Q18: 0 | R18: 0 | S18: 0 | T18: 0 | U18: 0 | V18: 0 | W18: 0 | X18: 0 | Y18: 0 | Z18: 0 | AA18: 0 | AB18: 0 | AC18: 0 | AD18: 0 | AE18: 0 | AF18: 0 | AG18: 0 | AH18: 0 | AI18: 1 | AJ18: 1 | AK18: 0 | AL18: 2 | AM18: 1 | AN18: 0 | AO18: 0 | AP18: 0 | AQ18: 1 | AR18: 0 | AS18: 0 | AT18: 0 | AU18: 0 | AV18: 0 | AW18: 0 | AX18: 0 | AY18: 0 | AZ18: 0 | BA18: =SUM(AW18:AZ18) -> 0 | BB18: 0 | BC18: 0 | BD18: 0 | BE18: 0 | BF18: =SUM(BB18:BE18) -> 0 | BG18: 0 | BH18: 0 | BI18: 0 | BJ18: 0 | BK18: =SUM(BG18:BJ18) -> 0 | BL18: 0 | BM18: 0 | BN18: 0 | BO18: 0 | BP18: =SUM(BL18:BO18) -> 0 | BU18: =SUM(BQ18:BT18) -> 0 | BV18: 0 | BW18: 0 | BX18: 0 | BY18: 0 | BZ18: =SUM(BV18:BY18) -> 0 | CE18: =SUM(CA18:CD18) -> 0 | CF18: 0 | CJ18: =SUM(CF18:CI18) -> 0
A19: 16 | B19: Kacang Merah | C19: kuintal | D19: 1121 | E19: 784 | F19: 508 | G19: 388 | H19: 2801 | I19: 539 | J19: 582 | K19: 318 | L19: 290 | M19: 1729 | N19: 745 | O19: 549 | P19: 245 | Q19: 350 | R19: 1889 | S19: 468 | T19: 577 | U19: 319 | V19: 228 | W19: 1592 | X19: 218 | Y19: 222 | Z19: 297 | AA19: 122 | AB19: 859 | AC19: 178 | AD19: 86 | AE19: 83 | AF19: 13 | AG19: 360 | AH19: 190 | AI19: 221 | AJ19: 152 | AK19: 33 | AL19: 596 | AM19: 118 | AN19: 316 | AO19: 153 | AP19: 138 | AQ19: 725 | AR19: 261 | AS19: 125 | AT19: 59 | AU19: 50 | AV19: 495 | AW19: 177 | AX19: 218 | AY19: 49 | AZ19: 66 | BA19: =SUM(AW19:AZ19) -> 510 | BB19: 51 | BC19: 13 | BD19: 35 | BE19: 42 | BF19: =SUM(BB19:BE19) -> 141 | BG19: 0 | BH19: 0 | BI19: 0 | BJ19: 0 | BK19: =SUM(BG19:BJ19) -> 0 | BL19: 0 | BM19: 0 | BN19: 0 | BO19: 0 | BP19: =SUM(BL19:BO19) -> 0 | BU19: =SUM(BQ19:BT19) -> 0 | BV19: 0 | BW19: 0 | BX19: 0 | BY19: 0 | BZ19: =SUM(BV19:BY19) -> 0 | CE19: =SUM(CA19:CD19) -> 0 | CF19: 0 | CJ19: =SUM(CF19:CI19) -> 0
A20: 17 | B20: Labu Siam | C20: kuintal | D20: 12108 | E20: 4486 | F20: 1853 | G20: 5971 | H20: 24418 | I20: 2651 | J20: 2088 | K20: 3170 | L20: 3986 | M20: 11895 | N20: 11026 | O20: 4274 | P20: 6914 | Q20: 2929 | R20: 25143 | S20: 5328 | T20: 5935 | U20: 5065 | V20: 3435 | W20: 19763 | X20: 9659 | Y20: 5829 | Z20: 3456 | AA20: 1333 | AB20: 20277 | AC20: 3380 | AD20: 2941 | AE20: 1199 | AF20: 596 | AG20: 8116 | AH20: 1877 | AI20: 6442 | AJ20: 6235 | AK20: 3382 | AL20: 17936 | AM20: 3164 | AN20: 1260 | AO20: 1230 | AP20: 1464 | AQ20: 7118 | AR20: 2673 | AS20: 3257 | AT20: 1842 | AU20: 1238 | AV20: 9010 | AW20: 3524 | AX20: 2029 | AY20: 897 | AZ20: 626 | BA20: =SUM(AW20:AZ20) -> 7076 | BB20: 1241 | BC20: 2194 | BD20: 2748 | BE20: 1293 | BF20: =SUM(BB20:BE20) -> 7476 | BG20: 629 | BH20: 1332.7 | BI20: 2008 | BJ20: 1352.1 | BK20: =SUM(BG20:BJ20) -> 5321.8 | BL20: 1504.98 | BM20: 1535.27 | BN20: 1567.3 | BO20: 1399.4 | BP20: =SUM(BL20:BO20) -> 6006.95 | BQ20: 1839.4 | BR20: 1931.9 | BS20: 1448.16 | BT20: 1274.38 | BU20: =SUM(BQ20:BT20) -> 6493.84 | BV20: 2883.5 | BW20: 2317.39 | BX20: 2199.54 | BY20: 2244.28 | BZ20: =SUM(BV20:BY20) -> 9644.71 | CA20: 2077.2 | CB20: 984.8 | CC20: 862.2 | CD20: 817.2 | CE20: =SUM(CA20:CD20) -> 4741.4 | CF20: 4118.8 | CJ20: =SUM(CF20:CI20) -> 4118.8
A21: 18 | B21: Kembang Kol | C21: kuintal | D21: 539 | E21: 631 | F21: 538 | G21: 202 | H21: 1910 | I21: 105 | J21: 94 | K21: 10 | L21: 29 | M21: 238 | N21: 614 | O21: 313 | P21: 333 | Q21: 23 | R21: 1283 | S21: 0 | T21: 660 | U21: 23 | V21: 314 | W21: 997 | X21: 2 | Y21: 22 | Z21: 142 | AA21: 25 | AB21: 191 | AC21: 2 | AD21: 88 | AE21: 2 | AF21: 8 | AG21: 100 | AH21: 60 | AI21: 50 | AJ21: 280 | AK21: 10 | AL21: 400 | AM21: 2 | AN21: 64 | AO21: 37 | AP21: 61 | AQ21: 164 | AR21: 34 | AS21: 150 | AT21: 56 | AU21: 72 | AV21: 312 | AW21: 11 | AX21: 64 | AY21: 18 | AZ21: 185 | BA21: =SUM(AW21:AZ21) -> 278 | BB21: 24 | BC21: 5 | BD21: 60 | BE21: 34 | BF21: =SUM(BB21:BE21) -> 123 | BG21: 443 | BH21: 475 | BI21: 57 | BJ21: - | BK21: =SUM(BG21:BJ21) -> 975 | BL21: 2 | BM21: 113 | BN21: 1 | BO21: 39.4 | BP21: =SUM(BL21:BO21) -> 155.4 | BQ21: 57 | BR21: 16 | BS21: 50.5 | BT21: 22.5 | BU21: =SUM(BQ21:BT21) -> 146 | BV21: 14.75 | BW21: 17 | BX21: 47 | BY21: 84 | BZ21: =SUM(BV21:BY21) -> 162.75 | CA21: 2.6 | CB21: 20 | CC21: - | CD21: - | CE21: =SUM(CA21:CD21) -> 22.6 | CF21: 81 | CJ21: =SUM(CF21:CI21) -> 81
A22: 19 | B22: Jamur | C22: kuintal | D22: 0 | E22: 4 | F22: 0 | G22: 0 | H22: 4 | I22: 0 | J22: 0 | K22: 0 | L22: 0 | M22: 0 | N22: 0 | O22: 0 | P22: 0 | Q22: 0 | R22: 0 | S22: 0 | T22: 0 | U22: 0 | V22: 0 | W22: 0 | X22: 0 | Y22: 0 | Z22: 0 | AA22: 0 | AB22: 0 | AC22: 8 | AD22: 232 | AE22: 290 | AF22: 850 | AG22: 1380 | AH22: 530 | AI22: 1000 | AJ22: 750 | AK22: 670 | AL22: 2950 | AM22: 220 | AN22: 315 | AO22: 386 | AP22: 200 | AQ22: 1121 | AR22: 57 | AS22: 75 | AT22: 49 | AU22: 114 | AV22: 295 | AW22: 113 | AX22: 405 | AY22: 90 | AZ22: 128 | BA22: =SUM(AW22:AZ22) -> 736 | BB22: 91 | BC22: 30 | BD22: 0 | BE22: 0 | BF22: =SUM(BB22:BE22) -> 121 | BG22: 0.15 | BH22: 7.22 | BI22: 6.7 | BJ22: 1.95 | BK22: =SUM(BG22:BJ22) -> 16.02 | BL22: 11.7 | BM22: 49.3 | BN22: 59.7 | BO22: 16 | BP22: =SUM(BL22:BO22) -> 136.7 | BQ22: 22 | BR22: 25.55 | BS22: 43.87 | BT22: 47.75 | BU22: =SUM(BQ22:BT22) -> 139.17 | BV22: 33.31 | BW22: 40.66 | BX22: 27.45 | BY22: 28.92 | BZ22: =SUM(BV22:BY22) -> 130.34 | CA22: 244.6 | CB22: 191.2 | CC22: 139.05 | CD22: 118.25 | CE22: =SUM(CA22:CD22) -> 693.1 | CF22: 27.8 | CJ22: =SUM(CF22:CI22) -> 27.8
A23: Buah Semusim | C23: satuan | D23: 2010 | I23: 2011 | N23: 2012 | S23: 2013 | X23: 2014 | AC23: 2015 | AH23: 2016 | AM23: 2017 | AR23: 2018 | AW23: 2019 | BB23: 2020 | BG23: 2021 | BL23: 2022 | BQ23: 2023 | BV23: 2024 | CA23: 2025 | CF23: 2026
D24: Triw.1 | E24: Triw.2 | F24: Triw.3 | G24: Triw.4 | H24: Jumlah | I24: Triw.1 | J24: Triw.2 | K24: Triw.3 | L24: Triw.4 | M24: Jumlah | N24: Triw.1 | O24: Triw.2 | P24: Triw.3 | Q24: Triw.4 | R24: Jumlah | S24: Triw.1 | T24: Triw.2 | U24: Triw.3 | V24: Triw.4 | W24: Jumlah | X24: Triw.1 | Y24: Triw.2 | Z24: Triw.3 | AA24: Triw.4 | AB24: Jumlah | AC24: Triw.1 | AD24: Triw.2 | AE24: Triw.3 | AF24: Triw.4 | AG24: Jumlah | AH24: Triw.1 | AI24: Triw.2 | AJ24: Triw.3 | AK24: Triw.4 | AL24: Jumlah | AM24: Triw.1 | AN24: Triw.2 | AO24: Triw.3 | AP24: Triw.4 | AQ24: Jumlah | AW24: I | AX24: II | AY24: III | AZ24: IV | BA24: Jumlah | BB24: I | BC24: II | BD24: III | BE24: IV | BF24: Jumlah | BG24: I | BH24: II | BI24: III | BJ24: IV | BK24: Jumlah | BL24: I | BM24: II | BN24: III | BO24: IV | BP24: Jumlah | BQ24: Triw. 1 | BR24: Triw.2 | BS24: Triw.3 | BT24: Triw.4 | BU24: Jumlah | BV24: Triw. 1 | BW24: Triw.2 | BX24: Triw.3 | BY24: Triw.4 | BZ24: Jumlah | CA24: Triw. 1 | CB24: Triw.2 | CC24: Triw.3 | CD24: Triw.4 | CE24: Jumlah | CF24: Triw. 1 | CG24: Triw.2 | CH24: Triw.3 | CI24: Triw.4 | CJ24: Jumlah
A25: 20 | B25: Semangka | C25: kuintal | D25: 4073 | E25: 2658 | F25: 1576 | G25: 3766 | H25: 12073 | I25: 2354 | J25: 2380 | K25: 3287 | L25: 8698 | M25: 16719 | N25: 13833 | O25: 1434 | P25: 4155 | Q25: 3067 | R25: 22489 | S25: 5529 | T25: 3809 | U25: 4722 | V25: 4804 | W25: 18864 | X25: 3888 | Y25: 2640 | Z25: 2981 | AA25: 3123 | AC25: 2457 | AD25: 940 | AE25: 1885 | AF25: 1319 | AH25: 830 | AI25: 2324 | AJ25: 4108 | AK25: 6577 | AL25: 13839 | AM25: 2239 | AN25: 1864 | AO25: 971 | AP25: 2962 | AQ25: 8036 | AR25: 2877 | AS25: 1791 | AT25: 1276 | AU25: 3422 | AV25: 9366 | AW25: 2211 | AX25: 7414 | AY25: 6396 | AZ25: 3873 | BA25: =SUM(AW25:AZ25) -> 19894 | BB25: 2799 | BC25: 3821 | BD25: 3845 | BE25: 6518 | BF25: =SUM(BB25:BE25) -> 16983 | BG25: 3117 | BH25: 2755 | BI25: 3027 | BJ25: 3000.55 | BK25: =SUM(BG25:BJ25) -> 11899.55 | BL25: 1910.7 | BM25: 2996.08 | BN25: 3379.2 | BO25: 4244.8 | BP25: =SUM(BL25:BO25) -> 12530.78 | BQ25: 5083.5 | BR25: 6582.1 | BS25: 6262.3 | BT25: 5535.8 | BU25: =SUM(BQ25:BT25) -> 23463.7 | BV25: 6925.38 | BW25: 4661.55 | BX25: 4905.4 | BY25: 6346.63 | BZ25: =SUM(BV25:BY25) -> 22838.96 | CA25: 6076.46 | CB25: 6121.1 | CC25: 5360.7 | CD25: 7869.6 | CE25: =SUM(CA25:CD25) -> 25427.86 | CF25: 6728.7 | CJ25: =SUM(CF25:CI25) -> 6728.7
A26: 21 | B26: Melon | C26: kuintal | D26: 0 | E26: 81 | F26: 2 | G26: 0 | H26: 83 | I26: 0 | J26: 30 | K26: 30 | L26: 0 | M26: 60 | N26: 0 | O26: 0 | P26: 25 | Q26: 9 | R26: 34 | S26: 0 | T26: 0 | U26: 7 | V26: 0 | W26: 7 | X26: 24 | Y26: 0 | Z26: 75 | AA26: 345 | AC26: 131 | AD26: 40 | AE26: 64 | AF26: 60 | AH26: 50 | AI26: 360 | AJ26: 591 | AK26: 966 | AL26: 1967 | AM26: 330 | AN26: 65 | AO26: 93 | AP26: 171 | AQ26: 659 | AR26: 1046 | AS26: 277 | AT26: 163 | AU26: 500 | AV26: 1986 | AW26: 364 | AX26: 767 | AY26: 732 | AZ26: 604 | BA26: =SUM(AW26:AZ26) -> 2467 | BB26: 234 | BC26: 2263 | BD26: 154 | BE26: 160 | BF26: =SUM(BB26:BE26) -> 2811 | BG26: 157 | BH26: 495 | BI26: 1235 | BJ26: 1357.1 | BK26: =SUM(BG26:BJ26) -> 3244.1 | BL26: 423 | BM26: 385 | BN26: 479 | BO26: 758.2 | BP26: =SUM(BL26:BO26) -> 2045.2 | BQ26: 611.1 | BR26: 313 | BS26: 439 | BT26: 248.1 | BU26: =SUM(BQ26:BT26) -> 1611.2 | BV26: 354 | BW26: 294.1 | BX26: 166.6 | BY26: 1152.5 | BZ26: =SUM(BV26:BY26) -> 1967.2 | CA26: 1641 | CB26: 928 | CC26: 2049.7 | CD26: 792 | CE26: =SUM(CA26:CD26) -> 5410.7 | CF26: 1000.7 | CJ26: =SUM(CF26:CI26) -> 1000.7
A27: 22 | B27: Blewah | C27: kuintal | D27: 0 | E27: 0 | F27: 0 | G27: 0 | H27: 0 | I27: 0 | J27: 0 | K27: 0 | L27: 0 | M27: 0 | N27: 1 | O27: 5 | P27: 0 | Q27: 0 | R27: 6 | S27: 0 | T27: 0 | U27: 100 | V27: 120 | W27: 220 | X27: 0 | Y27: 0 | Z27: 0 | AA27: 0 | AC27: 0 | AD27: 0 | AE27: 3 | AF27: 0 | AH27: 0 | AI27: 0 | AJ27: 7 | AK27: 4 | AL27: 11 | AM27: 10 | AN27: 12 | AO27: 52 | AP27: 52 | AQ27: 126 | AR27: 0 | AS27: 0 | AT27: 0 | AU27: 0 | AV27: 0 | AW27: 0 | AX27: 10 | AY27: 0 | AZ27: 0 | BA27: =SUM(AW27:AZ27) -> 10 | BB27: 30 | BC27: 30 | BD27: 0 | BE27: 0 | BF27: =SUM(BB27:BE27) -> 60 | BG27: 0 | BH27: 0 | BI27: 0 | BJ27: 0 | BK27: =SUM(BG27:BJ27) -> 0 | BL27: 0 | BM27: 0 | BN27: 3 | BO27: 10 | BP27: =SUM(BL27:BO27) -> 13 | BQ27: 0 | BR27: 0 | BS27: 0 | BT27: 0 | BU27: =SUM(BQ27:BT27) -> 0 | BV27: 0 | BW27: 0 | BX27: 0 | BY27: 0 | BZ27: =SUM(BV27:BY27) -> 0 | CA27: 0 | CB27: 0 | CC27: 0 | CD27: 0 | CE27: =SUM(CA27:CD27) -> 0 | CF27: 0 | CJ27: =SUM(CF27:CI27) -> 0
A28: Tanaman Hias Semusim | C28: satuan | D28: 2010 | I28: 2011 | N28: 2012 | S28: 2013 | X28: 2014 | AC28: 2015 | AH28: 2016 | AM28: 2017 | AR28: 2018 | AW28: 2019 | BB28: 2020 | BG28: 2021 | BL28: 2022 | BQ28: 2023 | BV28: 2024 | CA28: 2025 | CF28: 2026
D29: Triw.1 | E29: Triw.2 | F29: Triw.3 | G29: Triw.4 | H29: Jumlah | I29: Triw.1 | J29: Triw.2 | K29: Triw.3 | L29: Triw.4 | M29: Jumlah | N29: Triw.1 | O29: Triw.2 | P29: Triw.3 | Q29: Triw.4 | R29: Jumlah | S29: Triw.1 | T29: Triw.2 | U29: Triw.3 | V29: Triw.4 | W29: Jumlah | X29: Triw.1 | Y29: Triw.2 | Z29: Triw.3 | AA29: Triw.4 | AB29: Jumlah | AC29: Triw.1 | AD29: Triw.2 | AE29: Triw.3 | AF29: Triw.4 | AG29: Jumlah | AH29: Triw.1 | AI29: Triw.2 | AJ29: Triw.3 | AK29: Triw.4 | AL29: Jumlah | AM29: Triw.1 | AN29: Triw.2 | AO29: Triw.3 | AP29: Triw.4 | AQ29: Jumlah | AW29: I | AX29: II | AY29: III | AZ29: IV | BA29: Jumlah | BB29: I | BC29: II | BD29: III | BE29: IV | BF29: Jumlah | BG29: I | BH29: II | BI29: III | BJ29: IV | BK29: Jumlah | BL29: I | BM29: II | BN29: III | BO29: IV | BP29: Jumlah | BQ29: Triw. 1 | BR29: Triw.2 | BS29: Triw.3 | BT29: Triw.4 | BU29: Jumlah | BV29: Triw. 1 | BW29: Triw.2 | BX29: Triw.3 | BY29: Triw.4 | BZ29: Jumlah | CA29: Triw. 1 | CB29: Triw.2 | CC29: Triw.3 | CD29: Triw.4 | CE29: Jumlah | CF29: Triw. 1 | CG29: Triw.2 | CH29: Triw.3 | CI29: Triw.4 | CJ29: Jumlah
A30: 1 | B30: Anggrek | C30: tangkai | D30: 12579 | E30: 7666 | F30: 4375 | G30: 4258 | H30: 28878 | I30: 9349 | J30: 14043 | K30: 5373 | L30: 2909 | M30: 31674 | N30: 4776 | O30: 5881 | P30: 5811 | Q30: 5946 | R30: 22414 | S30: 5832 | T30: 8869 | U30: 5233 | V30: 6745 | W30: 26679 | X30: 2158 | Y30: 3064 | Z30: 1424 | AA30: 1197 | AB30: 7843 | AC30: 1130 | AD30: 1194 | AE30: 1394 | AF30: 1133 | AG30: 4851 | AH30: 1516 | AI30: 1073 | AJ30: 920 | AK30: 1627 | AL30: 5136 | AM30: 1235 | AN30: 788 | AO30: 850 | AP30: 3781 | AQ30: 6654 | AR30: 5339 | AS30: 271 | AT30: 799 | AU30: 777 | AV30: 7186 | AW30: 5371 | AX30: 3324 | AY30: 3265 | AZ30: 3016 | BA30: =SUM(AW30:AZ30) -> 14976 | BB30: 2520 | BC30: 317 | BD30: 1426 | BE30: 500 | BF30: =SUM(BB30:BE30) -> 4763 | BG30: 1413 | BH30: 653 | BI30: 679 | BJ30: 2970 | BK30: =SUM(BG30:BJ30) -> 5715 | BL30: 594 | BM30: 1315 | BN30: 2692 | BO30: 2144 | BP30: =SUM(BL30:BO30) -> 6745 | BQ30: 1406 | BR30: 500 | BS30: 1836 | BT30: 1400 | BU30: =SUM(BQ30:BT30) -> 5142 | BV30: 811 | BW30: 681 | BX30: 483 | BY30: 343 | BZ30: =SUM(BV30:BY30) -> 2318 | CA30: 466 | CB30: 372 | CC30: 989 | CD30: 631 | CE30: =SUM(CA30:CD30) -> 2458 | CF30: 3528 | CJ30: =SUM(CF30:CI30) -> 3528
A31: 2 | B31: Anthurium Bunga | C31: tangkai | D31: 2681 | E31: 5357 | F31: 4246 | G31: 924 | H31: 13208 | I31: 1427 | J31: 1461 | K31: 1352 | L31: 1374 | M31: 5614 | N31: 1573 | O31: 3003 | P31: 1512 | Q31: 1497 | R31: 7585 | S31: 2682 | T31: 1898 | U31: 544 | V31: 1519 | W31: 6643 | X31: 564 | Y31: 617 | Z31: 592 | AA31: 745 | AB31: 2518 | AC31: 358 | AD31: 279 | AE31: 532 | AF31: 504 | AG31: 1673 | AH31: 604 | AI31: 395 | AJ31: 367 | AK31: 629 | AL31: 1995 | AM31: 257 | AN31: 130 | AO31: 705 | AP31: 351 | AQ31: 1443 | AR31: 555 | AS31: 203 | AT31: 143 | AU31: 146 | AV31: 1047 | AW31: 1483 | AX31: 1653 | AY31: 1642 | AZ31: 1493 | BA31: =SUM(AW31:AZ31) -> 6271 | BB31: 1497 | BC31: 1448 | BD31: 1625 | BE31: 323 | BF31: =SUM(BB31:BE31) -> 4893 | BG31: 319 | BH31: 127 | BI31: 327 | BJ31: 228 | BK31: =SUM(BG31:BJ31) -> 1001 | BL31: 16 | BM31: 99 | BN31: 725 | BO31: 782 | BP31: =SUM(BL31:BO31) -> 1622 | BQ31: 476 | BR31: 452 | BS31: 683 | BT31: 406 | BU31: =SUM(BQ31:BT31) -> 2017 | BV31: 715 | BW31: 105 | BX31: 52 | BY31: 94 | BZ31: =SUM(BV31:BY31) -> 966 | CA31: 652 | CB31: 679 | CC31: 597 | CD31: 111 | CE31: =SUM(CA31:CD31) -> 2039 | CF31: 680 | CJ31: =SUM(CF31:CI31) -> 680
A32: 3 | B32: Anyelir | C32: tangkai | D32: 204 | E32: 128 | F32: 416 | G32: 293 | H32: 1041 | I32: 728 | J32: 404 | K32: 260 | L32: 458 | M32: 1850 | N32: 229 | O32: 554 | P32: 427 | Q32: 269 | R32: 1479 | S32: 54 | T32: 155 | U32: 143 | V32: 340 | W32: 692 | X32: 81 | Y32: 73 | Z32: 69 | AA32: 69 | AB32: 292 | AC32: 102 | AD32: 127 | AE32: 299 | AF32: 86 | AG32: 614 | AH32: 96 | AI32: 168 | AJ32: 82 | AK32: 294 | AL32: 640 | AM32: 72 | AN32: 81 | AO32: 163 | AP32: 336 | AQ32: 652 | AR32: 155 | AS32: 30 | AT32: 45 | AU32: 35 | AV32: 265 | AW32: 884 | AX32: 30 | AY32: 15 | AZ32: 70 | BA32: =SUM(AW32:AZ32) -> 999 | BB32: 0 | BC32: 0 | BD32: 45 | BE32: 54 | BF32: =SUM(BB32:BE32) -> 99 | BG32: 0 | BH32: 0 | BI32: 0 | BJ32: 0 | BK32: =SUM(BG32:BJ32) -> 0 | BP32: =SUM(BL32:BO32) -> 0 | BU32: =SUM(BQ32:BT32) -> 0 | BZ32: =SUM(BV32:BY32) -> 0 | CE32: =SUM(CA32:CD32) -> 0 | CJ32: =SUM(CF32:CI32) -> 0
A33: 4 | B33: Gerbera | C33: tangkai | D33: 724 | E33: 901 | F33: 1806 | G33: 467 | H33: 3898 | I33: 499 | J33: 538 | K33: 845 | L33: 8772 | M33: 10654 | N33: 582 | O33: 788 | P33: 366 | Q33: 205 | R33: 1941 | S33: 199 | T33: 102 | U33: 338 | V33: 41 | W33: 680 | X33: 98 | Y33: 85 | Z33: 77 | AA33: 116 | AB33: 376 | AC33: 90 | AD33: 69 | AE33: 140 | AF33: 100 | AG33: 399 | AH33: 106 | AI33: 378 | AJ33: 89 | AK33: 273 | AL33: 846 | AM33: 158 | AN33: 424 | AO33: 298 | AP33: 450 | AQ33: 1330 | AR33: 213 | AS33: 52 | AT33: 117 | AU33: 45 | AV33: 427 | AW33: 285 | AX33: 43 | AY33: 67 | AZ33: 65 | BA33: =SUM(AW33:AZ33) -> 460 | BB33: 0 | BC33: 15 | BD33: 66 | BE33: 210 | BF33: =SUM(BB33:BE33) -> 291 | BG33: 253 | BH33: 232 | BI33: 181 | BJ33: 286 | BK33: =SUM(BG33:BJ33) -> 952 | BL33: 198 | BM33: 212 | BN33: 831 | BO33: 1154 | BP33: =SUM(BL33:BO33) -> 2395 | BQ33: 702 | BR33: 442 | BS33: 570 | BT33: 404 | BU33: =SUM(BQ33:BT33) -> 2118 | BV33: 574 | BW33: 210 | BX33: 10 | BY33: 6 | BZ33: =SUM(BV33:BY33) -> 800 | CA33: 329 | CB33: 12 | CC33: 344 | CD33: 34 | CE33: =SUM(CA33:CD33) -> 719 | CF33: 300 | CJ33: =SUM(CF33:CI33) -> 300
A34: 5 | B34: Gladiol | C34: tangkai | D34: 537 | E34: 2109 | F34: 459 | G34: 179 | H34: 3284 | I34: 199 | J34: 462 | K34: 200 | L34: 775 | M34: 1636 | N34: 181 | O34: 863 | P34: 178 | Q34: 284 | R34: 1506 | S34: 164 | T34: 274 | U34: 284 | V34: 189 | W34: 911 | X34: 128 | Y34: 162 | Z34: 123 | AA34: 101 | AB34: 514 | AC34: 165 | AD34: 148 | AE34: 172 | AF34: 153 | AG34: 638 | AH34: 166 | AI34: 148 | AJ34: 218 | AK34: 174 | AL34: 706 | AM34: 228 | AN34: 300 | AO34: 687 | AP34: 338 | AQ34: 1553 | AR34: 760 | AS34: 37 | AT34: 48 | AU34: 71 | AV34: 916 | AW34: 90 | AX34: 50 | AY34: 67 | AZ34: 52 | BA34: =SUM(AW34:AZ34) -> 259 | BB34: 10 | BC34: 16 | BD34: 45 | BE34: 190 | BF34: =SUM(BB34:BE34) -> 261 | BG34: 0 | BH34: 0 | BI34: 0 | BJ34: 0 | BK34: =SUM(BG34:BJ34) -> 0 | BP34: =SUM(BL34:BO34) -> 0 | BU34: =SUM(BQ34:BT34) -> 0 | BZ34: =SUM(BV34:BY34) -> 0 | CE34: =SUM(CA34:CD34) -> 0 | CJ34: =SUM(CF34:CI34) -> 0
A35: 6 | B35: Pisang-pisangan | C35: tangkai | D35: 7540 | E35: 9648 | F35: 3249 | G35: 3500 | H35: 23937 | I35: 4291 | J35: 10779 | K35: 897 | L35: 4325 | M35: 20292 | N35: 4191 | O35: 4462 | P35: 4433 | Q35: 4388 | R35: 17474 | S35: 4100 | T35: 4188 | U35: 3394 | V35: 3993 | W35: 15675 | X35: 4227 | Y35: 4125 | Z35: 4040 | AA35: 629 | AB35: 13021 | AC35: 754 | AD35: 195 | AE35: 805 | AF35: 5765 | AG35: 7519 | AH35: 249 | AI35: 2554 | AJ35: 766 | AK35: 2142 | AL35: 5711 | AM35: 2122 | AN35: 503 | AO35: 632 | AP35: 2395 | AQ35: 5652 | AR35: 557 | AS35: 318 | AT35: 457 | AU35: 403 | AV35: 1735 | AW35: 1125 | AX35: 869 | AY35: 661 | AZ35: 799 | BA35: =SUM(AW35:AZ35) -> 3454 | BB35: 837 | BC35: 345 | BD35: 211 | BE35: 645 | BF35: =SUM(BB35:BE35) -> 2038 | BG35: 632 | BH35: 718 | BI35: 808 | BJ35: 832 | BK35: =SUM(BG35:BJ35) -> 2990 | BL35: 287 | BM35: 481 | BN35: 1005 | BO35: 840 | BP35: =SUM(BL35:BO35) -> 2613 | BQ35: 858 | BR35: 492 | BS35: 2202 | BT35: 2335 | BU35: =SUM(BQ35:BT35) -> 5887 | BV35: 770 | BW35: 329 | BX35: 217 | BY35: 51 | BZ35: =SUM(BV35:BY35) -> 1367 | CA35: 498 | CB35: 163 | CC35: 430 | CD35: 179 | CE35: =SUM(CA35:CD35) -> 1270 | CF35: 2150 | CJ35: =SUM(CF35:CI35) -> 2150
A36: 7 | B36: Krisan | C36: tangkai | D36: 1083 | E36: 2183 | F36: 17081 | G36: 5342 | H36: 25689 | I36: 2681 | J36: 4203 | K36: 931 | L36: 1681 | M36: 9496 | N36: 565 | O36: 799 | P36: 816 | Q36: 1805 | R36: 3985 | S36: 33 | T36: 229 | U36: 435 | V36: 329 | W36: 1026 | X36: 78 | Y36: 77 | Z36: 74 | AA36: 5 | AB36: 234 | AC36: 151 | AD36: 16 | AE36: 68 | AF36: 20 | AG36: 255 | AH36: 38 | AI36: 75 | AJ36: 20 | AK36: 93 | AL36: 226 | AM36: 94 | AN36: 82 | AO36: 110 | AP36: 30 | AQ36: 316 | AR36: 200 | AS36: 111 | AT36: 65 | AU36: 215 | AV36: 591 | AW36: 0 | AX36: 232 | AY36: 212 | AZ36: 0 | BA36: =SUM(AW36:AZ36) -> 444 | BB36: 0 | BC36: 4 | BD36: 0 | BE36: 0 | BF36: =SUM(BB36:BE36) -> 4 | BG36: 0 | BH36: 6 | BI36: 32 | BJ36: 60 | BK36: =SUM(BG36:BJ36) -> 98 | BL36: 250 | BM36: 230 | BN36: 140 | BO36: 707 | BP36: =SUM(BL36:BO36) -> 1327 | BQ36: 0 | BR36: 2 | BS36: 30 | BT36: 0 | BU36: =SUM(BQ36:BT36) -> 32 | BV36: 0 | BW36: 2 | BX36: 0 | BY36: 0 | BZ36: =SUM(BV36:BY36) -> 2 | CA36: 0 | CB36: 5 | CC36: 5 | CD36: 25 | CE36: =SUM(CA36:CD36) -> 35 | CF36: 0 | CJ36: =SUM(CF36:CI36) -> 0
A37: 8 | B37: Mawar | C37: tangkai | D37: 5739 | E37: 2155 | F37: 4643 | G37: 1369 | H37: 13906 | I37: 9665 | J37: 2340 | K37: 1801 | L37: 5127 | M37: 18933 | N37: 4984 | O37: 2955 | P37: 3273 | Q37: 1422 | R37: 12634 | S37: 817 | T37: 774 | U37: 1568 | V37: 1500 | W37: 4659 | X37: 590 | Y37: 498 | Z37: 534 | AA37: 636 | AB37: 2258 | AC37: 230 | AD37: 103 | AE37: 372 | AF37: 664 | AG37: 1369 | AH37: 221 | AI37: 600 | AJ37: 1065 | AK37: 1439 | AL37: 3325 | AM37: 289 | AN37: 297 | AO37: 615 | AP37: 532 | AQ37: 1733 | AR37: 1258 | AS37: 245 | AT37: 421 | AU37: 844 | AV37: 2768 | AW37: 503 | AX37: 2235 | AY37: 1024 | AZ37: 214 | BA37: =SUM(AW37:AZ37) -> 3976 | BB37: 170 | BC37: 90 | BD37: 158 | BE37: 311 | BF37: =SUM(BB37:BE37) -> 729 | BG37: 665 | BH37: 572 | BI37: 655 | BJ37: 391 | BK37: =SUM(BG37:BJ37) -> 2283 | BL37: 456 | BM37: 502 | BN37: 618 | BO37: 741 | BP37: =SUM(BL37:BO37) -> 2317 | BQ37: 399 | BR37: 416 | BS37: 829 | BT37: 782 | BU37: =SUM(BQ37:BT37) -> 2426 | BV37: 386 | BW37: 206 | BX37: 216 | BY37: 152 | BZ37: =SUM(BV37:BY37) -> 960 | CA37: 289 | CB37: 164 | CC37: 1396 | CD37: 254 | CE37: =SUM(CA37:CD37) -> 2103 | CF37: 2300 | CJ37: =SUM(CF37:CI37) -> 2300
A38: 9 | B38: Sedap malam | C38: tangkai | D38: 1672 | E38: 857 | F38: 4904 | G38: 740 | H38: 8173 | I38: 2017 | J38: 1039 | K38: 1150 | L38: 977 | M38: 5183 | N38: 503 | O38: 698 | P38: 972 | Q38: 353 | R38: 2526 | S38: 253 | T38: 309 | U38: 1037 | V38: 23 | W38: 1622 | X38: 218 | Y38: 285 | Z38: 190 | AA38: 170 | AB38: 863 | AC38: 112 | AD38: 107 | AE38: 171 | AF38: 111 | AG38: 501 | AH38: 144 | AI38: 221 | AJ38: 155 | AK38: 316 | AL38: 836 | AM38: 82 | AN38: 265 | AO38: 489 | AP38: 199 | AQ38: 1035 | AR38: 389 | AS38: 0 | AT38: 51 | AU38: 73 | AV38: 513 | AW38: 870 | AX38: 2195 | AY38: 2169 | AZ38: 2203 | BA38: =SUM(AW38:AZ38) -> 7437 | BB38: 1020 | BC38: 24 | BD38: 3 | BE38: 40 | BF38: =SUM(BB38:BE38) -> 1087 | BG38: 125 | BH38: 650 | BI38: 615 | BJ38: 212 | BK38: =SUM(BG38:BJ38) -> 1602 | BL38: 402 | BM38: 430 | BN38: 781 | BO38: 844 | BP38: =SUM(BL38:BO38) -> 2457 | BQ38: 777 | BR38: 719 | BS38: 1206 | BT38: 1212 | BU38: =SUM(BQ38:BT38) -> 3914 | BV38: 841 | BW38: 223 | BX38: 191 | BY38: 162 | BZ38: =SUM(BV38:BY38) -> 1417 | CA38: 580 | CB38: 236 | CC38: 420 | CD38: 265 | CE38: =SUM(CA38:CD38) -> 1501 | CF38: 420 | CJ38: =SUM(CF38:CI38) -> 420
B39: Dracaena | BG39: 120 | BH39: 235 | BI39: 332 | BJ39: 212 | BK39: =SUM(BG39:BJ39) -> 899 | BL39: 2 | BM39: 153 | BN39: 585 | BO39: 586 | BP39: =SUM(BL39:BO39) -> 1326 | BQ39: 519 | BR39: 354 | BS39: 721 | BT39: 659 | BU39: =SUM(BQ39:BT39) -> 2253 | BV39: 414 | BW39: 75 | BX39: 50 | BY39: 15 | BZ39: =SUM(BV39:BY39) -> 554 | CA39: 290 | CB39: 60 | CC39: 317 | CD39: 186 | CE39: =SUM(CA39:CD39) -> 853 | CF39: 1200 | CJ39: =SUM(CF39:CI39) -> 1200
A40: 10 | B40: Melati | C40: kg | D40: 2056 | E40: 2428 | F40: 1576 | G40: 1866 | H40: 7926 | I40: 3765 | J40: 3666 | K40: 1515 | L40: 1825 | M40: 10771 | N40: 658 | O40: 4177 | P40: 1757 | Q40: 1001 | R40: 7593 | S40: 1156 | T40: 3604 | U40: 1265 | V40: 713 | W40: 6738 | X40: 839 | Y40: 1012 | Z40: 753 | AA40: 595 | AB40: 3199 | AC40: 359 | AD40: 194 | AE40: 190 | AF40: 442 | AG40: 1185 | AH40: 392 | AI40: 583 | AJ40: 510 | AK40: 496 | AL40: 1981 | AM40: 389 | AN40: 423 | AO40: 347 | AP40: 513 | AQ40: 1672 | AR40: 280 | AS40: 130 | AT40: 187 | AU40: 204 | AV40: 801 | AW40: 585 | AX40: 519 | AY40: 420 | AZ40: 371 | BA40: =SUM(AW40:AZ40) -> 1895 | BB40: 285 | BC40: 134 | BD40: 383 | BE40: 147 | BF40: =SUM(BB40:BE40) -> 949 | BG40: 476 | BH40: 64 | BI40: 166 | BJ40: 55 | BK40: =SUM(BG40:BJ40) -> 761 | BL40: 257 | BM40: 365 | BN40: 388 | BO40: 720 | BP40: =SUM(BL40:BO40) -> 1730 | BQ40: 536 | BR40: 331 | BS40: 452 | BT40: 215 | BU40: =SUM(BQ40:BT40) -> 1534 | BV40: 348 | BW40: 170 | BX40: 97 | BY40: 45 | BZ40: =SUM(BV40:BY40) -> 660 | CA40: 334 | CB40: 129 | CC40: 653 | CD40: 203 | CE40: =SUM(CA40:CD40) -> 1319 | CF40: 165 | CJ40: =SUM(CF40:CI40) -> 165
...

Sheet ADHK
A1: Home | B1: 1.1 Pertanian, Kehutanan & Perikanan | D1: 2010 | E1: 2012 | F1: 2014 | G1: 2016 | H1: 2018 | I1: 2020 | J1: 2022 | K1: 2024 | U1: 2010 | V1: 2012 | W1: 2014 | X1: 2016 | Y1: 2018 | Z1: 2020 | AA1: 2022 | AB1: 2024 | AL1: 2010 | AM1: 2012 | AN1: 2014 | AO1: 2016 | AP1: 2018 | AQ1: 2020 | AR1: 2022 | AS1: 2024 | BC1: 2010 | BD1: 2012 | BE1: 2014 | BF1: 2016 | BG1: 2018 | BH1: 2020 | BI1: 2022 | BJ1: 2024 | BT1: 2010 | BU1: 2012 | BV1: 2014 | BW1: 2016 | BX1: 2018 | BY1: 2020 | BZ1: 2022 | CA1: 2024 | CK1: 2010 | CL1: 2012 | CM1: 2014 | CN1: 2016 | CO1: 2018 | CP1: 2020 | CQ1: 2022 | CR1: 2024 | DB1: 2010 | DC1: 2012 | DD1: 2014 | DE1: 2016 | DF1: 2018 | DG1: 2020 | DH1: 2022 | DI1: 2024 | DS1: 2010 | DT1: 2012 | DU1: 2014 | DV1: 2016 | DW1: 2018 | DX1: 2020 | DY1: 2022 | DZ1: 2024 | EJ1: 2010 | EK1: 2012 | EL1: 2014 | EM1: 2016 | EN1: 2018 | EO1: 2020 | EP1: 2022 | EQ1: 2024 | FA1: 2010 | FB1: 2012 | FC1: 2014 | FD1: 2016 | FE1: 2018 | FF1: 2020 | FG1: 2022 | FH1: 2024 | FR1: 2010 | FS1: 2012 | FT1: 2014 | FU1: 2016 | FV1: 2018 | FW1: 2020 | FX1: 2022 | FY1: 2024 | GI1: 2010 | GJ1: 2012 | GK1: 2014 | GL1: 2016 | GM1: 2018 | GN1: 2020 | GO1: 2022 | GP1: 2024 | GZ1: 2010 | HA1: 2012 | HB1: 2014 | HC1: 2016 | HD1: 2018 | HE1: 2020 | HF1: 2022 | HG1: 2024 | HQ1: 2010 | HR1: 2012 | HS1: 2014 | HT1: 2016 | HU1: 2018 | HV1: 2020 | HW1: 2022 | HX1: 2024 | IH1: 2010 | II1: 2012 | IJ1: 2014 | IK1: 2016 | IL1: 2018 | IM1: 2020 | IN1: 2022 | IO1: 2024 | IY1: 2010 | IZ1: 2012 | JA1: 2014 | JB1: 2016 | JC1: 2018 | JD1: 2020 | JE1: 2022 | JF1: 2024 | JP1: 2010 | JQ1: 2012 | JR1: 2014 | JS1: 2016 | JT1: 2018 | JU1: 2020 | JV1: 2022 | JW1: 2024 | KG1: 2010 | KH1: 2012 | KI1: 2014 | KJ1: 2016 | KK1: 2018 | KL1: 2020 | KM1: 2022 | KN1: 2024
D2: 2011 | E2: 2013 | F2: 2015 | G2: 2017 | H2: 2019 | I2: 2021 | J2: 2023 | K2: 2025 | U2: 2011 | V2: 2013 | W2: 2015 | X2: 2017 | Y2: 2019 | Z2: 2021 | AA2: 2023 | AB2: 2025 | AL2: 2011 | AM2: 2013 | AN2: 2015 | AO2: 2017 | AP2: 2019 | AQ2: 2021 | AR2: 2023 | AS2: 2025 | BC2: 2011 | BD2: 2013 | BE2: 2015 | BF2: 2017 | BG2: 2019 | BH2: 2021 | BI2: 2023 | BJ2: 2025 | BT2: 2011 | BU2: 2013 | BV2: 2015 | BW2: 2017 | BX2: 2019 | BY2: 2021 | BZ2: 2023 | CA2: 2025 | CK2: 2011 | CL2: 2013 | CM2: 2015 | CN2: 2017 | CO2: 2019 | CP2: 2021 | CQ2: 2023 | CR2: 2025 | DB2: 2011 | DC2: 2013 | DD2: 2015 | DE2: 2017 | DF2: 2019 | DG2: 2021 | DH2: 2023 | DI2: 2025 | DS2: 2011 | DT2: 2013 | DU2: 2015 | DV2: 2017 | DW2: 2019 | DX2: 2021 | DY2: 2023 | DZ2: 2025 | EJ2: 2011 | EK2: 2013 | EL2: 2015 | EM2: 2017 | EN2: 2019 | EO2: 2021 | EP2: 2023 | EQ2: 2025 | FA2: 2011 | FB2: 2013 | FC2: 2015 | FD2: 2017 | FE2: 2019 | FF2: 2021 | FG2: 2023 | FH2: 2025 | FR2: 2011 | FS2: 2013 | FT2: 2015 | FU2: 2017 | FV2: 2019 | FW2: 2021 | FX2: 2023 | FY2: 2025 | GI2: 2011 | GJ2: 2013 | GK2: 2015 | GL2: 2017 | GM2: 2019 | GN2: 2021 | GO2: 2023 | GP2: 2025 | GZ2: 2011 | HA2: 2013 | HB2: 2015 | HC2: 2017 | HD2: 2019 | HE2: 2021 | HF2: 2023 | HG2: 2025 | HQ2: 2011 | HR2: 2013 | HS2: 2015 | HT2: 2017 | HU2: 2019 | HV2: 2021 | HW2: 2023 | HX2: 2025 | IH2: 2011 | II2: 2013 | IJ2: 2015 | IK2: 2017 | IL2: 2019 | IM2: 2021 | IN2: 2023 | IO2: 2025 | IY2: 2011 | IZ2: 2013 | JA2: 2015 | JB2: 2017 | JC2: 2019 | JD2: 2021 | JE2: 2023 | JF2: 2025 | JP2: 2011 | JQ2: 2013 | JR2: 2015 | JS2: 2017 | JT2: 2019 | JU2: 2021 | JV2: 2023 | JW2: 2025 | KG2: 2011 | KH2: 2013 | KI2: 2015 | KJ2: 2017 | KK2: 2019 | KL2: 2021 | KM2: 2023 | KN2: 2025
B4: Wilayah | C4: : Provinsi Sulawesi Tenggara | G4: Lembar Pengolahan Penghitungan | P4: ADHK | S4: Wilayah | T4: =C4 -> : Provinsi Sulawesi Tenggara | X4: Lembar Pengolahan Penghitungan | AG4: ADHK | AJ4: Wilayah | AK4: =T4 -> : Provinsi Sulawesi Tenggara | AO4: Lembar Pengolahan Penghitungan | AX4: ADHK | BA4: Wilayah | BB4: =AK4 -> : Provinsi Sulawesi Tenggara | BF4: Lembar Pengolahan Penghitungan | BO4: ADHK | BR4: Wilayah | BS4: =BB4 -> : Provinsi Sulawesi Tenggara | BW4: Lembar Pengolahan Penghitungan | CF4: ADHK | CI4: Wilayah | CJ4: =BS4 -> : Provinsi Sulawesi Tenggara | CN4: Lembar Pengolahan Penghitungan | CW4: ADHK | CZ4: Wilayah | DA4: =CJ4 -> : Provinsi Sulawesi Tenggara | DE4: Lembar Pengolahan Penghitungan | DN4: ADHK | DQ4: Wilayah | DR4: =DA4 -> : Provinsi Sulawesi Tenggara | DV4: Lembar Pengolahan Penghitungan | EE4: ADHK | EH4: Wilayah | EI4: =DR4 -> : Provinsi Sulawesi Tenggara | EM4: Lembar Pengolahan Penghitungan | EV4: ADHK | EY4: Wilayah | EZ4: =EI4 -> : Provinsi Sulawesi Tenggara | FD4: Lembar Pengolahan Penghitungan | FM4: ADHK | FP4: Wilayah | FQ4: =EZ4 -> : Provinsi Sulawesi Tenggara | FU4: Lembar Pengolahan Penghitungan | GD4: ADHK | GG4: Wilayah | GH4: =FQ4 -> : Provinsi Sulawesi Tenggara | GL4: Lembar Pengolahan Penghitungan | GU4: ADHK | GX4: Wilayah | GY4: =GH4 -> : Provinsi Sulawesi Tenggara | HC4: Lembar Pengolahan Penghitungan | HL4: ADHK | HO4: Wilayah | HP4: =GY4 -> : Provinsi Sulawesi Tenggara | HT4: Lembar Pengolahan Penghitungan | IC4: ADHK | IF4: Wilayah | IG4: =HP4 -> : Provinsi Sulawesi Tenggara | IK4: Lembar Pengolahan Penghitungan | IT4: ADHK | IW4: Wilayah | IX4: =IG4 -> : Provinsi Sulawesi Tenggara | JB4: Lembar Pengolahan Penghitungan | JK4: ADHK | JN4: Wilayah | JO4: =IX4 -> : Provinsi Sulawesi Tenggara | JS4: Lembar Pengolahan Penghitungan | KB4: ADHK | KE4: Wilayah | KF4: =JO4 -> : Provinsi Sulawesi Tenggara | KJ4: Lembar Pengolahan Penghitungan | KS4: ADHK
B5: Kategori | C5: : Pertanian, Kehutanan, dan Perikanan | G5: Nilai Tambah Bruto | S5: Kategori | T5: =C5 -> : Pertanian, Kehutanan, dan Perikanan | X5: Nilai Tambah Bruto | AJ5: Kategori | AK5: =T5 -> : Pertanian, Kehutanan, dan Perikanan | AO5: Nilai Tambah Bruto | BA5: Kategori | BB5: =AK5 -> : Pertanian, Kehutanan, dan Perikanan | BF5: Nilai Tambah Bruto | BR5: Kategori | BS5: =BB5 -> : Pertanian, Kehutanan, dan Perikanan | BW5: Nilai Tambah Bruto | CI5: Kategori | CJ5: =BS5 -> : Pertanian, Kehutanan, dan Perikanan | CN5: Nilai Tambah Bruto | CZ5: Kategori | DA5: =CJ5 -> : Pertanian, Kehutanan, dan Perikanan | DE5: Nilai Tambah Bruto | DQ5: Kategori | DR5: =DA5 -> : Pertanian, Kehutanan, dan Perikanan | DV5: Nilai Tambah Bruto | EH5: Kategori | EI5: =DR5 -> : Pertanian, Kehutanan, dan Perikanan | EM5: Nilai Tambah Bruto | EY5: Kategori | EZ5: =EI5 -> : Pertanian, Kehutanan, dan Perikanan | FD5: Nilai Tambah Bruto | FP5: Kategori | FQ5: =EZ5 -> : Pertanian, Kehutanan, dan Perikanan | FU5: Nilai Tambah Bruto | GG5: Kategori | GH5: =FQ5 -> : Pertanian, Kehutanan, dan Perikanan | GL5: Nilai Tambah Bruto | GX5: Kategori | GY5: =GH5 -> : Pertanian, Kehutanan, dan Perikanan | HC5: Nilai Tambah Bruto | HO5: Kategori | HP5: =GY5 -> : Pertanian, Kehutanan, dan Perikanan | HT5: Nilai Tambah Bruto | IF5: Kategori | IG5: =HP5 -> : Pertanian, Kehutanan, dan Perikanan | IK5: Nilai Tambah Bruto | IW5: Kategori | IX5: =IG5 -> : Pertanian, Kehutanan, dan Perikanan | JB5: Nilai Tambah Bruto | JN5: Kategori | JO5: =IX5 -> : Pertanian, Kehutanan, dan Perikanan | JS5: Nilai Tambah Bruto | KE5: Kategori | KF5: =JO5 -> : Pertanian, Kehutanan, dan Perikanan | KJ5: Nilai Tambah Bruto
B6: Subkategori | C6: : Pertanian, Peternakan, Perburuan dan Jasa Pertanian | G6: Atas Dasar Harga Konstan 2010=100 | P6: 2010 | S6: Subkategori | T6: =C6 -> : Pertanian, Peternakan, Perburuan dan Jasa Pertanian | X6: Atas Dasar Harga Konstan 2010=100 | AG6: =P6+1 -> 2011 | AJ6: Subkategori | AK6: =T6 -> : Pertanian, Peternakan, Perburuan dan Jasa Pertanian | AO6: Atas Dasar Harga Konstan 2010=100 | AX6: =AG6+1 -> 2012 | BA6: Subkategori | BB6: =AK6 -> : Pertanian, Peternakan, Perburuan dan Jasa Pertanian | BF6: Atas Dasar Harga Konstan 2010=100 | BO6: =AX6+1 -> 2013 | BR6: Subkategori | BS6: =BB6 -> : Pertanian, Peternakan, Perburuan dan Jasa Pertanian | BW6: Atas Dasar Harga Konstan 2010=100 | CF6: =BO6+1 -> 2014 | CI6: Subkategori | CJ6: =BS6 -> : Pertanian, Peternakan, Perburuan dan Jasa Pertanian | CN6: Atas Dasar Harga Konstan 2010=100 | CW6: =CF6+1 -> 2015 | CZ6: Subkategori | DA6: =CJ6 -> : Pertanian, Peternakan, Perburuan dan Jasa Pertanian | DE6: Atas Dasar Harga Konstan 2010=100 | DN6: =CW6+1 -> 2016 | DQ6: Subkategori | DR6: =DA6 -> : Pertanian, Peternakan, Perburuan dan Jasa Pertanian | DV6: Atas Dasar Harga Konstan 2010=100 | EE6: =DN6+1 -> 2017 | EH6: Subkategori | EI6: =DR6 -> : Pertanian, Peternakan, Perburuan dan Jasa Pertanian | EM6: Atas Dasar Harga Konstan 2010=100 | EV6: =EE6+1 -> 2018 | EY6: Subkategori | EZ6: =EI6 -> : Pertanian, Peternakan, Perburuan dan Jasa Pertanian | FD6: Atas Dasar Harga Konstan 2010=100 | FM6: =EV6+1 -> 2019 | FP6: Subkategori | FQ6: =EZ6 -> : Pertanian, Peternakan, Perburuan dan Jasa Pertanian | FU6: Atas Dasar Harga Konstan 2010=100 | GD6: =FM6+1 -> 2020 | GG6: Subkategori | GH6: =FQ6 -> : Pertanian, Peternakan, Perburuan dan Jasa Pertanian | GL6: Atas Dasar Harga Konstan 2010=100 | GU6: =GD6+1 -> 2021 | GX6: Subkategori | GY6: =GH6 -> : Pertanian, Peternakan, Perburuan dan Jasa Pertanian | HC6: Atas Dasar Harga Konstan 2010=100 | HL6: =GU6+1 -> 2022 | HO6: Subkategori | HP6: =GY6 -> : Pertanian, Peternakan, Perburuan dan Jasa Pertanian | HT6: Atas Dasar Harga Konstan 2010=100 | IC6: =HL6+1 -> 2023 | IF6: Subkategori | IG6: =HP6 -> : Pertanian, Peternakan, Perburuan dan Jasa Pertanian | IK6: Atas Dasar Harga Konstan 2010=100 | IT6: =IC6+1 -> 2024 | IW6: Subkategori | IX6: =IG6 -> : Pertanian, Peternakan, Perburuan dan Jasa Pertanian | JB6: Atas Dasar Harga Konstan 2010=100 | JK6: =IT6+1 -> 2025 | JN6: Subkategori | JO6: =IX6 -> : Pertanian, Peternakan, Perburuan dan Jasa Pertanian | JS6: Atas Dasar Harga Konstan 2010=100 | KB6: =JK6+1 -> 2026 | KE6: Subkategori | KF6: =JO6 -> : Pertanian, Peternakan, Perburuan dan Jasa Pertanian | KJ6: Atas Dasar Harga Konstan 2010=100 | KS6: =KB6+1 -> 2027
B7: Jenis Kegiatan | C7: : Tanaman Hortikultura Semusim | G7: ="Tahun "&P$6 -> Tahun 2010 | S7: Jenis Kegiatan | T7: =C7 -> : Tanaman Hortikultura Semusim | X7: ="Tahun "&AG$6 -> Tahun 2011 | AJ7: Jenis Kegiatan | AK7: =T7 -> : Tanaman Hortikultura Semusim | AO7: ="Tahun "&AX$6 -> Tahun 2012 | BA7: Jenis Kegiatan | BB7: =AK7 -> : Tanaman Hortikultura Semusim | BF7: ="Tahun "&BO$6 -> Tahun 2013 | BR7: Jenis Kegiatan | BS7: =BB7 -> : Tanaman Hortikultura Semusim | BW7: ="Tahun "&CF$6 -> Tahun 2014 | CI7: Jenis Kegiatan | CJ7: =BS7 -> : Tanaman Hortikultura Semusim | CN7: ="Tahun "&CW$6 -> Tahun 2015 | CZ7: Jenis Kegiatan | DA7: =CJ7 -> : Tanaman Hortikultura Semusim | DE7: ="Tahun "&DN$6 -> Tahun 2016 | DQ7: Jenis Kegiatan | DR7: =DA7 -> : Tanaman Hortikultura Semusim | DV7: ="Tahun "&EE$6 -> Tahun 2017 | EH7: Jenis Kegiatan | EI7: =DR7 -> : Tanaman Hortikultura Semusim | EM7: ="Tahun "&EV$6 -> Tahun 2018 | EY7: Jenis Kegiatan | EZ7: =EI7 -> : Tanaman Hortikultura Semusim | FD7: ="Tahun "&FM$6 -> Tahun 2019 | FP7: Jenis Kegiatan | FQ7: =EZ7 -> : Tanaman Hortikultura Semusim | FU7: ="Tahun "&GD$6 -> Tahun 2020 | GG7: Jenis Kegiatan | GH7: =FQ7 -> : Tanaman Hortikultura Semusim | GL7: ="Tahun "&GU$6 -> Tahun 2021 | GX7: Jenis Kegiatan | GY7: =GH7 -> : Tanaman Hortikultura Semusim | HC7: ="Tahun "&HL$6 -> Tahun 2022 | HO7: Jenis Kegiatan | HP7: =GY7 -> : Tanaman Hortikultura Semusim | HT7: ="Tahun "&IC$6 -> Tahun 2023 | IF7: Jenis Kegiatan | IG7: =HP7 -> : Tanaman Hortikultura Semusim | IK7: ="Tahun "&IT$6 -> Tahun 2024 | IW7: Jenis Kegiatan | IX7: =IG7 -> : Tanaman Hortikultura Semusim | JB7: ="Tahun "&JK$6 -> Tahun 2025 | JN7: Jenis Kegiatan | JO7: =IX7 -> : Tanaman Hortikultura Semusim | JS7: ="Tahun "&KB$6 -> Tahun 2026 | KE7: Jenis Kegiatan | KF7: =JO7 -> : Tanaman Hortikultura Semusim | KJ7: ="Tahun "&KS$6 -> Tahun 2027
B8: Metode Estimasi Output | C8: : Revaluasi | S8: Metode Estimasi Output | T8: =C8 -> : Revaluasi | AJ8: Metode Estimasi Output | AK8: =T8 -> : Revaluasi | BA8: Metode Estimasi Output | BB8: =AK8 -> : Revaluasi | BR8: Metode Estimasi Output | BS8: =BB8 -> : Revaluasi | CI8: Metode Estimasi Output | CJ8: =BS8 -> : Revaluasi | CZ8: Metode Estimasi Output | DA8: =CJ8 -> : Revaluasi | DQ8: Metode Estimasi Output | DR8: =DA8 -> : Revaluasi | EH8: Metode Estimasi Output | EI8: =DR8 -> : Revaluasi | EY8: Metode Estimasi Output | EZ8: =EI8 -> : Revaluasi | FP8: Metode Estimasi Output | FQ8: =EZ8 -> : Revaluasi | GG8: Metode Estimasi Output | GH8: =FQ8 -> : Revaluasi | GX8: Metode Estimasi Output | GY8: =GH8 -> : Revaluasi | HO8: Metode Estimasi Output | HP8: =GY8 -> : Revaluasi | IF8: Metode Estimasi Output | IG8: =HP8 -> : Revaluasi | IW8: Metode Estimasi Output | IX8: =IG8 -> : Revaluasi | JN8: Metode Estimasi Output | JO8: =IX8 -> : Revaluasi | KE8: Metode Estimasi Output | KF8: =JO8 -> : Revaluasi
A10: No. | B10: Subkategori/Jenis Kegiatan/Uraian Komoditi | C10: Output Utama | H10: Output Ikutan | J10: WIP | M10: Output ADH Produsen (Juta Rp) [(7)+(9)+(12)] | N10: Konsumsi Antara | P10: Nilai Tambah Bruto (Juta Rp) (13)-(15) | R10: No. | S10: Subkategori/Jenis Kegiatan/Uraian Komoditi | T10: Output Utama | Y10: Output Ikutan | AA10: WIP | AD10: Output ADH Produsen (Juta Rp) [(7)+(9)+(12)] | AE10: Konsumsi Antara | AG10: Nilai Tambah Bruto (Juta Rp) (13)-(15) | AI10: No. | AJ10: Subkategori/Jenis Kegiatan/Uraian Komoditi | AK10: Output Utama | AP10: Output Ikutan | AR10: WIP | AU10: Output ADH Produsen (Juta Rp) [(7)+(9)+(12)] | AV10: Konsumsi Antara | AX10: Nilai Tambah Bruto (Juta Rp) (13)-(15) | AZ10: No. | BA10: Subkategori/Jenis Kegiatan/Uraian Komoditi | BB10: Output Utama | BG10: Output Ikutan | BI10: WIP | BL10: Output ADH Produsen (Juta Rp) [(7)+(9)+(12)] | BM10: Konsumsi Antara | BO10: Nilai Tambah Bruto (Juta Rp) (13)-(15) | BQ10: No. | BR10: Subkategori/Jenis Kegiatan/Uraian Komoditi | BS10: Output Utama | BX10: Output Ikutan | BZ10: WIP | CC10: Output ADH Produsen (Juta Rp) [(7)+(9)+(12)] | CD10: Konsumsi Antara | CF10: Nilai Tambah Bruto (Juta Rp) (13)-(15) | CH10: No. | CI10: Subkategori/Jenis Kegiatan/Uraian Komoditi | CJ10: Output Utama | CO10: Output Ikutan | CQ10: WIP | CT10: Output ADH Produsen (Juta Rp) [(7)+(9)+(12)] | CU10: Konsumsi Antara | CW10: Nilai Tambah Bruto (Juta Rp) (13)-(15) | CY10: No. | CZ10: Subkategori/Jenis Kegiatan/Uraian Komoditi | DA10: Output Utama | DF10: Output Ikutan | DH10: WIP | DK10: Output ADH Produsen (Juta Rp) [(7)+(9)+(12)] | DL10: Konsumsi Antara | DN10: Nilai Tambah Bruto (Juta Rp) (13)-(15) | DP10: No. | DQ10: Subkategori/Jenis Kegiatan/Uraian Komoditi | DR10: Output Utama | DW10: Output Ikutan | DY10: WIP | EB10: Output ADH Produsen (Juta Rp) [(7)+(9)+(12)] | EC10: Konsumsi Antara | EE10: Nilai Tambah Bruto (Juta Rp) (13)-(15) | EG10: No. | EH10: Subkategori/Jenis Kegiatan/Uraian Komoditi | EI10: Output Utama | EN10: Output Ikutan | EP10: WIP | ES10: Output ADH Produsen (Juta Rp) [(7)+(9)+(12)] | ET10: Konsumsi Antara | EV10: Nilai Tambah Bruto (Juta Rp) (13)-(15) | EX10: No. | EY10: Subkategori/Jenis Kegiatan/Uraian Komoditi | EZ10: Output Utama | FE10: Output Ikutan | FG10: WIP | FJ10: Output ADH Produsen (Juta Rp) [(7)+(9)+(12)] | FK10: Konsumsi Antara | FM10: Nilai Tambah Bruto (Juta Rp) (13)-(15) | FO10: No. | FP10: Subkategori/Jenis Kegiatan/Uraian Komoditi | FQ10: Output Utama | FV10: Output Ikutan | FX10: WIP | GA10: Output ADH Produsen (Juta Rp) [(7)+(9)+(12)] | GB10: Konsumsi Antara | GD10: Nilai Tambah Bruto (Juta Rp) (13)-(15) | GF10: No. | GG10: Subkategori/Jenis Kegiatan/Uraian Komoditi | GH10: Output Utama | GM10: Output Ikutan | GO10: WIP | GR10: Output ADH Produsen (Juta Rp) [(7)+(9)+(12)] | GS10: Konsumsi Antara | GU10: Nilai Tambah Bruto (Juta Rp) (13)-(15) | GW10: No. | GX10: Subkategori/Jenis Kegiatan/Uraian Komoditi | GY10: Output Utama | HD10: Output Ikutan | HF10: WIP | HI10: Output ADH Produsen (Juta Rp) [(7)+(9)+(12)] | HJ10: Konsumsi Antara | HL10: Nilai Tambah Bruto (Juta Rp) (13)-(15) | HN10: No. | HO10: Subkategori/Jenis Kegiatan/Uraian Komoditi | HP10: Output Utama | HU10: Output Ikutan | HW10: WIP | HZ10: Output ADH Produsen (Juta Rp) [(7)+(9)+(12)] | IA10: Konsumsi Antara | IC10: Nilai Tambah Bruto (Juta Rp) (13)-(15) | IE10: No. | IF10: Subkategori/Jenis Kegiatan/Uraian Komoditi | IG10: Output Utama | IL10: Output Ikutan | IN10: WIP | IQ10: Output ADH Produsen (Juta Rp) [(7)+(9)+(12)] | IR10: Konsumsi Antara | IT10: Nilai Tambah Bruto (Juta Rp) (13)-(15) | IV10: No. | IW10: Subkategori/Jenis Kegiatan/Uraian Komoditi | IX10: Output Utama | JC10: Output Ikutan | JE10: WIP | JH10: Output ADH Produsen (Juta Rp) [(7)+(9)+(12)] | JI10: Konsumsi Antara | JK10: Nilai Tambah Bruto (Juta Rp) (13)-(15) | JM10: No. | JN10: Subkategori/Jenis Kegiatan/Uraian Komoditi | JO10: Output Utama | JT10: Output Ikutan | JV10: WIP | JY10: Output ADH Produsen (Juta Rp) [(7)+(9)+(12)] | JZ10: Konsumsi Antara | KB10: Nilai Tambah Bruto (Juta Rp) (13)-(15) | KD10: No. | KE10: Subkategori/Jenis Kegiatan/Uraian Komoditi | KF10: Output Utama | KK10: Output Ikutan | KM10: WIP | KP10: Output ADH Produsen (Juta Rp) [(7)+(9)+(12)] | KQ10: Konsumsi Antara | KS10: Nilai Tambah Bruto (Juta Rp) (13)-(15)
