Workbook
Name H: #REF!
Name BERLAKU: #REF!
Name BERLAKU: #REF!
Name BERLAKU: #REF!

Sheet Home
A1: HOME
B2: SISTEM | H2: ALAT BANTU PENGHITUNGAN ANGKA PDRB MENURUT LAPANGAN USAHA
B3: INFORMASI
B4: RILIS
B5: ANGKA PDRB | K5: LAPANGAN USAHA | O5: : | P5: =mid(ADHB!C5,3,9)&" --- "&mid(ADHB!C7,3,100) -> Pertanian --- Jasa Pertanian, dan Perburuan
B6: MELALUI LEMBAR KERJA | K6: WILAYAH | O6: : | P6: Provinsi Sulawesi Tenggara
B7: BERBASIS | K7: TAHUN | O7: : | P7: =IFERROR(__xludf.DUMMYFUNCTION("IMPORTRANGE(""https://docs.google.com/spreadsheets/d/14EziMEzuXiAhzZqRuQw8kN9sLyynoE6QsPgaj062Fa0/edit#gid=214337323"",""'LK PDRB Lapus'!E3:E4"")"),2026.0) -> 2026
B8: ONLINE | K8: TRIWULAN | O8: : | P8: =IFERROR(__xludf.DUMMYFUNCTION("""COMPUTED_VALUE"""),"I") -> I
B11: INPUT DATA | K11: OUTPUT | T11: MONEV
B15: 1 | C15: Lembar Kerja Penghitungan PDRB Atas Dasar Harga Berlaku | K15: 1 | L15: Rekap Angka PDRB Lapangan Usaha | T15: 1 | U15: MONEV Pemasukan Data
B16: =B15+1 -> 2 | C16: Lembar Kerja Penghitungan PDRB Atas Dasar Harga Konstan | K16: =K15+1 -> 2 | T16: =T15+1 -> 2

Sheet Hitung Output
A2: PENGHITUNGAN OUTPUT JASA PERTANIAN
A4: Kategori | B4: Uraian | D4: 2008 | I4: 2009 | N4: 2010 | S4: 2011 | X4: 2012 | AC4: 2013 | AH4: 2014 | AM4: 2015 | AR4: 2016 | AW4: 2017 | BB4: 2018 | BG4: 2019 | BL4: 2020 | BQ4: =BL4+1 -> 2021 | BV4: =BQ4+1 -> 2022 | CA4: =BV4+1 -> 2023 | CF4: =CA4+1 -> 2024 | CK4: =CF4+1 -> 2025 | CP4: =CK4+1 -> 2026 | CU4: =CP4+1 -> 2027
D5: I | E5: II | F5: III | G5: IV | H5: Total | I5: I | J5: II | K5: III | L5: IV | M5: Total | N5: I | O5: II | P5: III | Q5: IV | R5: Total | S5: I | T5: II | U5: III | V5: IV | W5: Total | X5: I | Y5: II | Z5: III | AA5: IV | AB5: Total | AC5: I | AD5: II | AE5: III | AF5: IV | AG5: Total | AH5: I | AI5: II | AJ5: III | AK5: IV | AL5: Total | AM5: I | AN5: II | AO5: III | AP5: IV | AQ5: Total | AR5: I | AS5: II | AT5: III | AU5: IV | AV5: Total | AW5: I | AX5: II | AY5: III | AZ5: IV | BA5: Total | BB5: I | BC5: II | BD5: III | BE5: IV | BF5: Total | BG5: I | BH5: II | BI5: III | BJ5: IV | BK5: Total | BL5: I | BM5: II | BN5: III | BO5: IV | BP5: Total | BQ5: I | BR5: II | BS5: III | BT5: IV | BU5: Total | BV5: I | BW5: II | BX5: III | BY5: IV | BZ5: Total | CA5: I | CB5: II | CC5: III | CD5: IV | CE5: Total | CF5: I | CG5: II | CH5: III | CI5: IV | CJ5: Total | CK5: I | CL5: II | CM5: III | CN5: IV | CO5: Total | CP5: I | CQ5: II | CR5: III | CS5: IV | CT5: Total | CU5: I | CV5: II | CW5: III | CX5: IV | CY5: Total
A7: -1 | B7: -2 | D7: =B7-1 -> -3 | E7: =D7-1 -> -4 | F7: =E7-1 -> -5 | G7: =F7-1 -> -6 | H7: =G7-1 -> -7 | I7: =H7-1 -> -8 | J7: =I7-1 -> -9 | K7: =J7-1 -> -10 | L7: =K7-1 -> -11 | ... CY7: =CX7-1 -> -102
A10: A | B10: NTB ADHB subkategori penyusun
C11: a. Tanaman Pangan | D11: =IFERROR(__xludf.DUMMYFUNCTION("IMPORTRANGE(""https://docs.google.com/spreadsheets/d/1fq0UU7JJVw2Mabie5r5T24vSCZ0NCG-3waFyMjDP7Qo/edit#gid=1235587625"",""Prod_Awal!D11:ZZ16"")"),"") | N11: =IFERROR(__xludf.DUMMYFUNCTION("""COMPUTED_VALUE"""),232254.35059033884) -> 232254.35 | O11: =IFERROR(__xludf.DUMMYFUNCTION("""COMPUTED_VALUE"""),418773.9234406652) -> 418773.92 | P11: =IFERROR(__xludf.DUMMYFUNCTION("""COMPUTED_VALUE"""),381795.4781181837) -> 381795.48 | Q11: =IFERROR(__xludf.DUMMYFUNCTION("""COMPUTED_VALUE"""),309260.3277478123) -> 309260.33 | R11: =IFERROR(__xludf.DUMMYFUNCTION("""COMPUTED_VALUE"""),1342084.079897) -> 1342084.1 | S11: =IFERROR(__xludf.DUMMYFUNCTION("""COMPUTED_VALUE"""),311278.7353187434) -> 311278.74 | T11: =IFERROR(__xludf.DUMMYFUNCTION("""COMPUTED_VALUE"""),404863.7340247067) -> 404863.73 | U11: =IFERROR(__xludf.DUMMYFUNCTION("""COMPUTED_VALUE"""),430576.07589403685) -> 430576.08 | V11: =IFERROR(__xludf.DUMMYFUNCTION("""COMPUTED_VALUE"""),343536.57169487444) -> 343536.57 | W11: =IFERROR(__xludf.DUMMYFUNCTION("""COMPUTED_VALUE"""),1490255.1169323614) -> 1490255.1 | X11: =IFERROR(__xludf.DUMMYFUNCTION("""COMPUTED_VALUE"""),376375.830442591) -> 376375.83 | Y11: =IFERROR(__xludf.DUMMYFUNCTION("""COMPUTED_VALUE"""),552864.8561710732) -> 552864.86 | Z11: =IFERROR(__xludf.DUMMYFUNCTION("""COMPUTED_VALUE"""),472053.4258662213) -> 472053.43 | AA11: =IFERROR(__xludf.DUMMYFUNCTION("""COMPUTED_VALUE"""),360677.7892274253) -> 360677.79 | AB11: =IFERROR(__xludf.DUMMYFUNCTION("""COMPUTED_VALUE"""),1761971.901707311) -> 1761971.9 | AC11: =IFERROR(__xludf.DUMMYFUNCTION("""COMPUTED_VALUE"""),440716.0222510425) -> 440716.02 | AD11: =IFERROR(__xludf.DUMMYFUNCTION("""COMPUTED_VALUE"""),557367.2602548022) -> 557367.26 | AE11: =IFERROR(__xludf.DUMMYFUNCTION("""COMPUTED_VALUE"""),488909.4686740373) -> 488909.47 | AF11: =IFERROR(__xludf.DUMMYFUNCTION("""COMPUTED_VALUE"""),431644.0046495912) -> 431644 | AG11: =IFERROR(__xludf.DUMMYFUNCTION("""COMPUTED_VALUE"""),1918636.7558294733) -> 1918636.8 | AH11: =IFERROR(__xludf.DUMMYFUNCTION("""COMPUTED_VALUE"""),530973.4353016787) -> 530973.44 | AI11: =IFERROR(__xludf.DUMMYFUNCTION("""COMPUTED_VALUE"""),582480.6620408448) -> 582480.66 | AJ11: =IFERROR(__xludf.DUMMYFUNCTION("""COMPUTED_VALUE"""),663543.0815713655) -> 663543.08 | AK11: =IFERROR(__xludf.DUMMYFUNCTION("""COMPUTED_VALUE"""),503397.239797868) -> 503397.24 | AL11: =IFERROR(__xludf.DUMMYFUNCTION("""COMPUTED_VALUE"""),2280394.418711757) -> 2280394.4 | AM11: =IFERROR(__xludf.DUMMYFUNCTION("""COMPUTED_VALUE"""),467916.9855157) -> 467916.99 | AN11: =IFERROR(__xludf.DUMMYFUNCTION("""COMPUTED_VALUE"""),683524.33421106) -> 683524.33 | AO11: =IFERROR(__xludf.DUMMYFUNCTION("""COMPUTED_VALUE"""),663740.00791083) -> 663740.01 | AP11: =IFERROR(__xludf.DUMMYFUNCTION("""COMPUTED_VALUE"""),613976.6316785201) -> 613976.63 | AQ11: =IFERROR(__xludf.DUMMYFUNCTION("""COMPUTED_VALUE"""),2429157.9593161102) -> 2429158 | AR11: =IFERROR(__xludf.DUMMYFUNCTION("""COMPUTED_VALUE"""),465739.3515028147) -> 465739.35 | AS11: =IFERROR(__xludf.DUMMYFUNCTION("""COMPUTED_VALUE"""),701389.7810608575) -> 701389.78 | AT11: =IFERROR(__xludf.DUMMYFUNCTION("""COMPUTED_VALUE"""),602924.491707013) -> 602924.49 | AU11: =IFERROR(__xludf.DUMMYFUNCTION("""COMPUTED_VALUE"""),642422.8040689554) -> 642422.8 | AV11: =IFERROR(__xludf.DUMMYFUNCTION("""COMPUTED_VALUE"""),2412476.4283396406) -> 2412476.4 | AW11: =IFERROR(__xludf.DUMMYFUNCTION("""COMPUTED_VALUE"""),507075.58485550666) -> 507075.58 | AX11: =IFERROR(__xludf.DUMMYFUNCTION("""COMPUTED_VALUE"""),678798.6780578363) -> 678798.68 | AY11: =IFERROR(__xludf.DUMMYFUNCTION("""COMPUTED_VALUE"""),578735.651261969) -> 578735.65 | AZ11: =IFERROR(__xludf.DUMMYFUNCTION("""COMPUTED_VALUE"""),614972.2600069038) -> 614972.26 | BA11: =IFERROR(__xludf.DUMMYFUNCTION("""COMPUTED_VALUE"""),2379582.1741822157) -> 2379582.2 | BB11: =IFERROR(__xludf.DUMMYFUNCTION("""COMPUTED_VALUE"""),594786.3752807037) -> 594786.38 | BC11: =IFERROR(__xludf.DUMMYFUNCTION("""COMPUTED_VALUE"""),684726.3405892988) -> 684726.34 | BD11: =IFERROR(__xludf.DUMMYFUNCTION("""COMPUTED_VALUE"""),581470.1858745128) -> 581470.19 | BE11: =IFERROR(__xludf.DUMMYFUNCTION("""COMPUTED_VALUE"""),632910.8188813117) -> 632910.82 | BF11: =IFERROR(__xludf.DUMMYFUNCTION("""COMPUTED_VALUE"""),2493893.720625827) -> 2493893.7 | BG11: =IFERROR(__xludf.DUMMYFUNCTION("""COMPUTED_VALUE"""),573854.923306916) -> 573854.92 | BH11: =IFERROR(__xludf.DUMMYFUNCTION("""COMPUTED_VALUE"""),763988.347861581) -> 763988.35 | BI11: =IFERROR(__xludf.DUMMYFUNCTION("""COMPUTED_VALUE"""),571875.679107313) -> 571875.68 | BJ11: =IFERROR(__xludf.DUMMYFUNCTION("""COMPUTED_VALUE"""),630315.70187785) -> 630315.7 | BK11: =IFERROR(__xludf.DUMMYFUNCTION("""COMPUTED_VALUE"""),2540034.65215366) -> 2540034.7 | BL11: =IFERROR(__xludf.DUMMYFUNCTION("""COMPUTED_VALUE"""),558463.642795182) -> 558463.64 | BM11: =IFERROR(__xludf.DUMMYFUNCTION("""COMPUTED_VALUE"""),735594.658469192) -> 735594.66 | BN11: =IFERROR(__xludf.DUMMYFUNCTION("""COMPUTED_VALUE"""),606454.071933118) -> 606454.07 | BO11: =IFERROR(__xludf.DUMMYFUNCTION("""COMPUTED_VALUE"""),668400.221359688) -> 668400.22 | BP11: =IFERROR(__xludf.DUMMYFUNCTION("""COMPUTED_VALUE"""),2568912.59455718) -> 2568912.6 | BQ11: =IFERROR(__xludf.DUMMYFUNCTION("""COMPUTED_VALUE"""),491815.793087705) -> 491815.79 | BR11: =IFERROR(__xludf.DUMMYFUNCTION("""COMPUTED_VALUE"""),855558.825348645) -> 855558.83 | BS11: =IFERROR(__xludf.DUMMYFUNCTION("""COMPUTED_VALUE"""),596918.825687963) -> 596918.83 | BT11: =IFERROR(__xludf.DUMMYFUNCTION("""COMPUTED_VALUE"""),672648.011285686) -> 672648.01 | BU11: =IFERROR(__xludf.DUMMYFUNCTION("""COMPUTED_VALUE"""),2616941.455409999) -> 2616941.5 | BV11: =IFERROR(__xludf.DUMMYFUNCTION("""COMPUTED_VALUE"""),511943.996282232) -> 511944 | BW11: =IFERROR(__xludf.DUMMYFUNCTION("""COMPUTED_VALUE"""),823133.639176224) -> 823133.64 | BX11: =IFERROR(__xludf.DUMMYFUNCTION("""COMPUTED_VALUE"""),595525.524378957) -> 595525.52 | BY11: =IFERROR(__xludf.DUMMYFUNCTION("""COMPUTED_VALUE"""),666784.396735545) -> 666784.4 | BZ11: =IFERROR(__xludf.DUMMYFUNCTION("""COMPUTED_VALUE"""),2597387.556572958) -> 2597387.6 | CA11: =IFERROR(__xludf.DUMMYFUNCTION("""COMPUTED_VALUE"""),520413.756245516) -> 520413.76 | CB11: =IFERROR(__xludf.DUMMYFUNCTION("""COMPUTED_VALUE"""),804865.32766185) -> 804865.33 | CC11: =IFERROR(__xludf.DUMMYFUNCTION("""COMPUTED_VALUE"""),680902.83) -> 680902.83 | CD11: =IFERROR(__xludf.DUMMYFUNCTION("""COMPUTED_VALUE"""),715429.891930603) -> 715429.89 | CE11: =IFERROR(__xludf.DUMMYFUNCTION("""COMPUTED_VALUE"""),2721611.805837969) -> 2721611.8 | CF11: =IFERROR(__xludf.DUMMYFUNCTION("""COMPUTED_VALUE"""),514030.308694285) -> 514030.31 | CG11: =IFERROR(__xludf.DUMMYFUNCTION("""COMPUTED_VALUE"""),900400.843786866) -> 900400.84 | CH11: =IFERROR(__xludf.DUMMYFUNCTION("""COMPUTED_VALUE"""),750996.123989417) -> 750996.12 | CI11: =IFERROR(__xludf.DUMMYFUNCTION("""COMPUTED_VALUE"""),835861.153693755) -> 835861.15 | CJ11: =IFERROR(__xludf.DUMMYFUNCTION("""COMPUTED_VALUE"""),3001288.430164323) -> 3001288.4 | CK11: =IFERROR(__xludf.DUMMYFUNCTION("""COMPUTED_VALUE"""),583599.910397981) -> 583599.91 | CL11: =IFERROR(__xludf.DUMMYFUNCTION("""COMPUTED_VALUE"""),991190.658082767) -> 991190.66 | CM11: =IFERROR(__xludf.DUMMYFUNCTION("""COMPUTED_VALUE"""),766380.327026072) -> 766380.33 | CN11: =IFERROR(__xludf.DUMMYFUNCTION("""COMPUTED_VALUE"""),950156.541707983) -> 950156.54 | CO11: =IFERROR(__xludf.DUMMYFUNCTION("""COMPUTED_VALUE"""),3291327.437214803) -> 3291327.4 | CP11: =IFERROR(__xludf.DUMMYFUNCTION("""COMPUTED_VALUE"""),599544.460061761) -> 599544.46 | CQ11: =IFERROR(__xludf.DUMMYFUNCTION("""COMPUTED_VALUE"""),0.0) -> 0 | CR11: =IFERROR(__xludf.DUMMYFUNCTION("""COMPUTED_VALUE"""),0.0) -> 0 | CS11: =IFERROR(__xludf.DUMMYFUNCTION("""COMPUTED_VALUE"""),0.0) -> 0 | CT11: =IFERROR(__xludf.DUMMYFUNCTION("""COMPUTED_VALUE"""),599544.460061761) -> 599544.46 | CU11: =IFERROR(__xludf.DUMMYFUNCTION("""COMPUTED_VALUE"""),0.0) -> 0 | CV11: =IFERROR(__xludf.DUMMYFUNCTION("""COMPUTED_VALUE"""),0.0) -> 0 | CW11: =IFERROR(__xludf.DUMMYFUNCTION("""COMPUTED_VALUE"""),0.0) -> 0 | CX11: =IFERROR(__xludf.DUMMYFUNCTION("""COMPUTED_VALUE"""),0.0) -> 0 | CY11: =IFERROR(__xludf.DUMMYFUNCTION("""COMPUTED_VALUE"""),0.0) -> 0
C12: b. Tanaman Hortikultura Semusim | N12: =IFERROR(__xludf.DUMMYFUNCTION("""COMPUTED_VALUE"""),106712.80948560573) -> 106712.81 | O12: =IFERROR(__xludf.DUMMYFUNCTION("""COMPUTED_VALUE"""),81373.66408554834) -> 81373.664 | P12: =IFERROR(__xludf.DUMMYFUNCTION("""COMPUTED_VALUE"""),77252.86836170754) -> 77252.868 | Q12: =IFERROR(__xludf.DUMMYFUNCTION("""COMPUTED_VALUE"""),76223.93806713843) -> 76223.938 | R12: =IFERROR(__xludf.DUMMYFUNCTION("""COMPUTED_VALUE"""),341563.28) -> 341563.28 | S12: =IFERROR(__xludf.DUMMYFUNCTION("""COMPUTED_VALUE"""),83199.7351180254) -> 83199.735 | T12: =IFERROR(__xludf.DUMMYFUNCTION("""COMPUTED_VALUE"""),69826.08883842791) -> 69826.089 | U12: =IFERROR(__xludf.DUMMYFUNCTION("""COMPUTED_VALUE"""),82374.77903701128) -> 82374.779 | V12: =IFERROR(__xludf.DUMMYFUNCTION("""COMPUTED_VALUE"""),87185.18537791875) -> 87185.185 | W12: =IFERROR(__xludf.DUMMYFUNCTION("""COMPUTED_VALUE"""),322585.7883713833) -> 322585.79 | X12: =IFERROR(__xludf.DUMMYFUNCTION("""COMPUTED_VALUE"""),83944.20851002214) -> 83944.209 | Y12: =IFERROR(__xludf.DUMMYFUNCTION("""COMPUTED_VALUE"""),66953.77974233618) -> 66953.78 | Z12: =IFERROR(__xludf.DUMMYFUNCTION("""COMPUTED_VALUE"""),82541.32956735545) -> 82541.33 | AA12: =IFERROR(__xludf.DUMMYFUNCTION("""COMPUTED_VALUE"""),71413.6583434014) -> 71413.658 | AB12: =IFERROR(__xludf.DUMMYFUNCTION("""COMPUTED_VALUE"""),304852.9761631152) -> 304852.98 | AC12: =IFERROR(__xludf.DUMMYFUNCTION("""COMPUTED_VALUE"""),80774.8158491343) -> 80774.816 | AD12: =IFERROR(__xludf.DUMMYFUNCTION("""COMPUTED_VALUE"""),87546.39278080477) -> 87546.393 | AE12: =IFERROR(__xludf.DUMMYFUNCTION("""COMPUTED_VALUE"""),84516.7048682133) -> 84516.705 | AF12: =IFERROR(__xludf.DUMMYFUNCTION("""COMPUTED_VALUE"""),68560.81992184762) -> 68560.82 | AG12: =IFERROR(__xludf.DUMMYFUNCTION("""COMPUTED_VALUE"""),321398.73342) -> 321398.73 | AH12: =IFERROR(__xludf.DUMMYFUNCTION("""COMPUTED_VALUE"""),84511.13662750149) -> 84511.137 | AI12: =IFERROR(__xludf.DUMMYFUNCTION("""COMPUTED_VALUE"""),78137.82864252958) -> 78137.829 | AJ12: =IFERROR(__xludf.DUMMYFUNCTION("""COMPUTED_VALUE"""),69868.8625818765) -> 69868.863 | AK12: =IFERROR(__xludf.DUMMYFUNCTION("""COMPUTED_VALUE"""),73504.74457473971) -> 73504.745 | AL12: =IFERROR(__xludf.DUMMYFUNCTION("""COMPUTED_VALUE"""),306022.5724266473) -> 306022.57 | AM12: =IFERROR(__xludf.DUMMYFUNCTION("""COMPUTED_VALUE"""),89842.17806591999) -> 89842.178 | AN12: =IFERROR(__xludf.DUMMYFUNCTION("""COMPUTED_VALUE"""),80333.01616605) -> 80333.016 | AO12: =IFERROR(__xludf.DUMMYFUNCTION("""COMPUTED_VALUE"""),75003.0829747) -> 75003.083 | AP12: =IFERROR(__xludf.DUMMYFUNCTION("""COMPUTED_VALUE"""),72203.01911918998) -> 72203.019 | AQ12: =IFERROR(__xludf.DUMMYFUNCTION("""COMPUTED_VALUE"""),317381.29632585996) -> 317381.3 | AR12: =IFERROR(__xludf.DUMMYFUNCTION("""COMPUTED_VALUE"""),69497.75744034775) -> 69497.757 | AS12: =IFERROR(__xludf.DUMMYFUNCTION("""COMPUTED_VALUE"""),83566.5243065827) -> 83566.524 | AT12: =IFERROR(__xludf.DUMMYFUNCTION("""COMPUTED_VALUE"""),88706.20835313929) -> 88706.208 | AU12: =IFERROR(__xludf.DUMMYFUNCTION("""COMPUTED_VALUE"""),96747.21235762075) -> 96747.212 | AV12: =IFERROR(__xludf.DUMMYFUNCTION("""COMPUTED_VALUE"""),338517.7024576905) -> 338517.7 | AW12: =IFERROR(__xludf.DUMMYFUNCTION("""COMPUTED_VALUE"""),78451.00249235304) -> 78451.002 | AX12: =IFERROR(__xludf.DUMMYFUNCTION("""COMPUTED_VALUE"""),86284.98571436226) -> 86284.986 | AY12: =IFERROR(__xludf.DUMMYFUNCTION("""COMPUTED_VALUE"""),88052.58110346312) -> 88052.581 | AZ12: =IFERROR(__xludf.DUMMYFUNCTION("""COMPUTED_VALUE"""),89014.54907794476) -> 89014.549 | BA12: =IFERROR(__xludf.DUMMYFUNCTION("""COMPUTED_VALUE"""),341803.1183881232) -> 341803.12 | BB12: =IFERROR(__xludf.DUMMYFUNCTION("""COMPUTED_VALUE"""),82438.38336901153) -> 82438.383 | BC12: =IFERROR(__xludf.DUMMYFUNCTION("""COMPUTED_VALUE"""),82416.22498168358) -> 82416.225 | BD12: =IFERROR(__xludf.DUMMYFUNCTION("""COMPUTED_VALUE"""),89026.36883566417) -> 89026.369 | BE12: =IFERROR(__xludf.DUMMYFUNCTION("""COMPUTED_VALUE"""),93691.91530647707) -> 93691.915 | BF12: =IFERROR(__xludf.DUMMYFUNCTION("""COMPUTED_VALUE"""),347572.89249283634) -> 347572.89 | BG12: =IFERROR(__xludf.DUMMYFUNCTION("""COMPUTED_VALUE"""),90599.1895865457) -> 90599.19 | BH12: =IFERROR(__xludf.DUMMYFUNCTION("""COMPUTED_VALUE"""),93050.8358039458) -> 93050.836 | BI12: =IFERROR(__xludf.DUMMYFUNCTION("""COMPUTED_VALUE"""),98042.8925684924) -> 98042.893 | BJ12: =IFERROR(__xludf.DUMMYFUNCTION("""COMPUTED_VALUE"""),95519.5619650932) -> 95519.562 | BK12: =IFERROR(__xludf.DUMMYFUNCTION("""COMPUTED_VALUE"""),377212.4799240771) -> 377212.48 | BL12: =IFERROR(__xludf.DUMMYFUNCTION("""COMPUTED_VALUE"""),90139.6453145785) -> 90139.645 | BM12: =IFERROR(__xludf.DUMMYFUNCTION("""COMPUTED_VALUE"""),89288.4952285842) -> 89288.495 | BN12: =IFERROR(__xludf.DUMMYFUNCTION("""COMPUTED_VALUE"""),96142.1998056872) -> 96142.2 | BO12: =IFERROR(__xludf.DUMMYFUNCTION("""COMPUTED_VALUE"""),89273.6845337092) -> 89273.685 | BP12: =IFERROR(__xludf.DUMMYFUNCTION("""COMPUTED_VALUE"""),364844.0248825591) -> 364844.02 | BQ12: =IFERROR(__xludf.DUMMYFUNCTION("""COMPUTED_VALUE"""),94251.3716531472) -> 94251.372 | BR12: =IFERROR(__xludf.DUMMYFUNCTION("""COMPUTED_VALUE"""),94985.9553625852) -> 94985.955 | BS12: =IFERROR(__xludf.DUMMYFUNCTION("""COMPUTED_VALUE"""),95674.4008439091) -> 95674.401 | BT12: =IFERROR(__xludf.DUMMYFUNCTION("""COMPUTED_VALUE"""),92892.7716847832) -> 92892.772 | BU12: =IFERROR(__xludf.DUMMYFUNCTION("""COMPUTED_VALUE"""),377804.49954442476) -> 377804.5 | BV12: =IFERROR(__xludf.DUMMYFUNCTION("""COMPUTED_VALUE"""),92945.8781337948) -> 92945.878 | BW12: =IFERROR(__xludf.DUMMYFUNCTION("""COMPUTED_VALUE"""),99016.5864111039) -> 99016.586 | BX12: =IFERROR(__xludf.DUMMYFUNCTION("""COMPUTED_VALUE"""),113835.765376666) -> 113835.77 | BY12: =IFERROR(__xludf.DUMMYFUNCTION("""COMPUTED_VALUE"""),114587.142532471) -> 114587.14 | BZ12: =IFERROR(__xludf.DUMMYFUNCTION("""COMPUTED_VALUE"""),420385.3724540357) -> 420385.37 | CA12: =IFERROR(__xludf.DUMMYFUNCTION("""COMPUTED_VALUE"""),107041.790452659) -> 107041.79 | CB12: =IFERROR(__xludf.DUMMYFUNCTION("""COMPUTED_VALUE"""),115978.153011141) -> 115978.15 | CC12: =IFERROR(__xludf.DUMMYFUNCTION("""COMPUTED_VALUE"""),106621.067606878) -> 106621.07 | CD12: =IFERROR(__xludf.DUMMYFUNCTION("""COMPUTED_VALUE"""),113507.502094277) -> 113507.5 | CE12: =IFERROR(__xludf.DUMMYFUNCTION("""COMPUTED_VALUE"""),443148.513164955) -> 443148.51 | CF12: =IFERROR(__xludf.DUMMYFUNCTION("""COMPUTED_VALUE"""),120763.649011681) -> 120763.65 | CG12: =IFERROR(__xludf.DUMMYFUNCTION("""COMPUTED_VALUE"""),117677.550119609) -> 117677.55 | CH12: =IFERROR(__xludf.DUMMYFUNCTION("""COMPUTED_VALUE"""),107000.437336148) -> 107000.44 | CI12: =IFERROR(__xludf.DUMMYFUNCTION("""COMPUTED_VALUE"""),118190.15086481) -> 118190.15 | CJ12: =IFERROR(__xludf.DUMMYFUNCTION("""COMPUTED_VALUE"""),463631.787332248) -> 463631.79 | CK12: =IFERROR(__xludf.DUMMYFUNCTION("""COMPUTED_VALUE"""),115500.227088164) -> 115500.23 | CL12: =IFERROR(__xludf.DUMMYFUNCTION("""COMPUTED_VALUE"""),110905.185067266) -> 110905.19 | CM12: =IFERROR(__xludf.DUMMYFUNCTION("""COMPUTED_VALUE"""),113346.953891159) -> 113346.95 | CN12: =IFERROR(__xludf.DUMMYFUNCTION("""COMPUTED_VALUE"""),123789.929345131) -> 123789.93 | CO12: =IFERROR(__xludf.DUMMYFUNCTION("""COMPUTED_VALUE"""),463542.29539171996) -> 463542.3 | CP12: =IFERROR(__xludf.DUMMYFUNCTION("""COMPUTED_VALUE"""),132115.49067001772) -> 132115.49 | CQ12: =IFERROR(__xludf.DUMMYFUNCTION("""COMPUTED_VALUE"""),0.0) -> 0 | CR12: =IFERROR(__xludf.DUMMYFUNCTION("""COMPUTED_VALUE"""),0.0) -> 0 | CS12: =IFERROR(__xludf.DUMMYFUNCTION("""COMPUTED_VALUE"""),0.0) -> 0 | CT12: =IFERROR(__xludf.DUMMYFUNCTION("""COMPUTED_VALUE"""),132115.49067001772) -> 132115.49 | CU12: =IFERROR(__xludf.DUMMYFUNCTION("""COMPUTED_VALUE"""),0.0) -> 0 | CV12: =IFERROR(__xludf.DUMMYFUNCTION("""COMPUTED_VALUE"""),0.0) -> 0 | CW12: =IFERROR(__xludf.DUMMYFUNCTION("""COMPUTED_VALUE"""),0.0) -> 0 | CX12: =IFERROR(__xludf.DUMMYFUNCTION("""COMPUTED_VALUE"""),0.0) -> 0 | CY12: =IFERROR(__xludf.DUMMYFUNCTION("""COMPUTED_VALUE"""),0.0) -> 0
C13: c. Perkebunan Semusim | N13: =IFERROR(__xludf.DUMMYFUNCTION("""COMPUTED_VALUE"""),2116.3448424180465) -> 2116.3448 | O13: =IFERROR(__xludf.DUMMYFUNCTION("""COMPUTED_VALUE"""),4815.117386138665) -> 4815.1174 | P13: =IFERROR(__xludf.DUMMYFUNCTION("""COMPUTED_VALUE"""),5444.012650725363) -> 5444.0127 | Q13: =IFERROR(__xludf.DUMMYFUNCTION("""COMPUTED_VALUE"""),3729.1450907179255) -> 3729.1451 | R13: =IFERROR(__xludf.DUMMYFUNCTION("""COMPUTED_VALUE"""),16104.61997) -> 16104.62 | S13: =IFERROR(__xludf.DUMMYFUNCTION("""COMPUTED_VALUE"""),6719.892956910391) -> 6719.893 | T13: =IFERROR(__xludf.DUMMYFUNCTION("""COMPUTED_VALUE"""),10492.298482451597) -> 10492.298 | U13: =IFERROR(__xludf.DUMMYFUNCTION("""COMPUTED_VALUE"""),5931.939349346798) -> 5931.9393 | V13: =IFERROR(__xludf.DUMMYFUNCTION("""COMPUTED_VALUE"""),10566.219476529037) -> 10566.219 | W13: =IFERROR(__xludf.DUMMYFUNCTION("""COMPUTED_VALUE"""),33710.35026523782) -> 33710.35 | X13: =IFERROR(__xludf.DUMMYFUNCTION("""COMPUTED_VALUE"""),11390.65493320067) -> 11390.655 | Y13: =IFERROR(__xludf.DUMMYFUNCTION("""COMPUTED_VALUE"""),22161.095912413606) -> 22161.096 | Z13: =IFERROR(__xludf.DUMMYFUNCTION("""COMPUTED_VALUE"""),13929.269066701267) -> 13929.269 | AA13: =IFERROR(__xludf.DUMMYFUNCTION("""COMPUTED_VALUE"""),15405.82785853386) -> 15405.828 | AB13: =IFERROR(__xludf.DUMMYFUNCTION("""COMPUTED_VALUE"""),62886.8477708494) -> 62886.848 | AC13: =IFERROR(__xludf.DUMMYFUNCTION("""COMPUTED_VALUE"""),10216.471883577713) -> 10216.472 | AD13: =IFERROR(__xludf.DUMMYFUNCTION("""COMPUTED_VALUE"""),13919.10967800903) -> 13919.11 | AE13: =IFERROR(__xludf.DUMMYFUNCTION("""COMPUTED_VALUE"""),19220.349928284282) -> 19220.35 | AF13: =IFERROR(__xludf.DUMMYFUNCTION("""COMPUTED_VALUE"""),23026.464303919336) -> 23026.464 | AG13: =IFERROR(__xludf.DUMMYFUNCTION("""COMPUTED_VALUE"""),66382.39579379036) -> 66382.396 | AH13: =IFERROR(__xludf.DUMMYFUNCTION("""COMPUTED_VALUE"""),10363.288394137595) -> 10363.288 | AI13: =IFERROR(__xludf.DUMMYFUNCTION("""COMPUTED_VALUE"""),16877.05256316253) -> 16877.053 | AJ13: =IFERROR(__xludf.DUMMYFUNCTION("""COMPUTED_VALUE"""),25305.505035786824) -> 25305.505 | AK13: =IFERROR(__xludf.DUMMYFUNCTION("""COMPUTED_VALUE"""),23753.852438579543) -> 23753.852 | AL13: =IFERROR(__xludf.DUMMYFUNCTION("""COMPUTED_VALUE"""),76299.69843166649) -> 76299.698 | AM13: =IFERROR(__xludf.DUMMYFUNCTION("""COMPUTED_VALUE"""),12699.32530253) -> 12699.325 | AN13: =IFERROR(__xludf.DUMMYFUNCTION("""COMPUTED_VALUE"""),19918.57280212) -> 19918.573 | AO13: =IFERROR(__xludf.DUMMYFUNCTION("""COMPUTED_VALUE"""),31834.24460122) -> 31834.245 | AP13: =IFERROR(__xludf.DUMMYFUNCTION("""COMPUTED_VALUE"""),19308.00890652) -> 19308.009 | AQ13: =IFERROR(__xludf.DUMMYFUNCTION("""COMPUTED_VALUE"""),83760.15161239001) -> 83760.152 | AR13: =IFERROR(__xludf.DUMMYFUNCTION("""COMPUTED_VALUE"""),19382.5858433061) -> 19382.586 | AS13: =IFERROR(__xludf.DUMMYFUNCTION("""COMPUTED_VALUE"""),19188.2400098441) -> 19188.24 | AT13: =IFERROR(__xludf.DUMMYFUNCTION("""COMPUTED_VALUE"""),19183.4333743541) -> 19183.433 | AU13: =IFERROR(__xludf.DUMMYFUNCTION("""COMPUTED_VALUE"""),26378.1702168895) -> 26378.17 | AV13: =IFERROR(__xludf.DUMMYFUNCTION("""COMPUTED_VALUE"""),84132.4294443938) -> 84132.429 | AW13: =IFERROR(__xludf.DUMMYFUNCTION("""COMPUTED_VALUE"""),23961.354860871) -> 23961.355 | AX13: =IFERROR(__xludf.DUMMYFUNCTION("""COMPUTED_VALUE"""),19525.0601423297) -> 19525.06 | AY13: =IFERROR(__xludf.DUMMYFUNCTION("""COMPUTED_VALUE"""),19368.64269126) -> 19368.643 | AZ13: =IFERROR(__xludf.DUMMYFUNCTION("""COMPUTED_VALUE"""),19441.9319898109) -> 19441.932 | BA13: =IFERROR(__xludf.DUMMYFUNCTION("""COMPUTED_VALUE"""),82296.9896842716) -> 82296.99 | BB13: =IFERROR(__xludf.DUMMYFUNCTION("""COMPUTED_VALUE"""),21896.8904667456) -> 21896.89 | BC13: =IFERROR(__xludf.DUMMYFUNCTION("""COMPUTED_VALUE"""),21348.9295915327) -> 21348.93 | BD13: =IFERROR(__xludf.DUMMYFUNCTION("""COMPUTED_VALUE"""),21512.7053825152) -> 21512.705 | BE13: =IFERROR(__xludf.DUMMYFUNCTION("""COMPUTED_VALUE"""),21682.7489679934) -> 21682.749 | BF13: =IFERROR(__xludf.DUMMYFUNCTION("""COMPUTED_VALUE"""),86441.2744087869) -> 86441.274 | BG13: =IFERROR(__xludf.DUMMYFUNCTION("""COMPUTED_VALUE"""),21953.5767055757) -> 21953.577 | BH13: =IFERROR(__xludf.DUMMYFUNCTION("""COMPUTED_VALUE"""),23061.443766719) -> 23061.444 | BI13: =IFERROR(__xludf.DUMMYFUNCTION("""COMPUTED_VALUE"""),23462.3957436444) -> 23462.396 | BJ13: =IFERROR(__xludf.DUMMYFUNCTION("""COMPUTED_VALUE"""),23437.9590682014) -> 23437.959 | BK13: =IFERROR(__xludf.DUMMYFUNCTION("""COMPUTED_VALUE"""),91915.3752841405) -> 91915.375 | BL13: =IFERROR(__xludf.DUMMYFUNCTION("""COMPUTED_VALUE"""),24646.4035303814) -> 24646.404 | BM13: =IFERROR(__xludf.DUMMYFUNCTION("""COMPUTED_VALUE"""),25292.8891480748) -> 25292.889 | BN13: =IFERROR(__xludf.DUMMYFUNCTION("""COMPUTED_VALUE"""),24462.0268376755) -> 24462.027 | BO13: =IFERROR(__xludf.DUMMYFUNCTION("""COMPUTED_VALUE"""),24904.5743603591) -> 24904.574 | BP13: =IFERROR(__xludf.DUMMYFUNCTION("""COMPUTED_VALUE"""),99305.8938764908) -> 99305.894 | BQ13: =IFERROR(__xludf.DUMMYFUNCTION("""COMPUTED_VALUE"""),22766.4640306032) -> 22766.464 | BR13: =IFERROR(__xludf.DUMMYFUNCTION("""COMPUTED_VALUE"""),23818.4993596191) -> 23818.499 | BS13: =IFERROR(__xludf.DUMMYFUNCTION("""COMPUTED_VALUE"""),39263.4522471625) -> 39263.452 | BT13: =IFERROR(__xludf.DUMMYFUNCTION("""COMPUTED_VALUE"""),43720.3153523842) -> 43720.315 | BU13: =IFERROR(__xludf.DUMMYFUNCTION("""COMPUTED_VALUE"""),129568.73098976901) -> 129568.73 | BV13: =IFERROR(__xludf.DUMMYFUNCTION("""COMPUTED_VALUE"""),30069.4528335517) -> 30069.453 | BW13: =IFERROR(__xludf.DUMMYFUNCTION("""COMPUTED_VALUE"""),22189.6158289094) -> 22189.616 | BX13: =IFERROR(__xludf.DUMMYFUNCTION("""COMPUTED_VALUE"""),42660.2796991622) -> 42660.28 | BY13: =IFERROR(__xludf.DUMMYFUNCTION("""COMPUTED_VALUE"""),44980.2101691211) -> 44980.21 | BZ13: =IFERROR(__xludf.DUMMYFUNCTION("""COMPUTED_VALUE"""),139899.5585307444) -> 139899.56 | CA13: =IFERROR(__xludf.DUMMYFUNCTION("""COMPUTED_VALUE"""),23979.1398312281) -> 23979.14 | CB13: =IFERROR(__xludf.DUMMYFUNCTION("""COMPUTED_VALUE"""),26355.2296627875) -> 26355.23 | CC13: =IFERROR(__xludf.DUMMYFUNCTION("""COMPUTED_VALUE"""),46970.772942389) -> 46970.773 | CD13: =IFERROR(__xludf.DUMMYFUNCTION("""COMPUTED_VALUE"""),58158.8942387214) -> 58158.894 | CE13: =IFERROR(__xludf.DUMMYFUNCTION("""COMPUTED_VALUE"""),155464.036675126) -> 155464.04 | CF13: =IFERROR(__xludf.DUMMYFUNCTION("""COMPUTED_VALUE"""),27627.874109663) -> 27627.874 | CG13: =IFERROR(__xludf.DUMMYFUNCTION("""COMPUTED_VALUE"""),36467.241247446) -> 36467.241 | CH13: =IFERROR(__xludf.DUMMYFUNCTION("""COMPUTED_VALUE"""),70002.9621215585) -> 70002.962 | CI13: =IFERROR(__xludf.DUMMYFUNCTION("""COMPUTED_VALUE"""),168263.543529105) -> 168263.54 | CJ13: =IFERROR(__xludf.DUMMYFUNCTION("""COMPUTED_VALUE"""),302361.6210077725) -> 302361.62 | CK13: =IFERROR(__xludf.DUMMYFUNCTION("""COMPUTED_VALUE"""),95817.038380516) -> 95817.038 | CL13: =IFERROR(__xludf.DUMMYFUNCTION("""COMPUTED_VALUE"""),68444.7040835188) -> 68444.704 | CM13: =IFERROR(__xludf.DUMMYFUNCTION("""COMPUTED_VALUE"""),90955.8796444188) -> 90955.88 | CN13: =IFERROR(__xludf.DUMMYFUNCTION("""COMPUTED_VALUE"""),138760.882458869) -> 138760.88 | CO13: =IFERROR(__xludf.DUMMYFUNCTION("""COMPUTED_VALUE"""),393978.50456732255) -> 393978.5 | CP13: =IFERROR(__xludf.DUMMYFUNCTION("""COMPUTED_VALUE"""),81912.40000679449) -> 81912.4 | CQ13: =IFERROR(__xludf.DUMMYFUNCTION("""COMPUTED_VALUE"""),0.0) -> 0 | CR13: =IFERROR(__xludf.DUMMYFUNCTION("""COMPUTED_VALUE"""),0.0) -> 0 | CS13: =IFERROR(__xludf.DUMMYFUNCTION("""COMPUTED_VALUE"""),0.0) -> 0 | CT13: =IFERROR(__xludf.DUMMYFUNCTION("""COMPUTED_VALUE"""),81912.40000679449) -> 81912.4 | CU13: =IFERROR(__xludf.DUMMYFUNCTION("""COMPUTED_VALUE"""),0.0) -> 0 | CV13: =IFERROR(__xludf.DUMMYFUNCTION("""COMPUTED_VALUE"""),0.0) -> 0 | CW13: =IFERROR(__xludf.DUMMYFUNCTION("""COMPUTED_VALUE"""),0.0) -> 0 | CX13: =IFERROR(__xludf.DUMMYFUNCTION("""COMPUTED_VALUE"""),0.0) -> 0 | CY13: =IFERROR(__xludf.DUMMYFUNCTION("""COMPUTED_VALUE"""),0.0) -> 0
C14: d. Tanaman Hortikultura Tahunan & Lainnya | N14: =IFERROR(__xludf.DUMMYFUNCTION("""COMPUTED_VALUE"""),109215.43577774275) -> 109215.44 | O14: =IFERROR(__xludf.DUMMYFUNCTION("""COMPUTED_VALUE"""),148338.7761547298) -> 148338.78 | P14: =IFERROR(__xludf.DUMMYFUNCTION("""COMPUTED_VALUE"""),266813.3915232591) -> 266813.39 | Q14: =IFERROR(__xludf.DUMMYFUNCTION("""COMPUTED_VALUE"""),227278.46652586324) -> 227278.47 | R14: =IFERROR(__xludf.DUMMYFUNCTION("""COMPUTED_VALUE"""),751646.0699815949) -> 751646.07 | S14: =IFERROR(__xludf.DUMMYFUNCTION("""COMPUTED_VALUE"""),125116.4986724918) -> 125116.5 | T14: =IFERROR(__xludf.DUMMYFUNCTION("""COMPUTED_VALUE"""),91861.3180866057) -> 91861.318 | U14: =IFERROR(__xludf.DUMMYFUNCTION("""COMPUTED_VALUE"""),166507.657684949) -> 166507.66 | V14: =IFERROR(__xludf.DUMMYFUNCTION("""COMPUTED_VALUE"""),388492.9380464213) -> 388492.94 | W14: =IFERROR(__xludf.DUMMYFUNCTION("""COMPUTED_VALUE"""),771978.4124904678) -> 771978.41 | X14: =IFERROR(__xludf.DUMMYFUNCTION("""COMPUTED_VALUE"""),195554.30027510866) -> 195554.3 | Y14: =IFERROR(__xludf.DUMMYFUNCTION("""COMPUTED_VALUE"""),211994.31014850002) -> 211994.31 | Z14: =IFERROR(__xludf.DUMMYFUNCTION("""COMPUTED_VALUE"""),131125.28607157047) -> 131125.29 | AA14: =IFERROR(__xludf.DUMMYFUNCTION("""COMPUTED_VALUE"""),150811.70569482094) -> 150811.71 | AB14: =IFERROR(__xludf.DUMMYFUNCTION("""COMPUTED_VALUE"""),689485.6021900001) -> 689485.6 | AC14: =IFERROR(__xludf.DUMMYFUNCTION("""COMPUTED_VALUE"""),134117.77813120256) -> 134117.78 | AD14: =IFERROR(__xludf.DUMMYFUNCTION("""COMPUTED_VALUE"""),246419.51523205172) -> 246419.52 | AE14: =IFERROR(__xludf.DUMMYFUNCTION("""COMPUTED_VALUE"""),200369.2414846951) -> 200369.24 | AF14: =IFERROR(__xludf.DUMMYFUNCTION("""COMPUTED_VALUE"""),177432.93107418405) -> 177432.93 | AG14: =IFERROR(__xludf.DUMMYFUNCTION("""COMPUTED_VALUE"""),758339.4659221334) -> 758339.47 | AH14: =IFERROR(__xludf.DUMMYFUNCTION("""COMPUTED_VALUE"""),177886.07076749514) -> 177886.07 | AI14: =IFERROR(__xludf.DUMMYFUNCTION("""COMPUTED_VALUE"""),192487.46381731745) -> 192487.46 | AJ14: =IFERROR(__xludf.DUMMYFUNCTION("""COMPUTED_VALUE"""),174697.47961631103) -> 174697.48 | AK14: =IFERROR(__xludf.DUMMYFUNCTION("""COMPUTED_VALUE"""),137985.9444685468) -> 137985.94 | AL14: =IFERROR(__xludf.DUMMYFUNCTION("""COMPUTED_VALUE"""),683056.9586696704) -> 683056.96 | AM14: =IFERROR(__xludf.DUMMYFUNCTION("""COMPUTED_VALUE"""),217943.21951923) -> 217943.22 | AN14: =IFERROR(__xludf.DUMMYFUNCTION("""COMPUTED_VALUE"""),144608.43289153) -> 144608.43 | AO14: =IFERROR(__xludf.DUMMYFUNCTION("""COMPUTED_VALUE"""),222927.43593755) -> 222927.44 | AP14: =IFERROR(__xludf.DUMMYFUNCTION("""COMPUTED_VALUE"""),159477.99723801) -> 159478 | AQ14: =IFERROR(__xludf.DUMMYFUNCTION("""COMPUTED_VALUE"""),744957.0855863201) -> 744957.09 | AR14: =IFERROR(__xludf.DUMMYFUNCTION("""COMPUTED_VALUE"""),204432.01075383445) -> 204432.01 | AS14: =IFERROR(__xludf.DUMMYFUNCTION("""COMPUTED_VALUE"""),154443.7) -> 154443.7 | AT14: =IFERROR(__xludf.DUMMYFUNCTION("""COMPUTED_VALUE"""),160976.4671365742) -> 160976.47 | AU14: =IFERROR(__xludf.DUMMYFUNCTION("""COMPUTED_VALUE"""),182010.903424898) -> 182010.9 | AV14: =IFERROR(__xludf.DUMMYFUNCTION("""COMPUTED_VALUE"""),701863.0813153067) -> 701863.08 | AW14: =IFERROR(__xludf.DUMMYFUNCTION("""COMPUTED_VALUE"""),185301.85707843452) -> 185301.86 | AX14: =IFERROR(__xludf.DUMMYFUNCTION("""COMPUTED_VALUE"""),168089.587309174) -> 168089.59 | AY14: =IFERROR(__xludf.DUMMYFUNCTION("""COMPUTED_VALUE"""),166694.21960143326) -> 166694.22 | AZ14: =IFERROR(__xludf.DUMMYFUNCTION("""COMPUTED_VALUE"""),174256.5431013048) -> 174256.54 | BA14: =IFERROR(__xludf.DUMMYFUNCTION("""COMPUTED_VALUE"""),694342.2070903466) -> 694342.21 | BB14: =IFERROR(__xludf.DUMMYFUNCTION("""COMPUTED_VALUE"""),200322.81776253734) -> 200322.82 | BC14: =IFERROR(__xludf.DUMMYFUNCTION("""COMPUTED_VALUE"""),184323.74416901407) -> 184323.74 | BD14: =IFERROR(__xludf.DUMMYFUNCTION("""COMPUTED_VALUE"""),188398.42780079038) -> 188398.43 | BE14: =IFERROR(__xludf.DUMMYFUNCTION("""COMPUTED_VALUE"""),198564.21175991758) -> 198564.21 | BF14: =IFERROR(__xludf.DUMMYFUNCTION("""COMPUTED_VALUE"""),771609.2014922594) -> 771609.2 | BG14: =IFERROR(__xludf.DUMMYFUNCTION("""COMPUTED_VALUE"""),213502.248506687) -> 213502.25 | BH14: =IFERROR(__xludf.DUMMYFUNCTION("""COMPUTED_VALUE"""),210267.498382881) -> 210267.5 | BI14: =IFERROR(__xludf.DUMMYFUNCTION("""COMPUTED_VALUE"""),214883.485228756) -> 214883.49 | BJ14: =IFERROR(__xludf.DUMMYFUNCTION("""COMPUTED_VALUE"""),225170.267269606) -> 225170.27 | BK14: =IFERROR(__xludf.DUMMYFUNCTION("""COMPUTED_VALUE"""),863823.49938793) -> 863823.5 | BL14: =IFERROR(__xludf.DUMMYFUNCTION("""COMPUTED_VALUE"""),224648.918298923) -> 224648.92 | BM14: =IFERROR(__xludf.DUMMYFUNCTION("""COMPUTED_VALUE"""),218459.789080531) -> 218459.79 | BN14: =IFERROR(__xludf.DUMMYFUNCTION("""COMPUTED_VALUE"""),223925.962438111) -> 223925.96 | BO14: =IFERROR(__xludf.DUMMYFUNCTION("""COMPUTED_VALUE"""),224438.059059275) -> 224438.06 | BP14: =IFERROR(__xludf.DUMMYFUNCTION("""COMPUTED_VALUE"""),891472.72887684) -> 891472.73 | BQ14: =IFERROR(__xludf.DUMMYFUNCTION("""COMPUTED_VALUE"""),228462.140752216) -> 228462.14 | BR14: =IFERROR(__xludf.DUMMYFUNCTION("""COMPUTED_VALUE"""),223964.221042609) -> 223964.22 | BS14: =IFERROR(__xludf.DUMMYFUNCTION("""COMPUTED_VALUE"""),226251.76066239) -> 226251.76 | BT14: =IFERROR(__xludf.DUMMYFUNCTION("""COMPUTED_VALUE"""),249897.51784165) -> 249897.52 | BU14: =IFERROR(__xludf.DUMMYFUNCTION("""COMPUTED_VALUE"""),928575.640298865) -> 928575.64 | BV14: =IFERROR(__xludf.DUMMYFUNCTION("""COMPUTED_VALUE"""),234752.624401181) -> 234752.62 | BW14: =IFERROR(__xludf.DUMMYFUNCTION("""COMPUTED_VALUE"""),238927.285448567) -> 238927.29 | BX14: =IFERROR(__xludf.DUMMYFUNCTION("""COMPUTED_VALUE"""),242559.572984058) -> 242559.57 | BY14: =IFERROR(__xludf.DUMMYFUNCTION("""COMPUTED_VALUE"""),255159.572984058) -> 255159.57 | BZ14: =IFERROR(__xludf.DUMMYFUNCTION("""COMPUTED_VALUE"""),971399.0558178639) -> 971399.06 | CA14: =IFERROR(__xludf.DUMMYFUNCTION("""COMPUTED_VALUE"""),264302.200293002) -> 264302.2 | CB14: =IFERROR(__xludf.DUMMYFUNCTION("""COMPUTED_VALUE"""),254186.867244336) -> 254186.87 | CC14: =IFERROR(__xludf.DUMMYFUNCTION("""COMPUTED_VALUE"""),256024.339905322) -> 256024.34 | CD14: =IFERROR(__xludf.DUMMYFUNCTION("""COMPUTED_VALUE"""),261974.376649898) -> 261974.38 | CE14: =IFERROR(__xludf.DUMMYFUNCTION("""COMPUTED_VALUE"""),1036487.7840925581) -> 1036487.8 | CF14: =IFERROR(__xludf.DUMMYFUNCTION("""COMPUTED_VALUE"""),293708.452721066) -> 293708.45 | CG14: =IFERROR(__xludf.DUMMYFUNCTION("""COMPUTED_VALUE"""),253507.997442967) -> 253508 | CH14: =IFERROR(__xludf.DUMMYFUNCTION("""COMPUTED_VALUE"""),261779.62142343) -> 261779.62 | CI14: =IFERROR(__xludf.DUMMYFUNCTION("""COMPUTED_VALUE"""),265487.632822228) -> 265487.63 | CJ14: =IFERROR(__xludf.DUMMYFUNCTION("""COMPUTED_VALUE"""),1074483.704409691) -> 1074483.7 | CK14: =IFERROR(__xludf.DUMMYFUNCTION("""COMPUTED_VALUE"""),284039.62246468) -> 284039.62 | CL14: =IFERROR(__xludf.DUMMYFUNCTION("""COMPUTED_VALUE"""),253273.567597335) -> 253273.57 | CM14: =IFERROR(__xludf.DUMMYFUNCTION("""COMPUTED_VALUE"""),252410.603429681) -> 252410.6 | CN14: =IFERROR(__xludf.DUMMYFUNCTION("""COMPUTED_VALUE"""),309673.051206847) -> 309673.05 | CO14: =IFERROR(__xludf.DUMMYFUNCTION("""COMPUTED_VALUE"""),1099396.844698543) -> 1099396.8 | CP14: =IFERROR(__xludf.DUMMYFUNCTION("""COMPUTED_VALUE"""),284903.2299485325) -> 284903.23 | CQ14: =IFERROR(__xludf.DUMMYFUNCTION("""COMPUTED_VALUE"""),0.0) -> 0 | CR14: =IFERROR(__xludf.DUMMYFUNCTION("""COMPUTED_VALUE"""),0.0) -> 0 | CS14: =IFERROR(__xludf.DUMMYFUNCTION("""COMPUTED_VALUE"""),0.0) -> 0 | CT14: =IFERROR(__xludf.DUMMYFUNCTION("""COMPUTED_VALUE"""),284903.2299485325) -> 284903.23 | CU14: =IFERROR(__xludf.DUMMYFUNCTION("""COMPUTED_VALUE"""),0.0) -> 0 | CV14: =IFERROR(__xludf.DUMMYFUNCTION("""COMPUTED_VALUE"""),0.0) -> 0 | CW14: =IFERROR(__xludf.DUMMYFUNCTION("""COMPUTED_VALUE"""),0.0) -> 0 | CX14: =IFERROR(__xludf.DUMMYFUNCTION("""COMPUTED_VALUE"""),0.0) -> 0 | CY14: =IFERROR(__xludf.DUMMYFUNCTION("""COMPUTED_VALUE"""),0.0) -> 0
C15: e. Perkebunan Tahunan | N15: =IFERROR(__xludf.DUMMYFUNCTION("""COMPUTED_VALUE"""),602137.5174183884) -> 602137.52 | O15: =IFERROR(__xludf.DUMMYFUNCTION("""COMPUTED_VALUE"""),1023718.6808247706) -> 1023718.7 | P15: =IFERROR(__xludf.DUMMYFUNCTION("""COMPUTED_VALUE"""),1014932.091438585) -> 1014932.1 | Q15: =IFERROR(__xludf.DUMMYFUNCTION("""COMPUTED_VALUE"""),1186967.710266147) -> 1186967.7 | R15: =IFERROR(__xludf.DUMMYFUNCTION("""COMPUTED_VALUE"""),3827755.9999478906) -> 3827756 | S15: =IFERROR(__xludf.DUMMYFUNCTION("""COMPUTED_VALUE"""),711913.247562702) -> 711913.25 | T15: =IFERROR(__xludf.DUMMYFUNCTION("""COMPUTED_VALUE"""),985308.6139442446) -> 985308.61 | U15: =IFERROR(__xludf.DUMMYFUNCTION("""COMPUTED_VALUE"""),1333513.706923312) -> 1333513.7 | V15: =IFERROR(__xludf.DUMMYFUNCTION("""COMPUTED_VALUE"""),849103.4189824851) -> 849103.42 | W15: =IFERROR(__xludf.DUMMYFUNCTION("""COMPUTED_VALUE"""),3879838.987412744) -> 3879839 | X15: =IFERROR(__xludf.DUMMYFUNCTION("""COMPUTED_VALUE"""),834420.7132840295) -> 834420.71 | Y15: =IFERROR(__xludf.DUMMYFUNCTION("""COMPUTED_VALUE"""),1107734.1525375296) -> 1107734.2 | Z15: =IFERROR(__xludf.DUMMYFUNCTION("""COMPUTED_VALUE"""),1418291.8526917615) -> 1418291.9 | AA15: =IFERROR(__xludf.DUMMYFUNCTION("""COMPUTED_VALUE"""),1067809.8130500868) -> 1067809.8 | AB15: =IFERROR(__xludf.DUMMYFUNCTION("""COMPUTED_VALUE"""),4428256.531563407) -> 4428256.5 | AC15: =IFERROR(__xludf.DUMMYFUNCTION("""COMPUTED_VALUE"""),990535.6749296719) -> 990535.67 | AD15: =IFERROR(__xludf.DUMMYFUNCTION("""COMPUTED_VALUE"""),1248044.0503780053) -> 1248044.1 | AE15: =IFERROR(__xludf.DUMMYFUNCTION("""COMPUTED_VALUE"""),1458259.3504754952) -> 1458259.4 | AF15: =IFERROR(__xludf.DUMMYFUNCTION("""COMPUTED_VALUE"""),1137380.40133775) -> 1137380.4 | AG15: =IFERROR(__xludf.DUMMYFUNCTION("""COMPUTED_VALUE"""),4834219.477120922) -> 4834219.5 | AH15: =IFERROR(__xludf.DUMMYFUNCTION("""COMPUTED_VALUE"""),1112306.5471986558) -> 1112306.5 | AI15: =IFERROR(__xludf.DUMMYFUNCTION("""COMPUTED_VALUE"""),1463974.8764705476) -> 1463974.9 | AJ15: =IFERROR(__xludf.DUMMYFUNCTION("""COMPUTED_VALUE"""),1578622.097557781) -> 1578622.1 | AK15: =IFERROR(__xludf.DUMMYFUNCTION("""COMPUTED_VALUE"""),1202494.9975940587) -> 1202495 | AL15: =IFERROR(__xludf.DUMMYFUNCTION("""COMPUTED_VALUE"""),5357398.518821043) -> 5357398.5 | AM15: =IFERROR(__xludf.DUMMYFUNCTION("""COMPUTED_VALUE"""),1168606.7411244202) -> 1168606.7 | AN15: =IFERROR(__xludf.DUMMYFUNCTION("""COMPUTED_VALUE"""),1393876.7265054) -> 1393876.7 | AO15: =IFERROR(__xludf.DUMMYFUNCTION("""COMPUTED_VALUE"""),1554281.7272092802) -> 1554281.7 | AP15: =IFERROR(__xludf.DUMMYFUNCTION("""COMPUTED_VALUE"""),1394977.6071792003) -> 1394977.6 | AQ15: =IFERROR(__xludf.DUMMYFUNCTION("""COMPUTED_VALUE"""),5511742.802018301) -> 5511742.8 | AR15: =IFERROR(__xludf.DUMMYFUNCTION("""COMPUTED_VALUE"""),1467635.6290511084) -> 1467635.6 | AS15: =IFERROR(__xludf.DUMMYFUNCTION("""COMPUTED_VALUE"""),1477892.48869876) -> 1477892.5 | AT15: =IFERROR(__xludf.DUMMYFUNCTION("""COMPUTED_VALUE"""),1588481.3386148552) -> 1588481.3 | AU15: =IFERROR(__xludf.DUMMYFUNCTION("""COMPUTED_VALUE"""),1609709.1681762799) -> 1609709.2 | AV15: =IFERROR(__xludf.DUMMYFUNCTION("""COMPUTED_VALUE"""),6143718.624541003) -> 6143718.6 | AW15: =IFERROR(__xludf.DUMMYFUNCTION("""COMPUTED_VALUE"""),1547638.0312886229) -> 1547638 | AX15: =IFERROR(__xludf.DUMMYFUNCTION("""COMPUTED_VALUE"""),1657029.1620123) -> 1657029.2 | AY15: =IFERROR(__xludf.DUMMYFUNCTION("""COMPUTED_VALUE"""),1743307.9860910429) -> 1743308 | AZ15: =IFERROR(__xludf.DUMMYFUNCTION("""COMPUTED_VALUE"""),1835541.2639800399) -> 1835541.3 | BA15: =IFERROR(__xludf.DUMMYFUNCTION("""COMPUTED_VALUE"""),6783516.443372006) -> 6783516.4 | BB15: =IFERROR(__xludf.DUMMYFUNCTION("""COMPUTED_VALUE"""),1670981.5163096616) -> 1670981.5 | BC15: =IFERROR(__xludf.DUMMYFUNCTION("""COMPUTED_VALUE"""),1815004.7453295002) -> 1815004.7 | BD15: =IFERROR(__xludf.DUMMYFUNCTION("""COMPUTED_VALUE"""),1899145.1790209818) -> 1899145.2 | BE15: =IFERROR(__xludf.DUMMYFUNCTION("""COMPUTED_VALUE"""),1959238.29803108) -> 1959238.3 | BF15: =IFERROR(__xludf.DUMMYFUNCTION("""COMPUTED_VALUE"""),7344369.738691224) -> 7344369.7 | BG15: =IFERROR(__xludf.DUMMYFUNCTION("""COMPUTED_VALUE"""),1816511.18184097) -> 1816511.2 | BH15: =IFERROR(__xludf.DUMMYFUNCTION("""COMPUTED_VALUE"""),2031236.31308636) -> 2031236.3 | BI15: =IFERROR(__xludf.DUMMYFUNCTION("""COMPUTED_VALUE"""),2035725.8062069) -> 2035725.8 | BJ15: =IFERROR(__xludf.DUMMYFUNCTION("""COMPUTED_VALUE"""),2165400.93252933) -> 2165400.9 | BK15: =IFERROR(__xludf.DUMMYFUNCTION("""COMPUTED_VALUE"""),8048874.233663559) -> 8048874.2 | BL15: =IFERROR(__xludf.DUMMYFUNCTION("""COMPUTED_VALUE"""),2043900.97901724) -> 2043901 | BM15: =IFERROR(__xludf.DUMMYFUNCTION("""COMPUTED_VALUE"""),2022345.48432292) -> 2022345.5 | BN15: =IFERROR(__xludf.DUMMYFUNCTION("""COMPUTED_VALUE"""),1984572.80517599) -> 1984572.8 | BO15: =IFERROR(__xludf.DUMMYFUNCTION("""COMPUTED_VALUE"""),2034751.28564921) -> 2034751.3 | BP15: =IFERROR(__xludf.DUMMYFUNCTION("""COMPUTED_VALUE"""),8085570.5541653605) -> 8085570.6 | BQ15: =IFERROR(__xludf.DUMMYFUNCTION("""COMPUTED_VALUE"""),2148317.45339409) -> 2148317.5 | BR15: =IFERROR(__xludf.DUMMYFUNCTION("""COMPUTED_VALUE"""),2071668.35) -> 2071668.4 | BS15: =IFERROR(__xludf.DUMMYFUNCTION("""COMPUTED_VALUE"""),2125901.12587276) -> 2125901.1 | BT15: =IFERROR(__xludf.DUMMYFUNCTION("""COMPUTED_VALUE"""),2143168.96448895) -> 2143169 | BU15: =IFERROR(__xludf.DUMMYFUNCTION("""COMPUTED_VALUE"""),8489055.893755801) -> 8489055.9 | BV15: =IFERROR(__xludf.DUMMYFUNCTION("""COMPUTED_VALUE"""),2503201.73864588) -> 2503201.7 | BW15: =IFERROR(__xludf.DUMMYFUNCTION("""COMPUTED_VALUE"""),2401738.68267887) -> 2401738.7 | BX15: =IFERROR(__xludf.DUMMYFUNCTION("""COMPUTED_VALUE"""),2256432.57929879) -> 2256432.6 | BY15: =IFERROR(__xludf.DUMMYFUNCTION("""COMPUTED_VALUE"""),2381903.4731653) -> 2381903.5 | BZ15: =IFERROR(__xludf.DUMMYFUNCTION("""COMPUTED_VALUE"""),9543276.47378884) -> 9543276.5 | CA15: =IFERROR(__xludf.DUMMYFUNCTION("""COMPUTED_VALUE"""),2627012.45524066) -> 2627012.5 | CB15: =IFERROR(__xludf.DUMMYFUNCTION("""COMPUTED_VALUE"""),2578557.77544992) -> 2578557.8 | CC15: =IFERROR(__xludf.DUMMYFUNCTION("""COMPUTED_VALUE"""),2678147.95152602) -> 2678148 | CD15: =IFERROR(__xludf.DUMMYFUNCTION("""COMPUTED_VALUE"""),2847362.13086854) -> 2847362.1 | CE15: =IFERROR(__xludf.DUMMYFUNCTION("""COMPUTED_VALUE"""),1.0731080313085139E7) -> 10731080 | CF15: =IFERROR(__xludf.DUMMYFUNCTION("""COMPUTED_VALUE"""),3277823.30083551) -> 3277823.3 | CG15: =IFERROR(__xludf.DUMMYFUNCTION("""COMPUTED_VALUE"""),3513608.6723921) -> 3513608.7 | CH15: =IFERROR(__xludf.DUMMYFUNCTION("""COMPUTED_VALUE"""),3548100.98970006) -> 3548101 | CI15: =IFERROR(__xludf.DUMMYFUNCTION("""COMPUTED_VALUE"""),3612682.00334681) -> 3612682 | CJ15: =IFERROR(__xludf.DUMMYFUNCTION("""COMPUTED_VALUE"""),1.395221496627448E7) -> 13952215 | CK15: =IFERROR(__xludf.DUMMYFUNCTION("""COMPUTED_VALUE"""),3766568.09164883) -> 3766568.1 | CL15: =IFERROR(__xludf.DUMMYFUNCTION("""COMPUTED_VALUE"""),4120876.22151634) -> 4120876.2 | CM15: =IFERROR(__xludf.DUMMYFUNCTION("""COMPUTED_VALUE"""),4266449.32185761) -> 4266449.3 | CN15: =IFERROR(__xludf.DUMMYFUNCTION("""COMPUTED_VALUE"""),4016680.00725197) -> 4016680 | CO15: =IFERROR(__xludf.DUMMYFUNCTION("""COMPUTED_VALUE"""),1.617057364227475E7) -> 16170574 | CP15: =IFERROR(__xludf.DUMMYFUNCTION("""COMPUTED_VALUE"""),3947265.9511385583) -> 3947266 | CQ15: =IFERROR(__xludf.DUMMYFUNCTION("""COMPUTED_VALUE"""),0.0) -> 0 | CR15: =IFERROR(__xludf.DUMMYFUNCTION("""COMPUTED_VALUE"""),0.0) -> 0 | CS15: =IFERROR(__xludf.DUMMYFUNCTION("""COMPUTED_VALUE"""),0.0) -> 0 | CT15: =IFERROR(__xludf.DUMMYFUNCTION("""COMPUTED_VALUE"""),3947265.9511385583) -> 3947266 | CU15: =IFERROR(__xludf.DUMMYFUNCTION("""COMPUTED_VALUE"""),0.0) -> 0 | CV15: =IFERROR(__xludf.DUMMYFUNCTION("""COMPUTED_VALUE"""),0.0) -> 0 | CW15: =IFERROR(__xludf.DUMMYFUNCTION("""COMPUTED_VALUE"""),0.0) -> 0 | CX15: =IFERROR(__xludf.DUMMYFUNCTION("""COMPUTED_VALUE"""),0.0) -> 0 | CY15: =IFERROR(__xludf.DUMMYFUNCTION("""COMPUTED_VALUE"""),0.0) -> 0
C16: f. Peternakan | N16: =IFERROR(__xludf.DUMMYFUNCTION("""COMPUTED_VALUE"""),362240.3262) -> 362240.33 | O16: =IFERROR(__xludf.DUMMYFUNCTION("""COMPUTED_VALUE"""),362501.3177) -> 362501.32 | P16: =IFERROR(__xludf.DUMMYFUNCTION("""COMPUTED_VALUE"""),401232.7554) -> 401232.76 | Q16: =IFERROR(__xludf.DUMMYFUNCTION("""COMPUTED_VALUE"""),414320.8208) -> 414320.82 | R16: =IFERROR(__xludf.DUMMYFUNCTION("""COMPUTED_VALUE"""),1540295.2201) -> 1540295.2 | S16: =IFERROR(__xludf.DUMMYFUNCTION("""COMPUTED_VALUE"""),377051.26652603573) -> 377051.27 | T16: =IFERROR(__xludf.DUMMYFUNCTION("""COMPUTED_VALUE"""),390341.94287185423) -> 390341.94 | U16: =IFERROR(__xludf.DUMMYFUNCTION("""COMPUTED_VALUE"""),423917.9818343075) -> 423917.98 | V16: =IFERROR(__xludf.DUMMYFUNCTION("""COMPUTED_VALUE"""),435301.99881417665) -> 435302 | W16: =IFERROR(__xludf.DUMMYFUNCTION("""COMPUTED_VALUE"""),1626613.1900463742) -> 1626613.2 | X16: =IFERROR(__xludf.DUMMYFUNCTION("""COMPUTED_VALUE"""),427159.5814621727) -> 427159.58 | Y16: =IFERROR(__xludf.DUMMYFUNCTION("""COMPUTED_VALUE"""),437813.8545400495) -> 437813.85 | Z16: =IFERROR(__xludf.DUMMYFUNCTION("""COMPUTED_VALUE"""),469149.48610392923) -> 469149.49 | AA16: =IFERROR(__xludf.DUMMYFUNCTION("""COMPUTED_VALUE"""),482474.98174147174) -> 482474.98 | AB16: =IFERROR(__xludf.DUMMYFUNCTION("""COMPUTED_VALUE"""),1816597.9038476232) -> 1816597.9 | AC16: =IFERROR(__xludf.DUMMYFUNCTION("""COMPUTED_VALUE"""),472292.04128236126) -> 472292.04 | AD16: =IFERROR(__xludf.DUMMYFUNCTION("""COMPUTED_VALUE"""),469105.5069995481) -> 469105.51 | AE16: =IFERROR(__xludf.DUMMYFUNCTION("""COMPUTED_VALUE"""),499837.68370522535) -> 499837.68 | AF16: =IFERROR(__xludf.DUMMYFUNCTION("""COMPUTED_VALUE"""),523459.48198398994) -> 523459.48 | AG16: =IFERROR(__xludf.DUMMYFUNCTION("""COMPUTED_VALUE"""),1964694.7139711247) -> 1964694.7 | AH16: =IFERROR(__xludf.DUMMYFUNCTION("""COMPUTED_VALUE"""),505108.5218749903) -> 505108.52 | AI16: =IFERROR(__xludf.DUMMYFUNCTION("""COMPUTED_VALUE"""),513162.8027346973) -> 513162.8 | AJ16: =IFERROR(__xludf.DUMMYFUNCTION("""COMPUTED_VALUE"""),553219.0136763353) -> 553219.01 | AK16: =IFERROR(__xludf.DUMMYFUNCTION("""COMPUTED_VALUE"""),547018.3619524098) -> 547018.36 | AL16: =IFERROR(__xludf.DUMMYFUNCTION("""COMPUTED_VALUE"""),2118508.7002384327) -> 2118508.7 | AM16: =IFERROR(__xludf.DUMMYFUNCTION("""COMPUTED_VALUE"""),533836.31337666) -> 533836.31 | AN16: =IFERROR(__xludf.DUMMYFUNCTION("""COMPUTED_VALUE"""),540864.48864124) -> 540864.49 | AO16: =IFERROR(__xludf.DUMMYFUNCTION("""COMPUTED_VALUE"""),587679.7754391) -> 587679.78 | AP16: =IFERROR(__xludf.DUMMYFUNCTION("""COMPUTED_VALUE"""),584878.09072848) -> 584878.09 | AQ16: =IFERROR(__xludf.DUMMYFUNCTION("""COMPUTED_VALUE"""),2247258.66818548) -> 2247258.7 | AR16: =IFERROR(__xludf.DUMMYFUNCTION("""COMPUTED_VALUE"""),583483.2961394248) -> 583483.3 | AS16: =IFERROR(__xludf.DUMMYFUNCTION("""COMPUTED_VALUE"""),602741.047115364) -> 602741.05 | AT16: =IFERROR(__xludf.DUMMYFUNCTION("""COMPUTED_VALUE"""),684780.1635632575) -> 684780.16 | AU16: =IFERROR(__xludf.DUMMYFUNCTION("""COMPUTED_VALUE"""),616033.8228806028) -> 616033.82 | AV16: =IFERROR(__xludf.DUMMYFUNCTION("""COMPUTED_VALUE"""),2487038.3296986492) -> 2487038.3 | AW16: =IFERROR(__xludf.DUMMYFUNCTION("""COMPUTED_VALUE"""),615752.0291323302) -> 615752.03 | AX16: =IFERROR(__xludf.DUMMYFUNCTION("""COMPUTED_VALUE"""),674323.6406829208) -> 674323.64 | AY16: =IFERROR(__xludf.DUMMYFUNCTION("""COMPUTED_VALUE"""),729272.615326016) -> 729272.62 | AZ16: =IFERROR(__xludf.DUMMYFUNCTION("""COMPUTED_VALUE"""),735966.9461435517) -> 735966.95 | BA16: =IFERROR(__xludf.DUMMYFUNCTION("""COMPUTED_VALUE"""),2755315.2312848186) -> 2755315.2 | BB16: =IFERROR(__xludf.DUMMYFUNCTION("""COMPUTED_VALUE"""),685249.2813047878) -> 685249.28 | BC16: =IFERROR(__xludf.DUMMYFUNCTION("""COMPUTED_VALUE"""),736100.9262173842) -> 736100.93 | BD16: =IFERROR(__xludf.DUMMYFUNCTION("""COMPUTED_VALUE"""),770691.2329658972) -> 770691.23 | BE16: =IFERROR(__xludf.DUMMYFUNCTION("""COMPUTED_VALUE"""),790241.0415808649) -> 790241.04 | BF16: =IFERROR(__xludf.DUMMYFUNCTION("""COMPUTED_VALUE"""),2982282.4820689345) -> 2982282.5 | BG16: =IFERROR(__xludf.DUMMYFUNCTION("""COMPUTED_VALUE"""),753580.481815433) -> 753580.48 | BH16: =IFERROR(__xludf.DUMMYFUNCTION("""COMPUTED_VALUE"""),809182.048032302) -> 809182.05 | BI16: =IFERROR(__xludf.DUMMYFUNCTION("""COMPUTED_VALUE"""),864496.469989277) -> 864496.47 | BJ16: =IFERROR(__xludf.DUMMYFUNCTION("""COMPUTED_VALUE"""),836640.958379983) -> 836640.96 | BK16: =IFERROR(__xludf.DUMMYFUNCTION("""COMPUTED_VALUE"""),3263899.958216995) -> 3263900 | BL16: =IFERROR(__xludf.DUMMYFUNCTION("""COMPUTED_VALUE"""),825815.125724241) -> 825815.13 | BM16: =IFERROR(__xludf.DUMMYFUNCTION("""COMPUTED_VALUE"""),817135.317841383) -> 817135.32 | BN16: =IFERROR(__xludf.DUMMYFUNCTION("""COMPUTED_VALUE"""),877914.881504096) -> 877914.88 | BO16: =IFERROR(__xludf.DUMMYFUNCTION("""COMPUTED_VALUE"""),855628.301574455) -> 855628.3 | BP16: =IFERROR(__xludf.DUMMYFUNCTION("""COMPUTED_VALUE"""),3376493.626644175) -> 3376493.6 | BQ16: =IFERROR(__xludf.DUMMYFUNCTION("""COMPUTED_VALUE"""),849240.605288961) -> 849240.61 | BR16: =IFERROR(__xludf.DUMMYFUNCTION("""COMPUTED_VALUE"""),894532.302180636) -> 894532.3 | BS16: =IFERROR(__xludf.DUMMYFUNCTION("""COMPUTED_VALUE"""),885857.302180636) -> 885857.3 | BT16: =IFERROR(__xludf.DUMMYFUNCTION("""COMPUTED_VALUE"""),895879.472488258) -> 895879.47 | BU16: =IFERROR(__xludf.DUMMYFUNCTION("""COMPUTED_VALUE"""),3525509.682138491) -> 3525509.7 | BV16: =IFERROR(__xludf.DUMMYFUNCTION("""COMPUTED_VALUE"""),907065.048965356) -> 907065.05 | BW16: =IFERROR(__xludf.DUMMYFUNCTION("""COMPUTED_VALUE"""),920059.930991239) -> 920059.93 | BX16: =IFERROR(__xludf.DUMMYFUNCTION("""COMPUTED_VALUE"""),969281.760632443) -> 969281.76 | BY16: =IFERROR(__xludf.DUMMYFUNCTION("""COMPUTED_VALUE"""),926982.35138615) -> 926982.35 | BZ16: =IFERROR(__xludf.DUMMYFUNCTION("""COMPUTED_VALUE"""),3723389.091975188) -> 3723389.1 | CA16: =IFERROR(__xludf.DUMMYFUNCTION("""COMPUTED_VALUE"""),975356.83024959) -> 975356.83 | CB16: =IFERROR(__xludf.DUMMYFUNCTION("""COMPUTED_VALUE"""),1086530.59666561) -> 1086530.6 | CC16: =IFERROR(__xludf.DUMMYFUNCTION("""COMPUTED_VALUE"""),1036863.09879652) -> 1036863.1 | CD16: =IFERROR(__xludf.DUMMYFUNCTION("""COMPUTED_VALUE"""),1003677.07598025) -> 1003677.1 | CE16: =IFERROR(__xludf.DUMMYFUNCTION("""COMPUTED_VALUE"""),4102427.6016919697) -> 4102427.6 | CF16: =IFERROR(__xludf.DUMMYFUNCTION("""COMPUTED_VALUE"""),992937.74777168) -> 992937.75 | CG16: =IFERROR(__xludf.DUMMYFUNCTION("""COMPUTED_VALUE"""),1116372.00379097) -> 1116372 | CH16: =IFERROR(__xludf.DUMMYFUNCTION("""COMPUTED_VALUE"""),1043676.40651546) -> 1043676.4 | CI16: =IFERROR(__xludf.DUMMYFUNCTION("""COMPUTED_VALUE"""),1056589.51098157) -> 1056589.5 | CJ16: =IFERROR(__xludf.DUMMYFUNCTION("""COMPUTED_VALUE"""),4209575.66905968) -> 4209575.7 | CK16: =IFERROR(__xludf.DUMMYFUNCTION("""COMPUTED_VALUE"""),1116303.90868905) -> 1116303.9 | CL16: =IFERROR(__xludf.DUMMYFUNCTION("""COMPUTED_VALUE"""),1243100.34396255) -> 1243100.3 | CM16: =IFERROR(__xludf.DUMMYFUNCTION("""COMPUTED_VALUE"""),1153996.00717777) -> 1153996 | CN16: =IFERROR(__xludf.DUMMYFUNCTION("""COMPUTED_VALUE"""),1197732.44768692) -> 1197732.4 | CO16: =IFERROR(__xludf.DUMMYFUNCTION("""COMPUTED_VALUE"""),4711132.70751629) -> 4711132.7 | CP16: =IFERROR(__xludf.DUMMYFUNCTION("""COMPUTED_VALUE"""),1278176.892361933) -> 1278176.9 | CQ16: =IFERROR(__xludf.DUMMYFUNCTION("""COMPUTED_VALUE"""),0.0) -> 0 | CR16: =IFERROR(__xludf.DUMMYFUNCTION("""COMPUTED_VALUE"""),0.0) -> 0 | CS16: =IFERROR(__xludf.DUMMYFUNCTION("""COMPUTED_VALUE"""),0.0) -> 0 | CT16: =IFERROR(__xludf.DUMMYFUNCTION("""COMPUTED_VALUE"""),1278176.892361933) -> 1278176.9 | CU16: =IFERROR(__xludf.DUMMYFUNCTION("""COMPUTED_VALUE"""),0.0) -> 0 | CV16: =IFERROR(__xludf.DUMMYFUNCTION("""COMPUTED_VALUE"""),0.0) -> 0 | CW16: =IFERROR(__xludf.DUMMYFUNCTION("""COMPUTED_VALUE"""),0.0) -> 0 | CX16: =IFERROR(__xludf.DUMMYFUNCTION("""COMPUTED_VALUE"""),0.0) -> 0 | CY16: =IFERROR(__xludf.DUMMYFUNCTION("""COMPUTED_VALUE"""),0.0) -> 0
A19: B | B19: Rasio Input Antara
C20: a. Tanaman Pangan | AV20: 0.11180062 | AW20: 0.11180062 | AX20: 0.11180062 | AY20: 0.11180062 | AZ20: 0.11180062 | BA20: 0.11180062 | BB20: 0.11180062 | BC20: 0.11180062 | BD20: 0.11180062 | BE20: 0.11180062 | BF20: 0.11180062 | BG20: 0.11180062 | BH20: 0.11180062 | BI20: 0.11180062 | BJ20: 0.11180062 | BK20: 0.11180062 | BL20: 0.11180062 | BM20: 0.11180062 | BN20: 0.11180062 | BO20: 0.11180062 | BP20: 0.11180062 | BQ20: 0.11180062 | BR20: 0.11180062 | BS20: 0.11180062 | BT20: 0.11180062 | BU20: 0.11180062 | BV20: 0.11180062 | BW20: 0.11180062 | BX20: 0.11180062 | BY20: 0.11180062 | CA20: 0.11180062 | CB20: 0.11180062 | CC20: 0.11180062 | CD20: 0.11180062 | CE20: 0.11180062 | CF20: 0.11180062 | CG20: 0.11180062 | CH20: 0.11180062 | CI20: 0.11180062 | CK20: 0.11180062 | CL20: 0.11180062 | CM20: 0.11180062 | CN20: 0.11180062 | CP20: 0.11180062 | CQ20: 0.11180062 | CR20: 0.11180062 | CS20: 0.11180062
C21: b. Tanaman Hortikultura Semusim | AV21: 0.060719258 | AW21: 0.060719258 | AX21: 0.060719258 | AY21: 0.060719258 | AZ21: 0.060719258 | BA21: 0.060719258 | BB21: 0.060719258 | BC21: 0.060719258 | BD21: 0.060719258 | BE21: 0.060719258 | BF21: 0.060719258 | BG21: 0.060719258 | BH21: 0.060719258 | BI21: 0.060719258 | BJ21: 0.060719258 | BK21: 0.060719258 | BL21: 0.060719258 | BM21: 0.060719258 | BN21: 0.060719258 | BO21: 0.060719258 | BP21: 0.060719258 | BQ21: 0.060719258 | BR21: 0.060719258 | BS21: 0.060719258 | BT21: 0.060719258 | BU21: 0.060719258 | BV21: 0.060719258 | BW21: 0.060719258 | BX21: 0.060719258 | BY21: 0.060719258 | CA21: 0.060719258 | CB21: 0.060719258 | CC21: 0.060719258 | CD21: 0.060719258 | CE21: 0.060719258 | CF21: 0.060719258 | CG21: 0.060719258 | CH21: 0.060719258 | CI21: 0.060719258 | CK21: 0.060719258 | CL21: 0.060719258 | CM21: 0.060719258 | CN21: 0.060719258 | CP21: 0.060719258 | CQ21: 0.060719258 | CR21: 0.060719258 | CS21: 0.060719258
C22: c. Perkebunan Semusim | AV22: 0.18579106 | AW22: 0.18579106 | AX22: 0.18579106 | AY22: 0.18579106 | AZ22: 0.18579106 | BA22: 0.18579106 | BB22: 0.18579106 | BC22: 0.18579106 | BD22: 0.18579106 | BE22: 0.18579106 | BF22: 0.18579106 | BG22: 0.18579106 | BH22: 0.18579106 | BI22: 0.18579106 | BJ22: 0.18579106 | BK22: 0.18579106 | BL22: 0.18579106 | BM22: 0.18579106 | BN22: 0.18579106 | BO22: 0.18579106 | BP22: 0.18579106 | BQ22: 0.18579106 | BR22: 0.18579106 | BS22: 0.18579106 | BT22: 0.18579106 | BU22: 0.18579106 | BV22: 0.18579106 | BW22: 0.18579106 | BX22: 0.18579106 | BY22: 0.18579106 | CA22: 0.18579106 | CB22: 0.18579106 | CC22: 0.18579106 | CD22: 0.18579106 | CE22: 0.18579106 | CF22: 0.18579106 | CG22: 0.18579106 | CH22: 0.18579106 | CI22: 0.18579106 | CK22: 0.18579106 | CL22: 0.18579106 | CM22: 0.18579106 | CN22: 0.18579106 | CP22: 0.18579106 | CQ22: 0.18579106 | CR22: 0.18579106 | CS22: 0.18579106
C23: d. Tanaman Hortikultura Tahunan & Lainnya | AV23: 0.060719258 | AW23: 0.060719258 | AX23: 0.060719258 | AY23: 0.060719258 | AZ23: 0.060719258 | BA23: 0.060719258 | BB23: 0.060719258 | BC23: 0.060719258 | BD23: 0.060719258 | BE23: 0.060719258 | BF23: 0.060719258 | BG23: 0.060719258 | BH23: 0.060719258 | BI23: 0.060719258 | BJ23: 0.060719258 | BK23: 0.060719258 | BL23: 0.060719258 | BM23: 0.060719258 | BN23: 0.060719258 | BO23: 0.060719258 | BP23: 0.060719258 | BQ23: 0.060719258 | BR23: 0.060719258 | BS23: 0.060719258 | BT23: 0.060719258 | BU23: 0.060719258 | BV23: 0.060719258 | BW23: 0.060719258 | BX23: 0.060719258 | BY23: 0.060719258 | CA23: 0.060719258 | CB23: 0.060719258 | CC23: 0.060719258 | CD23: 0.060719258 | CE23: 0.060719258 | CF23: 0.060719258 | CG23: 0.060719258 | CH23: 0.060719258 | CI23: 0.060719258 | CK23: 0.060719258 | CL23: 0.060719258 | CM23: 0.060719258 | CN23: 0.060719258 | CP23: 0.060719258 | CQ23: 0.060719258 | CR23: 0.060719258 | CS23: 0.060719258
C24: e. Perkebunan Tahunan | AV24: 0.18579106 | AW24: 0.18579106 | AX24: 0.18579106 | AY24: 0.18579106 | AZ24: 0.18579106 | BA24: 0.18579106 | BB24: 0.18579106 | BC24: 0.18579106 | BD24: 0.18579106 | BE24: 0.18579106 | BF24: 0.18579106 | BG24: 0.18579106 | BH24: 0.18579106 | BI24: 0.18579106 | BJ24: 0.18579106 | BK24: 0.18579106 | BL24: 0.18579106 | BM24: 0.18579106 | BN24: 0.18579106 | BO24: 0.18579106 | BP24: 0.18579106 | BQ24: 0.18579106 | BR24: 0.18579106 | BS24: 0.18579106 | BT24: 0.18579106 | BU24: 0.18579106 | BV24: 0.18579106 | BW24: 0.18579106 | BX24: 0.18579106 | BY24: 0.18579106 | CA24: 0.18579106 | CB24: 0.18579106 | CC24: 0.18579106 | CD24: 0.18579106 | CE24: 0.18579106 | CF24: 0.18579106 | CG24: 0.18579106 | CH24: 0.18579106 | CI24: 0.18579106 | CK24: 0.18579106 | CL24: 0.18579106 | CM24: 0.18579106 | CN24: 0.18579106 | CP24: 0.18579106 | CQ24: 0.18579106 | CR24: 0.18579106 | CS24: 0.18579106
C25: f. Peternakan | AV25: 0.26808994 | AW25: 0.26808994 | AX25: 0.26808994 | AY25: 0.26808994 | AZ25: 0.26808994 | BA25: 0.26808994 | BB25: 0.26808994 | BC25: 0.26808994 | BD25: 0.26808994 | BE25: 0.26808994 | BF25: 0.26808994 | BG25: 0.26808994 | BH25: 0.26808994 | BI25: 0.26808994 | BJ25: 0.26808994 | BK25: 0.26808994 | BL25: 0.26808994 | BM25: 0.26808994 | BN25: 0.26808994 | BO25: 0.26808994 | BP25: 0.26808994 | BQ25: 0.26808994 | BR25: 0.26808994 | BS25: 0.26808994 | BT25: 0.26808994 | BU25: 0.26808994 | BV25: 0.26808994 | BW25: 0.26808994 | BX25: 0.26808994 | BY25: 0.26808994 | CA25: 0.26808994 | CB25: 0.26808994 | CC25: 0.26808994 | CD25: 0.26808994 | CE25: 0.26808994 | CF25: 0.26808994 | CG25: 0.26808994 | CH25: 0.26808994 | CI25: 0.26808994 | CK25: 0.26808994 | CL25: 0.26808994 | CM25: 0.26808994 | CN25: 0.26808994 | CP25: 0.26808994 | CQ25: 0.26808994 | CR25: 0.26808994 | CS25: 0.26808994
A28: C | B28: Output ADHB subkategori penyusun
C29: a. Tanaman Pangan | AW29: =AW11/(1-AW20) -> 570902.88 | AX29: =AX11/(1-AX20) -> 764241.33 | AY29: =AY11/(1-AY20) -> 651583.04 | AZ29: =AZ11/(1-AZ20) -> 692380.87 | BB29: =BB11/(1-BB20) -> 669654.12 | BC29: =BC11/(1-BC20) -> 770915.13 | BD29: =BD11/(1-BD20) -> 654661.78 | BE29: =BE11/(1-BE20) -> 712577.41 | BG29: =BG11/(1-BG20) -> 646087.96 | BH29: =BH11/(1-BH20) -> 860154.11 | BI29: =BI11/(1-BI20) -> 643859.58 | BJ29: =BJ11/(1-BJ20) -> 709655.64 | BL29: =BL11/(1-BL20) -> 628759.32 | BM29: =BM11/(1-BM20) -> 828186.41 | BN29: =BN11/(1-BN20) -> 682790.47 | BO29: =BO11/(1-BO20) -> 752533.98 | BQ29: =BQ11/(1-BQ20) -> 553722.29 | BR29: =BR11/(1-BR20) -> 963250.87 | BS29: =BS11/(1-BS20) -> 672054.99 | BT29: =BT11/(1-BT20) -> 757316.46 | BV29: =BV11/(1-BV20) -> 576384.09 | BW29: =BW11/(1-BW20) -> 926744.21 | BX29: =BX11/(1-BX20) -> 670486.31 | BY29: =BY11/(1-BY20) -> 750714.77 | CA29: =CA11/(1-CA20) -> 585919.97 | CB29: =CB11/(1-CB20) -> 906176.41 | CC29: =CC11/(1-CC20) -> 766610.34 | CD29: =CD11/(1-CD20) -> 805483.44 | CE29: =CE11/(1-CE20) -> 3064190.2 | CF29: =CF11/(1-CF20) -> 578733.02 | CG29: =CG11/(1-CG20) -> 1013737.3 | CH29: =CH11/(1-CH20) -> 845526.51 | CI29: =CI11/(1-CI20) -> 941073.78 | CK29: =CK11/(1-CK20) -> 657059.58 | CL29: =CL11/(1-CL20) -> 1115955.1 | CM29: =CM11/(1-CM20) -> 862847.17 | CN29: =CN11/(1-CN20) -> 1069755.9 | CP29: =CP11/(1-CP20) -> 675011.12 | CQ29: =CQ11/(1-CQ20) -> 0 | CR29: =CR11/(1-CR20) -> 0 | CS29: =CS11/(1-CS20) -> 0
