Workbook
Name BERLAKU: #REF!
Name BERLAKU: #REF!
Name BERLAKU: #REF!
Name H: #REF!

Sheet Home
A1: HOME
B2: SISTEM | H2: ALAT BANTU PENGHITUNGAN ANGKA PDRB MENURUT LAPANGAN USAHA
B3: INFORMASI
B4: RILIS
B5: ANGKA PDRB | K5: LAPANGAN USAHA | O5: : | P5: =mid(ADHB!C5,3,9)&" --- "&mid(ADHB!C7,3,100) -> Pertanian --- Perikanan
B6: MELALUI LEMBAR KERJA | K6: WILAYAH | O6: : | P6: Provinsi Sulawesi Tenggara
B7: BERBASIS | K7: TAHUN | O7: : | P7: =IFERROR(__xludf.DUMMYFUNCTION("IMPORTRANGE(""https://docs.google.com/spreadsheets/d/14EziMEzuXiAhzZqRuQw8kN9sLyynoE6QsPgaj062Fa0/edit#gid=214337323"",""'LK PDRB Lapus'!E3:E4"")"),2026.0) -> 2026
B8: ONLINE | K8: TRIWULAN | O8: : | P8: =IFERROR(__xludf.DUMMYFUNCTION("""COMPUTED_VALUE"""),"I") -> I
B11: INPUT DATA | K11: OUTPUT | T11: MONEV
B15: 1 | C15: Lembar Kerja Penghitungan PDRB Atas Dasar Harga Berlaku | K15: 1 | L15: Rekap Angka PDRB Lapangan Usaha | T15: 1 | U15: MONEV Pemasukan Data
B16: =B15+1 -> 2 | C16: Lembar Kerja Penghitungan PDRB Atas Dasar Harga Konstan | K16: =K15+1 -> 2 | T16: =T15+1 -> 2

Sheet Produksi dan Harga
A1: , | CJ1: =CJ5/CH5*100-100 -> -23.799203
A2: No | B2: Lapangan Usaha | C2: 2008 | H2: 2009 | M2: 2010 | R2: 2011 | W2: 2012 | AB2: 2013 | AG2: 2014 | AL2: 2015 | AQ2: 2016 | AV2: 2017 | BA2: 2018 | BF2: 2019 | BK2: 2020 | BP2: 2021 | BU2: 2022 | BZ2: 2023 | CE2: 2024 | CJ2: 2025 | CO2: 2026
C3: I | D3: II | E3: III | F3: IV | G3: Jumlah | H3: I | I3: II | J3: III | K3: IV | L3: Jumlah | M3: I | N3: II | O3: III | P3: IV | Q3: Jumlah | R3: I | S3: II | T3: III | U3: IV | V3: Jumlah | W3: I | X3: II | Y3: III | Z3: IV | AA3: Jumlah | AB3: I | AC3: II | AD3: III | AE3: IV | AF3: Jumlah | AG3: I | AH3: II | AI3: III | AJ3: IV | AK3: Jumlah | AL3: I | AM3: II | AN3: III | AO3: IV | AP3: Jumlah | AQ3: I | AR3: II | AS3: III | AT3: IV | AU3: Jumlah | AV3: I | AW3: II | AX3: III | AY3: IV | AZ3: Jumlah | BA3: I | BB3: II | BC3: III | BD3: IV | BE3: Jumlah | BF3: I | BG3: II | BH3: III | BI3: IV | BJ3: Jumlah | BK3: I | BL3: II | BM3: III | BN3: IV | BO3: Jumlah | BP3: I | BQ3: II | BR3: III | BS3: IV | BT3: Jumlah | BU3: I | BV3: II | BW3: III | BX3: IV | BY3: Jumlah | BZ3: I | CA3: II | CB3: III | CC3: IV | CD3: Jumlah | CE3: I | CF3: II | CG3: III | CH3: IV | CI3: Jumlah | CJ3: I | CK3: II | CL3: III | CM3: IV | CN3: Jumlah | CO3: I | CP3: II | CQ3: III | CR3: IV | CS3: Jumlah
A4: -1 | B4: =A4-1 -> -2 | C4: =B4-1 -> -3 | D4: =C4-1 -> -4 | E4: =D4-1 -> -5 | F4: =E4-1 -> -6 | G4: =F4-1 -> -7 | H4: =G4-1 -> -8 | I4: =H4-1 -> -9 | ... CS4: =CR4-1 -> -97
B5: REKAP DATA PP-TPI | AV5: 15189.02 | AW5: 14220.82 | AX5: 18257.39 | AY5: 19115.83 | AZ5: 66783.06 | BA5: 15243.83 | BB5: 12532.64 | BC5: 88871.37 | BD5: 69074.34 | BE5: 185722.2 | BF5: 11046.162 | BG5: 5989.518 | BH5: 5518.506 | BI5: 6920.687 | BJ5: 294748.73 | BK5: 8735.885 | BL5: 5447.974 | BM5: 6235.596 | BN5: 9116.937 | BO5: 295363.92 | BP5: 8514.915 | BQ5: 5925.615 | BR5: 2823.964 | BS5: 8523.062 | BT5: 265351.57 | BU5: 8015.256 | BV5: 4665.455 | BW5: 9303.76 | BX5: 10058.887 | BY5: 0 | BZ5: 11366.47 | CA5: 5321.45 | CB5: 4754.47 | CC5: 6431.25 | CE5: 9281.51 | CF5: 5101.9 | CG5: 6847.32 | CH5: 7640.34 | CJ5: 5822 | CK5: 6024.42 | CL5: 6754.1 | CM5: 9269.763 | CO5: 9308.85
B6: REKAP DATA PIT | AV6: 49407.55 | AW6: 80476.59 | AX6: 84901.23 | AY6: 110942 | AZ6: 325727.15 | BA6: 72835.74 | BB6: 74552.38 | BC6: 79234.08 | BD6: 91600.2 | BE6: 318222.35 | BF6: 14018.474 | BG6: 9215.906 | BH6: 11448.917 | BI6: 11362.86 | BJ6: 460461.59 | BK6: 8684.122 | BL6: 9138.043 | BM6: 10347.365 | BN6: 10231.2 | BO6: 384007.78 | BP6: 8684.981 | BQ6: 8437.492 | BR6: 10213.718 | BS6: 3300.129 | BT6: 393391.69 | BU6: 11367.548 | BV6: 13358.201 | BW6: 8605.463 | BX6: 6832.258 | BY6: 0 | BZ6: 7594.56 | CA6: 8025.27 | CB6: 8535.39 | CC6: 9792.17 | CE6: 12578.02 | CF6: 12563.19 | CG6: 10126.47 | CH6: 11957.69 | CJ6: 13192.09 | CK6: 12160.1 | CL6: 9912.43 | CM6: 11518.84 | CO6: 9151.27
C8: =SUM(C6:C7) -> 0 | D8: =SUM(D6:D7) -> 0 | E8: =SUM(E6:E7) -> 0 | F8: =SUM(F6:F7) -> 0 | G8: =SUM(G6:G7) -> 0 | H8: =SUM(H6:H7) -> 0 | I8: =SUM(I6:I7) -> 0 | J8: =SUM(J6:J7) -> 0 | ... L8: =SUM(L6:L7) -> 0 | M8: =sum(M5:M6) -> 0 | N8: =sum(N5:N6) -> 0 | O8: =sum(O5:O6) -> 0 | P8: =sum(P5:P6) -> 0 | Q8: =sum(Q5:Q6) -> 0 | R8: =sum(R5:R6) -> 0 | S8: =sum(S5:S6) -> 0 | T8: =sum(T5:T6) -> 0 | ... CS8: =sum(CS5:CS6) -> 0
B10: Q to Q | BK10: =BK8/BI8*100-100 -> -4.7230442 | BL10: =BL8/BK8*100-100 -> -16.268593 | BM10: =BM8/BL8*100-100 -> 13.690811 | BN10: =BN8/BM8*100-100 -> 16.674803 | BP10: =BP8/BN8*100-100 -> -11.10309 | BQ10: =BQ8/BP8*100-100 -> -16.493059 | BR10: =BR8/BQ8*100-100 -> -9.2279825 | BS10: =BS8/BR8*100-100 -> -9.3152372 | BU10: =BU8/BS8*100-100 -> 63.938855 | BV10: =BV8/BU8*100-100 -> -7.012133 | BW10: =BW8/BV8*100-100 -> -0.63490448 | BX10: =BX8/BW8*100-100 -> -5.6846576 | BZ10: =BZ8/BX8*100-100 -> 12.254261 | CA10: =CA8/BZ8*100-100 -> -29.609731 | CB10: =CB8/CA8*100-100 -> -0.42602227 | CC10: =CC8/CB8*100-100 -> 22.073671 | CE10: =CE8/CC8*100-100 -> 34.740579 | CF10: =CF8/CE8*100-100 -> -19.188153 | CG10: =CG8/CF8*100-100 -> -3.9133681 | CH10: =CH8/CG8*100-100 -> 15.460542 | CJ10: =CJ8/CH8*100-100 -> -2.9795852 | CK10: =CK8/CJ8*100-100 -> -4.3629224 | CL10: =CL8/CK8*100-100 -> -8.3477045 | CM10: =CM8/CL8*100-100 -> 24.732641 | CO10: =CO8/CM8*100-100 -> -11.200767 | CP10: =CP8/CO8*100-100 -> -100 | CQ10: =CQ8/CP8*100-100 -> #DIV/0! | CR10: =CR8/CQ8*100-100 -> #DIV/0!
B11: Y on Y | BK11: =BK8/BF8*100-100 -> -30.499661 | BL11: =BL8/BG8*100-100 -> -4.0735924 | BM11: =BM8/BH8*100-100 -> -2.2658833 | BN11: =BN8/BI8*100-100 -> 5.8226667 | BP11: =BP8/BK8*100-100 -> -1.2635529 | BQ11: =BQ8/BL8*100-100 -> -1.5282445 | BR11: =BR8/BM8*100-100 -> -21.379047 | BS11: =BS8/BN8*100-100 -> -38.892354 | BU11: =BU8/BP8*100-100 -> 12.691402 | BV11: =BV8/BQ8*100-100 -> 25.485774 | BW11: =BW8/BR8*100-100 -> 37.365085 | BX11: =BX8/BS8*100-100 -> 42.864519 | BZ11: =BZ8/BU8*100-100 -> -2.1760216 | CA11: =CA8/BV8*100-100 -> -25.948875 | CB11: =CB8/BW8*100-100 -> -25.793207 | CC11: =CC8/BX8*100-100 -> -3.9531068 | CE11: =CE8/BZ8*100-100 -> 15.286617 | CF11: =CF8/CA8*100-100 -> 32.35529 | CG11: =CG8/CB8*100-100 -> 27.719856 | CH11: =CH8/CC8*100-100 -> 20.800855 | CJ11: =CJ8/CE8*100-100 -> -13.016931 | CK11: =CK8/CF8*100-100 -> 2.9404322 | CL11: =CL8/CG8*100-100 -> -1.8102027 | CM11: =CM8/CH8*100-100 -> 6.0749626 | CO11: =CO8/CJ8*100-100 -> -2.913471 | CP11: =CP8/CK8*100-100 -> -100 | CQ11: =CQ8/CL8*100-100 -> -100 | CR11: =CR8/CM8*100-100 -> -100
B12: C to C | BK12: =BK8/BF8*100-100 -> -30.499661 | BL12: =SUM(BK8:BL8)/SUM(BF8:BG8)*100-100 -> -20.521539 | BM12: =SUM(BK8:BM8)/SUM(BF8:BH8)*100-100 -> -15.10985 | BN12: =SUM(BK8:BN8)/SUM(BF8:BI8)*100-100 -> -10.042114 | BP12: =BP8/BK8*100-100 -> -1.2635529 | BQ12: =SUM(BP8:BQ8)/SUM(BK8:BL8)*100-100 -> -1.3841801 | BR12: =SUM(BP8:BR8)/SUM(BK8:BM8)*100-100 -> -8.208239 | BS12: =SUM(BP8:BS8)/SUM(BK8:BN8)*100-100 -> -16.946915 | BU12: =BU8/BP8*100-100 -> 12.691402 | BV12: =SUM(BU8:BV8)/SUM(BP8:BQ8)*100-100 -> 18.513628 | BW12: =SUM(BU8:BW8)/SUM(BP8:BR8)*100-100 -> 24.02429 | BX12: =SUM(BU8:BX8)/SUM(BP8:BS8)*100-100 -> 27.972116 | BZ12: =BZ8/BU8*100-100 -> -2.1760216 | CA12: =SUM(BZ8:CA8)/SUM(BU8:BV8)*100-100 -> -13.63056 | CB12: =SUM(BZ8:CB8)/SUM(BU8:BW8)*100-100 -> -17.568387 | CC12: =SUM(BZ8:CC8)/SUM(BU8:BX8)*100-100 -> -14.383402 | CE12: =CE8/BZ8*100-100 -> 15.286617 | CF12: =SUM(CE8:CF8)/SUM(BZ8:CA8)*100-100 -> 22.337891 | CG12: =SUM(CE8:CG8)/SUM(BZ8:CB8)*100-100 -> 23.906516 | CH12: =SUM(CE8:CH8)/SUM(BZ8:CC8)*100-100 -> 23.091511 | CJ12: =CJ8/CE8*100-100 -> -13.016931 | CK12: =SUM(CJ8:CK8)/SUM(CE8:CF8)*100-100 -> -5.8849649 | CL12: =SUM(CJ8:CL8)/SUM(CE8:CG8)*100-100 -> -4.660786 | CM12: =SUM(CJ8:CM8)/SUM(CE8:CH8)*100-100 -> -1.8958798 | CO12: =CO8/CJ8*100-100 -> -2.913471 | CP12: =SUM(CO8:CP8)/SUM(CJ8:CK8)*100-100 -> -50.374167 | CQ12: =SUM(CO8:CQ8)/SUM(CJ8:CL8)*100-100 -> -65.729004 | CR12: =SUM(CO8:CR8)/SUM(CJ8:CM8)*100-100 -> -75.272345
A15: IHP | M15: 2010 | R15: 2011 | W15: 2012 | AB15: 2013 | AG15: 2014 | AL15: 2015 | AQ15: 2016 | AV15: 2017 | BA15: 2018 | BF15: 2019 | BK15: 2020 | BP15: 2021 | BU15: 2022 | BZ15: 2023 | CE15: 2024 | CJ15: 2025 | CO15: 2025
M16: I | N16: II | O16: III | P16: IV | Q16: Jumlah | R16: I | S16: II | T16: III | U16: IV | V16: Jumlah | W16: I | X16: II | Y16: III | Z16: IV | AA16: Jumlah | AB16: I | AC16: II | AD16: III | AE16: IV | AF16: Jumlah | AG16: I | AH16: II | AI16: III | AJ16: IV | AK16: Jumlah | AL16: I | AM16: II | AN16: III | AO16: IV | AP16: Jumlah | AQ16: I | AR16: II | AS16: III | AT16: IV | AU16: Jumlah | AV16: I | AW16: II | AX16: III | AY16: IV | AZ16: Jumlah | BA16: I | BB16: II | BC16: III | BD16: IV | BE16: Jumlah | BF16: I | BG16: II | BH16: III | BI16: IV | BJ16: Jumlah | BK16: I | BL16: II | BM16: III | BN16: IV | BO16: Jumlah | BP16: I | BQ16: II | BR16: III | BS16: IV | BT16: Jumlah | BU16: I | BV16: II | BW16: III | BX16: IV | BY16: Jumlah | BZ16: I | CA16: II | CB16: III | CC16: IV | CD16: Jumlah | CE16: I | CF16: II | CG16: III | CH16: IV | CI16: Jumlah | CJ16: I | CK16: II | CL16: III | CM16: IV | CN16: Jumlah | CO16: I | CP16: II | CQ16: III | CR16: IV | CS16: Jumlah
M17: =L17-1 -> -1 | N17: =M17-1 -> -2 | O17: =N17-1 -> -3 | P17: =O17-1 -> -4 | Q17: =P17-1 -> -5 | R17: =Q17-1 -> -6 | S17: =R17-1 -> -7 | T17: =S17-1 -> -8 | ... CS17: =CR17-1 -> -85
B18: Perikanan Tangkap | M18: 98,53 | N18: 98,90 | O18: 100,96 | P18: 101,60 | R18: 102,84 | S18: 104,00 | T18: 105,07 | U18: 105,44 | W18: 106,05 | X18: 106,90 | Y18: 108,45 | Z18: 108,98 | AB18: 110,79 | AC18: 111,49 | AD18: 115,39 | AE18: 116,05 | AG18: 119,34 | AH18: 120,43 | AI18: 124,58 | AJ18: 126,76 | AL18: 130,36 | AM18: 130,90 | AN18: 134,61 | AO18: 134,54 | AQ18: 134,94 | AR18: 135,21 | AS18: 137,42 | AT18: 138,38 | AV18: 141,08 | AW18: 142,64 | AX18: 144,92 | AY18: 145,84 | BA18: 148,77 | BB18: 149,98 | BC18: 152,50 | BD18: 151,81 | BF18: 151,53 | BG18: 152,18 | BH18: 154,48 | BI18: 153,97 | BK18: 155,23 | BL18: 153,39 | BM18: 155,23 | BN18: 156,57 | BP18: 159.4102 | BQ18: 161.71088 | BR18: 162.84633 | BS18: 164.4242 | BU18: 166.39 | BV18: 168.89 | BW18: 172.33 | BX18: 173.5 | BZ18: 177.31 | CA18: 178.02 | CB18: 178.67 | CC18: 175.08 | CE18: =CC18+(CC18*-0.86/100) -> 173.57431 | CF18: =CE18+(CE18*1.0828941014689/100) -> 175.45394 | CG18: =CF18+(CF18*-0.13/100) -> 175.22585 | CH18: =CG18+(CG18*0.24/100) -> 175.64639 | CJ18: =CH18+(CH18*1.52/100) -> 178.31621 | CK18: =CJ18+(CJ18*2.53/100) -> 182.82762 | CL18: =CK18+(CK18*1.24/100) -> 185.09468 | CM18: =CL18+(CL18*1.24/100) -> 187.38985 | CO18: =CM18+(CM18*1.52/100) -> 190.23818
A21: HARGA | M21: 2010 | R21: 2011 | W21: 2012 | AB21: 2013 | AG21: 2014 | AL21: 2015 | AQ21: 2016 | AV21: 2017 | BA21: 2018 | BF21: 2019 | BK21: 2020 | BP21: 2021 | BU21: 2022 | BZ21: 2023 | CE21: 2024 | CJ21: 2025 | CO21: 2025
M22: I | N22: II | O22: III | P22: IV | Q22: Jumlah | R22: I | S22: II | T22: III | U22: IV | V22: Jumlah | W22: I | X22: II | Y22: III | Z22: IV | AA22: Jumlah | AB22: I | AC22: II | AD22: III | AE22: IV | AF22: Jumlah | AG22: I | AH22: II | AI22: III | AJ22: IV | AK22: Jumlah | AL22: I | AM22: II | AN22: III | AO22: IV | AP22: Jumlah | AQ22: I | AR22: II | AS22: III | AT22: IV | AU22: Jumlah | AV22: I | AW22: II | AX22: III | AY22: IV | AZ22: Jumlah | BA22: I | BB22: II | BC22: III | BD22: IV | BE22: Jumlah | BF22: I | BG22: II | BH22: III | BI22: IV | BJ22: Jumlah | BK22: I | BL22: II | BM22: III | BN22: IV | BO22: Jumlah | BP22: I | BQ22: II | BR22: III | BS22: IV | BT22: Jumlah | BU22: I | BV22: II | BW22: III | BX22: IV | BY22: Jumlah | BZ22: I | CA22: II | CB22: III | CC22: IV | CD22: Jumlah | CE22: I | CF22: II | CG22: III | CH22: IV | CI22: Jumlah | CJ22: I | CK22: II | CL22: III | CM22: IV | CN22: Jumlah | CO22: I | CP22: II | CQ22: III | CR22: IV | CS22: Jumlah
M23: =L23-1 -> -1 | N23: =M23-1 -> -2 | O23: =N23-1 -> -3 | P23: =O23-1 -> -4 | Q23: =P23-1 -> -5 | R23: =Q23-1 -> -6 | S23: =R23-1 -> -7 | T23: =S23-1 -> -8 | ... CS23: =CR23-1 -> -85
B24: Perikanan Tangkap | M24: =N24*M18/N18 -> 7339918.3 | N24: =O24*N18/O18 -> 7367481.2 | O24: =P24*O18/P18 -> 7520939.3 | P24: =R24*P18/R18 -> 7568615.6 | R24: =S24*R18/S18 -> 7660988.5 | S24: =T24*S18/T18 -> 7747401.8 | T24: =U24*T18/U18 -> 7827110.7 | U24: =W24*U18/W18 -> 7854673.5 | W24: =X24*W18/X18 -> 7900115 | X24: =Y24*X18/Y18 -> 7963435.1 | Y24: =Z24*Y18/Z18 -> 8078901.2 | Z24: =AB24*Z18/AB18 -> 8118383.2 | AB24: =AC24*AB18/AC18 -> 8253217.8 | AC24: =AD24*AC18/AD18 -> 8305363.7 | AD24: =AE24*AD18/AE18 -> 8595891.3 | AE24: =AG24*AE18/AG18 -> 8645057.5 | AG24: =AH24*AG18/AH18 -> 8890143.6 | AH24: =AI24*AH18/AI18 -> 8971342.3 | AI24: =AJ24*AI18/AJ18 -> 9280493.4 | AJ24: =AL24*AJ18/AL18 -> 9442890.9 | AL24: =AM24*AL18/AM18 -> 9711070.2 | AM24: =AN24*AM18/AN18 -> 9751297.1 | AN24: =AO24*AN18/AO18 -> 10027671 | AO24: =AQ24*AO18/AQ18 -> 10022456 | AQ24: =AR24*AQ18/AR18 -> 10052254 | AR24: =AS24*AR18/AS18 -> 10072367 | AS24: =AT24*AS18/AT18 -> 10237000 | AT24: =AV24*AT18/AV18 -> 10308514 | AV24: =AW24*AV18/AW18 -> 10509649 | AW24: =AX24*AW18/AX18 -> 10625860 | AX24: =AY24*AX18/AY18 -> 10795706 | AY24: =BA24*AY18/BA18 -> 10864241 | BA24: =BB24*BA18/BB18 -> 11082509 | BB24: =BC24*BB18/BC18 -> 11172647 | BC24: =BD24*BC18/BD18 -> 11360373 | BD24: =BF24*BD18/BF18 -> 11308972 | BF24: 11288113 | BG24: 25123396 | BH24: 28039260 | BI24: 21167297 | BK24: 18622076 | BL24: 23659216 | BM24: 23714951 | BN24: 20747544 | BP24: 18765434 | BQ24: 22958306 | BR24: 27917803 | BS24: 24537434 | BU24: 19506559 | BV24: 23117365 | BW24: 20417871 | BX24: 20726706 | BZ24: 20901190 | CA24: 25575244 | CB24: 23240809 | CC24: 20510160 | CE24: 20681316 | CF24: 23873976 | CG24: 24348246 | CH24: 23690341 | CJ24: 20477635 | CK24: 21417172 | CL24: 27272194 | CM24: 24818555 | CO24: =CM24+(CM24*1.52/100) -> 25195797
B30: DATA TERBARU PER TANGGAL 29 MEI 2024 PUKUL 10.46 | BU30: 2022 | BZ30: 2023 | CE30: 2024
BU31: I | BV31: II | BW31: III | BX31: IV | BY31: Jumlah | BZ31: I | CA31: II | CB31: III | CC31: IV | CD31: Jumlah | CE31: I | CF31: II | CG31: III | CH31: IV | CI31: Jumlah
BU32: =BT32-1 -> -1 | BV32: =BU32-1 -> -2 | BW32: =BV32-1 -> -3 | BX32: =BW32-1 -> -4 | BY32: =BX32-1 -> -5 | BZ32: =BY32-1 -> -6 | CA32: =BZ32-1 -> -7 | CB32: =CA32-1 -> -8 | ... CI32: =CH32-1 -> -15
BU33: 8015.256 | BV33: 4665.455 | BW33: 9303.76 | BX33: 10058.887 | BY33: 0 | BZ33: 11366.47 | CA33: 5321.45 | CB33: 4754.47 | CC33: 6431.25 | CE33: 9281.51 | CF33: 4391.59
BU34: 11367.548 | BV34: 13358.201 | BW34: 8605.463 | BX34: 6832.258 | BY34: 0 | BZ34: 7594.56 | CA34: 8025.27 | CB34: 8535.39 | CC34: 9792.17 | CE34: 12578.01 | CF34: 10960.67
BU36: =sum(BU33:BU34) -> 19382.804 | BV36: =sum(BV33:BV34) -> 18023.656 | BW36: =sum(BW33:BW34) -> 17909.223 | BX36: =sum(BX33:BX34) -> 16891.145 | BY36: =sum(BY33:BY34) -> 0 | BZ36: =sum(BZ33:BZ34) -> 18961.03 | CA36: =sum(CA33:CA34) -> 13346.72 | CB36: =sum(CB33:CB34) -> 13289.86 | ... CI36: =sum(CI33:CI34) -> 0
B38: Q to Q | BU38: =BU36/BS36*100-100 -> #DIV/0! | BV38: =BV36/BU36*100-100 -> -7.012133 | BW38: =BW36/BV36*100-100 -> -0.63490448 | BX38: =BX36/BW36*100-100 -> -5.6846576 | BZ38: =BZ36/BX36*100-100 -> 12.254261 | CA38: =CA36/BZ36*100-100 -> -29.609731 | CB38: =CB36/CA36*100-100 -> -0.42602227 | CC38: =CC36/CB36*100-100 -> 22.073671 | CE38: =CE36/CC36*100-100 -> 34.740517 | CF38: =CF36/CE36*100-100 -> -29.76854 | CG38: =CG36/CF36*100-100 -> -100 | CH38: =CH36/CG36*100-100 -> #DIV/0!
B39: Y on Y | BU39: =BU36/BP36*100-100 -> #DIV/0! | BV39: =BV36/BQ36*100-100 -> #DIV/0! | BW39: =BW36/BR36*100-100 -> #DIV/0! | BX39: =BX36/BS36*100-100 -> #DIV/0! | BZ39: =BZ36/BU36*100-100 -> -2.1760216 | CA39: =CA36/BV36*100-100 -> -25.948875 | CB39: =CB36/BW36*100-100 -> -25.793207 | CC39: =CC36/BX36*100-100 -> -3.9531068 | CE39: =CE36/BZ36*100-100 -> 15.286564 | CF39: =CF36/CA36*100-100 -> 15.026463 | CG39: =CG36/CB36*100-100 -> -100 | CH39: =CH36/CC36*100-100 -> -100
B40: C to C | BU40: =BU36/BP36*100-100 -> #DIV/0! | BV40: =SUM(BU36:BV36)/SUM(BP36:BQ36)*100-100 -> #DIV/0! | BW40: =SUM(BU36:BW36)/SUM(BP36:BR36)*100-100 -> #DIV/0! | BX40: =SUM(BU36:BX36)/SUM(BP36:BS36)*100-100 -> #DIV/0! | BZ40: =BZ36/BU36*100-100 -> -2.1760216 | CA40: =SUM(BZ36:CA36)/SUM(BU36:BV36)*100-100 -> -13.63056 | CB40: =SUM(BZ36:CB36)/SUM(BU36:BW36)*100-100 -> -17.568387 | CC40: =SUM(BZ36:CC36)/SUM(BU36:BX36)*100-100 -> -14.383402 | CE40: =CE36/BZ36*100-100 -> 15.286564 | CF40: =SUM(CE36:CF36)/SUM(BZ36:CA36)*100-100 -> 15.179113 | CG40: =SUM(CE36:CG36)/SUM(BZ36:CB36)*100-100 -> -18.390942 | CH40: =SUM(CE36:CH36)/SUM(BZ36:CC36)*100-100 -> -39.807247
BY42: Data sebelum perubahan | BZ42: 11190.55 | CA42: 5240.26 | CB42: 4726.27 | CC42: 10913.01
BY43: Data sebelum perubahan | BZ43: 14752.43 | CA43: 13506.73 | CB43: 11511.1 | CC43: 26293.82
CC48: DATA PPS DARI IG
CC50: 45681 | CD50: 1757808 | CF50: 45682 | CG50: 1217280 | CI50: Januari 2026 | CJ50: =1275828+479365 -> 1755193
CC51: 45712 | CD51: 2368331 | CF51: 45713 | CG51: 885112 | CI51: Februari 2026 | CJ51: =1845837+693240 -> 2539077
CC52: 45740 | CD52: 2339668 | CF52: 45741 | CG52: 1108536 | CI52: Maret 2026 | CJ52: 2339187
CC53: 45771 | CD53: 1037222 | CF53: 45772
CC54: 45801 | CD54: 990494 | CF54: 45802
CC55: 45832 | CD55: 849049 | CF55: 45833 | CG55: 1148164
CC56: 45862 | CD56: 970434 | CF56: 45863 | CG56: 1031640
CC57: 45893 | CD57: 1512590 | CF57: 45894 | CG57: 1258208
CC58: 45924 | CD58: 1277393 | CF58: 45925 | CG58: 1331123
CC59: 45954 | CD59: 1229250 | CF59: 45955
...

Sheet ADHK
A1: Home | B1: 1.1 Pertanian, Kehutanan & Perikanan | D1: 2010 | E1: 2012 | F1: 2014 | G1: 2016 | H1: 2018 | I1: 2020 | J1: 2022 | K1: 2024 | U1: 2010 | V1: 2012 | W1: 2014 | X1: 2016 | Y1: 2018 | Z1: 2020 | AA1: 2022 | AB1: 2024 | AL1: 2010 | AM1: 2012 | AN1: 2014 | AO1: 2016 | AP1: 2018 | AQ1: 2020 | AR1: 2022 | AS1: 2024 | BC1: 2010 | BD1: 2012 | BE1: 2014 | BF1: 2016 | BG1: 2018 | BH1: 2020 | BI1: 2022 | BJ1: 2024 | BT1: 2010 | BU1: 2012 | BV1: 2014 | BW1: 2016 | BX1: 2018 | BY1: 2020 | BZ1: 2022 | CA1: 2024 | CK1: 2010 | CL1: 2012 | CM1: 2014 | CN1: 2016 | CO1: 2018 | CP1: 2020 | CQ1: 2022 | CR1: 2024 | DB1: 2010 | DC1: 2012 | DD1: 2014 | DE1: 2016 | DF1: 2018 | DG1: 2020 | DH1: 2022 | DI1: 2024 | DS1: 2010 | DT1: 2012 | DU1: 2014 | DV1: 2016 | DW1: 2018 | DX1: 2020 | DY1: 2022 | DZ1: 2024 | EJ1: 2010 | EK1: 2012 | EL1: 2014 | EM1: 2016 | EN1: 2018 | EO1: 2020 | EP1: 2022 | EQ1: 2024 | FA1: 2010 | FB1: 2012 | FC1: 2014 | FD1: 2016 | FE1: 2018 | FF1: 2020 | FG1: 2022 | FH1: 2024 | FR1: 2010 | FS1: 2012 | FT1: 2014 | FU1: 2016 | FV1: 2018 | FW1: 2020 | FX1: 2022 | FY1: 2024 | GI1: 2010 | GJ1: 2012 | GK1: 2014 | GL1: 2016 | GM1: 2018 | GN1: 2020 | GO1: 2022 | GP1: 2024 | GZ1: 2010 | HA1: 2012 | HB1: 2014 | HC1: 2016 | HD1: 2018 | HE1: 2020 | HF1: 2022 | HG1: 2024 | HQ1: 2010 | HR1: 2012 | HS1: 2014 | HT1: 2016 | HU1: 2018 | HV1: 2020 | HW1: 2022 | HX1: 2024 | IH1: 2010 | II1: 2012 | IJ1: 2014 | IK1: 2016 | IL1: 2018 | IM1: 2020 | IN1: 2022 | IO1: 2024 | IY1: 2010 | IZ1: 2012 | JA1: 2014 | JB1: 2016 | JC1: 2018 | JD1: 2020 | JE1: 2022 | JF1: 2024 | JP1: 2010 | JQ1: 2012 | JR1: 2014 | JS1: 2016 | JT1: 2018 | JU1: 2020 | JV1: 2022 | JW1: 2024 | KG1: 2010 | KH1: 2012 | KI1: 2014 | KJ1: 2016 | KK1: 2018 | KL1: 2020 | KM1: 2022 | KN1: 2024
D2: 2011 | E2: 2013 | F2: 2015 | G2: 2017 | H2: 2019 | I2: 2021 | J2: 2023 | K2: 2025 | U2: 2011 | V2: 2013 | W2: 2015 | X2: 2017 | Y2: 2019 | Z2: 2021 | AA2: 2023 | AB2: 2025 | AL2: 2011 | AM2: 2013 | AN2: 2015 | AO2: 2017 | AP2: 2019 | AQ2: 2021 | AR2: 2023 | AS2: 2025 | BC2: 2011 | BD2: 2013 | BE2: 2015 | BF2: 2017 | BG2: 2019 | BH2: 2021 | BI2: 2023 | BJ2: 2025 | BT2: 2011 | BU2: 2013 | BV2: 2015 | BW2: 2017 | BX2: 2019 | BY2: 2021 | BZ2: 2023 | CA2: 2025 | CK2: 2011 | CL2: 2013 | CM2: 2015 | CN2: 2017 | CO2: 2019 | CP2: 2021 | CQ2: 2023 | CR2: 2025 | DB2: 2011 | DC2: 2013 | DD2: 2015 | DE2: 2017 | DF2: 2019 | DG2: 2021 | DH2: 2023 | DI2: 2025 | DS2: 2011 | DT2: 2013 | DU2: 2015 | DV2: 2017 | DW2: 2019 | DX2: 2021 | DY2: 2023 | DZ2: 2025 | EJ2: 2011 | EK2: 2013 | EL2: 2015 | EM2: 2017 | EN2: 2019 | EO2: 2021 | EP2: 2023 | EQ2: 2025 | FA2: 2011 | FB2: 2013 | FC2: 2015 | FD2: 2017 | FE2: 2019 | FF2: 2021 | FG2: 2023 | FH2: 2025 | FR2: 2011 | FS2: 2013 | FT2: 2015 | FU2: 2017 | FV2: 2019 | FW2: 2021 | FX2: 2023 | FY2: 2025 | GI2: 2011 | GJ2: 2013 | GK2: 2015 | GL2: 2017 | GM2: 2019 | GN2: 2021 | GO2: 2023 | GP2: 2025 | GZ2: 2011 | HA2: 2013 | HB2: 2015 | HC2: 2017 | HD2: 2019 | HE2: 2021 | HF2: 2023 | HG2: 2025 | HQ2: 2011 | HR2: 2013 | HS2: 2015 | HT2: 2017 | HU2: 2019 | HV2: 2021 | HW2: 2023 | HX2: 2025 | IH2: 2011 | II2: 2013 | IJ2: 2015 | IK2: 2017 | IL2: 2019 | IM2: 2021 | IN2: 2023 | IO2: 2025 | IY2: 2011 | IZ2: 2013 | JA2: 2015 | JB2: 2017 | JC2: 2019 | JD2: 2021 | JE2: 2023 | JF2: 2025 | JP2: 2011 | JQ2: 2013 | JR2: 2015 | JS2: 2017 | JT2: 2019 | JU2: 2021 | JV2: 2023 | JW2: 2025 | KG2: 2011 | KH2: 2013 | KI2: 2015 | KJ2: 2017 | KK2: 2019 | KL2: 2021 | KM2: 2023 | KN2: 2025
B4: Wilayah | C4: : Provinsi Sulawesi Tenggara | G4: Lembar Pengolahan Penghitungan | P4: ADHK | S4: Wilayah | T4: =C4 -> : Provinsi Sulawesi Tenggara | X4: Lembar Pengolahan Penghitungan | AG4: ADHK | AJ4: Wilayah | AK4: =T4 -> : Provinsi Sulawesi Tenggara | AO4: Lembar Pengolahan Penghitungan | AX4: ADHK | BA4: Wilayah | BB4: =AK4 -> : Provinsi Sulawesi Tenggara | BF4: Lembar Pengolahan Penghitungan | BO4: ADHK | BR4: Wilayah | BS4: =BB4 -> : Provinsi Sulawesi Tenggara | BW4: Lembar Pengolahan Penghitungan | CF4: ADHK | CI4: Wilayah | CJ4: =BS4 -> : Provinsi Sulawesi Tenggara | CN4: Lembar Pengolahan Penghitungan | CW4: ADHK | CZ4: Wilayah | DA4: =CJ4 -> : Provinsi Sulawesi Tenggara | DE4: Lembar Pengolahan Penghitungan | DN4: ADHK | DQ4: Wilayah | DR4: =DA4 -> : Provinsi Sulawesi Tenggara | DV4: Lembar Pengolahan Penghitungan | EE4: ADHK | EH4: Wilayah | EI4: =DR4 -> : Provinsi Sulawesi Tenggara | EM4: Lembar Pengolahan Penghitungan | EV4: ADHK | EY4: Wilayah | EZ4: =EI4 -> : Provinsi Sulawesi Tenggara | FD4: Lembar Pengolahan Penghitungan | FM4: ADHK | FP4: Wilayah | FQ4: =EZ4 -> : Provinsi Sulawesi Tenggara | FU4: Lembar Pengolahan Penghitungan | GD4: ADHK | GG4: Wilayah | GH4: =FQ4 -> : Provinsi Sulawesi Tenggara | GL4: Lembar Pengolahan Penghitungan | GU4: ADHK | GX4: Wilayah | GY4: =GH4 -> : Provinsi Sulawesi Tenggara | HC4: Lembar Pengolahan Penghitungan | HL4: ADHK | HO4: Wilayah | HP4: =GY4 -> : Provinsi Sulawesi Tenggara | HT4: Lembar Pengolahan Penghitungan | IC4: ADHK | IF4: Wilayah | IG4: =HP4 -> : Provinsi Sulawesi Tenggara | IK4: Lembar Pengolahan Penghitungan | IT4: ADHK | IW4: Wilayah | IX4: =IG4 -> : Provinsi Sulawesi Tenggara | JB4: Lembar Pengolahan Penghitungan | JK4: ADHK | JN4: Wilayah | JO4: =IX4 -> : Provinsi Sulawesi Tenggara | JS4: Lembar Pengolahan Penghitungan | KB4: ADHK | KE4: Wilayah | KF4: =JO4 -> : Provinsi Sulawesi Tenggara | KJ4: Lembar Pengolahan Penghitungan | KS4: ADHK
B5: Kategori | C5: : Pertanian, Kehutanan, dan Perikanan | G5: Nilai Tambah Bruto | S5: Kategori | T5: : Pertanian, Kehutanan, dan Perikanan | X5: Nilai Tambah Bruto | AJ5: Kategori | AK5: : Pertanian, Kehutanan, dan Perikanan | AO5: Nilai Tambah Bruto | BA5: Kategori | BB5: : Pertanian, Kehutanan, dan Perikanan | BF5: Nilai Tambah Bruto | BR5: Kategori | BS5: : Pertanian, Kehutanan, dan Perikanan | BW5: Nilai Tambah Bruto | CI5: Kategori | CJ5: : Pertanian, Kehutanan, dan Perikanan | CN5: Nilai Tambah Bruto | CZ5: Kategori | DA5: : Pertanian, Kehutanan, dan Perikanan | DE5: Nilai Tambah Bruto | DQ5: Kategori | DR5: : Pertanian, Kehutanan, dan Perikanan | DV5: Nilai Tambah Bruto | EH5: Kategori | EI5: : Pertanian, Kehutanan, dan Perikanan | EM5: Nilai Tambah Bruto | EY5: Kategori | EZ5: : Pertanian, Kehutanan, dan Perikanan | FD5: Nilai Tambah Bruto | FP5: Kategori | FQ5: : Pertanian, Kehutanan, dan Perikanan | FU5: Nilai Tambah Bruto | GG5: Kategori | GH5: : Pertanian, Kehutanan, dan Perikanan | GL5: Nilai Tambah Bruto | GX5: Kategori | GY5: : Pertanian, Kehutanan, dan Perikanan | HC5: Nilai Tambah Bruto | HO5: Kategori | HP5: : Pertanian, Kehutanan, dan Perikanan | HT5: Nilai Tambah Bruto | IF5: Kategori | IG5: : Pertanian, Kehutanan, dan Perikanan | IK5: Nilai Tambah Bruto | IW5: Kategori | IX5: : Pertanian, Kehutanan, dan Perikanan | JB5: Nilai Tambah Bruto | JN5: Kategori | JO5: : Pertanian, Kehutanan, dan Perikanan | JS5: Nilai Tambah Bruto | KE5: Kategori | KF5: : Pertanian, Kehutanan, dan Perikanan | KJ5: Nilai Tambah Bruto
B6: Subkategori | C6: : Perikanan | G6: Atas Dasar Harga Konstan 2010=100 | P6: 2010 | S6: Subkategori | T6: : Perikanan | X6: Atas Dasar Harga Konstan 2010=100 | AG6: =P6+1 -> 2011 | AJ6: Subkategori | AK6: : Perikanan | AO6: Atas Dasar Harga Konstan 2010=100 | AX6: =AG6+1 -> 2012 | BA6: Subkategori | BB6: : Perikanan | BF6: Atas Dasar Harga Konstan 2010=100 | BO6: =AX6+1 -> 2013 | BR6: Subkategori | BS6: : Perikanan | BW6: Atas Dasar Harga Konstan 2010=100 | CF6: =BO6+1 -> 2014 | CI6: Subkategori | CJ6: : Perikanan | CN6: Atas Dasar Harga Konstan 2010=100 | CW6: =CF6+1 -> 2015 | CZ6: Subkategori | DA6: : Perikanan | DE6: Atas Dasar Harga Konstan 2010=100 | DN6: =CW6+1 -> 2016 | DQ6: Subkategori | DR6: : Perikanan | DV6: Atas Dasar Harga Konstan 2010=100 | EE6: =DN6+1 -> 2017 | EH6: Subkategori | EI6: : Perikanan | EM6: Atas Dasar Harga Konstan 2010=100 | EV6: =EE6+1 -> 2018 | EY6: Subkategori | EZ6: : Perikanan | FD6: Atas Dasar Harga Konstan 2010=100 | FM6: =EV6+1 -> 2019 | FP6: Subkategori | FQ6: : Perikanan | FU6: Atas Dasar Harga Konstan 2010=100 | GD6: =FM6+1 -> 2020 | GG6: Subkategori | GH6: : Perikanan | GL6: Atas Dasar Harga Konstan 2010=100 | GU6: =GD6+1 -> 2021 | GX6: Subkategori | GY6: : Perikanan | HC6: Atas Dasar Harga Konstan 2010=100 | HL6: =GU6+1 -> 2022 | HO6: Subkategori | HP6: : Perikanan | HT6: Atas Dasar Harga Konstan 2010=100 | IC6: =HL6+1 -> 2023 | IF6: Subkategori | IG6: : Perikanan | IK6: Atas Dasar Harga Konstan 2010=100 | IT6: =IC6+1 -> 2024 | IW6: Subkategori | IX6: : Perikanan | JB6: Atas Dasar Harga Konstan 2010=100 | JK6: =IT6+1 -> 2025 | JN6: Subkategori | JO6: : Perikanan | JS6: Atas Dasar Harga Konstan 2010=100 | KB6: =JK6+1 -> 2026 | KE6: Subkategori | KF6: : Perikanan | KJ6: Atas Dasar Harga Konstan 2010=100 | KS6: =KB6+1 -> 2027
B7: Jenis Kegiatan | C7: : Perikanan | G7: ="Tahun "&P$6 -> Tahun 2010 | S7: Jenis Kegiatan | T7: : Perikanan | X7: ="Tahun "&AG$6 -> Tahun 2011 | AJ7: Jenis Kegiatan | AK7: : Perikanan | AO7: ="Tahun "&AX$6 -> Tahun 2012 | BA7: Jenis Kegiatan | BB7: : Perikanan | BF7: ="Tahun "&BO$6 -> Tahun 2013 | BR7: Jenis Kegiatan | BS7: : Perikanan | BW7: ="Tahun "&CF$6 -> Tahun 2014 | CI7: Jenis Kegiatan | CJ7: : Perikanan | CN7: ="Tahun "&CW$6 -> Tahun 2015 | CZ7: Jenis Kegiatan | DA7: : Perikanan | DE7: ="Tahun "&DN$6 -> Tahun 2016 | DQ7: Jenis Kegiatan | DR7: : Perikanan | DV7: ="Tahun "&EE$6 -> Tahun 2017 | EH7: Jenis Kegiatan | EI7: : Perikanan | EM7: ="Tahun "&EV$6 -> Tahun 2018 | EY7: Jenis Kegiatan | EZ7: : Perikanan | FD7: ="Tahun "&FM$6 -> Tahun 2019 | FP7: Jenis Kegiatan | FQ7: : Perikanan | FU7: ="Tahun "&GD$6 -> Tahun 2020 | GG7: Jenis Kegiatan | GH7: : Perikanan | GL7: ="Tahun "&GU$6 -> Tahun 2021 | GX7: Jenis Kegiatan | GY7: : Perikanan | HC7: ="Tahun "&HL$6 -> Tahun 2022 | HO7: Jenis Kegiatan | HP7: : Perikanan | HT7: ="Tahun "&IC$6 -> Tahun 2023 | IF7: Jenis Kegiatan | IG7: : Perikanan | IK7: ="Tahun "&IT$6 -> Tahun 2024 | IW7: Jenis Kegiatan | IX7: : Perikanan | JB7: ="Tahun "&JK$6 -> Tahun 2025 | JN7: Jenis Kegiatan | JO7: : Perikanan | JS7: ="Tahun "&KB$6 -> Tahun 2026 | KE7: Jenis Kegiatan | KF7: : Perikanan | KJ7: ="Tahun "&KS$6 -> Tahun 2027
B8: Metode Estimasi Output | C8: : Revaluasi | S8: Metode Estimasi Output | T8: : Revaluasi | AJ8: Metode Estimasi Output | AK8: : Revaluasi | BA8: Metode Estimasi Output | BB8: : Revaluasi | BR8: Metode Estimasi Output | BS8: : Revaluasi | CI8: Metode Estimasi Output | CJ8: : Revaluasi | CZ8: Metode Estimasi Output | DA8: : Revaluasi | DQ8: Metode Estimasi Output | DR8: : Revaluasi | EH8: Metode Estimasi Output | EI8: : Revaluasi | EY8: Metode Estimasi Output | EZ8: : Revaluasi | FP8: Metode Estimasi Output | FQ8: : Revaluasi | GG8: Metode Estimasi Output | GH8: : Revaluasi | GX8: Metode Estimasi Output | GY8: : Revaluasi | HO8: Metode Estimasi Output | HP8: : Revaluasi | IF8: Metode Estimasi Output | IG8: : Revaluasi | IW8: Metode Estimasi Output | IX8: : Revaluasi | JN8: Metode Estimasi Output | JO8: : Revaluasi | KE8: Metode Estimasi Output | KF8: : Revaluasi
A10: No. | B10: Subkategori/Jenis Kegiatan/Uraian Komoditi | C10: Output Utama | H10: Output Ikutan | J10: CBR/WIP | M10: Output ADH Produsen (Juta Rp) [(7)+(9)+(12)] | N10: Konsumsi Antara | P10: Nilai Tambah Bruto (Juta Rp) (13)-(15) | R10: No. | S10: Subkategori/Jenis Kegiatan/Uraian Komoditi | T10: Output Utama | Y10: Output Ikutan | AA10: CBR/WIP | AD10: Output ADH Produsen (Juta Rp) [(7)+(9)+(12)] | AE10: Konsumsi Antara | AG10: Nilai Tambah Bruto (Juta Rp) (13)-(15) | AI10: No. | AJ10: Subkategori/Jenis Kegiatan/Uraian Komoditi | AK10: Output Utama | AP10: Output Ikutan | AR10: CBR/WIP | AU10: Output ADH Produsen (Juta Rp) [(7)+(9)+(12)] | AV10: Konsumsi Antara | AX10: Nilai Tambah Bruto (Juta Rp) (13)-(15) | AZ10: No. | BA10: Subkategori/Jenis Kegiatan/Uraian Komoditi | BB10: Output Utama | BG10: Output Ikutan | BI10: CBR/WIP | BL10: Output ADH Produsen (Juta Rp) [(7)+(9)+(12)] | BM10: Konsumsi Antara | BO10: Nilai Tambah Bruto (Juta Rp) (13)-(15) | BQ10: No. | BR10: Subkategori/Jenis Kegiatan/Uraian Komoditi | BS10: Output Utama | BX10: Output Ikutan | BZ10: CBR/WIP | CC10: Output ADH Produsen (Juta Rp) [(7)+(9)+(12)] | CD10: Konsumsi Antara | CF10: Nilai Tambah Bruto (Juta Rp) (13)-(15) | CH10: No. | CI10: Subkategori/Jenis Kegiatan/Uraian Komoditi | CJ10: Output Utama | CO10: Output Ikutan | CQ10: CBR/WIP | CT10: Output ADH Produsen (Juta Rp) [(7)+(9)+(12)] | CU10: Konsumsi Antara | CW10: Nilai Tambah Bruto (Juta Rp) (13)-(15) | CY10: No. | CZ10: Subkategori/Jenis Kegiatan/Uraian Komoditi | DA10: Output Utama | DF10: Output Ikutan | DH10: CBR/WIP | DK10: Output ADH Produsen (Juta Rp) [(7)+(9)+(12)] | DL10: Konsumsi Antara | DN10: Nilai Tambah Bruto (Juta Rp) (13)-(15) | DP10: No. | DQ10: Subkategori/Jenis Kegiatan/Uraian Komoditi | DR10: Output Utama | DW10: Output Ikutan | DY10: CBR/WIP | EB10: Output ADH Produsen (Juta Rp) [(7)+(9)+(12)] | EC10: Konsumsi Antara | EE10: Nilai Tambah Bruto (Juta Rp) (13)-(15) | EG10: No. | EH10: Subkategori/Jenis Kegiatan/Uraian Komoditi | EI10: Output Utama | EN10: Output Ikutan | EP10: CBR/WIP | ES10: Output ADH Produsen (Juta Rp) [(7)+(9)+(12)] | ET10: Konsumsi Antara | EV10: Nilai Tambah Bruto (Juta Rp) (13)-(15) | EX10: No. | EY10: Subkategori/Jenis Kegiatan/Uraian Komoditi | EZ10: Output Utama | FE10: Output Ikutan | FG10: CBR/WIP | FJ10: Output ADH Produsen (Juta Rp) [(7)+(9)+(12)] | FK10: Konsumsi Antara | FM10: Nilai Tambah Bruto (Juta Rp) (13)-(15) | FO10: No. | FP10: Subkategori/Jenis Kegiatan/Uraian Komoditi | FQ10: Output Utama | FV10: Output Ikutan | FX10: CBR/WIP | GA10: Output ADH Produsen (Juta Rp) [(7)+(9)+(12)] | GB10: Konsumsi Antara | GD10: Nilai Tambah Bruto (Juta Rp) (13)-(15) | GF10: No. | GG10: Subkategori/Jenis Kegiatan/Uraian Komoditi | GH10: Output Utama | GM10: Output Ikutan | GO10: CBR/WIP | GR10: Output ADH Produsen (Juta Rp) [(7)+(9)+(12)] | GS10: Konsumsi Antara | GU10: Nilai Tambah Bruto (Juta Rp) (13)-(15) | GW10: No. | GX10: Subkategori/Jenis Kegiatan/Uraian Komoditi | GY10: Output Utama | HD10: Output Ikutan | HF10: CBR/WIP | HI10: Output ADH Produsen (Juta Rp) [(7)+(9)+(12)] | HJ10: Konsumsi Antara | HL10: Nilai Tambah Bruto (Juta Rp) (13)-(15) | HN10: No. | HO10: Subkategori/Jenis Kegiatan/Uraian Komoditi | HP10: Output Utama | HU10: Output Ikutan | HW10: CBR/WIP | HZ10: Output ADH Produsen (Juta Rp) [(7)+(9)+(12)] | IA10: Konsumsi Antara | IC10: Nilai Tambah Bruto (Juta Rp) (13)-(15) | IE10: No. | IF10: Subkategori/Jenis Kegiatan/Uraian Komoditi | IG10: Output Utama | IL10: Output Ikutan | IN10: CBR/WIP | IQ10: Output ADH Produsen (Juta Rp) [(7)+(9)+(12)] | IR10: Konsumsi Antara | IT10: Nilai Tambah Bruto (Juta Rp) (13)-(15) | IV10: No. | IW10: Subkategori/Jenis Kegiatan/Uraian Komoditi | IX10: Output Utama | JC10: Output Ikutan | JE10: CBR/WIP | JH10: Output ADH Produsen (Juta Rp) [(7)+(9)+(12)] | JI10: Konsumsi Antara | JK10: Nilai Tambah Bruto (Juta Rp) (13)-(15) | JM10: No. | JN10: Subkategori/Jenis Kegiatan/Uraian Komoditi | JO10: Output Utama | JT10: Output Ikutan | JV10: CBR/WIP | JY10: Output ADH Produsen (Juta Rp) [(7)+(9)+(12)] | JZ10: Konsumsi Antara | KB10: Nilai Tambah Bruto (Juta Rp) (13)-(15) | KD10: No. | KE10: Subkategori/Jenis Kegiatan/Uraian Komoditi | KF10: Output Utama | KK10: Output Ikutan | KM10: CBR/WIP | KP10: Output ADH Produsen (Juta Rp) [(7)+(9)+(12)] | KQ10: Konsumsi Antara | KS10: Nilai Tambah Bruto (Juta Rp) (13)-(15)
C11: Wujud/ Kegiatan | D11: Satuan/ Unit | E11: Kuantum | F11: Harga Produsen tahun 2010 (Rp/Unit) | G11: Nilai (Juta Rp) (5)x(6) | H11: Rasio Tahun 2010 | I11: Nilai (Juta Rp) (8)x(7) | J11: Deflator | K11: CBR/WIP Berlaku (Juta Rp) | L11: Nilai (Juta Rp) (11) / (10) x 100 | N11: Rasio Tahun 2010 | O11: Nilai (Juta Rp) ((13)-(12))x(14) | T11: Wujud/ Kegiatan | U11: Satuan/ Unit | V11: Kuantum | W11: Harga Produsen tahun 2010 (Rp/Unit) | X11: Nilai (Juta Rp) (5)x(6) | Y11: Rasio Tahun 2010 | Z11: Nilai (Juta Rp) (8)x(7) | AA11: Deflator | AB11: CBR/WIP Berlaku (Juta Rp) | AC11: Nilai (Juta Rp) (11) / (10) x 100 | AE11: Rasio Tahun 2010 | AF11: Nilai (Juta Rp) ((13)-(12))x(14) | AK11: Wujud/ Kegiatan | AL11: Satuan/ Unit | AM11: Kuantum | AN11: Harga Produsen tahun 2010 (Rp/Unit) | AO11: Nilai (Juta Rp) (5)x(6) | AP11: Rasio Tahun 2010 | AQ11: Nilai (Juta Rp) (8)x(7) | AR11: Deflator | AS11: CBR/WIP Berlaku (Juta Rp) | AT11: Nilai (Juta Rp) (11) / (10) x 100 | AV11: Rasio Tahun 2010 | AW11: Nilai (Juta Rp) ((13)-(12))x(14) | BB11: Wujud/ Kegiatan | BC11: Satuan/ Unit | BD11: Kuantum | BE11: Harga Produsen tahun 2010 (Rp/Unit) | BF11: Nilai (Juta Rp) (5)x(6) | BG11: Rasio Tahun 2010 | BH11: Nilai (Juta Rp) (8)x(7) | BI11: Deflator | BJ11: CBR/WIP Berlaku (Juta Rp) | BK11: Nilai (Juta Rp) (11) / (10) x 100 | BM11: Rasio Tahun 2010 | BN11: Nilai (Juta Rp) ((13)-(12))x(14) | BS11: Wujud/ Kegiatan | BT11: Satuan/ Unit | BU11: Kuantum | BV11: Harga Produsen tahun 2010 (Rp/Unit) | BW11: Nilai (Juta Rp) (5)x(6) | BX11: Rasio Tahun 2010 | BY11: Nilai (Juta Rp) (8)x(7) | BZ11: Deflator | CA11: CBR/WIP Berlaku (Juta Rp) | CB11: Nilai (Juta Rp) (11) / (10) x 100 | CD11: Rasio Tahun 2010 | CE11: Nilai (Juta Rp) ((13)-(12))x(14) | CJ11: Wujud/ Kegiatan | CK11: Satuan/ Unit | CL11: Kuantum | CM11: Harga Produsen tahun 2010 (Rp/Unit) | CN11: Nilai (Juta Rp) (5)x(6) | CO11: Rasio Tahun 2010 | CP11: Nilai (Juta Rp) (8)x(7) | CQ11: Deflator | CR11: CBR/WIP Berlaku (Juta Rp) | CS11: Nilai (Juta Rp) (11) / (10) x 100 | CU11: Rasio Tahun 2010 | CV11: Nilai (Juta Rp) ((13)-(12))x(14) | DA11: Wujud/ Kegiatan | DB11: Satuan/ Unit | DC11: Kuantum | DD11: Harga Produsen tahun 2010 (Rp/Unit) | DE11: Nilai (Juta Rp) (5)x(6) | DF11: Rasio Tahun 2010 | DG11: Nilai (Juta Rp) (8)x(7) | DH11: Deflator | DI11: CBR/WIP Berlaku (Juta Rp) | DJ11: Nilai (Juta Rp) (11) / (10) x 100 | DL11: Rasio Tahun 2010 | DM11: Nilai (Juta Rp) ((13)-(12))x(14) | DR11: Wujud/ Kegiatan | DS11: Satuan/ Unit | DT11: Kuantum | DU11: Harga Produsen tahun 2010 (Rp/Unit) | DV11: Nilai (Juta Rp) (5)x(6) | DW11: Rasio Tahun 2010 | DX11: Nilai (Juta Rp) (8)x(7) | DY11: Deflator | DZ11: CBR/WIP Berlaku (Juta Rp) | EA11: Nilai (Juta Rp) (11) / (10) x 100 | EC11: Rasio Tahun 2010 | ED11: Nilai (Juta Rp) ((13)-(12))x(14) | EI11: Wujud/ Kegiatan | EJ11: Satuan/ Unit | EK11: Kuantum | EL11: Harga Produsen tahun 2010 (Rp/Unit) | EM11: Nilai (Juta Rp) (5)x(6) | EN11: Rasio Tahun 2010 | EO11: Nilai (Juta Rp) (8)x(7) | EP11: Deflator | EQ11: CBR/WIP Berlaku (Juta Rp) | ER11: Nilai (Juta Rp) (11) / (10) x 100 | ET11: Rasio Tahun 2010 | EU11: Nilai (Juta Rp) ((13)-(12))x(14) | EZ11: Wujud/ Kegiatan | FA11: Satuan/ Unit | FB11: Kuantum | FC11: Harga Produsen tahun 2010 (Rp/Unit) | FD11: Nilai (Juta Rp) (5)x(6) | FE11: Rasio Tahun 2010 | FF11: Nilai (Juta Rp) (8)x(7) | FG11: Deflator | FH11: CBR/WIP Berlaku (Juta Rp) | FI11: Nilai (Juta Rp) (11) / (10) x 100 | FK11: Rasio Tahun 2010 | FL11: Nilai (Juta Rp) ((13)-(12))x(14) | FQ11: Wujud/ Kegiatan | FR11: Satuan/ Unit | FS11: Kuantum | FT11: Harga Produsen tahun 2010 (Rp/Unit) | FU11: Nilai (Juta Rp) (5)x(6) | FV11: Rasio Tahun 2010 | FW11: Nilai (Juta Rp) (8)x(7) | FX11: Deflator | FY11: CBR/WIP Berlaku (Juta Rp) | FZ11: Nilai (Juta Rp) (11) / (10) x 100 | GB11: Rasio Tahun 2010 | GC11: Nilai (Juta Rp) ((13)-(12))x(14) | GH11: Wujud/ Kegiatan | GI11: Satuan/ Unit | GJ11: Kuantum | GK11: Harga Produsen tahun 2010 (Rp/Unit) | GL11: Nilai (Juta Rp) (5)x(6) | GM11: Rasio Tahun 2010 | GN11: Nilai (Juta Rp) (8)x(7) | GO11: Deflator | GP11: CBR/WIP Berlaku (Juta Rp) | GQ11: Nilai (Juta Rp) (11) / (10) x 100 | GS11: Rasio Tahun 2010 | GT11: Nilai (Juta Rp) ((13)-(12))x(14) | GY11: Wujud/ Kegiatan | GZ11: Satuan/ Unit | HA11: Kuantum | HB11: Harga Produsen tahun 2010 (Rp/Unit) | HC11: Nilai (Juta Rp) (5)x(6) | HD11: Rasio Tahun 2010 | HE11: Nilai (Juta Rp) (8)x(7) | HF11: Deflator | HG11: CBR/WIP Berlaku (Juta Rp) | HH11: Nilai (Juta Rp) (11) / (10) x 100 | HJ11: Rasio Tahun 2010 | HK11: Nilai (Juta Rp) ((13)-(12))x(14) | HP11: Wujud/ Kegiatan | HQ11: Satuan/ Unit | HR11: Kuantum | HS11: Harga Produsen tahun 2010 (Rp/Unit) | HT11: Nilai (Juta Rp) (5)x(6) | HU11: Rasio Tahun 2010 | HV11: Nilai (Juta Rp) (8)x(7) | HW11: Deflator | HX11: CBR/WIP Berlaku (Juta Rp) | HY11: Nilai (Juta Rp) (11) / (10) x 100 | IA11: Rasio Tahun 2010 | IB11: Nilai (Juta Rp) ((13)-(12))x(14) | IG11: Wujud/ Kegiatan | IH11: Satuan/ Unit | II11: Kuantum | IJ11: Harga Produsen tahun 2010 (Rp/Unit) | IK11: Nilai (Juta Rp) (5)x(6) | IL11: Rasio Tahun 2010 | IM11: Nilai (Juta Rp) (8)x(7) | IN11: Deflator | IO11: CBR/WIP Berlaku (Juta Rp) | IP11: Nilai (Juta Rp) (11) / (10) x 100 | IR11: Rasio Tahun 2010 | IS11: Nilai (Juta Rp) ((13)-(12))x(14) | IX11: Wujud/ Kegiatan | IY11: Satuan/ Unit | IZ11: Kuantum | JA11: Harga Produsen tahun 2010 (Rp/Unit) | JB11: Nilai (Juta Rp) (5)x(6) | JC11: Rasio Tahun 2010 | JD11: Nilai (Juta Rp) (8)x(7) | JE11: Deflator | JF11: CBR/WIP Berlaku (Juta Rp) | JG11: Nilai (Juta Rp) (11) / (10) x 100 | JI11: Rasio Tahun 2010 | JJ11: Nilai (Juta Rp) ((13)-(12))x(14) | JO11: Wujud/ Kegiatan | JP11: Satuan/ Unit | JQ11: Kuantum | JR11: Harga Produsen tahun 2010 (Rp/Unit) | JS11: Nilai (Juta Rp) (5)x(6) | JT11: Rasio Tahun 2010 | JU11: Nilai (Juta Rp) (8)x(7) | JV11: Deflator | JW11: CBR/WIP Berlaku (Juta Rp) | JX11: Nilai (Juta Rp) (11) / (10) x 100 | JZ11: Rasio Tahun 2010 | KA11: Nilai (Juta Rp) ((13)-(12))x(14) | KF11: Wujud/ Kegiatan | KG11: Satuan/ Unit | KH11: Kuantum | KI11: Harga Produsen tahun 2010 (Rp/Unit) | KJ11: Nilai (Juta Rp) (5)x(6) | KK11: Rasio Tahun 2010 | KL11: Nilai (Juta Rp) (8)x(7) | KM11: Deflator | KN11: CBR/WIP Berlaku (Juta Rp) | KO11: Nilai (Juta Rp) (11) / (10) x 100 | KQ11: Rasio Tahun 2010 | KR11: Nilai (Juta Rp) ((13)-(12))x(14)
A12: -1 | B12: -2 | C12: -3 | D12: -4 | E12: -5 | F12: -6 | G12: -7 | H12: -8 | I12: -9 | J12: -10 | K12: -11 | L12: -12 | M12: -13 | N12: -14 | O12: -15 | P12: -16 | R12: -1 | S12: -2 | T12: -3 | U12: -4 | V12: -5 | W12: -6 | X12: -7 | Y12: -8 | Z12: -9 | AA12: -10 | AB12: -11 | AC12: -12 | AD12: -13 | AE12: -14 | AF12: -15 | AG12: -16 | AI12: -1 | AJ12: -2 | AK12: -3 | AL12: -4 | AM12: -5 | AN12: -6 | AO12: -7 | AP12: -8 | AQ12: -9 | AR12: -10 | AS12: -11 | AT12: -12 | AU12: -13 | AV12: -14 | AW12: -15 | AX12: -16 | AZ12: -1 | BA12: -2 | BB12: -3 | BC12: -4 | BD12: -5 | BE12: -6 | BF12: -7 | BG12: -8 | BH12: -9 | BI12: -10 | BJ12: -11 | BK12: -12 | BL12: -13 | BM12: -14 | BN12: -15 | BO12: -16 | BQ12: -1 | BR12: -2 | BS12: -3 | BT12: -4 | BU12: -5 | BV12: -6 | BW12: -7 | BX12: -8 | BY12: -9 | BZ12: -10 | CA12: -11 | CB12: -12 | CC12: -13 | CD12: -14 | CE12: -15 | CF12: -16 | CH12: -1 | CI12: -2 | CJ12: -3 | CK12: -4 | CL12: -5 | CM12: -6 | CN12: -7 | CO12: -8 | CP12: -9 | CQ12: -10 | CR12: -11 | CS12: -12 | CT12: -13 | CU12: -14 | CV12: -15 | CW12: -16 | CY12: -1 | CZ12: -2 | DA12: -3 | DB12: -4 | DC12: -5 | DD12: -6 | DE12: -7 | DF12: -8 | DG12: -9 | DH12: -10 | DI12: -11 | DJ12: -12 | DK12: -13 | DL12: -14 | DM12: -15 | DN12: -16 | DP12: -1 | DQ12: -2 | DR12: -3 | DS12: -4 | DT12: -5 | DU12: -6 | DV12: -7 | DW12: -8 | DX12: -9 | DY12: -10 | DZ12: -11 | EA12: -12 | EB12: -13 | EC12: -14 | ED12: -15 | EE12: -16 | EG12: -1 | EH12: -2 | EI12: -3 | EJ12: -4 | EK12: -5 | EL12: -6 | EM12: -7 | EN12: -8 | EO12: -9 | EP12: -10 | EQ12: -11 | ER12: -12 | ES12: -13 | ET12: -14 | EU12: -15 | EV12: -16 | EX12: -1 | EY12: -2 | EZ12: -3 | FA12: -4 | FB12: -5 | FC12: -6 | FD12: -7 | FE12: -8 | FF12: -9 | FG12: -10 | FH12: -11 | FI12: -12 | FJ12: -13 | FK12: -14 | FL12: -15 | FM12: -16 | FO12: -1 | FP12: -2 | FQ12: -3 | FR12: -4 | FS12: -5 | FT12: -6 | FU12: -7 | FV12: -8 | FW12: -9 | FX12: -10 | FY12: -11 | FZ12: -12 | GA12: -13 | GB12: -14 | GC12: -15 | GD12: -16 | GF12: -1 | GG12: -2 | GH12: -3 | GI12: -4 | GJ12: -5 | GK12: -6 | GL12: -7 | GM12: -8 | GN12: -9 | GO12: -10 | GP12: -11 | GQ12: -12 | GR12: -13 | GS12: -14 | GT12: -15 | GU12: -16 | GW12: -1 | GX12: -2 | GY12: -3 | GZ12: -4 | HA12: -5 | HB12: -6 | HC12: -7 | HD12: -8 | HE12: -9 | HF12: -10 | HG12: -11 | HH12: -12 | HI12: -13 | HJ12: -14 | HK12: -15 | HL12: -16 | HN12: -1 | HO12: -2 | HP12: -3 | HQ12: -4 | HR12: -5 | HS12: -6 | HT12: -7 | HU12: -8 | HV12: -9 | HW12: -10 | HX12: -11 | HY12: -12 | HZ12: -13 | IA12: -14 | IB12: -15 | IC12: -16 | IE12: -1 | IF12: -2 | IG12: -3 | IH12: -4 | II12: -5 | IJ12: -6 | IK12: -7 | IL12: -8 | IM12: -9 | IN12: -10 | IO12: -11 | IP12: -12 | IQ12: -13 | IR12: -14 | IS12: -15 | IT12: -16 | IV12: -1 | IW12: -2 | IX12: -3 | IY12: -4 | IZ12: -5 | JA12: -6 | JB12: -7 | JC12: -8 | JD12: -9 | JE12: -10 | JF12: -11 | JG12: -12 | JH12: -13 | JI12: -14 | JJ12: -15 | JK12: -16 | JM12: -1 | JN12: -2 | JO12: -3 | JP12: -4 | JQ12: -5 | JR12: -6 | JS12: -7 | JT12: -8 | JU12: -9 | JV12: -10 | JW12: -11 | JX12: -12 | JY12: -13 | JZ12: -14 | KA12: -15 | KB12: -16 | KD12: -1 | KE12: -2 | KF12: -3 | KG12: -4 | KH12: -5 | KI12: -6 | KJ12: -7 | KK12: -8 | KL12: -9 | KM12: -10 | KN12: -11 | KO12: -12 | KP12: -13 | KQ12: -14 | KR12: -15 | KS12: -16
B13: Perikanan Tangkap | S13: Perikanan Tangkap | AJ13: Perikanan Tangkap | BA13: Perikanan Tangkap | BR13: Perikanan Tangkap | CI13: Perikanan Tangkap | CZ13: Perikanan Tangkap | DQ13: Perikanan Tangkap | EH13: Perikanan Tangkap | EY13: Perikanan Tangkap | FP13: Perikanan Tangkap | GG13: Perikanan Tangkap | GX13: Perikanan Tangkap | HO13: Perikanan Tangkap | IF13: Perikanan Tangkap | IW13: Perikanan Tangkap | JN13: Perikanan Tangkap | KE13: Perikanan Tangkap
A14: 1 | B14: Ikan di Laut | D14: Ton | E14: =E115+E216+E317+E418 -> 0 | F14: =IFERROR(G14/E14*1000000,0) -> 0 | G14: =G115+G216+G317+G418 -> 0 | I14: =I115+I216+I317+I418 -> 0 | M14: =M115+M216+M317+M418 -> 0 | N14: 0.29428987 | O14: =O115+O216+O317+O418 -> 0 | P14: =IFERROR(+(IF(M14="","0",M14))-(IF(O14="","0",O14)),"") -> 0 | R14: 1 | S14: Ikan di Laut | U14: Ton | V14: =V115+V216+V317+V418 -> 0 | W14: =IFERROR(X14/V14*1000000,0) -> 0 | X14: =X115+X216+X317+X418 -> 0 | Z14: =Z115+Z216+Z317+Z418 -> 0 | AD14: =AD115+AD216+AD317+AD418 -> 0 | AE14: 0.29428987 | AF14: =AF115+AF216+AF317+AF418 -> 0 | AG14: =IFERROR(+(IF(AD14="","0",AD14))-(IF(AF14="","0",AF14)),"") -> 0 | AI14: 1 | AJ14: Ikan di Laut | AL14: Ton | AM14: =AM115+AM216+AM317+AM418 -> 0 | AN14: =IFERROR(AO14/AM14*1000000,0) -> 0 | AO14: =AO115+AO216+AO317+AO418 -> 0 | AQ14: =AQ115+AQ216+AQ317+AQ418 -> 0 | AU14: =AU115+AU216+AU317+AU418 -> 0 | AV14: 0.29428987 | AW14: =AW115+AW216+AW317+AW418 -> 0 | AX14: =IFERROR(+(IF(AU14="","0",AU14))-(IF(AW14="","0",AW14)),"") -> 0 | AZ14: 1 | BA14: Ikan di Laut | BC14: Ton | BD14: =BD115+BD216+BD317+BD418 -> 0 | BE14: =IFERROR(BF14/BD14*1000000,0) -> 0 | BF14: =BF115+BF216+BF317+BF418 -> 0 | BH14: =BH115+BH216+BH317+BH418 -> 0 | BL14: =BL115+BL216+BL317+BL418 -> 0 | BM14: 0.29428987 | BN14: =BN115+BN216+BN317+BN418 -> 0 | BO14: =IFERROR(+(IF(BL14="","0",BL14))-(IF(BN14="","0",BN14)),"") -> 0 | BQ14: 1 | BR14: Ikan di Laut | BT14: Ton | BU14: =BU115+BU216+BU317+BU418 -> 0 | BV14: =IFERROR(BW14/BU14*1000000,0) -> 0 | BW14: =BW115+BW216+BW317+BW418 -> 0 | BY14: =BY115+BY216+BY317+BY418 -> 0 | CC14: =CC115+CC216+CC317+CC418 -> 0 | CD14: 0.29428987 | CE14: =CE115+CE216+CE317+CE418 -> 0 | CF14: =IFERROR(+(IF(CC14="","0",CC14))-(IF(CE14="","0",CE14)),"") -> 0 | CH14: 1 | CI14: Ikan di Laut | CK14: Ton | CL14: =CL115+CL216+CL317+CL418 -> 0 | CM14: =IFERROR(CN14/CL14*1000000,0) -> 0 | CN14: =CN115+CN216+CN317+CN418 -> 0 | CP14: =CP115+CP216+CP317+CP418 -> 0 | CT14: =CT115+CT216+CT317+CT418 -> 0 | CU14: 0.29428987 | CV14: =CV115+CV216+CV317+CV418 -> 0 | CW14: =IFERROR(+(IF(CT14="","0",CT14))-(IF(CV14="","0",CV14)),"") -> 0 | CY14: 1 | CZ14: Ikan di Laut | DB14: Ton | DC14: =DC115+DC216+DC317+DC418 -> 0 | DD14: =IFERROR(DE14/DC14*1000000,0) -> 0 | DE14: =DE115+DE216+DE317+DE418 -> 0 | DG14: =DG115+DG216+DG317+DG418 -> 0 | DK14: =DK115+DK216+DK317+DK418 -> 0 | DL14: 0.29428987 | DM14: =DM115+DM216+DM317+DM418 -> 0 | DN14: =IFERROR(+(IF(DK14="","0",DK14))-(IF(DM14="","0",DM14)),"") -> 0 | DP14: 1 | DQ14: Ikan di Laut | DS14: Ton | DT14: =DT115+DT216+DT317+DT418 -> 0 | DU14: =IFERROR(DV14/DT14*1000000,0) -> 0 | DV14: =DV115+DV216+DV317+DV418 -> 0 | DX14: =DX115+DX216+DX317+DX418 -> 0 | EB14: =EB115+EB216+EB317+EB418 -> 0 | EC14: 0.29428987 | ED14: =ED115+ED216+ED317+ED418 -> 0 | EE14: =IFERROR(+(IF(EB14="","0",EB14))-(IF(ED14="","0",ED14)),"") -> 0 | EG14: 1 | EH14: Ikan di Laut | EJ14: Ton | EK14: =EK115+EK216+EK317+EK418 -> 0 | EL14: =IFERROR(EM14/EK14*1000000,0) -> 0 | EM14: =EM115+EM216+EM317+EM418 -> 0 | EO14: =EO115+EO216+EO317+EO418 -> 0 | ES14: =ES115+ES216+ES317+ES418 -> 0 | ET14: 0.29428987 | EU14: =EU115+EU216+EU317+EU418 -> 0 | EV14: =IFERROR(+(IF(ES14="","0",ES14))-(IF(EU14="","0",EU14)),"") -> 0 | EX14: 1 | EY14: Ikan di Laut | FA14: Ton | FB14: =FB115+FB216+FB317+FB418 -> 75521.03 | FC14: =IFERROR(FD14/FB14*1000000,0) -> 7441505.4 | FD14: =FD115+FD216+FD317+FD418 -> 561990.15 | FF14: =FF115+FF216+FF317+FF418 -> 0 | FJ14: =FJ115+FJ216+FJ317+FJ418 -> 561990.15 | FK14: 0.29428987 | FL14: =FL115+FL216+FL317+FL418 -> 165388.01 | FM14: =IFERROR(+(IF(FJ14="","0",FJ14))-(IF(FL14="","0",FL14)),"") -> 396602.15 | FO14: 1 | FP14: Ikan di Laut | FR14: Ton | FS14: =FS115+FS216+FS317+FS418 -> 67937.122 | FT14: =IFERROR(FU14/FS14*1000000,0) -> 7455153.7 | FU14: =FU115+FU216+FU317+FU418 -> 506481.69 | FW14: =FW115+FW216+FW317+FW418 -> 0 | GA14: =GA115+GA216+GA317+GA418 -> 506481.69 | GB14: 0.29428987 | GC14: =GC115+GC216+GC317+GC418 -> 149052.43 | GD14: =IFERROR(+(IF(GA14="","0",GA14))-(IF(GC14="","0",GC14)),"") -> 357429.26 | GF14: 1 | GG14: Ikan di Laut | GI14: Ton | GJ14: =GJ115+GJ216+GJ317+GJ418 -> 56423.876 | GK14: =IFERROR(GL14/GJ14*1000000,0) -> 7436684.3 | GL14: =GL115+GL216+GL317+GL418 -> 419606.55 | GN14: =GN115+GN216+GN317+GN418 -> 0 | GR14: =GR115+GR216+GR317+GR418 -> 419606.55 | GS14: 0.29428987 | GT14: =GT115+GT216+GT317+GT418 -> 123485.96 | GU14: =IFERROR(+(IF(GR14="","0",GR14))-(IF(GT14="","0",GT14)),"") -> 296120.6 | GW14: 1 | GX14: Ikan di Laut | GZ14: Ton | HA14: =HA115+HA216+HA317+HA418 -> 72206.828 | HB14: =IFERROR(HC14/HA14*1000000,0) -> 7445194.9 | HC14: =HC115+HC216+HC317+HC418 -> 537593.91 | HE14: =HE115+HE216+HE317+HE418 -> 0 | HI14: =HI115+HI216+HI317+HI418 -> 537593.91 | HJ14: 0.29428987 | HK14: =HK115+HK216+HK317+HK418 -> 158208.44 | HL14: =IFERROR(+(IF(HI14="","0",HI14))-(IF(HK14="","0",HK14)),"") -> 379385.47 | HN14: 1 | HO14: Ikan di Laut | HQ14: Ton | HR14: =HR115+HR216+HR317+HR418 -> 61821.03 | HS14: =IFERROR(HT14/HR14*1000000,0) -> 7444799.6 | HT14: =HT115+HT216+HT317+HT418 -> 460245.18 | HV14: =HV115+HV216+HV317+HV418 -> 0 | HZ14: =HZ115+HZ216+HZ317+HZ418 -> 460245.18 | IA14: 0.29428987 | IB14: =IB115+IB216+IB317+IB418 -> 135445.49 | IC14: =IFERROR(+(IF(HZ14="","0",HZ14))-(IF(IB14="","0",IB14)),"") -> 324799.69 | IE14: 1 | IF14: Ikan di Laut | IH14: Ton | II14: =II115+II216+II317+II418 -> 76096.44 | IJ14: =IFERROR(IK14/II14*1000000,0) -> 7445593.8 | IK14: =IK115+IK216+IK317+IK418 -> 566583.18 | IM14: =IM115+IM216+IM317+IM418 -> 0 | IQ14: =IQ115+IQ216+IQ317+IQ418 -> 566583.18 | IR14: 0.29428987 | IS14: =IS115+IS216+IS317+IS418 -> 166739.69 | IT14: =IFERROR(+(IF(IQ14="","0",IQ14))-(IF(IS14="","0",IS14)),"") -> 399843.49 | IV14: 1 | IW14: Ikan di Laut | IY14: Ton | IZ14: =IZ115+IZ216+IZ317+IZ418 -> 74653.743 | JA14: =IFERROR(JB14/IZ14*1000000,0) -> 7339918.3 | JB14: =JB115+JB216+JB317+JB418 -> 547952.37 | JD14: =JD115+JD216+JD317+JD418 -> 0 | JH14: =JH115+JH216+JH317+JH418 -> 547952.37 | JI14: 0.29428987 | JJ14: =JJ115+JJ216+JJ317+JJ418 -> 161256.83 | JK14: =IFERROR(+(IF(JH14="","0",JH14))-(IF(JJ14="","0",JJ14)),"") -> 386695.54 | JM14: 1 | JN14: Ikan di Laut | JP14: Ton | JQ14: =JQ115+JQ216+JQ317+JQ418 -> 18460.12 | JR14: =IFERROR(JS14/JQ14*1000000,0) -> 7339918.3 | JS14: =JS115+JS216+JS317+JS418 -> 135495.77 | JU14: =JU115+JU216+JU317+JU418 -> 0 | JY14: =JY115+JY216+JY317+JY418 -> 135495.77 | JZ14: 0.29428987 | KA14: =KA115+KA216+KA317+KA418 -> 39875.033 | KB14: =IFERROR(+(IF(JY14="","0",JY14))-(IF(KA14="","0",KA14)),"") -> 95620.74 | KD14: 1 | KE14: Ikan di Laut | KG14: Ton | KH14: =KH115+KH216+KH317+KH418 -> 0 | KI14: =IFERROR(KJ14/KH14*1000000,0) -> 0 | KJ14: =KJ115+KJ216+KJ317+KJ418 -> 0 | KL14: =KL115+KL216+KL317+KL418 -> 0 | KP14: =KP115+KP216+KP317+KP418 -> 0 | KQ14: 0.29428987 | KR14: =KR115+KR216+KR317+KR418 -> 0 | KS14: =IFERROR(+(IF(KP14="","0",KP14))-(IF(KR14="","0",KR14)),"") -> 0
A15: 2 | B15: Ikan di Perairan Umum | D15: Ton | E15: =E116+E217+E318+E419 -> 0 | F15: =IFERROR(G15/E15*1000000,0) -> 0 | G15: =G116+G217+G318+G419 -> 0 | I15: =I116+I217+I318+I419 -> 0 | M15: =M116+M217+M318+M419 -> 0 | N15: 0.29428987 | O15: =O116+O217+O318+O419 -> 0 | P15: =IFERROR(+(IF(M15="","0",M15))-(IF(O15="","0",O15)),"") -> 0 | R15: 2 | S15: Ikan di Perairan Umum | U15: Ton | V15: =V116+V217+V318+V419 -> 0 | W15: =IFERROR(X15/V15*1000000,0) -> 0 | X15: =X116+X217+X318+X419 -> 0 | Z15: =Z116+Z217+Z318+Z419 -> 0 | AD15: =AD116+AD217+AD318+AD419 -> 0 | AE15: 0.29428987 | AF15: =AF116+AF217+AF318+AF419 -> 0 | AG15: =IFERROR(+(IF(AD15="","0",AD15))-(IF(AF15="","0",AF15)),"") -> 0 | AI15: 2 | AJ15: Ikan di Perairan Umum | AL15: Ton | AM15: =AM116+AM217+AM318+AM419 -> 0 | AN15: =IFERROR(AO15/AM15*1000000,0) -> 0 | AO15: =AO116+AO217+AO318+AO419 -> 0 | AQ15: =AQ116+AQ217+AQ318+AQ419 -> 0 | AU15: =AU116+AU217+AU318+AU419 -> 0 | AV15: 0.29428987 | AW15: =AW116+AW217+AW318+AW419 -> 0 | AX15: =IFERROR(+(IF(AU15="","0",AU15))-(IF(AW15="","0",AW15)),"") -> 0 | AZ15: 2 | BA15: Ikan di Perairan Umum | BC15: Ton | BD15: =BD116+BD217+BD318+BD419 -> 0 | BE15: =IFERROR(BF15/BD15*1000000,0) -> 0 | BF15: =BF116+BF217+BF318+BF419 -> 0 | BH15: =BH116+BH217+BH318+BH419 -> 0 | BL15: =BL116+BL217+BL318+BL419 -> 0 | BM15: 0.29428987 | BN15: =BN116+BN217+BN318+BN419 -> 0 | BO15: =IFERROR(+(IF(BL15="","0",BL15))-(IF(BN15="","0",BN15)),"") -> 0 | BQ15: 2 | BR15: Ikan di Perairan Umum | BT15: Ton | BU15: =BU116+BU217+BU318+BU419 -> 0 | BV15: =IFERROR(BW15/BU15*1000000,0) -> 0 | BW15: =BW116+BW217+BW318+BW419 -> 0 | BY15: =BY116+BY217+BY318+BY419 -> 0 | CC15: =CC116+CC217+CC318+CC419 -> 0 | CD15: 0.29428987 | CE15: =CE116+CE217+CE318+CE419 -> 0 | CF15: =IFERROR(+(IF(CC15="","0",CC15))-(IF(CE15="","0",CE15)),"") -> 0 | CH15: 2 | CI15: Ikan di Perairan Umum | CK15: Ton | CL15: =CL116+CL217+CL318+CL419 -> 0 | CM15: =IFERROR(CN15/CL15*1000000,0) -> 0 | CN15: =CN116+CN217+CN318+CN419 -> 0 | CP15: =CP116+CP217+CP318+CP419 -> 0 | CT15: =CT116+CT217+CT318+CT419 -> 0 | CU15: 0.29428987 | CV15: =CV116+CV217+CV318+CV419 -> 0 | CW15: =IFERROR(+(IF(CT15="","0",CT15))-(IF(CV15="","0",CV15)),"") -> 0 | CY15: 2 | CZ15: Ikan di Perairan Umum | DB15: Ton | DC15: =DC116+DC217+DC318+DC419 -> 0 | DD15: =IFERROR(DE15/DC15*1000000,0) -> 0 | DE15: =DE116+DE217+DE318+DE419 -> 0 | DG15: =DG116+DG217+DG318+DG419 -> 0 | DK15: =DK116+DK217+DK318+DK419 -> 0 | DL15: 0.29428987 | DM15: =DM116+DM217+DM318+DM419 -> 0 | DN15: =IFERROR(+(IF(DK15="","0",DK15))-(IF(DM15="","0",DM15)),"") -> 0 | DP15: 2 | DQ15: Ikan di Perairan Umum | DS15: Ton | DT15: =DT116+DT217+DT318+DT419 -> 0 | DU15: =IFERROR(DV15/DT15*1000000,0) -> 0 | DV15: =DV116+DV217+DV318+DV419 -> 0 | DX15: =DX116+DX217+DX318+DX419 -> 0 | EB15: =EB116+EB217+EB318+EB419 -> 0 | EC15: 0.29428987 | ED15: =ED116+ED217+ED318+ED419 -> 0 | EE15: =IFERROR(+(IF(EB15="","0",EB15))-(IF(ED15="","0",ED15)),"") -> 0 | EG15: 2 | EH15: Ikan di Perairan Umum | EJ15: Ton | EK15: =EK116+EK217+EK318+EK419 -> 0 | EL15: =IFERROR(EM15/EK15*1000000,0) -> 0 | EM15: =EM116+EM217+EM318+EM419 -> 0 | EO15: =EO116+EO217+EO318+EO419 -> 0 | ES15: =ES116+ES217+ES318+ES419 -> 0 | ET15: 0.29428987 | EU15: =EU116+EU217+EU318+EU419 -> 0 | EV15: =IFERROR(+(IF(ES15="","0",ES15))-(IF(EU15="","0",EU15)),"") -> 0 | EX15: 2 | EY15: Ikan di Perairan Umum | FA15: Ton | FB15: =FB116+FB217+FB318+FB419 -> 0 | FC15: =IFERROR(FD15/FB15*1000000,0) -> 0 | FD15: =FD116+FD217+FD318+FD419 -> 0 | FF15: =FF116+FF217+FF318+FF419 -> 0 | FJ15: =FJ116+FJ217+FJ318+FJ419 -> 0 | FK15: 0.29428987 | FL15: =FL116+FL217+FL318+FL419 -> 0 | FM15: =IFERROR(+(IF(FJ15="","0",FJ15))-(IF(FL15="","0",FL15)),"") -> 0 | FO15: 2 | FP15: Ikan di Perairan Umum | FR15: Ton | FS15: =FS116+FS217+FS318+FS419 -> 0 | FT15: =IFERROR(FU15/FS15*1000000,0) -> 0 | FU15: =FU116+FU217+FU318+FU419 -> 0 | FW15: =FW116+FW217+FW318+FW419 -> 0 | GA15: =GA116+GA217+GA318+GA419 -> 0 | GB15: 0.29428987 | GC15: =GC116+GC217+GC318+GC419 -> 0 | GD15: =IFERROR(+(IF(GA15="","0",GA15))-(IF(GC15="","0",GC15)),"") -> 0 | GF15: 2 | GG15: Ikan di Perairan Umum | GI15: Ton | GJ15: =GJ116+GJ217+GJ318+GJ419 -> 0 | GK15: =IFERROR(GL15/GJ15*1000000,0) -> 0 | GL15: =GL116+GL217+GL318+GL419 -> 0 | GN15: =GN116+GN217+GN318+GN419 -> 0 | GR15: =GR116+GR217+GR318+GR419 -> 0 | GS15: 0.29428987 | GT15: =GT116+GT217+GT318+GT419 -> 0 | GU15: =IFERROR(+(IF(GR15="","0",GR15))-(IF(GT15="","0",GT15)),"") -> 0 | GW15: 2 | GX15: Ikan di Perairan Umum | GZ15: Ton | HA15: =HA116+HA217+HA318+HA419 -> 0 | HB15: =IFERROR(HC15/HA15*1000000,0) -> 0 | HC15: =HC116+HC217+HC318+HC419 -> 0 | HE15: =HE116+HE217+HE318+HE419 -> 0 | HI15: =HI116+HI217+HI318+HI419 -> 0 | HJ15: 0.29428987 | HK15: =HK116+HK217+HK318+HK419 -> 0 | HL15: =IFERROR(+(IF(HI15="","0",HI15))-(IF(HK15="","0",HK15)),"") -> 0 | HN15: 2 | HO15: Ikan di Perairan Umum | HQ15: Ton | HR15: =HR116+HR217+HR318+HR419 -> 0 | HS15: =IFERROR(HT15/HR15*1000000,0) -> 0 | HT15: =HT116+HT217+HT318+HT419 -> 0 | HV15: =HV116+HV217+HV318+HV419 -> 0 | HZ15: =HZ116+HZ217+HZ318+HZ419 -> 0 | IA15: 0.29428987 | IB15: =IB116+IB217+IB318+IB419 -> 0 | IC15: =IFERROR(+(IF(HZ15="","0",HZ15))-(IF(IB15="","0",IB15)),"") -> 0 | IE15: 2 | IF15: Ikan di Perairan Umum | IH15: Ton | II15: =II116+II217+II318+II419 -> 0 | IJ15: =IFERROR(IK15/II15*1000000,0) -> 0 | IK15: =IK116+IK217+IK318+IK419 -> 0 | IM15: =IM116+IM217+IM318+IM419 -> 0 | IQ15: =IQ116+IQ217+IQ318+IQ419 -> 0 | IR15: 0.29428987 | IS15: =IS116+IS217+IS318+IS419 -> 0 | IT15: =IFERROR(+(IF(IQ15="","0",IQ15))-(IF(IS15="","0",IS15)),"") -> 0 | IV15: 2 | IW15: Ikan di Perairan Umum | IY15: Ton | IZ15: =IZ116+IZ217+IZ318+IZ419 -> 0 | JA15: =IFERROR(JB15/IZ15*1000000,0) -> 0 | JB15: =JB116+JB217+JB318+JB419 -> 0 | JD15: =JD116+JD217+JD318+JD419 -> 0 | JH15: =JH116+JH217+JH318+JH419 -> 0 | JI15: 0.29428987 | JJ15: =JJ116+JJ217+JJ318+JJ419 -> 0 | JK15: =IFERROR(+(IF(JH15="","0",JH15))-(IF(JJ15="","0",JJ15)),"") -> 0 | JM15: 2 | JN15: Ikan di Perairan Umum | JP15: Ton | JQ15: =JQ116+JQ217+JQ318+JQ419 -> 0 | JR15: =IFERROR(JS15/JQ15*1000000,0) -> 0 | JS15: =JS116+JS217+JS318+JS419 -> 0 | JU15: =JU116+JU217+JU318+JU419 -> 0 | JY15: =JY116+JY217+JY318+JY419 -> 0 | JZ15: 0.29428987 | KA15: =KA116+KA217+KA318+KA419 -> 0 | KB15: =IFERROR(+(IF(JY15="","0",JY15))-(IF(KA15="","0",KA15)),"") -> 0 | KD15: 2 | KE15: Ikan di Perairan Umum | KG15: Ton | KH15: =KH116+KH217+KH318+KH419 -> 0 | KI15: =IFERROR(KJ15/KH15*1000000,0) -> 0 | KJ15: =KJ116+KJ217+KJ318+KJ419 -> 0 | KL15: =KL116+KL217+KL318+KL419 -> 0 | KP15: =KP116+KP217+KP318+KP419 -> 0 | KQ15: 0.29428987 | KR15: =KR116+KR217+KR318+KR419 -> 0 | KS15: =IFERROR(+(IF(KP15="","0",KP15))-(IF(KR15="","0",KR15)),"") -> 0
