Workbook
Name H: #REF!
Name BERLAKU: #REF!
Name BERLAKU: #REF!

Sheet Home
A1: HOME
B2: SISTEM | H2: ALAT BANTU PENGHITUNGAN ANGKA PDRB MENURUT LAPANGAN USAHA
B3: INFORMASI
B4: RILIS
B5: ANGKA PDRB | K5: LAPANGAN USAHA | O5: : | P5: =mid(ADHB!C6,3,100) -> Pertambangan Bijih Logam
B6: MELALUI LEMBAR KERJA | K6: WILAYAH | O6: : | P6: Provinsi Sulawesi Tenggara
B7: BERBASIS | K7: TAHUN | O7: : | P7: =IFERROR(__xludf.DUMMYFUNCTION("IMPORTRANGE(""https://docs.google.com/spreadsheets/d/14EziMEzuXiAhzZqRuQw8kN9sLyynoE6QsPgaj062Fa0/edit#gid=214337323"",""'LK PDRB Lapus'!E3:E4"")"),2026.0) -> 2026
B8: ONLINE | K8: TRIWULAN | O8: : | P8: =IFERROR(__xludf.DUMMYFUNCTION("""COMPUTED_VALUE"""),"I") -> I
B11: INPUT DATA | K11: OUTPUT | T11: MONEV
B15: 1 | C15: Lembar Kerja Penghitungan PDRB Atas Dasar Harga Berlaku | K15: 1 | L15: Rekap Angka PDRB Lapangan Usaha | T15: 1 | U15: MONEV Pemasukan Data
B16: =B15+1 -> 2 | C16: Lembar Kerja Penghitungan PDRB Atas Dasar Harga Konstan | K16: =K15+1 -> 2 | T16: =T15+1 -> 2

Sheet ADHB
A1: Home | B1: 2.3 Pertambangan Bijih Logam | D1: 2010 | E1: 2012 | F1: 2014 | G1: 2016 | H1: 2018 | I1: 2020 | J1: 2022 | K1: 2024 | U1: 2010 | V1: 2012 | W1: 2014 | X1: 2016 | Y1: 2018 | Z1: 2020 | AA1: 2022 | AB1: 2024 | AL1: 2010 | AM1: 2012 | AN1: 2014 | AO1: 2016 | AP1: 2018 | AQ1: 2020 | AR1: 2022 | AS1: 2024 | BC1: 2010 | BD1: 2012 | BE1: 2014 | BF1: 2016 | BG1: 2018 | BH1: 2020 | BI1: 2022 | BJ1: 2024 | BT1: 2010 | BU1: 2012 | BV1: 2014 | BW1: 2016 | BX1: 2018 | BY1: 2020 | BZ1: 2022 | CA1: 2024 | CK1: 2010 | CL1: 2012 | CM1: 2014 | CN1: 2016 | CO1: 2018 | CP1: 2020 | CQ1: 2022 | CR1: 2024 | DB1: 2010 | DC1: 2012 | DD1: 2014 | DE1: 2016 | DF1: 2018 | DG1: 2020 | DH1: 2022 | DI1: 2024 | DS1: 2010 | DT1: 2012 | DU1: 2014 | DV1: 2016 | DW1: 2018 | DX1: 2020 | DY1: 2022 | DZ1: 2024 | EJ1: 2010 | EK1: 2012 | EL1: 2014 | EM1: 2016 | EN1: 2018 | EO1: 2020 | EP1: 2022 | EQ1: 2024 | FA1: 2010 | FB1: 2012 | FC1: 2014 | FD1: 2016 | FE1: 2018 | FF1: 2020 | FG1: 2022 | FH1: 2024 | FR1: 2010 | FS1: 2012 | FT1: 2014 | FU1: 2016 | FV1: 2018 | FW1: 2020 | FX1: 2022 | FY1: 2024 | GI1: 2010 | GJ1: 2012 | GK1: 2014 | GL1: 2016 | GM1: 2018 | GN1: 2020 | GO1: 2022 | GP1: 2024 | GR1: 312703.4 | GZ1: 2010 | HA1: 2012 | HB1: 2014 | HC1: 2016 | HD1: 2018 | HE1: 2020 | HF1: 2022 | HG1: 2024 | HQ1: 2010 | HR1: 2012 | HS1: 2014 | HT1: 2016 | HU1: 2018 | HV1: 2020 | HW1: 2022 | HX1: 2024 | IH1: 2010 | II1: 2012 | IJ1: 2014 | IK1: 2016 | IL1: 2018 | IM1: 2020 | IN1: 2022 | IO1: 2024 | IY1: 2010 | IZ1: 2012 | JA1: 2014 | JB1: 2016 | JC1: 2018 | JD1: 2020 | JE1: 2022 | JF1: 2024 | JP1: 2010 | JQ1: 2012 | JR1: 2014 | JS1: 2016 | JT1: 2018 | JU1: 2020 | JV1: 2022 | JW1: 2024 | KG1: 2010 | KH1: 2012 | KI1: 2014 | KJ1: 2016 | KK1: 2018 | KL1: 2020 | KM1: 2022 | KN1: 2024
D2: 2011 | E2: 2013 | F2: 2015 | G2: 2017 | H2: 2019 | I2: 2021 | J2: 2023 | K2: 2025 | U2: 2011 | V2: 2013 | W2: 2015 | X2: 2017 | Y2: 2019 | Z2: 2021 | AA2: 2023 | AB2: 2025 | AL2: 2011 | AM2: 2013 | AN2: 2015 | AO2: 2017 | AP2: 2019 | AQ2: 2021 | AR2: 2023 | AS2: 2025 | BC2: 2011 | BD2: 2013 | BE2: 2015 | BF2: 2017 | BG2: 2019 | BH2: 2021 | BI2: 2023 | BJ2: 2025 | BT2: 2011 | BU2: 2013 | BV2: 2015 | BW2: 2017 | BX2: 2019 | BY2: 2021 | BZ2: 2023 | CA2: 2025 | CK2: 2011 | CL2: 2013 | CM2: 2015 | CN2: 2017 | CO2: 2019 | CP2: 2021 | CQ2: 2023 | CR2: 2025 | DB2: 2011 | DC2: 2013 | DD2: 2015 | DE2: 2017 | DF2: 2019 | DG2: 2021 | DH2: 2023 | DI2: 2025 | DS2: 2011 | DT2: 2013 | DU2: 2015 | DV2: 2017 | DW2: 2019 | DX2: 2021 | DY2: 2023 | DZ2: 2025 | EJ2: 2011 | EK2: 2013 | EL2: 2015 | EM2: 2017 | EN2: 2019 | EO2: 2021 | EP2: 2023 | EQ2: 2025 | FA2: 2011 | FB2: 2013 | FC2: 2015 | FD2: 2017 | FE2: 2019 | FF2: 2021 | FG2: 2023 | FH2: 2025 | FR2: 2011 | FS2: 2013 | FT2: 2015 | FU2: 2017 | FV2: 2019 | FW2: 2021 | FX2: 2023 | FY2: 2025 | GI2: 2011 | GJ2: 2013 | GK2: 2015 | GL2: 2017 | GM2: 2019 | GN2: 2021 | GO2: 2023 | GP2: 2025 | GZ2: 2011 | HA2: 2013 | HB2: 2015 | HC2: 2017 | HD2: 2019 | HE2: 2021 | HF2: 2023 | HG2: 2025 | HQ2: 2011 | HR2: 2013 | HS2: 2015 | HT2: 2017 | HU2: 2019 | HV2: 2021 | HW2: 2023 | HX2: 2025 | IH2: 2011 | II2: 2013 | IJ2: 2015 | IK2: 2017 | IL2: 2019 | IM2: 2021 | IN2: 2023 | IO2: 2025 | IY2: 2011 | IZ2: 2013 | JA2: 2015 | JB2: 2017 | JC2: 2019 | JD2: 2021 | JE2: 2023 | JF2: 2025 | JP2: 2011 | JQ2: 2013 | JR2: 2015 | JS2: 2017 | JT2: 2019 | JU2: 2021 | JV2: 2023 | JW2: 2025 | KG2: 2011 | KH2: 2013 | KI2: 2015 | KJ2: 2017 | KK2: 2019 | KL2: 2021 | KM2: 2023 | KN2: 2025
B4: Wilayah | C4: =ADHK!C4 -> : Provinsi Sulawesi Tenggara | G4: Lembar Pengolahan Penghitungan | P4: ADHB | S4: Wilayah | T4: =C4 -> : Provinsi Sulawesi Tenggara | X4: Lembar Pengolahan Penghitungan | AG4: ADHB | AJ4: Wilayah | AK4: =T4 -> : Provinsi Sulawesi Tenggara | AO4: Lembar Pengolahan Penghitungan | AX4: ADHB | BA4: Wilayah | BB4: =AK4 -> : Provinsi Sulawesi Tenggara | BF4: Lembar Pengolahan Penghitungan | BO4: ADHB | BR4: Wilayah | BS4: =BB4 -> : Provinsi Sulawesi Tenggara | BW4: Lembar Pengolahan Penghitungan | CF4: ADHB | CI4: Wilayah | CJ4: =BS4 -> : Provinsi Sulawesi Tenggara | CN4: Lembar Pengolahan Penghitungan | CW4: ADHB | CZ4: Wilayah | DA4: =CJ4 -> : Provinsi Sulawesi Tenggara | DE4: Lembar Pengolahan Penghitungan | DN4: ADHB | DQ4: Wilayah | DR4: =DA4 -> : Provinsi Sulawesi Tenggara | DV4: Lembar Pengolahan Penghitungan | EE4: ADHB | EH4: Wilayah | EI4: =DR4 -> : Provinsi Sulawesi Tenggara | EM4: Lembar Pengolahan Penghitungan | EV4: ADHB | EY4: Wilayah | EZ4: =EI4 -> : Provinsi Sulawesi Tenggara | FD4: Lembar Pengolahan Penghitungan | FM4: ADHB | FP4: Wilayah | FQ4: =EZ4 -> : Provinsi Sulawesi Tenggara | FU4: Lembar Pengolahan Penghitungan | GD4: ADHB | GG4: Wilayah | GH4: =FQ4 -> : Provinsi Sulawesi Tenggara | GL4: Lembar Pengolahan Penghitungan | GU4: ADHB | GX4: Wilayah | GY4: =GH4 -> : Provinsi Sulawesi Tenggara | HC4: Lembar Pengolahan Penghitungan | HL4: ADHB | HO4: Wilayah | HP4: =GY4 -> : Provinsi Sulawesi Tenggara | HT4: Lembar Pengolahan Penghitungan | IC4: ADHB | IF4: Wilayah | IG4: =HP4 -> : Provinsi Sulawesi Tenggara | IK4: Lembar Pengolahan Penghitungan | IT4: ADHB | IW4: Wilayah | IX4: =IG4 -> : Provinsi Sulawesi Tenggara | JB4: Lembar Pengolahan Penghitungan | JK4: ADHB | JN4: Wilayah | JO4: =IX4 -> : Provinsi Sulawesi Tenggara | JS4: Lembar Pengolahan Penghitungan | KB4: ADHB | KE4: Wilayah | KF4: =JO4 -> : Provinsi Sulawesi Tenggara | KJ4: Lembar Pengolahan Penghitungan | KS4: ADHB
B5: Kategori | C5: =ADHK!C5 -> : Pertambangan dan Penggalian | G5: Nilai Tambah Bruto | S5: Kategori | T5: =C5 -> : Pertambangan dan Penggalian | X5: Nilai Tambah Bruto | AJ5: Kategori | AK5: =T5 -> : Pertambangan dan Penggalian | AO5: Nilai Tambah Bruto | BA5: Kategori | BB5: =AK5 -> : Pertambangan dan Penggalian | BF5: Nilai Tambah Bruto | BR5: Kategori | BS5: =BB5 -> : Pertambangan dan Penggalian | BW5: Nilai Tambah Bruto | CI5: Kategori | CJ5: =BS5 -> : Pertambangan dan Penggalian | CN5: Nilai Tambah Bruto | CZ5: Kategori | DA5: =CJ5 -> : Pertambangan dan Penggalian | DE5: Nilai Tambah Bruto | DQ5: Kategori | DR5: =DA5 -> : Pertambangan dan Penggalian | DV5: Nilai Tambah Bruto | EH5: Kategori | EI5: =DR5 -> : Pertambangan dan Penggalian | EM5: Nilai Tambah Bruto | EY5: Kategori | EZ5: =EI5 -> : Pertambangan dan Penggalian | FD5: Nilai Tambah Bruto | FP5: Kategori | FQ5: =EZ5 -> : Pertambangan dan Penggalian | FU5: Nilai Tambah Bruto | GG5: Kategori | GH5: =FQ5 -> : Pertambangan dan Penggalian | GL5: Nilai Tambah Bruto | GX5: Kategori | GY5: =GH5 -> : Pertambangan dan Penggalian | HC5: Nilai Tambah Bruto | HO5: Kategori | HP5: =GY5 -> : Pertambangan dan Penggalian | HT5: Nilai Tambah Bruto | IF5: Kategori | IG5: =HP5 -> : Pertambangan dan Penggalian | IK5: Nilai Tambah Bruto | IW5: Kategori | IX5: =IG5 -> : Pertambangan dan Penggalian | JB5: Nilai Tambah Bruto | JN5: Kategori | JO5: =IX5 -> : Pertambangan dan Penggalian | JS5: Nilai Tambah Bruto | KE5: Kategori | KF5: =JO5 -> : Pertambangan dan Penggalian | KJ5: Nilai Tambah Bruto
B6: Subkategori | C6: =ADHK!C6 -> : Pertambangan Bijih Logam | G6: Atas Dasar Harga Berlaku | P6: 2010 | S6: Subkategori | T6: =C6 -> : Pertambangan Bijih Logam | X6: Atas Dasar Harga Berlaku | AG6: =P6+1 -> 2011 | AJ6: Subkategori | AK6: =T6 -> : Pertambangan Bijih Logam | AO6: Atas Dasar Harga Berlaku | AX6: =AG6+1 -> 2012 | BA6: Subkategori | BB6: =AK6 -> : Pertambangan Bijih Logam | BF6: Atas Dasar Harga Berlaku | BO6: =AX6+1 -> 2013 | BR6: Subkategori | BS6: =BB6 -> : Pertambangan Bijih Logam | BW6: Atas Dasar Harga Berlaku | CF6: =BO6+1 -> 2014 | CI6: Subkategori | CJ6: =BS6 -> : Pertambangan Bijih Logam | CN6: Atas Dasar Harga Berlaku | CW6: =CF6+1 -> 2015 | CZ6: Subkategori | DA6: =CJ6 -> : Pertambangan Bijih Logam | DE6: Atas Dasar Harga Berlaku | DN6: =CW6+1 -> 2016 | DQ6: Subkategori | DR6: =DA6 -> : Pertambangan Bijih Logam | DV6: Atas Dasar Harga Berlaku | EE6: =DN6+1 -> 2017 | EH6: Subkategori | EI6: =DR6 -> : Pertambangan Bijih Logam | EM6: Atas Dasar Harga Berlaku | EV6: =EE6+1 -> 2018 | EY6: Subkategori | EZ6: =EI6 -> : Pertambangan Bijih Logam | FD6: Atas Dasar Harga Berlaku | FM6: =EV6+1 -> 2019 | FP6: Subkategori | FQ6: =EZ6 -> : Pertambangan Bijih Logam | FU6: Atas Dasar Harga Berlaku | GD6: =FM6+1 -> 2020 | GG6: Subkategori | GH6: =FQ6 -> : Pertambangan Bijih Logam | GL6: Atas Dasar Harga Berlaku | GU6: =GD6+1 -> 2021 | GX6: Subkategori | GY6: =GH6 -> : Pertambangan Bijih Logam | HC6: Atas Dasar Harga Berlaku | HL6: =GU6+1 -> 2022 | HO6: Subkategori | HP6: =GY6 -> : Pertambangan Bijih Logam | HT6: Atas Dasar Harga Berlaku | IC6: =HL6+1 -> 2023 | IF6: Subkategori | IG6: =HP6 -> : Pertambangan Bijih Logam | IK6: Atas Dasar Harga Berlaku | IT6: =IC6+1 -> 2024 | IW6: Subkategori | IX6: =IG6 -> : Pertambangan Bijih Logam | JB6: Atas Dasar Harga Berlaku | JK6: =IT6+1 -> 2025 | JN6: Subkategori | JO6: =IX6 -> : Pertambangan Bijih Logam | JS6: Atas Dasar Harga Berlaku | KB6: =JK6+1 -> 2026 | KE6: Subkategori | KF6: =JO6 -> : Pertambangan Bijih Logam | KJ6: Atas Dasar Harga Berlaku | KS6: =KB6+1 -> 2027
B7: Jenis Kegiatan | C7: =ADHK!C7 -> : Pertambangan Bijih Logam | G7: ="Tahun "&P$6 -> Tahun 2010 | S7: Jenis Kegiatan | T7: =C7 -> : Pertambangan Bijih Logam | X7: ="Tahun "&AG$6 -> Tahun 2011 | AJ7: Jenis Kegiatan | AK7: =T7 -> : Pertambangan Bijih Logam | AO7: ="Tahun "&AX$6 -> Tahun 2012 | BA7: Jenis Kegiatan | BB7: =AK7 -> : Pertambangan Bijih Logam | BF7: ="Tahun "&BO$6 -> Tahun 2013 | BR7: Jenis Kegiatan | BS7: =BB7 -> : Pertambangan Bijih Logam | BW7: ="Tahun "&CF$6 -> Tahun 2014 | CI7: Jenis Kegiatan | CJ7: =BS7 -> : Pertambangan Bijih Logam | CN7: ="Tahun "&CW$6 -> Tahun 2015 | CZ7: Jenis Kegiatan | DA7: =CJ7 -> : Pertambangan Bijih Logam | DE7: ="Tahun "&DN$6 -> Tahun 2016 | DQ7: Jenis Kegiatan | DR7: =DA7 -> : Pertambangan Bijih Logam | DV7: ="Tahun "&EE$6 -> Tahun 2017 | EH7: Jenis Kegiatan | EI7: =DR7 -> : Pertambangan Bijih Logam | EM7: ="Tahun "&EV$6 -> Tahun 2018 | EY7: Jenis Kegiatan | EZ7: =EI7 -> : Pertambangan Bijih Logam | FD7: ="Tahun "&FM$6 -> Tahun 2019 | FP7: Jenis Kegiatan | FQ7: =EZ7 -> : Pertambangan Bijih Logam | FU7: ="Tahun "&GD$6 -> Tahun 2020 | GG7: Jenis Kegiatan | GH7: =FQ7 -> : Pertambangan Bijih Logam | GL7: ="Tahun "&GU$6 -> Tahun 2021 | GX7: Jenis Kegiatan | GY7: =GH7 -> : Pertambangan Bijih Logam | HC7: ="Tahun "&HL$6 -> Tahun 2022 | HO7: Jenis Kegiatan | HP7: =GY7 -> : Pertambangan Bijih Logam | HT7: ="Tahun "&IC$6 -> Tahun 2023 | IF7: Jenis Kegiatan | IG7: =HP7 -> : Pertambangan Bijih Logam | IK7: ="Tahun "&IT$6 -> Tahun 2024 | IW7: Jenis Kegiatan | IX7: =IG7 -> : Pertambangan Bijih Logam | JB7: ="Tahun "&JK$6 -> Tahun 2025 | JN7: Jenis Kegiatan | JO7: =IX7 -> : Pertambangan Bijih Logam | JS7: ="Tahun "&KB$6 -> Tahun 2026 | KE7: Jenis Kegiatan | KF7: =JO7 -> : Pertambangan Bijih Logam | KJ7: ="Tahun "&KS$6 -> Tahun 2027
B8: Metode Estimasi Output | C8: : Produksi | S8: Metode Estimasi Output | T8: : Produksi | AJ8: Metode Estimasi Output | AK8: : Produksi | BA8: Metode Estimasi Output | BB8: : Produksi | BR8: Metode Estimasi Output | BS8: : Produksi | CI8: Metode Estimasi Output | CJ8: : Produksi | CZ8: Metode Estimasi Output | DA8: : Produksi | DQ8: Metode Estimasi Output | DR8: : Produksi | EH8: Metode Estimasi Output | EI8: : Produksi | EY8: Metode Estimasi Output | EZ8: : Produksi | FP8: Metode Estimasi Output | FQ8: : Produksi | GG8: Metode Estimasi Output | GH8: : Produksi | GX8: Metode Estimasi Output | GY8: : Produksi | HO8: Metode Estimasi Output | HP8: : Produksi | IF8: Metode Estimasi Output | IG8: : Produksi | IW8: Metode Estimasi Output | IX8: : Produksi | JN8: Metode Estimasi Output | JO8: : Produksi | KE8: Metode Estimasi Output | KF8: : Produksi
A10: No. | B10: Subkategori/Jenis Kegiatan/Uraian Komoditi | C10: Output Utama | H10: Jasa Pertambangan, Jasa ahli, teknis & bisnis lainnya | J10: WIP/CBR | M10: Output ADH Produsen (Juta Rp) [(7)+(9)+(12)] | N10: Konsumsi Antara | P10: Nilai Tambah Bruto (Juta Rp) (13)-(15) | R10: No. | S10: Subkategori/Jenis Kegiatan/Uraian Komoditi | T10: Output Utama | Y10: Jasa Pertambangan, Jasa ahli, teknis & bisnis lainnya | AA10: WIP/CBR | AD10: Output ADH Produsen (Juta Rp) [(7)+(9)+(12)] | AE10: Konsumsi Antara | AG10: Nilai Tambah Bruto (Juta Rp) (13)-(15) | AI10: No. | AJ10: Subkategori/Jenis Kegiatan/Uraian Komoditi | AK10: Output Utama | AP10: Jasa Pertambangan, Jasa ahli, teknis & bisnis lainnya | AR10: WIP/CBR | AU10: Output ADH Produsen (Juta Rp) [(7)+(9)+(12)] | AV10: Konsumsi Antara | AX10: Nilai Tambah Bruto (Juta Rp) (13)-(15) | AZ10: No. | BA10: Subkategori/Jenis Kegiatan/Uraian Komoditi | BB10: Output Utama | BG10: Jasa Pertambangan, Jasa ahli, teknis & bisnis lainnya | BI10: WIP/CBR | BL10: Output ADH Produsen (Juta Rp) [(7)+(9)+(12)] | BM10: Konsumsi Antara | BO10: Nilai Tambah Bruto (Juta Rp) (13)-(15) | BQ10: No. | BR10: Subkategori/Jenis Kegiatan/Uraian Komoditi | BS10: Output Utama | BX10: Jasa Pertambangan, Jasa ahli, teknis & bisnis lainnya | BZ10: WIP/CBR | CC10: Output ADH Produsen (Juta Rp) [(7)+(9)+(12)] | CD10: Konsumsi Antara | CF10: Nilai Tambah Bruto (Juta Rp) (13)-(15) | CH10: No. | CI10: Subkategori/Jenis Kegiatan/Uraian Komoditi | CJ10: Output Utama | CO10: Jasa Pertambangan, Jasa ahli, teknis & bisnis lainnya | CQ10: WIP/CBR | CT10: Output ADH Produsen (Juta Rp) [(7)+(9)+(12)] | CU10: Konsumsi Antara | CW10: Nilai Tambah Bruto (Juta Rp) (13)-(15) | CY10: No. | CZ10: Subkategori/Jenis Kegiatan/Uraian Komoditi | DA10: Output Utama | DF10: Jasa Pertambangan, Jasa ahli, teknis & bisnis lainnya | DH10: WIP/CBR | DK10: Output ADH Produsen (Juta Rp) [(7)+(9)+(12)] | DL10: Konsumsi Antara | DN10: Nilai Tambah Bruto (Juta Rp) (13)-(15) | DP10: No. | DQ10: Subkategori/Jenis Kegiatan/Uraian Komoditi | DR10: Output Utama | DW10: Jasa Pertambangan, Jasa ahli, teknis & bisnis lainnya | DY10: WIP/CBR | EB10: Output ADH Produsen (Juta Rp) [(7)+(9)+(12)] | EC10: Konsumsi Antara | EE10: Nilai Tambah Bruto (Juta Rp) (13)-(15) | EG10: No. | EH10: Subkategori/Jenis Kegiatan/Uraian Komoditi | EI10: Output Utama | EN10: Jasa Pertambangan, Jasa ahli, teknis & bisnis lainnya | EP10: WIP/CBR | ES10: Output ADH Produsen (Juta Rp) [(7)+(9)+(12)] | ET10: Konsumsi Antara | EV10: Nilai Tambah Bruto (Juta Rp) (13)-(15) | EX10: No. | EY10: Subkategori/Jenis Kegiatan/Uraian Komoditi | EZ10: Output Utama | FE10: Jasa Pertambangan, Jasa ahli, teknis & bisnis lainnya | FG10: WIP/CBR | FJ10: Output ADH Produsen (Juta Rp) [(7)+(9)+(12)] | FK10: Konsumsi Antara | FM10: Nilai Tambah Bruto (Juta Rp) (13)-(15) | FO10: No. | FP10: Subkategori/Jenis Kegiatan/Uraian Komoditi | FQ10: Output Utama | FV10: Jasa Pertambangan, Jasa ahli, teknis & bisnis lainnya | FX10: WIP/CBR | GA10: Output ADH Produsen (Juta Rp) [(7)+(9)+(12)] | GB10: Konsumsi Antara | GD10: Nilai Tambah Bruto (Juta Rp) (13)-(15) | GF10: No. | GG10: Subkategori/Jenis Kegiatan/Uraian Komoditi | GH10: Output Utama | GM10: Jasa Pertambangan, Jasa ahli, teknis & bisnis lainnya | GO10: WIP/CBR | GR10: Output ADH Produsen (Juta Rp) [(7)+(9)+(12)] | GS10: Konsumsi Antara | GU10: Nilai Tambah Bruto (Juta Rp) (13)-(15) | GW10: No. | GX10: Subkategori/Jenis Kegiatan/Uraian Komoditi | GY10: Output Utama | HD10: Jasa Pertambangan, Jasa ahli, teknis & bisnis lainnya | HF10: WIP/CBR | HI10: Output ADH Produsen (Juta Rp) [(7)+(9)+(12)] | HJ10: Konsumsi Antara | HL10: Nilai Tambah Bruto (Juta Rp) (13)-(15) | HN10: No. | HO10: Subkategori/Jenis Kegiatan/Uraian Komoditi | HP10: Output Utama | HU10: Jasa Pertambangan, Jasa ahli, teknis & bisnis lainnya | HW10: WIP/CBR | HZ10: Output ADH Produsen (Juta Rp) [(7)+(9)+(12)] | IA10: Konsumsi Antara | IC10: Nilai Tambah Bruto (Juta Rp) (13)-(15) | IE10: No. | IF10: Subkategori/Jenis Kegiatan/Uraian Komoditi | IG10: Output Utama | IL10: Jasa Pertambangan, Jasa ahli, teknis & bisnis lainnya | IN10: WIP/CBR | IQ10: Output ADH Produsen (Juta Rp) [(7)+(9)+(12)] | IR10: Konsumsi Antara | IT10: Nilai Tambah Bruto (Juta Rp) (13)-(15) | IV10: No. | IW10: Subkategori/Jenis Kegiatan/Uraian Komoditi | IX10: Output Utama | JC10: Jasa Pertambangan, Jasa ahli, teknis & bisnis lainnya | JE10: WIP/CBR | JH10: Output ADH Produsen (Juta Rp) [(7)+(9)+(12)] | JI10: Konsumsi Antara | JK10: Nilai Tambah Bruto (Juta Rp) (13)-(15) | JM10: No. | JN10: Subkategori/Jenis Kegiatan/Uraian Komoditi | JO10: Output Utama | JT10: Jasa Pertambangan, Jasa ahli, teknis & bisnis lainnya | JV10: WIP/CBR | JY10: Output ADH Produsen (Juta Rp) [(7)+(9)+(12)] | JZ10: Konsumsi Antara | KB10: Nilai Tambah Bruto (Juta Rp) (13)-(15) | KD10: No. | KE10: Subkategori/Jenis Kegiatan/Uraian Komoditi | KF10: Output Utama | KK10: Jasa Pertambangan, Jasa ahli, teknis & bisnis lainnya | KM10: WIP/CBR | KP10: Output ADH Produsen (Juta Rp) [(7)+(9)+(12)] | KQ10: Konsumsi Antara | KS10: Nilai Tambah Bruto (Juta Rp) (13)-(15)
C11: Wujud/ Kegiatan | D11: Satuan/ Unit | E11: Kuantum | F11: Harga Produsen tahun berjalan (Rp/Unit) | G11: Nilai (Juta Rp) (5)x(6) | H11: Rasio tahun berjalan | I11: Nilai (Juta Rp) (8)x(7) | J11: ="Total Biaya Perawatan "&G7&" (Juta Rp)" -> Total Biaya Perawatan Tahun 2010 (Juta Rp) | K11: ="Total Biaya Perawatan Tahun "&P6-1&" (Juta Rp)" -> Total Biaya Perawatan Tahun 2009 (Juta Rp) | L11: Nilai (Juta Rp) (10) - (11) | N11: Rasio tahun berjalan | O11: Nilai (Juta Rp) ((13)-(12))x(14) | T11: Wujud/ Kegiatan | U11: Satuan/ Unit | V11: Kuantum | W11: Harga Produsen tahun berjalan (Rp/Unit) | X11: Nilai (Juta Rp) (5)x(6) | Y11: Rasio tahun berjalan | Z11: Nilai (Juta Rp) (8)x(7) | AA11: ="Total Biaya Perawatan "&X7&" (Juta Rp)" -> Total Biaya Perawatan Tahun 2011 (Juta Rp) | AB11: ="Total Biaya Perawatan Tahun "&AG6-1&" (Juta Rp)" -> Total Biaya Perawatan Tahun 2010 (Juta Rp) | AC11: Nilai (Juta Rp) (10) - (11) | AE11: Rasio tahun berjalan | AF11: Nilai (Juta Rp) ((13)-(12))x(14) | AK11: Wujud/ Kegiatan | AL11: Satuan/ Unit | AM11: Kuantum | AN11: Harga Produsen tahun berjalan (Rp/Unit) | AO11: Nilai (Juta Rp) (5)x(6) | AP11: Rasio tahun berjalan | AQ11: Nilai (Juta Rp) (8)x(7) | AR11: ="Total Biaya Perawatan "&AO7&" (Juta Rp)" -> Total Biaya Perawatan Tahun 2012 (Juta Rp) | AS11: ="Total Biaya Perawatan Tahun "&AX6-1&" (Juta Rp)" -> Total Biaya Perawatan Tahun 2011 (Juta Rp) | AT11: Nilai (Juta Rp) (10) - (11) | AV11: Rasio tahun berjalan | AW11: Nilai (Juta Rp) ((13)-(12))x(14) | BB11: Wujud/ Kegiatan | BC11: Satuan/ Unit | BD11: Kuantum | BE11: Harga Produsen tahun berjalan (Rp/Unit) | BF11: Nilai (Juta Rp) (5)x(6) | BG11: Rasio tahun berjalan | BH11: Nilai (Juta Rp) (8)x(7) | BI11: ="Total Biaya Perawatan "&BF7&" (Juta Rp)" -> Total Biaya Perawatan Tahun 2013 (Juta Rp) | BJ11: ="Total Biaya Perawatan Tahun "&BO6-1&" (Juta Rp)" -> Total Biaya Perawatan Tahun 2012 (Juta Rp) | BK11: Nilai (Juta Rp) (10) - (11) | BM11: Rasio tahun berjalan | BN11: Nilai (Juta Rp) ((13)-(12))x(14) | BS11: Wujud/ Kegiatan | BT11: Satuan/ Unit | BU11: Kuantum | BV11: Harga Produsen tahun berjalan (Rp/Unit) | BW11: Nilai (Juta Rp) (5)x(6) | BX11: Rasio tahun berjalan | BY11: Nilai (Juta Rp) (8)x(7) | BZ11: ="Total Biaya Perawatan "&BW7&" (Juta Rp)" -> Total Biaya Perawatan Tahun 2014 (Juta Rp) | CA11: ="Total Biaya Perawatan Tahun "&CF6-1&" (Juta Rp)" -> Total Biaya Perawatan Tahun 2013 (Juta Rp) | CB11: Nilai (Juta Rp) (10) - (11) | CD11: Rasio tahun berjalan | CE11: Nilai (Juta Rp) ((13)-(12))x(14) | CJ11: Wujud/ Kegiatan | CK11: Satuan/ Unit | CL11: Kuantum | CM11: Harga Produsen tahun berjalan (Rp/Unit) | CN11: Nilai (Juta Rp) (5)x(6) | CO11: Rasio tahun berjalan | CP11: Nilai (Juta Rp) (8)x(7) | CQ11: ="Total Biaya Perawatan "&CN7&" (Juta Rp)" -> Total Biaya Perawatan Tahun 2015 (Juta Rp) | CR11: ="Total Biaya Perawatan Tahun "&CW6-1&" (Juta Rp)" -> Total Biaya Perawatan Tahun 2014 (Juta Rp) | CS11: Nilai (Juta Rp) (10) - (11) | CU11: Rasio tahun berjalan | CV11: Nilai (Juta Rp) ((13)-(12))x(14) | DA11: Wujud/ Kegiatan | DB11: Satuan/ Unit | DC11: Kuantum | DD11: Harga Produsen tahun berjalan (Rp/Unit) | DE11: Nilai (Juta Rp) (5)x(6) | DF11: Rasio tahun berjalan | DG11: Nilai (Juta Rp) (8)x(7) | DH11: ="Total Biaya Perawatan "&DE7&" (Juta Rp)" -> Total Biaya Perawatan Tahun 2016 (Juta Rp) | DI11: ="Total Biaya Perawatan Tahun "&DN6-1&" (Juta Rp)" -> Total Biaya Perawatan Tahun 2015 (Juta Rp) | DJ11: Nilai (Juta Rp) (10) - (11) | DL11: Rasio tahun berjalan | DM11: Nilai (Juta Rp) ((13)-(12))x(14) | DR11: Wujud/ Kegiatan | DS11: Satuan/ Unit | DT11: Kuantum | DU11: Harga Produsen tahun berjalan (Rp/Unit) | DV11: Nilai (Juta Rp) (5)x(6) | DW11: Rasio tahun berjalan | DX11: Nilai (Juta Rp) (8)x(7) | DY11: ="Total Biaya Perawatan "&DV7&" (Juta Rp)" -> Total Biaya Perawatan Tahun 2017 (Juta Rp) | DZ11: ="Total Biaya Perawatan Tahun "&EE6-1&" (Juta Rp)" -> Total Biaya Perawatan Tahun 2016 (Juta Rp) | EA11: Nilai (Juta Rp) (10) - (11) | EC11: Rasio tahun berjalan | ED11: Nilai (Juta Rp) ((13)-(12))x(14) | EI11: Wujud/ Kegiatan | EJ11: Satuan/ Unit | EK11: Kuantum | EL11: Harga Produsen tahun berjalan (Rp/Unit) | EM11: Nilai (Juta Rp) (5)x(6) | EN11: Rasio tahun berjalan | EO11: Nilai (Juta Rp) (8)x(7) | EP11: ="Total Biaya Perawatan "&EM7&" (Juta Rp)" -> Total Biaya Perawatan Tahun 2018 (Juta Rp) | EQ11: ="Total Biaya Perawatan Tahun "&EV6-1&" (Juta Rp)" -> Total Biaya Perawatan Tahun 2017 (Juta Rp) | ER11: Nilai (Juta Rp) (10) - (11) | ET11: Rasio tahun berjalan | EU11: Nilai (Juta Rp) ((13)-(12))x(14) | EZ11: Wujud/ Kegiatan | FA11: Satuan/ Unit | FB11: Kuantum | FC11: Harga Produsen tahun berjalan (Rp/Unit) | FD11: Nilai (Juta Rp) (5)x(6) | FE11: Rasio tahun berjalan | FF11: Nilai (Juta Rp) (8)x(7) | FG11: ="Total Biaya Perawatan "&FD7&" (Juta Rp)" -> Total Biaya Perawatan Tahun 2019 (Juta Rp) | FH11: ="Total Biaya Perawatan Tahun "&FM6-1&" (Juta Rp)" -> Total Biaya Perawatan Tahun 2018 (Juta Rp) | FI11: Nilai (Juta Rp) (10) - (11) | FK11: Rasio tahun berjalan | FL11: Nilai (Juta Rp) ((13)-(12))x(14) | FQ11: Wujud/ Kegiatan | FR11: Satuan/ Unit | FS11: Kuantum | FT11: Harga Produsen tahun berjalan (Rp/Unit) | FU11: Nilai (Juta Rp) (5)x(6) | FV11: Rasio tahun berjalan | FW11: Nilai (Juta Rp) (8)x(7) | FX11: ="Total Biaya Perawatan "&FU7&" (Juta Rp)" -> Total Biaya Perawatan Tahun 2020 (Juta Rp) | FY11: ="Total Biaya Perawatan Tahun "&GD6-1&" (Juta Rp)" -> Total Biaya Perawatan Tahun 2019 (Juta Rp) | FZ11: Nilai (Juta Rp) (10) - (11) | GB11: Rasio tahun berjalan | GC11: Nilai (Juta Rp) ((13)-(12))x(14) | GH11: Wujud/ Kegiatan | GI11: Satuan/ Unit | GJ11: Kuantum | GK11: Harga Produsen tahun berjalan (Rp/Unit) | GL11: Nilai (Juta Rp) (5)x(6) | GM11: Rasio tahun berjalan | GN11: Nilai (Juta Rp) (8)x(7) | GO11: ="Total Biaya Perawatan "&GL7&" (Juta Rp)" -> Total Biaya Perawatan Tahun 2021 (Juta Rp) | GP11: ="Total Biaya Perawatan Tahun "&GU6-1&" (Juta Rp)" -> Total Biaya Perawatan Tahun 2020 (Juta Rp) | GQ11: Nilai (Juta Rp) (10) - (11) | GS11: Rasio tahun berjalan | GT11: Nilai (Juta Rp) ((13)-(12))x(14) | GY11: Wujud/ Kegiatan | GZ11: Satuan/ Unit | HA11: Kuantum | HB11: Harga Produsen tahun berjalan (Rp/Unit) | HC11: Nilai (Juta Rp) (5)x(6) | HD11: Rasio tahun berjalan | HE11: Nilai (Juta Rp) (8)x(7) | HF11: ="Total Biaya Perawatan "&HC7&" (Juta Rp)" -> Total Biaya Perawatan Tahun 2022 (Juta Rp) | HG11: ="Total Biaya Perawatan Tahun "&HL6-1&" (Juta Rp)" -> Total Biaya Perawatan Tahun 2021 (Juta Rp) | HH11: Nilai (Juta Rp) (10) - (11) | HJ11: Rasio tahun berjalan | HK11: Nilai (Juta Rp) ((13)-(12))x(14) | HP11: Wujud/ Kegiatan | HQ11: Satuan/ Unit | HR11: Kuantum | HS11: Harga Produsen tahun berjalan (Rp/Unit) | HT11: Nilai (Juta Rp) (5)x(6) | HU11: Rasio tahun berjalan | HV11: Nilai (Juta Rp) (8)x(7) | HW11: ="Total Biaya Perawatan "&HT7&" (Juta Rp)" -> Total Biaya Perawatan Tahun 2023 (Juta Rp) | HX11: ="Total Biaya Perawatan Tahun "&IC6-1&" (Juta Rp)" -> Total Biaya Perawatan Tahun 2022 (Juta Rp) | HY11: Nilai (Juta Rp) (10) - (11) | IA11: Rasio tahun berjalan | IB11: Nilai (Juta Rp) ((13)-(12))x(14) | IG11: Wujud/ Kegiatan | IH11: Satuan/ Unit | II11: Kuantum | IJ11: Harga Produsen tahun berjalan (Rp/Unit) | IK11: Nilai (Juta Rp) (5)x(6) | IL11: Rasio tahun berjalan | IM11: Nilai (Juta Rp) (8)x(7) | IN11: ="Total Biaya Perawatan "&IK7&" (Juta Rp)" -> Total Biaya Perawatan Tahun 2024 (Juta Rp) | IO11: ="Total Biaya Perawatan Tahun "&IT6-1&" (Juta Rp)" -> Total Biaya Perawatan Tahun 2023 (Juta Rp) | IP11: Nilai (Juta Rp) (10) - (11) | IR11: Rasio tahun berjalan | IS11: Nilai (Juta Rp) ((13)-(12))x(14) | IX11: Wujud/ Kegiatan | IY11: Satuan/ Unit | IZ11: Kuantum | JA11: Harga Produsen tahun berjalan (Rp/Unit) | JB11: Nilai (Juta Rp) (5)x(6) | JC11: Rasio tahun berjalan | JD11: Nilai (Juta Rp) (8)x(7) | JE11: ="Total Biaya Perawatan "&JB7&" (Juta Rp)" -> Total Biaya Perawatan Tahun 2025 (Juta Rp) | JF11: ="Total Biaya Perawatan Tahun "&JK6-1&" (Juta Rp)" -> Total Biaya Perawatan Tahun 2024 (Juta Rp) | JG11: Nilai (Juta Rp) (10) - (11) | JI11: Rasio tahun berjalan | JJ11: Nilai (Juta Rp) ((13)-(12))x(14) | JO11: Wujud/ Kegiatan | JP11: Satuan/ Unit | JQ11: Kuantum | JR11: Harga Produsen tahun berjalan (Rp/Unit) | JS11: Nilai (Juta Rp) (5)x(6) | JT11: Rasio tahun berjalan | JU11: Nilai (Juta Rp) (8)x(7) | JV11: ="Total Biaya Perawatan "&JS7&" (Juta Rp)" -> Total Biaya Perawatan Tahun 2026 (Juta Rp) | JW11: ="Total Biaya Perawatan Tahun "&KB6-1&" (Juta Rp)" -> Total Biaya Perawatan Tahun 2025 (Juta Rp) | JX11: Nilai (Juta Rp) (10) - (11) | JZ11: Rasio tahun berjalan | KA11: Nilai (Juta Rp) ((13)-(12))x(14) | KF11: Wujud/ Kegiatan | KG11: Satuan/ Unit | KH11: Kuantum | KI11: Harga Produsen tahun berjalan (Rp/Unit) | KJ11: Nilai (Juta Rp) (5)x(6) | KK11: Rasio tahun berjalan | KL11: Nilai (Juta Rp) (8)x(7) | KM11: ="Total Biaya Perawatan "&KJ7&" (Juta Rp)" -> Total Biaya Perawatan Tahun 2027 (Juta Rp) | KN11: ="Total Biaya Perawatan Tahun "&KS6-1&" (Juta Rp)" -> Total Biaya Perawatan Tahun 2026 (Juta Rp) | KO11: Nilai (Juta Rp) (10) - (11) | KQ11: Rasio tahun berjalan | KR11: Nilai (Juta Rp) ((13)-(12))x(14)
A12: -1 | B12: -2 | C12: -3 | D12: -4 | E12: -5 | F12: -6 | G12: -7 | H12: -8 | I12: -9 | J12: -10 | K12: -11 | L12: -12 | M12: -13 | N12: -14 | O12: -15 | P12: -16 | R12: -1 | S12: -2 | T12: -3 | U12: -4 | V12: -5 | W12: -6 | X12: -7 | Y12: -8 | Z12: -9 | AA12: -10 | AB12: -11 | AC12: -12 | AD12: -13 | AE12: -14 | AF12: -15 | AG12: -16 | AI12: -1 | AJ12: -2 | AK12: -3 | AL12: -4 | AM12: -5 | AN12: -6 | AO12: -7 | AP12: -8 | AQ12: -9 | AR12: -10 | AS12: -11 | AT12: -12 | AU12: -13 | AV12: -14 | AW12: -15 | AX12: -16 | AZ12: -1 | BA12: -2 | BB12: -3 | BC12: -4 | BD12: -5 | BE12: -6 | BF12: -7 | BG12: -8 | BH12: -9 | BI12: -10 | BJ12: -11 | BK12: -12 | BL12: -13 | BM12: -14 | BN12: -15 | BO12: -16 | BQ12: -1 | BR12: -2 | BS12: -3 | BT12: -4 | BU12: -5 | BV12: -6 | BW12: -7 | BX12: -8 | BY12: -9 | BZ12: -10 | CA12: -11 | CB12: -12 | CC12: -13 | CD12: -14 | CE12: -15 | CF12: -16 | CH12: -1 | CI12: -2 | CJ12: -3 | CK12: -4 | CL12: -5 | CM12: -6 | CN12: -7 | CO12: -8 | CP12: -9 | CQ12: -10 | CR12: -11 | CS12: -12 | CT12: -13 | CU12: -14 | CV12: -15 | CW12: -16 | CY12: -1 | CZ12: -2 | DA12: -3 | DB12: -4 | DC12: -5 | DD12: -6 | DE12: -7 | DF12: -8 | DG12: -9 | DH12: -10 | DI12: -11 | DJ12: -12 | DK12: -13 | DL12: -14 | DM12: -15 | DN12: -16 | DP12: -1 | DQ12: -2 | DR12: -3 | DS12: -4 | DT12: -5 | DU12: -6 | DV12: -7 | DW12: -8 | DX12: -9 | DY12: -10 | DZ12: -11 | EA12: -12 | EB12: -13 | EC12: -14 | ED12: -15 | EE12: -16 | EG12: -1 | EH12: -2 | EI12: -3 | EJ12: -4 | EK12: -5 | EL12: -6 | EM12: -7 | EN12: -8 | EO12: -9 | EP12: -10 | EQ12: -11 | ER12: -12 | ES12: -13 | ET12: -14 | EU12: -15 | EV12: -16 | EX12: -1 | EY12: -2 | EZ12: -3 | FA12: -4 | FB12: -5 | FC12: -6 | FD12: -7 | FE12: -8 | FF12: -9 | FG12: -10 | FH12: -11 | FI12: -12 | FJ12: -13 | FK12: -14 | FL12: -15 | FM12: -16 | FO12: -1 | FP12: -2 | FQ12: -3 | FR12: -4 | FS12: -5 | FT12: -6 | FU12: -7 | FV12: -8 | FW12: -9 | FX12: -10 | FY12: -11 | FZ12: -12 | GA12: -13 | GB12: -14 | GC12: -15 | GD12: -16 | GF12: -1 | GG12: -2 | GH12: -3 | GI12: -4 | GJ12: -5 | GK12: -6 | GL12: -7 | GM12: -8 | GN12: -9 | GO12: -10 | GP12: -11 | GQ12: -12 | GR12: -13 | GS12: -14 | GT12: -15 | GU12: -16 | GW12: -1 | GX12: -2 | GY12: -3 | GZ12: -4 | HA12: -5 | HB12: -6 | HC12: -7 | HD12: -8 | HE12: -9 | HF12: -10 | HG12: -11 | HH12: -12 | HI12: -13 | HJ12: -14 | HK12: -15 | HL12: -16 | HN12: -1 | HO12: -2 | HP12: -3 | HQ12: -4 | HR12: -5 | HS12: -6 | HT12: -7 | HU12: -8 | HV12: -9 | HW12: -10 | HX12: -11 | HY12: -12 | HZ12: -13 | IA12: -14 | IB12: -15 | IC12: -16 | IE12: -1 | IF12: -2 | IG12: -3 | IH12: -4 | II12: -5 | IJ12: -6 | IK12: -7 | IL12: -8 | IM12: -9 | IN12: -10 | IO12: -11 | IP12: -12 | IQ12: -13 | IR12: -14 | IS12: -15 | IT12: -16 | IV12: -1 | IW12: -2 | IX12: -3 | IY12: -4 | IZ12: -5 | JA12: -6 | JB12: -7 | JC12: -8 | JD12: -9 | JE12: -10 | JF12: -11 | JG12: -12 | JH12: -13 | JI12: -14 | JJ12: -15 | JK12: -16 | JM12: -1 | JN12: -2 | JO12: -3 | JP12: -4 | JQ12: -5 | JR12: -6 | JS12: -7 | JT12: -8 | JU12: -9 | JV12: -10 | JW12: -11 | JX12: -12 | JY12: -13 | JZ12: -14 | KA12: -15 | KB12: -16 | KD12: -1 | KE12: -2 | KF12: -3 | KG12: -4 | KH12: -5 | KI12: -6 | KJ12: -7 | KK12: -8 | KL12: -9 | KM12: -10 | KN12: -11 | KO12: -12 | KP12: -13 | KQ12: -14 | KR12: -15 | KS12: -16
A13: 1 | B13: =IFERROR(VLOOKUP($R13,ADHK!$A$13:$D$30,-B$12,FALSE),"") -> Bijih Emas | C13: =IFERROR(VLOOKUP($R13,ADHK!$A$13:$D$30,-C$12,FALSE),"") -> Bijih | D13: =IFERROR(VLOOKUP($R13,ADHK!$A$13:$D$30,-D$12,FALSE),"") -> Kg | E13: =E49+E85+E121+E157 -> 0 | F13: =G13/E13*1000000 -> #DIV/0! | G13: =G49+G85+G121+G157 -> 0 | I13: =IFERROR(+G13*H13,"") -> 0 | M13: =IFERROR(+(IF(G13="","0",G13))+(IF(I13="","0",I13))+(IF(L13="","0",L13)),"") -> 0 | N13: =ADHK!N13 -> 0.46044713 | O13: =IFERROR(+N13*(M13-L13),"") -> 0 | P13: =IFERROR(+(IF(M13="","0",M13))-(IF(O13="","0",O13)),"") -> 0 | R13: 1 | S13: =IFERROR(VLOOKUP($R13,$A$13:$D$30,-S$12,FALSE),"") -> Bijih Emas | T13: =IFERROR(VLOOKUP($R13,$A$13:$D$30,-T$12,FALSE),"") -> Bijih | U13: =IFERROR(VLOOKUP($R13,$A$13:$D$30,-U$12,FALSE),"") -> Kg | V13: =V49+V85+V121+V157 -> 0 | W13: =X13/V13*1000000 -> #DIV/0! | X13: =X49+X85+X121+X157 -> 0 | Z13: =IFERROR(+X13*Y13,"") -> 0 | AD13: =IFERROR(+(IF(X13="","0",X13))+(IF(Z13="","0",Z13))+(IF(AC13="","0",AC13)),"") -> 0 | AE13: =N13 -> 0.46044713 | AF13: =IFERROR(+AE13*(AD13-AC13),"") -> 0 | AG13: =IFERROR(+(IF(AD13="","0",AD13))-(IF(AF13="","0",AF13)),"") -> 0 | AI13: 1 | AJ13: =IFERROR(VLOOKUP($R13,$A$13:$D$30,-AJ$12,FALSE),"") -> Bijih Emas | AK13: =IFERROR(VLOOKUP($R13,$A$13:$D$30,-AK$12,FALSE),"") -> Bijih | AL13: =IFERROR(VLOOKUP($R13,$A$13:$D$30,-AL$12,FALSE),"") -> Kg | AM13: =AM49+AM85+AM121+AM157 -> 0 | AN13: =AO13/AM13*1000000 -> #DIV/0! | AO13: =AO49+AO85+AO121+AO157 -> 0 | AQ13: =IFERROR(+AO13*AP13,"") -> 0 | AU13: =IFERROR(+(IF(AO13="","0",AO13))+(IF(AQ13="","0",AQ13))+(IF(AT13="","0",AT13)),"") -> 0 | AV13: =AE13 -> 0.46044713 | AW13: =IFERROR(+AV13*(AU13-AT13),"") -> 0 | AX13: =IFERROR(+(IF(AU13="","0",AU13))-(IF(AW13="","0",AW13)),"") -> 0 | AZ13: 1 | BA13: =IFERROR(VLOOKUP($R13,$A$13:$D$30,-BA$12,FALSE),"") -> Bijih Emas | BB13: =IFERROR(VLOOKUP($R13,$A$13:$D$30,-BB$12,FALSE),"") -> Bijih | BC13: =IFERROR(VLOOKUP($R13,$A$13:$D$30,-BC$12,FALSE),"") -> Kg | BD13: =BD49+BD85+BD121+BD157 -> 0 | BE13: =BF13/BD13*1000000 -> #DIV/0! | BF13: =BF49+BF85+BF121+BF157 -> 0 | BH13: =IFERROR(+BF13*BG13,"") -> 0 | BL13: =IFERROR(+(IF(BF13="","0",BF13))+(IF(BH13="","0",BH13))+(IF(BK13="","0",BK13)),"") -> 0 | BM13: =AV13 -> 0.46044713 | BN13: =IFERROR(+BM13*(BL13-BK13),"") -> 0 | BO13: =IFERROR(+(IF(BL13="","0",BL13))-(IF(BN13="","0",BN13)),"") -> 0 | BQ13: 1 | BR13: =IFERROR(VLOOKUP($R13,$A$13:$D$30,-BR$12,FALSE),"") -> Bijih Emas | BS13: =IFERROR(VLOOKUP($R13,$A$13:$D$30,-BS$12,FALSE),"") -> Bijih | BT13: =IFERROR(VLOOKUP($R13,$A$13:$D$30,-BT$12,FALSE),"") -> Kg | BU13: =BU49+BU85+BU121+BU157 -> 0 | BV13: =BW13/BU13*1000000 -> #DIV/0! | BW13: =BW49+BW85+BW121+BW157 -> 0 | BY13: =IFERROR(+BW13*BX13,"") -> 0 | CC13: =IFERROR(+(IF(BW13="","0",BW13))+(IF(BY13="","0",BY13))+(IF(CB13="","0",CB13)),"") -> 0 | CD13: =BM13 -> 0.46044713 | CE13: =IFERROR(+CD13*(CC13-CB13),"") -> 0 | CF13: =IFERROR(+(IF(CC13="","0",CC13))-(IF(CE13="","0",CE13)),"") -> 0 | CH13: 1 | CI13: =IFERROR(VLOOKUP($R13,$A$13:$D$30,-CI$12,FALSE),"") -> Bijih Emas | CJ13: =IFERROR(VLOOKUP($R13,$A$13:$D$30,-CJ$12,FALSE),"") -> Bijih | CK13: =IFERROR(VLOOKUP($R13,$A$13:$D$30,-CK$12,FALSE),"") -> Kg | CL13: =CL49+CL85+CL121+CL157 -> 0 | CM13: =CN13/CL13*1000000 -> #DIV/0! | CN13: =CN49+CN85+CN121+CN157 -> 0 | CP13: =IFERROR(+CN13*CO13,"") -> 0 | CT13: =IFERROR(+(IF(CN13="","0",CN13))+(IF(CP13="","0",CP13))+(IF(CS13="","0",CS13)),"") -> 0 | CU13: =CD13 -> 0.46044713 | CV13: =IFERROR(+CU13*(CT13-CS13),"") -> 0 | CW13: =IFERROR(+(IF(CT13="","0",CT13))-(IF(CV13="","0",CV13)),"") -> 0 | CY13: 1 | CZ13: =IFERROR(VLOOKUP($R13,$A$13:$D$30,-CZ$12,FALSE),"") -> Bijih Emas | DA13: =IFERROR(VLOOKUP($R13,$A$13:$D$30,-DA$12,FALSE),"") -> Bijih | DB13: =IFERROR(VLOOKUP($R13,$A$13:$D$30,-DB$12,FALSE),"") -> Kg | DC13: =DC49+DC85+DC121+DC157 -> 0 | DD13: =DE13/DC13*1000000 -> #DIV/0! | DE13: =DE49+DE85+DE121+DE157 -> 0 | DG13: =IFERROR(+DE13*DF13,"") -> 0 | DK13: =IFERROR(+(IF(DE13="","0",DE13))+(IF(DG13="","0",DG13))+(IF(DJ13="","0",DJ13)),"") -> 0 | DL13: =CU13 -> 0.46044713 | DM13: =IFERROR(+DL13*(DK13-DJ13),"") -> 0 | DN13: =IFERROR(+(IF(DK13="","0",DK13))-(IF(DM13="","0",DM13)),"") -> 0 | DP13: 1 | DQ13: =IFERROR(VLOOKUP($R13,$A$13:$D$30,-DQ$12,FALSE),"") -> Bijih Emas | DR13: =IFERROR(VLOOKUP($R13,$A$13:$D$30,-DR$12,FALSE),"") -> Bijih | DS13: =IFERROR(VLOOKUP($R13,$A$13:$D$30,-DS$12,FALSE),"") -> Kg | DT13: =DT49+DT85+DT121+DT157 -> 0 | DU13: =DV13/DT13*1000000 -> #DIV/0! | DV13: =DV49+DV85+DV121+DV157 -> 0 | DX13: =IFERROR(+DV13*DW13,"") -> 0 | EB13: =IFERROR(+(IF(DV13="","0",DV13))+(IF(DX13="","0",DX13))+(IF(EA13="","0",EA13)),"") -> 0 | EC13: =DL13 -> 0.46044713 | ED13: =IFERROR(+EC13*(EB13-EA13),"") -> 0 | EE13: =IFERROR(+(IF(EB13="","0",EB13))-(IF(ED13="","0",ED13)),"") -> 0 | EG13: 1 | EH13: =IFERROR(VLOOKUP($R13,$A$13:$D$30,-EH$12,FALSE),"") -> Bijih Emas | EI13: =IFERROR(VLOOKUP($R13,$A$13:$D$30,-EI$12,FALSE),"") -> Bijih | EJ13: =IFERROR(VLOOKUP($R13,$A$13:$D$30,-EJ$12,FALSE),"") -> Kg | EK13: =EK49+EK85+EK121+EK157 -> 0 | EL13: =EM13/EK13*1000000 -> #DIV/0! | EM13: =EM49+EM85+EM121+EM157 -> 0 | EO13: =IFERROR(+EM13*EN13,"") -> 0 | ES13: =IFERROR(+(IF(EM13="","0",EM13))+(IF(EO13="","0",EO13))+(IF(ER13="","0",ER13)),"") -> 0 | ET13: =EC13 -> 0.46044713 | EU13: =IFERROR(+ET13*(ES13-ER13),"") -> 0 | EV13: =IFERROR(+(IF(ES13="","0",ES13))-(IF(EU13="","0",EU13)),"") -> 0 | EX13: 1 | EY13: =IFERROR(VLOOKUP($R13,$A$13:$D$30,-EY$12,FALSE),"") -> Bijih Emas | EZ13: =IFERROR(VLOOKUP($R13,$A$13:$D$30,-EZ$12,FALSE),"") -> Bijih | FA13: =IFERROR(VLOOKUP($R13,$A$13:$D$30,-FA$12,FALSE),"") -> Kg | FB13: =FB49+FB85+FB121+FB157 -> 0 | FC13: =FD13/FB13*1000000 -> #DIV/0! | FD13: =FD49+FD85+FD121+FD157 -> 0 | FF13: =IFERROR(+FD13*FE13,"") -> 0 | FJ13: =IFERROR(+(IF(FD13="","0",FD13))+(IF(FF13="","0",FF13))+(IF(FI13="","0",FI13)),"") -> 0 | FK13: =ET13 -> 0.46044713 | FL13: =IFERROR(+FK13*(FJ13-FI13),"") -> 0 | FM13: =IFERROR(+(IF(FJ13="","0",FJ13))-(IF(FL13="","0",FL13)),"") -> 0 | FO13: 1 | FP13: =IFERROR(VLOOKUP($R13,$A$13:$D$30,-FP$12,FALSE),"") -> Bijih Emas | FQ13: =IFERROR(VLOOKUP($R13,$A$13:$D$30,-FQ$12,FALSE),"") -> Bijih | FR13: =IFERROR(VLOOKUP($R13,$A$13:$D$30,-FR$12,FALSE),"") -> Kg | FS13: =FS49+FS85+FS121+FS157 -> 0 | FT13: =FU13/FS13*1000000 -> #DIV/0! | FU13: =FU49+FU85+FU121+FU157 -> 0 | FW13: =IFERROR(+FU13*FV13,"") -> 0 | GA13: =IFERROR(+(IF(FU13="","0",FU13))+(IF(FW13="","0",FW13))+(IF(FZ13="","0",FZ13)),"") -> 0 | GB13: =FK13 -> 0.46044713 | GC13: =IFERROR(+GB13*(GA13-FZ13),"") -> 0 | GD13: =IFERROR(+(IF(GA13="","0",GA13))-(IF(GC13="","0",GC13)),"") -> 0 | GF13: 1 | GG13: =IFERROR(VLOOKUP($R13,$A$13:$D$30,-GG$12,FALSE),"") -> Bijih Emas | GH13: =IFERROR(VLOOKUP($R13,$A$13:$D$30,-GH$12,FALSE),"") -> Bijih | GI13: =IFERROR(VLOOKUP($R13,$A$13:$D$30,-GI$12,FALSE),"") -> Kg | GJ13: =GJ49+GJ85+GJ121+GJ157 -> 0 | GK13: =GL13/GJ13*1000000 -> #DIV/0! | GL13: =GL49+GL85+GL121+GL157 -> 0 | GN13: =IFERROR(+GL13*GM13,"") -> 0 | GR13: =IFERROR(+(IF(GL13="","0",GL13))+(IF(GN13="","0",GN13))+(IF(GQ13="","0",GQ13)),"") -> 0 | GS13: =GB13 -> 0.46044713 | GT13: =IFERROR(+GS13*(GR13-GQ13),"") -> 0 | GU13: =IFERROR(+(IF(GR13="","0",GR13))-(IF(GT13="","0",GT13)),"") -> 0 | GW13: 1 | GX13: =IFERROR(VLOOKUP($R13,$A$13:$D$30,-GX$12,FALSE),"") -> Bijih Emas | GY13: =IFERROR(VLOOKUP($R13,$A$13:$D$30,-GY$12,FALSE),"") -> Bijih | GZ13: =IFERROR(VLOOKUP($R13,$A$13:$D$30,-GZ$12,FALSE),"") -> Kg | HA13: =HA49+HA85+HA121+HA157 -> 0 | HB13: =HC13/HA13*1000000 -> #DIV/0! | HC13: =HC49+HC85+HC121+HC157 -> 0 | HE13: =IFERROR(+HC13*HD13,"") -> 0 | HI13: =IFERROR(+(IF(HC13="","0",HC13))+(IF(HE13="","0",HE13))+(IF(HH13="","0",HH13)),"") -> 0 | HJ13: =GS13 -> 0.46044713 | HK13: =IFERROR(+HJ13*(HI13-HH13),"") -> 0 | HL13: =IFERROR(+(IF(HI13="","0",HI13))-(IF(HK13="","0",HK13)),"") -> 0 | HN13: 1 | HO13: =IFERROR(VLOOKUP($R13,$A$13:$D$30,-HO$12,FALSE),"") -> Bijih Emas | HP13: =IFERROR(VLOOKUP($R13,$A$13:$D$30,-HP$12,FALSE),"") -> Bijih | HQ13: =IFERROR(VLOOKUP($R13,$A$13:$D$30,-HQ$12,FALSE),"") -> Kg | HR13: =HR49+HR85+HR121+HR157 -> 0 | HS13: =HT13/HR13*1000000 -> #DIV/0! | HT13: =HT49+HT85+HT121+HT157 -> 0 | HV13: =IFERROR(+HT13*HU13,"") -> 0 | HZ13: =IFERROR(+(IF(HT13="","0",HT13))+(IF(HV13="","0",HV13))+(IF(HY13="","0",HY13)),"") -> 0 | IA13: =HJ13 -> 0.46044713 | IB13: =IFERROR(+IA13*(HZ13-HY13),"") -> 0 | IC13: =IFERROR(+(IF(HZ13="","0",HZ13))-(IF(IB13="","0",IB13)),"") -> 0 | IE13: 1 | IF13: =IFERROR(VLOOKUP($R13,$A$13:$D$30,-IF$12,FALSE),"") -> Bijih Emas | IG13: =IFERROR(VLOOKUP($R13,$A$13:$D$30,-IG$12,FALSE),"") -> Bijih | IH13: =IFERROR(VLOOKUP($R13,$A$13:$D$30,-IH$12,FALSE),"") -> Kg | II13: =II49+II85+II121+II157 -> 0 | IJ13: =IK13/II13*1000000 -> #DIV/0! | IK13: =IK49+IK85+IK121+IK157 -> 0 | IM13: =IFERROR(+IK13*IL13,"") -> 0 | IQ13: =IFERROR(+(IF(IK13="","0",IK13))+(IF(IM13="","0",IM13))+(IF(IP13="","0",IP13)),"") -> 0 | IR13: =IA13 -> 0.46044713 | IS13: =IFERROR(+IR13*(IQ13-IP13),"") -> 0 | IT13: =IFERROR(+(IF(IQ13="","0",IQ13))-(IF(IS13="","0",IS13)),"") -> 0 | IV13: 1 | IW13: =IFERROR(VLOOKUP($R13,$A$13:$D$30,-IW$12,FALSE),"") -> Bijih Emas | IX13: =IFERROR(VLOOKUP($R13,$A$13:$D$30,-IX$12,FALSE),"") -> Bijih | IY13: =IFERROR(VLOOKUP($R13,$A$13:$D$30,-IY$12,FALSE),"") -> Kg | IZ13: =IZ49+IZ85+IZ121+IZ157 -> 0 | JA13: =JB13/IZ13*1000000 -> #DIV/0! | JB13: =JB49+JB85+JB121+JB157 -> 0 | JD13: =IFERROR(+JB13*JC13,"") -> 0 | JH13: =IFERROR(+(IF(JB13="","0",JB13))+(IF(JD13="","0",JD13))+(IF(JG13="","0",JG13)),"") -> 0 | JI13: =IR13 -> 0.46044713 | JJ13: =IFERROR(+JI13*(JH13-JG13),"") -> 0 | JK13: =IFERROR(+(IF(JH13="","0",JH13))-(IF(JJ13="","0",JJ13)),"") -> 0 | JM13: 1 | JN13: =IFERROR(VLOOKUP($R13,$A$13:$D$30,-JN$12,FALSE),"") -> Bijih Emas | JO13: =IFERROR(VLOOKUP($R13,$A$13:$D$30,-JO$12,FALSE),"") -> Bijih | JP13: =IFERROR(VLOOKUP($R13,$A$13:$D$30,-JP$12,FALSE),"") -> Kg | JQ13: =JQ49+JQ85+JQ121+JQ157 -> 0 | JR13: =JS13/JQ13*1000000 -> #DIV/0! | JS13: =JS49+JS85+JS121+JS157 -> 0 | JU13: =IFERROR(+JS13*JT13,"") -> 0 | JY13: =IFERROR(+(IF(JS13="","0",JS13))+(IF(JU13="","0",JU13))+(IF(JX13="","0",JX13)),"") -> 0 | JZ13: =JI13 -> 0.46044713 | KA13: =IFERROR(+JZ13*(JY13-JX13),"") -> 0 | KB13: =IFERROR(+(IF(JY13="","0",JY13))-(IF(KA13="","0",KA13)),"") -> 0 | KD13: 1 | KE13: =IFERROR(VLOOKUP($R13,$A$13:$D$30,-KE$12,FALSE),"") -> Bijih Emas | KF13: =IFERROR(VLOOKUP($R13,$A$13:$D$30,-KF$12,FALSE),"") -> Bijih | KG13: =IFERROR(VLOOKUP($R13,$A$13:$D$30,-KG$12,FALSE),"") -> Kg | KH13: =KH49+KH85+KH121+KH157 -> 0 | KI13: =KJ13/KH13*1000000 -> #DIV/0! | KJ13: =KJ49+KJ85+KJ121+KJ157 -> 0 | KL13: =IFERROR(+KJ13*KK13,"") -> 0 | KP13: =IFERROR(+(IF(KJ13="","0",KJ13))+(IF(KL13="","0",KL13))+(IF(KO13="","0",KO13)),"") -> 0 | KQ13: =JZ13 -> 0.46044713 | KR13: =IFERROR(+KQ13*(KP13-KO13),"") -> 0 | KS13: =IFERROR(+(IF(KP13="","0",KP13))-(IF(KR13="","0",KR13)),"") -> 0
A14: =A13+1 -> 2 | B14: =IFERROR(VLOOKUP($R14,ADHK!$A$13:$D$30,-B$12,FALSE),"") -> Bijih Perak | C14: =IFERROR(VLOOKUP($R14,ADHK!$A$13:$D$30,-C$12,FALSE),"") -> Bijih | D14: =IFERROR(VLOOKUP($R14,ADHK!$A$13:$D$30,-D$12,FALSE),"") -> Kg | E14: =E50+E86+E122+E158 -> 0 | F14: =G14/E14*1000000 -> #DIV/0! | G14: =G50+G86+G122+G158 -> 0 | I14: =IFERROR(+G14*H14,"") -> 0 | M14: =IFERROR(+(IF(G14="","0",G14))+(IF(I14="","0",I14))+(IF(L14="","0",L14)),"") -> 0 | N14: =ADHK!N14 -> 0.46044713 | O14: =IFERROR(+N14*(M14-L14),"") -> 0 | P14: =IFERROR(+(IF(M14="","0",M14))-(IF(O14="","0",O14)),"") -> 0 | R14: =R13+1 -> 2 | S14: =IFERROR(VLOOKUP($R14,$A$13:$D$30,-S$12,FALSE),"") -> Bijih Perak | T14: =IFERROR(VLOOKUP($R14,$A$13:$D$30,-T$12,FALSE),"") -> Bijih | U14: =IFERROR(VLOOKUP($R14,$A$13:$D$30,-U$12,FALSE),"") -> Kg | V14: =V50+V86+V122+V158 -> 0 | W14: =X14/V14*1000000 -> #DIV/0! | X14: =X50+X86+X122+X158 -> 0 | Z14: =IFERROR(+X14*Y14,"") -> 0 | AD14: =IFERROR(+(IF(X14="","0",X14))+(IF(Z14="","0",Z14))+(IF(AC14="","0",AC14)),"") -> 0 | AE14: =N14 -> 0.46044713 | AF14: =IFERROR(+AE14*(AD14-AC14),"") -> 0 | AG14: =IFERROR(+(IF(AD14="","0",AD14))-(IF(AF14="","0",AF14)),"") -> 0 | AI14: =AI13+1 -> 2 | AJ14: =IFERROR(VLOOKUP($R14,$A$13:$D$30,-AJ$12,FALSE),"") -> Bijih Perak | AK14: =IFERROR(VLOOKUP($R14,$A$13:$D$30,-AK$12,FALSE),"") -> Bijih | AL14: =IFERROR(VLOOKUP($R14,$A$13:$D$30,-AL$12,FALSE),"") -> Kg | AM14: =AM50+AM86+AM122+AM158 -> 0 | AN14: =AO14/AM14*1000000 -> #DIV/0! | AO14: =AO50+AO86+AO122+AO158 -> 0 | AQ14: =IFERROR(+AO14*AP14,"") -> 0 | AU14: =IFERROR(+(IF(AO14="","0",AO14))+(IF(AQ14="","0",AQ14))+(IF(AT14="","0",AT14)),"") -> 0 | AV14: =AE14 -> 0.46044713 | AW14: =IFERROR(+AV14*(AU14-AT14),"") -> 0 | AX14: =IFERROR(+(IF(AU14="","0",AU14))-(IF(AW14="","0",AW14)),"") -> 0 | AZ14: =AZ13+1 -> 2 | BA14: =IFERROR(VLOOKUP($R14,$A$13:$D$30,-BA$12,FALSE),"") -> Bijih Perak | BB14: =IFERROR(VLOOKUP($R14,$A$13:$D$30,-BB$12,FALSE),"") -> Bijih | BC14: =IFERROR(VLOOKUP($R14,$A$13:$D$30,-BC$12,FALSE),"") -> Kg | BD14: =BD50+BD86+BD122+BD158 -> 0 | BE14: =BF14/BD14*1000000 -> #DIV/0! | BF14: =BF50+BF86+BF122+BF158 -> 0 | BH14: =IFERROR(+BF14*BG14,"") -> 0 | BL14: =IFERROR(+(IF(BF14="","0",BF14))+(IF(BH14="","0",BH14))+(IF(BK14="","0",BK14)),"") -> 0 | BM14: =AV14 -> 0.46044713 | BN14: =IFERROR(+BM14*(BL14-BK14),"") -> 0 | BO14: =IFERROR(+(IF(BL14="","0",BL14))-(IF(BN14="","0",BN14)),"") -> 0 | BQ14: =BQ13+1 -> 2 | BR14: =IFERROR(VLOOKUP($R14,$A$13:$D$30,-BR$12,FALSE),"") -> Bijih Perak | BS14: =IFERROR(VLOOKUP($R14,$A$13:$D$30,-BS$12,FALSE),"") -> Bijih | BT14: =IFERROR(VLOOKUP($R14,$A$13:$D$30,-BT$12,FALSE),"") -> Kg | BU14: =BU50+BU86+BU122+BU158 -> 0 | BV14: =BW14/BU14*1000000 -> #DIV/0! | BW14: =BW50+BW86+BW122+BW158 -> 0 | BY14: =IFERROR(+BW14*BX14,"") -> 0 | CC14: =IFERROR(+(IF(BW14="","0",BW14))+(IF(BY14="","0",BY14))+(IF(CB14="","0",CB14)),"") -> 0 | CD14: =BM14 -> 0.46044713 | CE14: =IFERROR(+CD14*(CC14-CB14),"") -> 0 | CF14: =IFERROR(+(IF(CC14="","0",CC14))-(IF(CE14="","0",CE14)),"") -> 0 | CH14: =CH13+1 -> 2 | CI14: =IFERROR(VLOOKUP($R14,$A$13:$D$30,-CI$12,FALSE),"") -> Bijih Perak | CJ14: =IFERROR(VLOOKUP($R14,$A$13:$D$30,-CJ$12,FALSE),"") -> Bijih | CK14: =IFERROR(VLOOKUP($R14,$A$13:$D$30,-CK$12,FALSE),"") -> Kg | CL14: =CL50+CL86+CL122+CL158 -> 0 | CM14: =CN14/CL14*1000000 -> #DIV/0! | CN14: =CN50+CN86+CN122+CN158 -> 0 | CP14: =IFERROR(+CN14*CO14,"") -> 0 | CT14: =IFERROR(+(IF(CN14="","0",CN14))+(IF(CP14="","0",CP14))+(IF(CS14="","0",CS14)),"") -> 0 | CU14: =CD14 -> 0.46044713 | CV14: =IFERROR(+CU14*(CT14-CS14),"") -> 0 | CW14: =IFERROR(+(IF(CT14="","0",CT14))-(IF(CV14="","0",CV14)),"") -> 0 | CY14: =CY13+1 -> 2 | CZ14: =IFERROR(VLOOKUP($R14,$A$13:$D$30,-CZ$12,FALSE),"") -> Bijih Perak | DA14: =IFERROR(VLOOKUP($R14,$A$13:$D$30,-DA$12,FALSE),"") -> Bijih | DB14: =IFERROR(VLOOKUP($R14,$A$13:$D$30,-DB$12,FALSE),"") -> Kg | DC14: =DC50+DC86+DC122+DC158 -> 0 | DD14: =DE14/DC14*1000000 -> #DIV/0! | DE14: =DE50+DE86+DE122+DE158 -> 0 | DG14: =IFERROR(+DE14*DF14,"") -> 0 | DK14: =IFERROR(+(IF(DE14="","0",DE14))+(IF(DG14="","0",DG14))+(IF(DJ14="","0",DJ14)),"") -> 0 | DL14: =CU14 -> 0.46044713 | DM14: =IFERROR(+DL14*(DK14-DJ14),"") -> 0 | DN14: =IFERROR(+(IF(DK14="","0",DK14))-(IF(DM14="","0",DM14)),"") -> 0 | DP14: =DP13+1 -> 2 | DQ14: =IFERROR(VLOOKUP($R14,$A$13:$D$30,-DQ$12,FALSE),"") -> Bijih Perak | DR14: =IFERROR(VLOOKUP($R14,$A$13:$D$30,-DR$12,FALSE),"") -> Bijih | DS14: =IFERROR(VLOOKUP($R14,$A$13:$D$30,-DS$12,FALSE),"") -> Kg | DT14: =DT50+DT86+DT122+DT158 -> 0 | DU14: =DV14/DT14*1000000 -> #DIV/0! | DV14: =DV50+DV86+DV122+DV158 -> 0 | DX14: =IFERROR(+DV14*DW14,"") -> 0 | EB14: =IFERROR(+(IF(DV14="","0",DV14))+(IF(DX14="","0",DX14))+(IF(EA14="","0",EA14)),"") -> 0 | EC14: =DL14 -> 0.46044713 | ED14: =IFERROR(+EC14*(EB14-EA14),"") -> 0 | EE14: =IFERROR(+(IF(EB14="","0",EB14))-(IF(ED14="","0",ED14)),"") -> 0 | EG14: =EG13+1 -> 2 | EH14: =IFERROR(VLOOKUP($R14,$A$13:$D$30,-EH$12,FALSE),"") -> Bijih Perak | EI14: =IFERROR(VLOOKUP($R14,$A$13:$D$30,-EI$12,FALSE),"") -> Bijih | EJ14: =IFERROR(VLOOKUP($R14,$A$13:$D$30,-EJ$12,FALSE),"") -> Kg | EK14: =EK50+EK86+EK122+EK158 -> 0 | EL14: =EM14/EK14*1000000 -> #DIV/0! | EM14: =EM50+EM86+EM122+EM158 -> 0 | EO14: =IFERROR(+EM14*EN14,"") -> 0 | ES14: =IFERROR(+(IF(EM14="","0",EM14))+(IF(EO14="","0",EO14))+(IF(ER14="","0",ER14)),"") -> 0 | ET14: =EC14 -> 0.46044713 | EU14: =IFERROR(+ET14*(ES14-ER14),"") -> 0 | EV14: =IFERROR(+(IF(ES14="","0",ES14))-(IF(EU14="","0",EU14)),"") -> 0 | EX14: =EX13+1 -> 2 | EY14: =IFERROR(VLOOKUP($R14,$A$13:$D$30,-EY$12,FALSE),"") -> Bijih Perak | EZ14: =IFERROR(VLOOKUP($R14,$A$13:$D$30,-EZ$12,FALSE),"") -> Bijih | FA14: =IFERROR(VLOOKUP($R14,$A$13:$D$30,-FA$12,FALSE),"") -> Kg | FB14: =FB50+FB86+FB122+FB158 -> 0 | FC14: =FD14/FB14*1000000 -> #DIV/0! | FD14: =FD50+FD86+FD122+FD158 -> 0 | FF14: =IFERROR(+FD14*FE14,"") -> 0 | FJ14: =IFERROR(+(IF(FD14="","0",FD14))+(IF(FF14="","0",FF14))+(IF(FI14="","0",FI14)),"") -> 0 | FK14: =ET14 -> 0.46044713 | FL14: =IFERROR(+FK14*(FJ14-FI14),"") -> 0 | FM14: =IFERROR(+(IF(FJ14="","0",FJ14))-(IF(FL14="","0",FL14)),"") -> 0 | FO14: =FO13+1 -> 2 | FP14: =IFERROR(VLOOKUP($R14,$A$13:$D$30,-FP$12,FALSE),"") -> Bijih Perak | FQ14: =IFERROR(VLOOKUP($R14,$A$13:$D$30,-FQ$12,FALSE),"") -> Bijih | FR14: =IFERROR(VLOOKUP($R14,$A$13:$D$30,-FR$12,FALSE),"") -> Kg | FS14: =FS50+FS86+FS122+FS158 -> 0 | FT14: =FU14/FS14*1000000 -> #DIV/0! | FU14: =FU50+FU86+FU122+FU158 -> 0 | FW14: =IFERROR(+FU14*FV14,"") -> 0 | GA14: =IFERROR(+(IF(FU14="","0",FU14))+(IF(FW14="","0",FW14))+(IF(FZ14="","0",FZ14)),"") -> 0 | GB14: =FK14 -> 0.46044713 | GC14: =IFERROR(+GB14*(GA14-FZ14),"") -> 0 | GD14: =IFERROR(+(IF(GA14="","0",GA14))-(IF(GC14="","0",GC14)),"") -> 0 | GF14: =GF13+1 -> 2 | GG14: =IFERROR(VLOOKUP($R14,$A$13:$D$30,-GG$12,FALSE),"") -> Bijih Perak | GH14: =IFERROR(VLOOKUP($R14,$A$13:$D$30,-GH$12,FALSE),"") -> Bijih | GI14: =IFERROR(VLOOKUP($R14,$A$13:$D$30,-GI$12,FALSE),"") -> Kg | GJ14: =GJ50+GJ86+GJ122+GJ158 -> 0 | GK14: =GL14/GJ14*1000000 -> #DIV/0! | GL14: =GL50+GL86+GL122+GL158 -> 0 | GN14: =IFERROR(+GL14*GM14,"") -> 0 | GR14: =IFERROR(+(IF(GL14="","0",GL14))+(IF(GN14="","0",GN14))+(IF(GQ14="","0",GQ14)),"") -> 0 | GS14: =GB14 -> 0.46044713 | GT14: =IFERROR(+GS14*(GR14-GQ14),"") -> 0 | GU14: =IFERROR(+(IF(GR14="","0",GR14))-(IF(GT14="","0",GT14)),"") -> 0 | GW14: =GW13+1 -> 2 | GX14: =IFERROR(VLOOKUP($R14,$A$13:$D$30,-GX$12,FALSE),"") -> Bijih Perak | GY14: =IFERROR(VLOOKUP($R14,$A$13:$D$30,-GY$12,FALSE),"") -> Bijih | GZ14: =IFERROR(VLOOKUP($R14,$A$13:$D$30,-GZ$12,FALSE),"") -> Kg | HA14: =HA50+HA86+HA122+HA158 -> 0 | HB14: =HC14/HA14*1000000 -> #DIV/0! | HC14: =HC50+HC86+HC122+HC158 -> 0 | HE14: =IFERROR(+HC14*HD14,"") -> 0 | HI14: =IFERROR(+(IF(HC14="","0",HC14))+(IF(HE14="","0",HE14))+(IF(HH14="","0",HH14)),"") -> 0 | HJ14: =GS14 -> 0.46044713 | HK14: =IFERROR(+HJ14*(HI14-HH14),"") -> 0 | HL14: =IFERROR(+(IF(HI14="","0",HI14))-(IF(HK14="","0",HK14)),"") -> 0 | HN14: =HN13+1 -> 2 | HO14: =IFERROR(VLOOKUP($R14,$A$13:$D$30,-HO$12,FALSE),"") -> Bijih Perak | HP14: =IFERROR(VLOOKUP($R14,$A$13:$D$30,-HP$12,FALSE),"") -> Bijih | HQ14: =IFERROR(VLOOKUP($R14,$A$13:$D$30,-HQ$12,FALSE),"") -> Kg | HR14: =HR50+HR86+HR122+HR158 -> 0 | HS14: =HT14/HR14*1000000 -> #DIV/0! | HT14: =HT50+HT86+HT122+HT158 -> 0 | HV14: =IFERROR(+HT14*HU14,"") -> 0 | HZ14: =IFERROR(+(IF(HT14="","0",HT14))+(IF(HV14="","0",HV14))+(IF(HY14="","0",HY14)),"") -> 0 | IA14: =HJ14 -> 0.46044713 | IB14: =IFERROR(+IA14*(HZ14-HY14),"") -> 0 | IC14: =IFERROR(+(IF(HZ14="","0",HZ14))-(IF(IB14="","0",IB14)),"") -> 0 | IE14: =IE13+1 -> 2 | IF14: =IFERROR(VLOOKUP($R14,$A$13:$D$30,-IF$12,FALSE),"") -> Bijih Perak | IG14: =IFERROR(VLOOKUP($R14,$A$13:$D$30,-IG$12,FALSE),"") -> Bijih | IH14: =IFERROR(VLOOKUP($R14,$A$13:$D$30,-IH$12,FALSE),"") -> Kg | II14: =II50+II86+II122+II158 -> 0 | IJ14: =IK14/II14*1000000 -> #DIV/0! | IK14: =IK50+IK86+IK122+IK158 -> 0 | IM14: =IFERROR(+IK14*IL14,"") -> 0 | IQ14: =IFERROR(+(IF(IK14="","0",IK14))+(IF(IM14="","0",IM14))+(IF(IP14="","0",IP14)),"") -> 0 | IR14: =IA14 -> 0.46044713 | IS14: =IFERROR(+IR14*(IQ14-IP14),"") -> 0 | IT14: =IFERROR(+(IF(IQ14="","0",IQ14))-(IF(IS14="","0",IS14)),"") -> 0 | IV14: =IV13+1 -> 2 | IW14: =IFERROR(VLOOKUP($R14,$A$13:$D$30,-IW$12,FALSE),"") -> Bijih Perak | IX14: =IFERROR(VLOOKUP($R14,$A$13:$D$30,-IX$12,FALSE),"") -> Bijih | IY14: =IFERROR(VLOOKUP($R14,$A$13:$D$30,-IY$12,FALSE),"") -> Kg | IZ14: =IZ50+IZ86+IZ122+IZ158 -> 0 | JA14: =JB14/IZ14*1000000 -> #DIV/0! | JB14: =JB50+JB86+JB122+JB158 -> 0 | JD14: =IFERROR(+JB14*JC14,"") -> 0 | JH14: =IFERROR(+(IF(JB14="","0",JB14))+(IF(JD14="","0",JD14))+(IF(JG14="","0",JG14)),"") -> 0 | JI14: =IR14 -> 0.46044713 | JJ14: =IFERROR(+JI14*(JH14-JG14),"") -> 0 | JK14: =IFERROR(+(IF(JH14="","0",JH14))-(IF(JJ14="","0",JJ14)),"") -> 0 | JM14: =JM13+1 -> 2 | JN14: =IFERROR(VLOOKUP($R14,$A$13:$D$30,-JN$12,FALSE),"") -> Bijih Perak | JO14: =IFERROR(VLOOKUP($R14,$A$13:$D$30,-JO$12,FALSE),"") -> Bijih | JP14: =IFERROR(VLOOKUP($R14,$A$13:$D$30,-JP$12,FALSE),"") -> Kg | JQ14: =JQ50+JQ86+JQ122+JQ158 -> 0 | JR14: =JS14/JQ14*1000000 -> #DIV/0! | JS14: =JS50+JS86+JS122+JS158 -> 0 | JU14: =IFERROR(+JS14*JT14,"") -> 0 | JY14: =IFERROR(+(IF(JS14="","0",JS14))+(IF(JU14="","0",JU14))+(IF(JX14="","0",JX14)),"") -> 0 | JZ14: =JI14 -> 0.46044713 | KA14: =IFERROR(+JZ14*(JY14-JX14),"") -> 0 | KB14: =IFERROR(+(IF(JY14="","0",JY14))-(IF(KA14="","0",KA14)),"") -> 0 | KD14: =KD13+1 -> 2 | KE14: =IFERROR(VLOOKUP($R14,$A$13:$D$30,-KE$12,FALSE),"") -> Bijih Perak | KF14: =IFERROR(VLOOKUP($R14,$A$13:$D$30,-KF$12,FALSE),"") -> Bijih | KG14: =IFERROR(VLOOKUP($R14,$A$13:$D$30,-KG$12,FALSE),"") -> Kg | KH14: =KH50+KH86+KH122+KH158 -> 0 | KI14: =KJ14/KH14*1000000 -> #DIV/0! | KJ14: =KJ50+KJ86+KJ122+KJ158 -> 0 | KL14: =IFERROR(+KJ14*KK14,"") -> 0 | KP14: =IFERROR(+(IF(KJ14="","0",KJ14))+(IF(KL14="","0",KL14))+(IF(KO14="","0",KO14)),"") -> 0 | KQ14: =JZ14 -> 0.46044713 | KR14: =IFERROR(+KQ14*(KP14-KO14),"") -> 0 | KS14: =IFERROR(+(IF(KP14="","0",KP14))-(IF(KR14="","0",KR14)),"") -> 0
